Workbook
Name LST_MUSTERI_ADI: MUSTERILER!$C$7:$C$106
Name LST_HESAP: HESAPLAR!$B$7:$B$16
Name LST_KATEGORI: SISTEM!$K$8:$K$37
Name CARI_BAKIYE: MUSTERI_360!$I$7:$I$106
Name GECIKMIS_29: MUSTERI_360!$M$7:$M$106
Name NAKIT_POZISYON: HESAPLAR!$K$18
Name SISTEM_SONUC: SISTEM!$F$23:$F$50

Sheet PANO
A1: NECATİBEY OFİS YÖNETİM SİSTEMİ │ YÖNETİM PANOSU
A2: ="Bu ekran karar, alarm ve seçim ekranıdır │ SİSTEM DURUMU: "&IF(COUNTIF(SISTEM!$F$23:$F$50,"KALDI")=0,"KULLANIMA UYGUN","KONTROL GEREKİR")&" │ "&COUNTIF(SISTEM!$F$23:$F$50,"GEÇTİ")&" / "&COUNTIF(SISTEM!$F$23:$F$50,"<>BİLGİ")&" kontrol geçti"
B4: =TEXT(TODAY(),"dd.mm.yyyy")&" │ "&SISTEM!$C$7
B5: MENÜ | D5: AKTİF MÜŞTERİ | G5: TOPLAM CARİ ALACAK | J5: 29+ GÜN GECİKMİŞ | M5: KASA + BANKA
B6: =HYPERLINK("#PANO!A1"," PANO") | D6: =COUNTIF(MUSTERILER!$D$7:$D$106,"Aktif") | G6: =SUM(MUSTERI_360!$I$7:$I$106) | J6: =SUM(MUSTERI_360!$M$7:$M$106) | M6: =HESAPLAR!$K$18
B7: =HYPERLINK("#MUSTERILER!A1"," Müşteriler") | D7: =COUNTA(MUSTERILER!$B$7:$B$106)&" kayıtlı müşteri" | G7: =COUNTIF(MUSTERI_360!$I$7:$I$106,">0")&" müşteride açık bakiye" | J7: =TEXT(IFERROR(SUM(MUSTERI_360!$M$7:$M$106)/SUM(MUSTERI_360!$I$7:$I$106),0),"0,0%")&" toplam alacağın payı" | M7: =COUNTIF(HESAPLAR!$D$7:$D$16,"Aktif")&" aktif hesap"
B8: =HYPERLINK("#UCRETLER!A1"," Haftalık Ücretler")
B9: =HYPERLINK("#TAHSILAT!A1"," Tahsilat") | D9: BU AY NAKİT KÂR | G9: BU AY TAHSİLAT | J9: HAFTALIK TAHAKKUK | M9: GECİKMİŞ İŞ
B10: =HYPERLINK("#GELIR_GIDER!A1"," Gelir / Gider") | D10: =SUMIFS(AY_SONU!$I$7:$I$42,AY_SONU!$B$7:$B$42,">="&EOMONTH(TODAY(),-1)+1,AY_SONU!$B$7:$B$42,"<="&EOMONTH(TODAY(),0)) | G10: =SUMIFS(AY_SONU!$D$7:$D$42,AY_SONU!$B$7:$B$42,">="&EOMONTH(TODAY(),-1)+1,AY_SONU!$B$7:$B$42,"<="&EOMONTH(TODAY(),0)) | J10: =SUMIFS(UCRETLER!$F$7:$F$406,UCRETLER!$G$7:$G$406,"Aktif") | M10: =COUNTIF(AKTIVITE!$Q$7:$Q$1006,"GECİKMİŞ")
B11: =HYPERLINK("#VIRMAN!A1"," Virman") | D11: =TEXT(TODAY(),"mmmm yyyy")&" dönemi" | G11: ="Ay tahakkuku "&TEXT(SUMIFS(AY_SONU!$C$7:$C$42,AY_SONU!$B$7:$B$42,">="&EOMONTH(TODAY(),-1)+1,AY_SONU!$B$7:$B$42,"<="&EOMONTH(TODAY(),0)),"#,##0")&" ₺" | J11: =COUNTIFS(UCRETLER!$G$7:$G$406,"Aktif")&" aktif ücret dönemi" | M11: =COUNTIF(AKTIVITE!$Q$7:$Q$1006,"BUGÜN")&" iş bugün teslim"
B12: =HYPERLINK("#AKTIVITE!A1"," Aktivite")
B13: =HYPERLINK("#MUSTERI_360!A1"," Müşteri 360") | D13: AYLIK NAKİT KÂR EĞRİSİ | H13: TAHAKKUK ↔ TAHSİLAT | L13: ALACAK YAŞLANDIRMASI
B14: =HYPERLINK("#HESAPLAR!A1"," Hesaplar")
B15: =HYPERLINK("#AY_SONU!A1"," Ay Sonu")
B16: =HYPERLINK("#SISTEM!A1"," Sistem & Kontrol")
B17: =HYPERLINK("#BASLANGIC!A1"," Başlangıç")
D23: MÜŞTERİ HIZLI KARTI | J23: BUGÜNÜN UYARILARI
D24: Müşteri seçin | F24: ANKARA HAVANA LTD.ŞTİ. | J24: Gecikmiş müşteri işi | O24: =COUNTIF(AKTIVITE!$Q$7:$Q$1006,"GECİKMİŞ")
D25: Müşteri No | F25: =IF($F$24="","",IFERROR(INDEX(MUSTERI_360!$C$7:$C$106,MATCH($F$24,MUSTERI_360!$C$7:$C$106,0)),"")) | J25: Bugün teslim edilecek iş | O25: =COUNTIF(AKTIVITE!$Q$7:$Q$1006,"BUGÜN")
D26: Borç Durumu | F26: =IF($F$24="","",IFERROR(INDEX(MUSTERI_360!$P$7:$P$106,MATCH($F$24,MUSTERI_360!$C$7:$C$106,0)),"")) | J26: 7 gün içindeki işler | O26: =COUNTIF(AKTIVITE!$Q$7:$Q$1006,"7 GÜN İÇİNDE")
D27: Haftalık Ücret | F27: =IF($F$24="","",IFERROR(INDEX(MUSTERI_360!$D$7:$D$106,MATCH($F$24,MUSTERI_360!$C$7:$C$106,0)),"")) | J27: Gecikmiş müşteri teması | O27: =COUNTIFS(AKTIVITE!$C$7:$C$1006,"Görüşme",AKTIVITE!$Q$7:$Q$1006,"GECİKMİŞ")
D28: Devir Alacağı | F28: =IF($F$24="","",IFERROR(INDEX(MUSTERI_360!$E$7:$E$106,MATCH($F$24,MUSTERI_360!$C$7:$C$106,0)),"")) | J28: Kritik borç durumundaki müşteri | O28: =COUNTIF(MUSTERI_360!$P$7:$P$106,"KRİTİK")
D29: Yeni Tahakkuk | F29: =IF($F$24="","",IFERROR(INDEX(MUSTERI_360!$F$7:$F$106,MATCH($F$24,MUSTERI_360!$C$7:$C$106,0)),"")) | J29: Bilgisi eksik müşteri kaydı | O29: =COUNTIF(MUSTERILER!$P$7:$P$106,"EKSİK")
D30: Toplam Borç | F30: =IF($F$24="","",IFERROR(INDEX(MUSTERI_360!$G$7:$G$106,MATCH($F$24,MUSTERI_360!$C$7:$C$106,0)),"")) | J30: Aktif ama ücretsiz müşteri | O30: =COUNTIFS(MUSTERILER!$D$7:$D$106,"Aktif",MUSTERILER!$O$7:$O$106,"HAYIR")
D31: Toplam Tahsilat | F31: =IF($F$24="","",IFERROR(INDEX(MUSTERI_360!$H$7:$H$106,MATCH($F$24,MUSTERI_360!$C$7:$C$106,0)),"")) | J31: Eksik tahsilat kaydı | O31: =COUNTIF(TAHSILAT!$M$7:$M$1506,"EKSİK")
D32: Cari Bakiye | F32: =IF($F$24="","",IFERROR(INDEX(MUSTERI_360!$I$7:$I$106,MATCH($F$24,MUSTERI_360!$C$7:$C$106,0)),"")) | J32: Eksik gelir/gider kaydı | O32: =COUNTIF(GELIR_GIDER!$M$7:$M$1206,"EKSİK")
D33: 0–7 Gün | F33: =IF($F$24="","",IFERROR(INDEX(MUSTERI_360!$J$7:$J$106,MATCH($F$24,MUSTERI_360!$C$7:$C$106,0)),"")) | J33: Sistem kontrolünde KALDI satırı | O33: =COUNTIF(SISTEM!$F$23:$F$50,"KALDI")
D34: 8–14 Gün | F34: =IF($F$24="","",IFERROR(INDEX(MUSTERI_360!$K$7:$K$106,MATCH($F$24,MUSTERI_360!$C$7:$C$106,0)),""))
D35: 15–28 Gün | F35: =IF($F$24="","",IFERROR(INDEX(MUSTERI_360!$L$7:$L$106,MATCH($F$24,MUSTERI_360!$C$7:$C$106,0)),""))
D36: 29+ Gün | F36: =IF($F$24="","",IFERROR(INDEX(MUSTERI_360!$M$7:$M$106,MATCH($F$24,MUSTERI_360!$C$7:$C$106,0)),""))
D37: Tahsilat Oranı | F37: =IF($F$24="","",IFERROR(INDEX(MUSTERI_360!$N$7:$N$106,MATCH($F$24,MUSTERI_360!$C$7:$C$106,0)),""))
D38: Son Tahsilat | F38: =IF($F$24="","",IFERROR(INDEX(MUSTERI_360!$O$7:$O$106,MATCH($F$24,MUSTERI_360!$C$7:$C$106,0)),""))
D39: Önerilen İşlem | F39: =IF($F$24="","",IFERROR(INDEX(MUSTERI_360!$Q$7:$Q$106,MATCH($F$24,MUSTERI_360!$C$7:$C$106,0)),""))

Sheet BASLANGIC
A1: NECATİBEY OFİS YÖNETİM SİSTEMİ │ BAŞLANGIÇ │ AMAÇ, RENK KİLAVUZU VE KULLANIM
A2: Bu ekran sistemin kimlik kartıdır │ İlk kez açıyorsanız baştan sona okuyun
B4: =HYPERLINK("#PANO!A1","← PANO")
B5: NECATİBEY MUHASEBE OFİSİ │ OFİS YÖNETİM SİSTEMİ
B6: Enterprise Exclusive sürüm │ Haftalık ücretle çalışan muhasebe ofisleri için müşteri, tahakkuk, tahsilat, cari, kasa ve ortak payı yönetimi
B8: 1. BU EXCEL NE İÇİN ÜRETİLDİ?
B9: Başlık | D9: Açıklama
B10: Amaç | D10: Haftalık ücretle çalışan bir muhasebe ofisinin tüm ticari işleyişini tek dosyada, tek veri girişiyle ve kendi kendini denetleyen bir yapıyla yönetmek.
B11: Kimin için? | D11: Müşterilerinden haftalık / dönemsel ücret tahsil eden, ortaklı veya tek kişilik muhasebe ve mali müşavirlik ofisleri için.
B12: Neyi çözer? | D12: “Kim ne kadar borçlu, bu borç kaç günlük, kasada ne kadar param var, bu ay gerçekten ne kazandım ve ortaklara ne dağıtabilirim” sorularını tahmine dayanmadan cevaplar.
B13: Nasıl çalışır? | D13: Siz yalnızca sarı hücrelere gerçek işlemi girersiniz. Cari hesap, yaşlandırma, kasa bakiyesi, aylık kapanış ve ortak payları otomatik olarak hesaplanır.
B14: Neden güvenilir? | D14: Sistem her açılışta 28 otomatik kontrol çalıştırır. Bir tanesi bile KALDI verirse ay kapatılamaz; hata sessizce geçmez.
B15: Tahakkuk esası | D15: Haftalık ücret her Cumartesi otomatik tahakkuk eder. Ücret değiştiğinde eski dönem kapatılır, yeni dönem açılır; geçmiş hesaplar asla bozulmaz.
B16: Kâr esası | D16: Dağıtım yalnız tahsil edilmiş nakit kârdan yapılır. Tahsil edilmemiş müşteri alacağı kâr sayılmaz ve ortaklara dağıtılmaz.
B18: 2. RENK KİLAVUZU │ EKRANDAKİ RENKLER NE ANLAMA GELİR?
B19: Renk | C19: Ne görünür | E19: Anlamı | G19: Ne yapmanız gerekir
B20: ■ | C20: SARI ZEMİN / MAVİ YAZI | E20: Veri giriş alanı | G20: Bu hücrelere siz yazarsınız. Sistemin tek besleme kaynağı bu alanlardır.
B21: ■ | C21: BEYAZ ZEMİN / SİYAH YAZI | E21: Otomatik hesaplanan alan | G21: Sistem hesaplar, kilitlidir. Elle değiştirilemez; değiştirmeye çalışırsanız uyarı alırsınız.
B22: ■ | C22: LACİVERT BANT | E22: Başlık ve tablo başlığı | G22: Ekran adı ve sütun başlıkları. Altındaki altın çizgi tablonun başladığı yeri gösterir.
B23: ■ | C23: AÇIK MAVİ SATIR | E23: TOPLAM satırı | G23: Tablo başlığının hemen üstünde durur ve aşağı kaydırsanız da ekranda kalır.
B24: ■ | C24: YEŞİL ROZET | E24: UYGUN / GEÇTİ / TEMİZ | G24: Kayıt eksiksiz, kontrol başarılı. Herhangi bir işlem gerekmiyor.
B25: ■ | C25: TURUNCU ROZET | E25: EKSİK / BUGÜN / ORTA | G25: Dikkat gerektirir. Kayıt tamamlanmalı veya iş bugün teslim edilmeli.
B26: ■ | C26: KIRMIZI ROZET | E26: HATA / KALDI / KRİTİK / GECİKMİŞ | G26: Acil müdahale. Kırmızı satır varken ay sonu kapatılmamalıdır.
B27: ■ | C27: GRİ ROZET | E27: PASİF / PLANLI / İZLE | G27: Bilgi amaçlıdır, işlem gerektirmez.
B29: 3. SEKME RENK HARİTASI │ ALTTAKİ SEKME RENKLERİ NE İŞE YARAR?
B30: Renk | C30: Sekme | D30: Ne için? | F30: Açıklama
B31: ■ | C31: =HYPERLINK("#PANO!A1","PANO") | D31: Yönetim panosu | F31: Günüe buradan başlayın: özet rakamlar, grafikler ve uyarılar.
B32: ■ | C32: =HYPERLINK("#BASLANGIC!A1","BASLANGIC") | D32: Kullanım kılavuzu | F32: Şu an okuduğunuz ekran. Amaç, renk kuralı ve adımlar.
B33: ■ | C33: =HYPERLINK("#MUSTERILER!A1","MUSTERILER") | D33: Ana müşteri kartı | F33: Her müşteri için tek kayıt. Devir alacağı burada tanımlanır.
B34: ■ | C34: =HYPERLINK("#UCRETLER!A1","UCRETLER") | D34: Haftalık ücret dönemleri | F34: Fiyat geçmişi. Tahakkuk motorunun kaynağı.
B35: ■ | C35: =HYPERLINK("#TAHSILAT!A1","TAHSILAT") | D35: Müşteri tahsilatı | F35: Müşteriden gelen her ödeme yalnız buraya girilir.
B36: ■ | C36: =HYPERLINK("#GELIR_GIDER!A1","GELIR_GIDER") | D36: Ofis gelir ve giderleri | F36: Kira, personel, fatura gibi müşteri dışı hareketler.
B37: ■ | C37: =HYPERLINK("#VIRMAN!A1","VIRMAN") | D37: Hesaplar arası transfer | F37: Kasadan bankaya para geçişi. Kârı etkilemez.
B38: ■ | C38: =HYPERLINK("#AKTIVITE!A1","AKTIVITE") | D38: İşler ve görüşmeler | F38: Beyanname, bildirim, telefon, toplantı ve son tarihler.
B39: ■ | C39: =HYPERLINK("#MUSTERI_360!A1","MUSTERI_360") | D39: Cari ve yaşlandırma | F39: Salt okunur karar ekranı. Kimden ne kadar alacaksınız?
B40: ■ | C40: =HYPERLINK("#HESAPLAR!A1","HESAPLAR") | D40: Kasa ve banka | F40: Her hesabın güncel bakiyesi ve toplam nakit pozisyonu.
B41: ■ | C41: =HYPERLINK("#AY_SONU!A1","AY_SONU") | D41: Aylık kapanış | F41: Nakit kâr, dağıtılabilir kâr ve ortak payları.
B42: ■ | C42: =HYPERLINK("#SISTEM!A1","SISTEM") | D42: Ayarlar ve kontrol | F42: Ortak payları, kategoriler ve 28 otomatik denetim.
B44: 4. 11 ADIMDA KULLANIM │ HANGİ EKRANA NE GİRİLİR?
B45: Adım | C45: Ne yapılacak? | D45: Hangi ekran? | E45: Kullanıcı ne girer? | G45: Sistem ne yapar? | H45: Kontrol noktası | I45: Sıklık
...

Sheet MUSTERILER
A1: NECATİBEY OFİS YÖNETİM SİSTEMİ │ MÜŞTERİLER
A2: Ana müşteri kartı │ Her müşteri için tek kayıt │ Devir alacağı bu ekranda tanımlanır
B4: =HYPERLINK("#PANO!A1","← PANO") | D4: =HYPERLINK("#UCRETLER!A1","Haftalık Ücretler") | F4: =HYPERLINK("#MUSTERI_360!A1","Müşteri 360") | H4: Sarı hücreler veri girişidir. Beyaz hücreler sistem tarafından hesaplanır ve kilitlidir. Devir Alacak Tarihi yaşlandırmayı belirler — boş bırakılırsa tutar 29+ gün kabul edilir.
C5: TOPLAM │ Aktif müşteri ve devir alacağı | D5: =COUNTIF($D$7:$D$106,"Aktif") | J5: =SUM($J$7:$J$106)
B6: Müşteri No | C6: Müşteri / Mükellef Unvanı | D6: Durum | E6: Sorumlu Kişi | F6: Telefon | G6: Vergi No | H6: Ödeme Şekli | I6: Başlangıç Tarihi | J6: Devir Alacağı | K6: Devir Alacak Tarihi | L6: Devir Kaynağı | M6: Özel Not | N6: Bilgi Durumu | O6: Aktif Ücret Tanımı | P6: Kayıt Kontrolü
B7: M001 | C7: ANKARA HAVANA LTD.ŞTİ. | D7: Aktif | J7: 16200 | K7: 46200 | L7: Eski dosya │ 27.06.2026 dahil alacaklar | N7: Doğrulandı | O7: =IF($B7="","",IF(COUNTIFS(UCRETLER!$B$7:$B$406,$B7,UCRETLER!$G$7:$G$406,"Aktif")>0,"EVET","HAYIR")) | P7: =IF($B7="","",IF($C7="","EKSİK",IF(COUNTIF($B$7:$B$106,$B7)>1,"NO TEKRARI",IF(AND($J7>0,$K7=""),"DEVİR TARİHİ EKSİK","UYGUN"))))
B8: M002 | C8: ESERLİ LTD.ŞTİ. | D8: Aktif | J8: 109700 | K8: 46200 | L8: Eski dosya │ 27.06.2026 dahil alacaklar | N8: Doğrulandı | O8: =IF($B8="","",IF(COUNTIFS(UCRETLER!$B$7:$B$406,$B8,UCRETLER!$G$7:$G$406,"Aktif")>0,"EVET","HAYIR")) | P8: =IF($B8="","",IF($C8="","EKSİK",IF(COUNTIF($B$7:$B$106,$B8)>1,"NO TEKRARI",IF(AND($J8>0,$K8=""),"DEVİR TARİHİ EKSİK","UYGUN"))))
B9: M003 | C9: TYANA LTD.ŞTİ. | D9: Aktif | J9: 87950 | K9: 46200 | L9: Eski dosya │ 27.06.2026 dahil alacaklar | N9: Doğrulandı | O9: =IF($B9="","",IF(COUNTIFS(UCRETLER!$B$7:$B$406,$B9,UCRETLER!$G$7:$G$406,"Aktif")>0,"EVET","HAYIR")) | P9: =IF($B9="","",IF($C9="","EKSİK",IF(COUNTIF($B$7:$B$106,$B9)>1,"NO TEKRARI",IF(AND($J9>0,$K9=""),"DEVİR TARİHİ EKSİK","UYGUN"))))
B10: M004 | C10: ZÜMRÜT EĞLENCE LTD.ŞTİ. | D10: Aktif | J10: 31900 | K10: 46200 | L10: Eski dosya │ 27.06.2026 dahil alacaklar | N10: Doğrulandı | O10: =IF($B10="","",IF(COUNTIFS(UCRETLER!$B$7:$B$406,$B10,UCRETLER!$G$7:$G$406,"Aktif")>0,"EVET","HAYIR")) | P10: =IF($B10="","",IF($C10="","EKSİK",IF(COUNTIF($B$7:$B$106,$B10)>1,"NO TEKRARI",IF(AND($J10>0,$K10=""),"DEVİR TARİHİ EKSİK","UYGUN"))))
B11: M005 | C11: ZÜMRÜT GRUP LTD.ŞTİ. | D11: Aktif | J11: 34700 | K11: 46200 | L11: Eski dosya │ 27.06.2026 dahil alacaklar | N11: Doğrulandı | O11: =IF($B11="","",IF(COUNTIFS(UCRETLER!$B$7:$B$406,$B11,UCRETLER!$G$7:$G$406,"Aktif")>0,"EVET","HAYIR")) | P11: =IF($B11="","",IF($C11="","EKSİK",IF(COUNTIF($B$7:$B$106,$B11)>1,"NO TEKRARI",IF(AND($J11>0,$K11=""),"DEVİR TARİHİ EKSİK","UYGUN"))))
B12: M006 | C12: VOLKAN AÇIK | D12: Aktif | J12: 25000 | K12: 46200 | L12: Eski dosya │ 27.06.2026 dahil alacaklar | N12: Doğrulandı | O12: =IF($B12="","",IF(COUNTIFS(UCRETLER!$B$7:$B$406,$B12,UCRETLER!$G$7:$G$406,"Aktif")>0,"EVET","HAYIR")) | P12: =IF($B12="","",IF($C12="","EKSİK",IF(COUNTIF($B$7:$B$106,$B12)>1,"NO TEKRARI",IF(AND($J12>0,$K12=""),"DEVİR TARİHİ EKSİK","UYGUN"))))
B13: M007 | C13: MONAMOUR LTD.ŞTİ. | D13: Aktif | J13: 30900 | K13: 46200 | L13: Eski dosya │ 27.06.2026 dahil alacaklar | N13: Doğrulandı | O13: =IF($B13="","",IF(COUNTIFS(UCRETLER!$B$7:$B$406,$B13,UCRETLER!$G$7:$G$406,"Aktif")>0,"EVET","HAYIR")) | P13: =IF($B13="","",IF($C13="","EKSİK",IF(COUNTIF($B$7:$B$106,$B13)>1,"NO TEKRARI",IF(AND($J13>0,$K13=""),"DEVİR TARİHİ EKSİK","UYGUN"))))
B14: M008 | C14: KÖŞK YÜKSELEN LTD.ŞTİ. | D14: Aktif | J14: 132650 | K14: 46200 | L14: Eski dosya │ 27.06.2026 dahil alacaklar | N14: Doğrulandı | O14: =IF($B14="","",IF(COUNTIFS(UCRETLER!$B$7:$B$406,$B14,UCRETLER!$G$7:$G$406,"Aktif")>0,"EVET","HAYIR")) | P14: =IF($B14="","",IF($C14="","EKSİK",IF(COUNTIF($B$7:$B$106,$B14)>1,"NO TEKRARI",IF(AND($J14>0,$K14=""),"DEVİR TARİHİ EKSİK","UYGUN"))))
B15: M009 | C15: PakYıldız Ltd.Şti. | D15: Beklemede | N15: Ücret doğrulanmalı | O15: =IF($B15="","",IF(COUNTIFS(UCRETLER!$B$7:$B$406,$B15,UCRETLER!$G$7:$G$406,"Aktif")>0,"EVET","HAYIR")) | P15: =IF($B15="","",IF($C15="","EKSİK",IF(COUNTIF($B$7:$B$106,$B15)>1,"NO TEKRARI",IF(AND($J15>0,$K15=""),"DEVİR TARİHİ EKSİK","UYGUN"))))
B16: M010 | C16: Özfidanlar Ltd.Şti. | D16: Beklemede | N16: Ücret doğrulanmalı | O16: =IF($B16="","",IF(COUNTIFS(UCRETLER!$B$7:$B$406,$B16,UCRETLER!$G$7:$G$406,"Aktif")>0,"EVET","HAYIR")) | P16: =IF($B16="","",IF($C16="","EKSİK",IF(COUNTIF($B$7:$B$106,$B16)>1,"NO TEKRARI",IF(AND($J16>0,$K16=""),"DEVİR TARİHİ EKSİK","UYGUN"))))
B17: M011 | C17: Eğlengör Ltd.Şti. | D17: Beklemede | N17: Ücret doğrulanmalı | O17: =IF($B17="","",IF(COUNTIFS(UCRETLER!$B$7:$B$406,$B17,UCRETLER!$G$7:$G$406,"Aktif")>0,"EVET","HAYIR")) | P17: =IF($B17="","",IF($C17="","EKSİK",IF(COUNTIF($B$7:$B$106,$B17)>1,"NO TEKRARI",IF(AND($J17>0,$K17=""),"DEVİR TARİHİ EKSİK","UYGUN"))))
B18: M012 | C18: İldeş Ltd.Şti. | D18: Beklemede | N18: Ücret doğrulanmalı | O18: =IF($B18="","",IF(COUNTIFS(UCRETLER!$B$7:$B$406,$B18,UCRETLER!$G$7:$G$406,"Aktif")>0,"EVET","HAYIR")) | P18: =IF($B18="","",IF($C18="","EKSİK",IF(COUNTIF($B$7:$B$106,$B18)>1,"NO TEKRARI",IF(AND($J18>0,$K18=""),"DEVİR TARİHİ EKSİK","UYGUN"))))
B19: M013 | C19: Naz 1 Gıda Ltd.Şti. | D19: Beklemede | N19: Ücret doğrulanmalı | O19: =IF($B19="","",IF(COUNTIFS(UCRETLER!$B$7:$B$406,$B19,UCRETLER!$G$7:$G$406,"Aktif")>0,"EVET","HAYIR")) | P19: =IF($B19="","",IF($C19="","EKSİK",IF(COUNTIF($B$7:$B$106,$B19)>1,"NO TEKRARI",IF(AND($J19>0,$K19=""),"DEVİR TARİHİ EKSİK","UYGUN"))))
B20: M014 | C20: Final Siyah Beyaz Ltd.Şti. | D20: Beklemede | N20: Ücret doğrulanmalı | O20: =IF($B20="","",IF(COUNTIFS(UCRETLER!$B$7:$B$406,$B20,UCRETLER!$G$7:$G$406,"Aktif")>0,"EVET","HAYIR")) | P20: =IF($B20="","",IF($C20="","EKSİK",IF(COUNTIF($B$7:$B$106,$B20)>1,"NO TEKRARI",IF(AND($J20>0,$K20=""),"DEVİR TARİHİ EKSİK","UYGUN"))))
B21: M015 | C21: Çayıralan Ltd.Şti. | D21: Beklemede | N21: Ücret doğrulanmalı | O21: =IF($B21="","",IF(COUNTIFS(UCRETLER!$B$7:$B$406,$B21,UCRETLER!$G$7:$G$406,"Aktif")>0,"EVET","HAYIR")) | P21: =IF($B21="","",IF($C21="","EKSİK",IF(COUNTIF($B$7:$B$106,$B21)>1,"NO TEKRARI",IF(AND($J21>0,$K21=""),"DEVİR TARİHİ EKSİK","UYGUN"))))
B22: M016 | C22: Rix Şow Ltd.Şti. | D22: Beklemede | N22: Ücret doğrulanmalı | O22: =IF($B22="","",IF(COUNTIFS(UCRETLER!$B$7:$B$406,$B22,UCRETLER!$G$7:$G$406,"Aktif")>0,"EVET","HAYIR")) | P22: =IF($B22="","",IF($C22="","EKSİK",IF(COUNTIF($B$7:$B$106,$B22)>1,"NO TEKRARI",IF(AND($J22>0,$K22=""),"DEVİR TARİHİ EKSİK","UYGUN"))))
B23: M017 | C23: ASM Eğlence Ltd.Şti. | D23: Beklemede | N23: Ücret doğrulanmalı | O23: =IF($B23="","",IF(COUNTIFS(UCRETLER!$B$7:$B$406,$B23,UCRETLER!$G$7:$G$406,"Aktif")>0,"EVET","HAYIR")) | P23: =IF($B23="","",IF($C23="","EKSİK",IF(COUNTIF($B$7:$B$106,$B23)>1,"NO TEKRARI",IF(AND($J23>0,$K23=""),"DEVİR TARİHİ EKSİK","UYGUN"))))
B24: M018 | C24: Çınarhan Ltd.Şti. | D24: Beklemede | N24: Ücret doğrulanmalı | O24: =IF($B24="","",IF(COUNTIFS(UCRETLER!$B$7:$B$406,$B24,UCRETLER!$G$7:$G$406,"Aktif")>0,"EVET","HAYIR")) | P24: =IF($B24="","",IF($C24="","EKSİK",IF(COUNTIF($B$7:$B$106,$B24)>1,"NO TEKRARI",IF(AND($J24>0,$K24=""),"DEVİR TARİHİ EKSİK","UYGUN"))))
B25: M019 | C25: AC Otel Ltd.Şti. | D25: Beklemede | N25: Ücret doğrulanmalı | O25: =IF($B25="","",IF(COUNTIFS(UCRETLER!$B$7:$B$406,$B25,UCRETLER!$G$7:$G$406,"Aktif")>0,"EVET","HAYIR")) | P25: =IF($B25="","",IF($C25="","EKSİK",IF(COUNTIF($B$7:$B$106,$B25)>1,"NO TEKRARI",IF(AND($J25>0,$K25=""),"DEVİR TARİHİ EKSİK","UYGUN"))))
B26: M020 | C26: Kristal Ltd.Şti. | D26: Beklemede | N26: Ücret doğrulanmalı | O26: =IF($B26="","",IF(COUNTIFS(UCRETLER!$B$7:$B$406,$B26,UCRETLER!$G$7:$G$406,"Aktif")>0,"EVET","HAYIR")) | P26: =IF($B26="","",IF($C26="","EKSİK",IF(COUNTIF($B$7:$B$106,$B26)>1,"NO TEKRARI",IF(AND($J26>0,$K26=""),"DEVİR TARİHİ EKSİK","UYGUN"))))
B27: M021 | C27: Aron Toptan Ltd.Şti. | D27: Beklemede | N27: Ücret doğrulanmalı | O27: =IF($B27="","",IF(COUNTIFS(UCRETLER!$B$7:$B$406,$B27,UCRETLER!$G$7:$G$406,"Aktif")>0,"EVET","HAYIR")) | P27: =IF($B27="","",IF($C27="","EKSİK",IF(COUNTIF($B$7:$B$106,$B27)>1,"NO TEKRARI",IF(AND($J27>0,$K27=""),"DEVİR TARİHİ EKSİK","UYGUN"))))
O28: =IF($B28="","",IF(COUNTIFS(UCRETLER!$B$7:$B$406,$B28,UCRETLER!$G$7:$G$406,"Aktif")>0,"EVET","HAYIR")) | P28: =IF($B28="","",IF($C28="","EKSİK",IF(COUNTIF($B$7:$B$106,$B28)>1,"NO TEKRARI",IF(AND($J28>0,$K28=""),"DEVİR TARİHİ EKSİK","UYGUN"))))
O29: =IF($B29="","",IF(COUNTIFS(UCRETLER!$B$7:$B$406,$B29,UCRETLER!$G$7:$G$406,"Aktif")>0,"EVET","HAYIR")) | P29: =IF($B29="","",IF($C29="","EKSİK",IF(COUNTIF($B$7:$B$106,$B29)>1,"NO TEKRARI",IF(AND($J29>0,$K29=""),"DEVİR TARİHİ EKSİK","UYGUN"))))
O30: =IF($B30="","",IF(COUNTIFS(UCRETLER!$B$7:$B$406,$B30,UCRETLER!$G$7:$G$406,"Aktif")>0,"EVET","HAYIR")) | P30: =IF($B30="","",IF($C30="","EKSİK",IF(COUNTIF($B$7:$B$106,$B30)>1,"NO TEKRARI",IF(AND($J30>0,$K30=""),"DEVİR TARİHİ EKSİK","UYGUN"))))
O31: =IF($B31="","",IF(COUNTIFS(UCRETLER!$B$7:$B$406,$B31,UCRETLER!$G$7:$G$406,"Aktif")>0,"EVET","HAYIR")) | P31: =IF($B31="","",IF($C31="","EKSİK",IF(COUNTIF($B$7:$B$106,$B31)>1,"NO TEKRARI",IF(AND($J31>0,$K31=""),"DEVİR TARİHİ EKSİK","UYGUN"))))
O32: =IF($B32="","",IF(COUNTIFS(UCRETLER!$B$7:$B$406,$B32,UCRETLER!$G$7:$G$406,"Aktif")>0,"EVET","HAYIR")) | P32: =IF($B32="","",IF($C32="","EKSİK",IF(COUNTIF($B$7:$B$106,$B32)>1,"NO TEKRARI",IF(AND($J32>0,$K32=""),"DEVİR TARİHİ EKSİK","UYGUN"))))
O33: =IF($B33="","",IF(COUNTIFS(UCRETLER!$B$7:$B$406,$B33,UCRETLER!$G$7:$G$406,"Aktif")>0,"EVET","HAYIR")) | P33: =IF($B33="","",IF($C33="","EKSİK",IF(COUNTIF($B$7:$B$106,$B33)>1,"NO TEKRARI",IF(AND($J33>0,$K33=""),"DEVİR TARİHİ EKSİK","UYGUN"))))
O34: =IF($B34="","",IF(COUNTIFS(UCRETLER!$B$7:$B$406,$B34,UCRETLER!$G$7:$G$406,"Aktif")>0,"EVET","HAYIR")) | P34: =IF($B34="","",IF($C34="","EKSİK",IF(COUNTIF($B$7:$B$106,$B34)>1,"NO TEKRARI",IF(AND($J34>0,$K34=""),"DEVİR TARİHİ EKSİK","UYGUN"))))
O35: =IF($B35="","",IF(COUNTIFS(UCRETLER!$B$7:$B$406,$B35,UCRETLER!$G$7:$G$406,"Aktif")>0,"EVET","HAYIR")) | P35: =IF($B35="","",IF($C35="","EKSİK",IF(COUNTIF($B$7:$B$106,$B35)>1,"NO TEKRARI",IF(AND($J35>0,$K35=""),"DEVİR TARİHİ EKSİK","UYGUN"))))
O36: =IF($B36="","",IF(COUNTIFS(UCRETLER!$B$7:$B$406,$B36,UCRETLER!$G$7:$G$406,"Aktif")>0,"EVET","HAYIR")) | P36: =IF($B36="","",IF($C36="","EKSİK",IF(COUNTIF($B$7:$B$106,$B36)>1,"NO TEKRARI",IF(AND($J36>0,$K36=""),"DEVİR TARİHİ EKSİK","UYGUN"))))
O37: =IF($B37="","",IF(COUNTIFS(UCRETLER!$B$7:$B$406,$B37,UCRETLER!$G$7:$G$406,"Aktif")>0,"EVET","HAYIR")) | P37: =IF($B37="","",IF($C37="","EKSİK",IF(COUNTIF($B$7:$B$106,$B37)>1,"NO TEKRARI",IF(AND($J37>0,$K37=""),"DEVİR TARİHİ EKSİK","UYGUN"))))
O38: =IF($B38="","",IF(COUNTIFS(UCRETLER!$B$7:$B$406,$B38,UCRETLER!$G$7:$G$406,"Aktif")>0,"EVET","HAYIR")) | P38: =IF($B38="","",IF($C38="","EKSİK",IF(COUNTIF($B$7:$B$106,$B38)>1,"NO TEKRARI",IF(AND($J38>0,$K38=""),"DEVİR TARİHİ EKSİK","UYGUN"))))
O39: =IF($B39="","",IF(COUNTIFS(UCRETLER!$B$7:$B$406,$B39,UCRETLER!$G$7:$G$406,"Aktif")>0,"EVET","HAYIR")) | P39: =IF($B39="","",IF($C39="","EKSİK",IF(COUNTIF($B$7:$B$106,$B39)>1,"NO TEKRARI",IF(AND($J39>0,$K39=""),"DEVİR TARİHİ EKSİK","UYGUN"))))
... O106: =IF($B106="","",IF(COUNTIFS(UCRETLER!$B$7:$B$406,$B106,UCRETLER!$G$7:$G$406,"Aktif")>0,"EVET","HAYIR")) | P106: =IF($B106="","",IF($C106="","EKSİK",IF(COUNTIF($B$7:$B$106,$B106)>1,"NO TEKRARI",IF(AND($J106>0,$K106=""),"DEVİR TARİHİ EKSİK","UYGUN"))))

Sheet UCRETLER
A1: NECATİBEY OFİS YÖNETİM SİSTEMİ │ HAFTALIK ÜCRET DÖNEMLERİ
A2: Ücret değişince eski dönemi kapat, yeni satır aç │ Geçmiş tahakkuk asla bozulmaz
B4: =HYPERLINK("#PANO!A1","← PANO") | D4: =HYPERLINK("#MUSTERILER!A1","Müşteriler") | F4: =HYPERLINK("#MUSTERI_360!A1","Müşteri 360") | H4: Sarı hücreler veri girişidir. Beyaz hücreler sistem tarafından hesaplanır ve kilitlidir. Başlangıç ve bitiş mutlaka Cumartesi olmalıdır.
C5: TOPLAM │ Aktif haftalık tahakkuk ve oluşan ücret | F5: =SUMIFS($F$7:$F$406,$G$7:$G$406,"Aktif") | H5: =SUM($H$7:$H$406)
B6: Müşteri No | C6: Müşteri | D6: Ücret Başlangıç (Cumartesi) | E6: Ücret Bitiş (Cumartesi) | F6: Haftalık Ücret | G6: Dönem Durumu | H6: Bugüne Kadar Oluşan | I6: 8 Gün Öncesine Kadar | J6: 15 Gün Öncesine Kadar | K6: 29 Gün Öncesine Kadar | L6: Oluşan Hafta | M6: Sistem Kontrolü | N6: Not
B7: M001 | C7: =IF($B7="","",IFERROR(INDEX(MUSTERILER!$C$7:$C$106,MATCH($B7,MUSTERILER!$B$7:$B$106,0)),"TANIMSIZ MÜŞTERİ")) | D7: 46263 | F7: 4000 | G7: Aktif | H7: =IF(OR($B7="",$D7="",$F7=""),0,$F7*MAX(0,INT((MIN(IF($E7="",TODAY(),$E7),TODAY())-$D7)/7)+1)) | I7: =IF(OR($B7="",$D7="",$F7=""),0,$F7*MAX(0,INT((MIN(IF($E7="",TODAY()-8,$E7),TODAY()-8)-$D7)/7)+1)) | J7: =IF(OR($B7="",$D7="",$F7=""),0,$F7*MAX(0,INT((MIN(IF($E7="",TODAY()-15,$E7),TODAY()-15)-$D7)/7)+1)) | K7: =IF(OR($B7="",$D7="",$F7=""),0,$F7*MAX(0,INT((MIN(IF($E7="",TODAY()-29,$E7),TODAY()-29)-$D7)/7)+1)) | L7: =IF($F7>0,$H7/$F7,0) | M7: =IF($B7="","",IF($C7="TANIMSIZ MÜŞTERİ","HATA",IF($G7="Pasif","PASİF",IF(AND(WEEKDAY($D7,2)=6,OR($E7="",WEEKDAY($E7,2)=6),$F7>0),"UYGUN","HATA")))) | N7: Mevcut dosyadan aktarıldı
B8: M002 | C8: =IF($B8="","",IFERROR(INDEX(MUSTERILER!$C$7:$C$106,MATCH($B8,MUSTERILER!$B$7:$B$106,0)),"TANIMSIZ MÜŞTERİ")) | D8: 46263 | F8: 3500 | G8: Aktif | H8: =IF(OR($B8="",$D8="",$F8=""),0,$F8*MAX(0,INT((MIN(IF($E8="",TODAY(),$E8),TODAY())-$D8)/7)+1)) | I8: =IF(OR($B8="",$D8="",$F8=""),0,$F8*MAX(0,INT((MIN(IF($E8="",TODAY()-8,$E8),TODAY()-8)-$D8)/7)+1)) | J8: =IF(OR($B8="",$D8="",$F8=""),0,$F8*MAX(0,INT((MIN(IF($E8="",TODAY()-15,$E8),TODAY()-15)-$D8)/7)+1)) | K8: =IF(OR($B8="",$D8="",$F8=""),0,$F8*MAX(0,INT((MIN(IF($E8="",TODAY()-29,$E8),TODAY()-29)-$D8)/7)+1)) | L8: =IF($F8>0,$H8/$F8,0) | M8: =IF($B8="","",IF($C8="TANIMSIZ MÜŞTERİ","HATA",IF($G8="Pasif","PASİF",IF(AND(WEEKDAY($D8,2)=6,OR($E8="",WEEKDAY($E8,2)=6),$F8>0),"UYGUN","HATA")))) | N8: Mevcut dosyadan aktarıldı
B9: M003 | C9: =IF($B9="","",IFERROR(INDEX(MUSTERILER!$C$7:$C$106,MATCH($B9,MUSTERILER!$B$7:$B$106,0)),"TANIMSIZ MÜŞTERİ")) | D9: 46263 | F9: 4000 | G9: Aktif | H9: =IF(OR($B9="",$D9="",$F9=""),0,$F9*MAX(0,INT((MIN(IF($E9="",TODAY(),$E9),TODAY())-$D9)/7)+1)) | I9: =IF(OR($B9="",$D9="",$F9=""),0,$F9*MAX(0,INT((MIN(IF($E9="",TODAY()-8,$E9),TODAY()-8)-$D9)/7)+1)) | J9: =IF(OR($B9="",$D9="",$F9=""),0,$F9*MAX(0,INT((MIN(IF($E9="",TODAY()-15,$E9),TODAY()-15)-$D9)/7)+1)) | K9: =IF(OR($B9="",$D9="",$F9=""),0,$F9*MAX(0,INT((MIN(IF($E9="",TODAY()-29,$E9),TODAY()-29)-$D9)/7)+1)) | L9: =IF($F9>0,$H9/$F9,0) | M9: =IF($B9="","",IF($C9="TANIMSIZ MÜŞTERİ","HATA",IF($G9="Pasif","PASİF",IF(AND(WEEKDAY($D9,2)=6,OR($E9="",WEEKDAY($E9,2)=6),$F9>0),"UYGUN","HATA")))) | N9: Mevcut dosyadan aktarıldı
B10: M004 | C10: =IF($B10="","",IFERROR(INDEX(MUSTERILER!$C$7:$C$106,MATCH($B10,MUSTERILER!$B$7:$B$106,0)),"TANIMSIZ MÜŞTERİ")) | D10: 46263 | F10: 1750 | G10: Aktif | H10: =IF(OR($B10="",$D10="",$F10=""),0,$F10*MAX(0,INT((MIN(IF($E10="",TODAY(),$E10),TODAY())-$D10)/7)+1)) | I10: =IF(OR($B10="",$D10="",$F10=""),0,$F10*MAX(0,INT((MIN(IF($E10="",TODAY()-8,$E10),TODAY()-8)-$D10)/7)+1)) | J10: =IF(OR($B10="",$D10="",$F10=""),0,$F10*MAX(0,INT((MIN(IF($E10="",TODAY()-15,$E10),TODAY()-15)-$D10)/7)+1)) | K10: =IF(OR($B10="",$D10="",$F10=""),0,$F10*MAX(0,INT((MIN(IF($E10="",TODAY()-29,$E10),TODAY()-29)-$D10)/7)+1)) | L10: =IF($F10>0,$H10/$F10,0) | M10: =IF($B10="","",IF($C10="TANIMSIZ MÜŞTERİ","HATA",IF($G10="Pasif","PASİF",IF(AND(WEEKDAY($D10,2)=6,OR($E10="",WEEKDAY($E10,2)=6),$F10>0),"UYGUN","HATA")))) | N10: Mevcut dosyadan aktarıldı
B11: M005 | C11: =IF($B11="","",IFERROR(INDEX(MUSTERILER!$C$7:$C$106,MATCH($B11,MUSTERILER!$B$7:$B$106,0)),"TANIMSIZ MÜŞTERİ")) | D11: 46263 | F11: 1750 | G11: Aktif | H11: =IF(OR($B11="",$D11="",$F11=""),0,$F11*MAX(0,INT((MIN(IF($E11="",TODAY(),$E11),TODAY())-$D11)/7)+1)) | I11: =IF(OR($B11="",$D11="",$F11=""),0,$F11*MAX(0,INT((MIN(IF($E11="",TODAY()-8,$E11),TODAY()-8)-$D11)/7)+1)) | J11: =IF(OR($B11="",$D11="",$F11=""),0,$F11*MAX(0,INT((MIN(IF($E11="",TODAY()-15,$E11),TODAY()-15)-$D11)/7)+1)) | K11: =IF(OR($B11="",$D11="",$F11=""),0,$F11*MAX(0,INT((MIN(IF($E11="",TODAY()-29,$E11),TODAY()-29)-$D11)/7)+1)) | L11: =IF($F11>0,$H11/$F11,0) | M11: =IF($B11="","",IF($C11="TANIMSIZ MÜŞTERİ","HATA",IF($G11="Pasif","PASİF",IF(AND(WEEKDAY($D11,2)=6,OR($E11="",WEEKDAY($E11,2)=6),$F11>0),"UYGUN","HATA")))) | N11: Mevcut dosyadan aktarıldı
B12: M006 | C12: =IF($B12="","",IFERROR(INDEX(MUSTERILER!$C$7:$C$106,MATCH($B12,MUSTERILER!$B$7:$B$106,0)),"TANIMSIZ MÜŞTERİ")) | D12: 46263 | F12: 1000 | G12: Aktif | H12: =IF(OR($B12="",$D12="",$F12=""),0,$F12*MAX(0,INT((MIN(IF($E12="",TODAY(),$E12),TODAY())-$D12)/7)+1)) | I12: =IF(OR($B12="",$D12="",$F12=""),0,$F12*MAX(0,INT((MIN(IF($E12="",TODAY()-8,$E12),TODAY()-8)-$D12)/7)+1)) | J12: =IF(OR($B12="",$D12="",$F12=""),0,$F12*MAX(0,INT((MIN(IF($E12="",TODAY()-15,$E12),TODAY()-15)-$D12)/7)+1)) | K12: =IF(OR($B12="",$D12="",$F12=""),0,$F12*MAX(0,INT((MIN(IF($E12="",TODAY()-29,$E12),TODAY()-29)-$D12)/7)+1)) | L12: =IF($F12>0,$H12/$F12,0) | M12: =IF($B12="","",IF($C12="TANIMSIZ MÜŞTERİ","HATA",IF($G12="Pasif","PASİF",IF(AND(WEEKDAY($D12,2)=6,OR($E12="",WEEKDAY($E12,2)=6),$F12>0),"UYGUN","HATA")))) | N12: Mevcut dosyadan aktarıldı
B13: M007 | C13: =IF($B13="","",IFERROR(INDEX(MUSTERILER!$C$7:$C$106,MATCH($B13,MUSTERILER!$B$7:$B$106,0)),"TANIMSIZ MÜŞTERİ")) | D13: 46263 | F13: 3500 | G13: Aktif | H13: =IF(OR($B13="",$D13="",$F13=""),0,$F13*MAX(0,INT((MIN(IF($E13="",TODAY(),$E13),TODAY())-$D13)/7)+1)) | I13: =IF(OR($B13="",$D13="",$F13=""),0,$F13*MAX(0,INT((MIN(IF($E13="",TODAY()-8,$E13),TODAY()-8)-$D13)/7)+1)) | J13: =IF(OR($B13="",$D13="",$F13=""),0,$F13*MAX(0,INT((MIN(IF($E13="",TODAY()-15,$E13),TODAY()-15)-$D13)/7)+1)) | K13: =IF(OR($B13="",$D13="",$F13=""),0,$F13*MAX(0,INT((MIN(IF($E13="",TODAY()-29,$E13),TODAY()-29)-$D13)/7)+1)) | L13: =IF($F13>0,$H13/$F13,0) | M13: =IF($B13="","",IF($C13="TANIMSIZ MÜŞTERİ","HATA",IF($G13="Pasif","PASİF",IF(AND(WEEKDAY($D13,2)=6,OR($E13="",WEEKDAY($E13,2)=6),$F13>0),"UYGUN","HATA")))) | N13: Mevcut dosyadan aktarıldı
B14: M008 | C14: =IF($B14="","",IFERROR(INDEX(MUSTERILER!$C$7:$C$106,MATCH($B14,MUSTERILER!$B$7:$B$106,0)),"TANIMSIZ MÜŞTERİ")) | D14: 46263 | F14: 3500 | G14: Aktif | H14: =IF(OR($B14="",$D14="",$F14=""),0,$F14*MAX(0,INT((MIN(IF($E14="",TODAY(),$E14),TODAY())-$D14)/7)+1)) | I14: =IF(OR($B14="",$D14="",$F14=""),0,$F14*MAX(0,INT((MIN(IF($E14="",TODAY()-8,$E14),TODAY()-8)-$D14)/7)+1)) | J14: =IF(OR($B14="",$D14="",$F14=""),0,$F14*MAX(0,INT((MIN(IF($E14="",TODAY()-15,$E14),TODAY()-15)-$D14)/7)+1)) | K14: =IF(OR($B14="",$D14="",$F14=""),0,$F14*MAX(0,INT((MIN(IF($E14="",TODAY()-29,$E14),TODAY()-29)-$D14)/7)+1)) | L14: =IF($F14>0,$H14/$F14,0) | M14: =IF($B14="","",IF($C14="TANIMSIZ MÜŞTERİ","HATA",IF($G14="Pasif","PASİF",IF(AND(WEEKDAY($D14,2)=6,OR($E14="",WEEKDAY($E14,2)=6),$F14>0),"UYGUN","HATA")))) | N14: Mevcut dosyadan aktarıldı
B15: M009 | C15: =IF($B15="","",IFERROR(INDEX(MUSTERILER!$C$7:$C$106,MATCH($B15,MUSTERILER!$B$7:$B$106,0)),"TANIMSIZ MÜŞTERİ")) | G15: Pasif | H15: =IF(OR($B15="",$D15="",$F15=""),0,$F15*MAX(0,INT((MIN(IF($E15="",TODAY(),$E15),TODAY())-$D15)/7)+1)) | I15: =IF(OR($B15="",$D15="",$F15=""),0,$F15*MAX(0,INT((MIN(IF($E15="",TODAY()-8,$E15),TODAY()-8)-$D15)/7)+1)) | J15: =IF(OR($B15="",$D15="",$F15=""),0,$F15*MAX(0,INT((MIN(IF($E15="",TODAY()-15,$E15),TODAY()-15)-$D15)/7)+1)) | K15: =IF(OR($B15="",$D15="",$F15=""),0,$F15*MAX(0,INT((MIN(IF($E15="",TODAY()-29,$E15),TODAY()-29)-$D15)/7)+1)) | L15: =IF($F15>0,$H15/$F15,0) | M15: =IF($B15="","",IF($C15="TANIMSIZ MÜŞTERİ","HATA",IF($G15="Pasif","PASİF",IF(AND(WEEKDAY($D15,2)=6,OR($E15="",WEEKDAY($E15,2)=6),$F15>0),"UYGUN","HATA")))) | N15: Haftalık ücret girilmeli
B16: M010 | C16: =IF($B16="","",IFERROR(INDEX(MUSTERILER!$C$7:$C$106,MATCH($B16,MUSTERILER!$B$7:$B$106,0)),"TANIMSIZ MÜŞTERİ")) | G16: Pasif | H16: =IF(OR($B16="",$D16="",$F16=""),0,$F16*MAX(0,INT((MIN(IF($E16="",TODAY(),$E16),TODAY())-$D16)/7)+1)) | I16: =IF(OR($B16="",$D16="",$F16=""),0,$F16*MAX(0,INT((MIN(IF($E16="",TODAY()-8,$E16),TODAY()-8)-$D16)/7)+1)) | J16: =IF(OR($B16="",$D16="",$F16=""),0,$F16*MAX(0,INT((MIN(IF($E16="",TODAY()-15,$E16),TODAY()-15)-$D16)/7)+1)) | K16: =IF(OR($B16="",$D16="",$F16=""),0,$F16*MAX(0,INT((MIN(IF($E16="",TODAY()-29,$E16),TODAY()-29)-$D16)/7)+1)) | L16: =IF($F16>0,$H16/$F16,0) | M16: =IF($B16="","",IF($C16="TANIMSIZ MÜŞTERİ","HATA",IF($G16="Pasif","PASİF",IF(AND(WEEKDAY($D16,2)=6,OR($E16="",WEEKDAY($E16,2)=6),$F16>0),"UYGUN","HATA")))) | N16: Haftalık ücret girilmeli
B17: M011 | C17: =IF($B17="","",IFERROR(INDEX(MUSTERILER!$C$7:$C$106,MATCH($B17,MUSTERILER!$B$7:$B$106,0)),"TANIMSIZ MÜŞTERİ")) | G17: Pasif | H17: =IF(OR($B17="",$D17="",$F17=""),0,$F17*MAX(0,INT((MIN(IF($E17="",TODAY(),$E17),TODAY())-$D17)/7)+1)) | I17: =IF(OR($B17="",$D17="",$F17=""),0,$F17*MAX(0,INT((MIN(IF($E17="",TODAY()-8,$E17),TODAY()-8)-$D17)/7)+1)) | J17: =IF(OR($B17="",$D17="",$F17=""),0,$F17*MAX(0,INT((MIN(IF($E17="",TODAY()-15,$E17),TODAY()-15)-$D17)/7)+1)) | K17: =IF(OR($B17="",$D17="",$F17=""),0,$F17*MAX(0,INT((MIN(IF($E17="",TODAY()-29,$E17),TODAY()-29)-$D17)/7)+1)) | L17: =IF($F17>0,$H17/$F17,0) | M17: =IF($B17="","",IF($C17="TANIMSIZ MÜŞTERİ","HATA",IF($G17="Pasif","PASİF",IF(AND(WEEKDAY($D17,2)=6,OR($E17="",WEEKDAY($E17,2)=6),$F17>0),"UYGUN","HATA")))) | N17: Haftalık ücret girilmeli
B18: M012 | C18: =IF($B18="","",IFERROR(INDEX(MUSTERILER!$C$7:$C$106,MATCH($B18,MUSTERILER!$B$7:$B$106,0)),"TANIMSIZ MÜŞTERİ")) | G18: Pasif | H18: =IF(OR($B18="",$D18="",$F18=""),0,$F18*MAX(0,INT((MIN(IF($E18="",TODAY(),$E18),TODAY())-$D18)/7)+1)) | I18: =IF(OR($B18="",$D18="",$F18=""),0,$F18*MAX(0,INT((MIN(IF($E18="",TODAY()-8,$E18),TODAY()-8)-$D18)/7)+1)) | J18: =IF(OR($B18="",$D18="",$F18=""),0,$F18*MAX(0,INT((MIN(IF($E18="",TODAY()-15,$E18),TODAY()-15)-$D18)/7)+1)) | K18: =IF(OR($B18="",$D18="",$F18=""),0,$F18*MAX(0,INT((MIN(IF($E18="",TODAY()-29,$E18),TODAY()-29)-$D18)/7)+1)) | L18: =IF($F18>0,$H18/$F18,0) | M18: =IF($B18="","",IF($C18="TANIMSIZ MÜŞTERİ","HATA",IF($G18="Pasif","PASİF",IF(AND(WEEKDAY($D18,2)=6,OR($E18="",WEEKDAY($E18,2)=6),$F18>0),"UYGUN","HATA")))) | N18: Haftalık ücret girilmeli
B19: M013 | C19: =IF($B19="","",IFERROR(INDEX(MUSTERILER!$C$7:$C$106,MATCH($B19,MUSTERILER!$B$7:$B$106,0)),"TANIMSIZ MÜŞTERİ")) | G19: Pasif | H19: =IF(OR($B19="",$D19="",$F19=""),0,$F19*MAX(0,INT((MIN(IF($E19="",TODAY(),$E19),TODAY())-$D19)/7)+1)) | I19: =IF(OR($B19="",$D19="",$F19=""),0,$F19*MAX(0,INT((MIN(IF($E19="",TODAY()-8,$E19),TODAY()-8)-$D19)/7)+1)) | J19: =IF(OR($B19="",$D19="",$F19=""),0,$F19*MAX(0,INT((MIN(IF($E19="",TODAY()-15,$E19),TODAY()-15)-$D19)/7)+1)) | K19: =IF(OR($B19="",$D19="",$F19=""),0,$F19*MAX(0,INT((MIN(IF($E19="",TODAY()-29,$E19),TODAY()-29)-$D19)/7)+1)) | L19: =IF($F19>0,$H19/$F19,0) | M19: =IF($B19="","",IF($C19="TANIMSIZ MÜŞTERİ","HATA",IF($G19="Pasif","PASİF",IF(AND(WEEKDAY($D19,2)=6,OR($E19="",WEEKDAY($E19,2)=6),$F19>0),"UYGUN","HATA")))) | N19: Haftalık ücret girilmeli
B20: M014 | C20: =IF($B20="","",IFERROR(INDEX(MUSTERILER!$C$7:$C$106,MATCH($B20,MUSTERILER!$B$7:$B$106,0)),"TANIMSIZ MÜŞTERİ")) | G20: Pasif | H20: =IF(OR($B20="",$D20="",$F20=""),0,$F20*MAX(0,INT((MIN(IF($E20="",TODAY(),$E20),TODAY())-$D20)/7)+1)) | I20: =IF(OR($B20="",$D20="",$F20=""),0,$F20*MAX(0,INT((MIN(IF($E20="",TODAY()-8,$E20),TODAY()-8)-$D20)/7)+1)) | J20: =IF(OR($B20="",$D20="",$F20=""),0,$F20*MAX(0,INT((MIN(IF($E20="",TODAY()-15,$E20),TODAY()-15)-$D20)/7)+1)) | K20: =IF(OR($B20="",$D20="",$F20=""),0,$F20*MAX(0,INT((MIN(IF($E20="",TODAY()-29,$E20),TODAY()-29)-$D20)/7)+1)) | L20: =IF($F20>0,$H20/$F20,0) | M20: =IF($B20="","",IF($C20="TANIMSIZ MÜŞTERİ","HATA",IF($G20="Pasif","PASİF",IF(AND(WEEKDAY($D20,2)=6,OR($E20="",WEEKDAY($E20,2)=6),$F20>0),"UYGUN","HATA")))) | N20: Haftalık ücret girilmeli
B21: M015 | C21: =IF($B21="","",IFERROR(INDEX(MUSTERILER!$C$7:$C$106,MATCH($B21,MUSTERILER!$B$7:$B$106,0)),"TANIMSIZ MÜŞTERİ")) | G21: Pasif | H21: =IF(OR($B21="",$D21="",$F21=""),0,$F21*MAX(0,INT((MIN(IF($E21="",TODAY(),$E21),TODAY())-$D21)/7)+1)) | I21: =IF(OR($B21="",$D21="",$F21=""),0,$F21*MAX(0,INT((MIN(IF($E21="",TODAY()-8,$E21),TODAY()-8)-$D21)/7)+1)) | J21: =IF(OR($B21="",$D21="",$F21=""),0,$F21*MAX(0,INT((MIN(IF($E21="",TODAY()-15,$E21),TODAY()-15)-$D21)/7)+1)) | K21: =IF(OR($B21="",$D21="",$F21=""),0,$F21*MAX(0,INT((MIN(IF($E21="",TODAY()-29,$E21),TODAY()-29)-$D21)/7)+1)) | L21: =IF($F21>0,$H21/$F21,0) | M21: =IF($B21="","",IF($C21="TANIMSIZ MÜŞTERİ","HATA",IF($G21="Pasif","PASİF",IF(AND(WEEKDAY($D21,2)=6,OR($E21="",WEEKDAY($E21,2)=6),$F21>0),"UYGUN","HATA")))) | N21: Haftalık ücret girilmeli
B22: M016 | C22: =IF($B22="","",IFERROR(INDEX(MUSTERILER!$C$7:$C$106,MATCH($B22,MUSTERILER!$B$7:$B$106,0)),"TANIMSIZ MÜŞTERİ")) | G22: Pasif | H22: =IF(OR($B22="",$D22="",$F22=""),0,$F22*MAX(0,INT((MIN(IF($E22="",TODAY(),$E22),TODAY())-$D22)/7)+1)) | I22: =IF(OR($B22="",$D22="",$F22=""),0,$F22*MAX(0,INT((MIN(IF($E22="",TODAY()-8,$E22),TODAY()-8)-$D22)/7)+1)) | J22: =IF(OR($B22="",$D22="",$F22=""),0,$F22*MAX(0,INT((MIN(IF($E22="",TODAY()-15,$E22),TODAY()-15)-$D22)/7)+1)) | K22: =IF(OR($B22="",$D22="",$F22=""),0,$F22*MAX(0,INT((MIN(IF($E22="",TODAY()-29,$E22),TODAY()-29)-$D22)/7)+1)) | L22: =IF($F22>0,$H22/$F22,0) | M22: =IF($B22="","",IF($C22="TANIMSIZ MÜŞTERİ","HATA",IF($G22="Pasif","PASİF",IF(AND(WEEKDAY($D22,2)=6,OR($E22="",WEEKDAY($E22,2)=6),$F22>0),"UYGUN","HATA")))) | N22: Haftalık ücret girilmeli
B23: M017 | C23: =IF($B23="","",IFERROR(INDEX(MUSTERILER!$C$7:$C$106,MATCH($B23,MUSTERILER!$B$7:$B$106,0)),"TANIMSIZ MÜŞTERİ")) | G23: Pasif | H23: =IF(OR($B23="",$D23="",$F23=""),0,$F23*MAX(0,INT((MIN(IF($E23="",TODAY(),$E23),TODAY())-$D23)/7)+1)) | I23: =IF(OR($B23="",$D23="",$F23=""),0,$F23*MAX(0,INT((MIN(IF($E23="",TODAY()-8,$E23),TODAY()-8)-$D23)/7)+1)) | J23: =IF(OR($B23="",$D23="",$F23=""),0,$F23*MAX(0,INT((MIN(IF($E23="",TODAY()-15,$E23),TODAY()-15)-$D23)/7)+1)) | K23: =IF(OR($B23="",$D23="",$F23=""),0,$F23*MAX(0,INT((MIN(IF($E23="",TODAY()-29,$E23),TODAY()-29)-$D23)/7)+1)) | L23: =IF($F23>0,$H23/$F23,0) | M23: =IF($B23="","",IF($C23="TANIMSIZ MÜŞTERİ","HATA",IF($G23="Pasif","PASİF",IF(AND(WEEKDAY($D23,2)=6,OR($E23="",WEEKDAY($E23,2)=6),$F23>0),"UYGUN","HATA")))) | N23: Haftalık ücret girilmeli
B24: M018 | C24: =IF($B24="","",IFERROR(INDEX(MUSTERILER!$C$7:$C$106,MATCH($B24,MUSTERILER!$B$7:$B$106,0)),"TANIMSIZ MÜŞTERİ")) | G24: Pasif | H24: =IF(OR($B24="",$D24="",$F24=""),0,$F24*MAX(0,INT((MIN(IF($E24="",TODAY(),$E24),TODAY())-$D24)/7)+1)) | I24: =IF(OR($B24="",$D24="",$F24=""),0,$F24*MAX(0,INT((MIN(IF($E24="",TODAY()-8,$E24),TODAY()-8)-$D24)/7)+1)) | J24: =IF(OR($B24="",$D24="",$F24=""),0,$F24*MAX(0,INT((MIN(IF($E24="",TODAY()-15,$E24),TODAY()-15)-$D24)/7)+1)) | K24: =IF(OR($B24="",$D24="",$F24=""),0,$F24*MAX(0,INT((MIN(IF($E24="",TODAY()-29,$E24),TODAY()-29)-$D24)/7)+1)) | L24: =IF($F24>0,$H24/$F24,0) | M24: =IF($B24="","",IF($C24="TANIMSIZ MÜŞTERİ","HATA",IF($G24="Pasif","PASİF",IF(AND(WEEKDAY($D24,2)=6,OR($E24="",WEEKDAY($E24,2)=6),$F24>0),"UYGUN","HATA")))) | N24: Haftalık ücret girilmeli
B25: M019 | C25: =IF($B25="","",IFERROR(INDEX(MUSTERILER!$C$7:$C$106,MATCH($B25,MUSTERILER!$B$7:$B$106,0)),"TANIMSIZ MÜŞTERİ")) | G25: Pasif | H25: =IF(OR($B25="",$D25="",$F25=""),0,$F25*MAX(0,INT((MIN(IF($E25="",TODAY(),$E25),TODAY())-$D25)/7)+1)) | I25: =IF(OR($B25="",$D25="",$F25=""),0,$F25*MAX(0,INT((MIN(IF($E25="",TODAY()-8,$E25),TODAY()-8)-$D25)/7)+1)) | J25: =IF(OR($B25="",$D25="",$F25=""),0,$F25*MAX(0,INT((MIN(IF($E25="",TODAY()-15,$E25),TODAY()-15)-$D25)/7)+1)) | K25: =IF(OR($B25="",$D25="",$F25=""),0,$F25*MAX(0,INT((MIN(IF($E25="",TODAY()-29,$E25),TODAY()-29)-$D25)/7)+1)) | L25: =IF($F25>0,$H25/$F25,0) | M25: =IF($B25="","",IF($C25="TANIMSIZ MÜŞTERİ","HATA",IF($G25="Pasif","PASİF",IF(AND(WEEKDAY($D25,2)=6,OR($E25="",WEEKDAY($E25,2)=6),$F25>0),"UYGUN","HATA")))) | N25: Haftalık ücret girilmeli
B26: M020 | C26: =IF($B26="","",IFERROR(INDEX(MUSTERILER!$C$7:$C$106,MATCH($B26,MUSTERILER!$B$7:$B$106,0)),"TANIMSIZ MÜŞTERİ")) | G26: Pasif | H26: =IF(OR($B26="",$D26="",$F26=""),0,$F26*MAX(0,INT((MIN(IF($E26="",TODAY(),$E26),TODAY())-$D26)/7)+1)) | I26: =IF(OR($B26="",$D26="",$F26=""),0,$F26*MAX(0,INT((MIN(IF($E26="",TODAY()-8,$E26),TODAY()-8)-$D26)/7)+1)) | J26: =IF(OR($B26="",$D26="",$F26=""),0,$F26*MAX(0,INT((MIN(IF($E26="",TODAY()-15,$E26),TODAY()-15)-$D26)/7)+1)) | K26: =IF(OR($B26="",$D26="",$F26=""),0,$F26*MAX(0,INT((MIN(IF($E26="",TODAY()-29,$E26),TODAY()-29)-$D26)/7)+1)) | L26: =IF($F26>0,$H26/$F26,0) | M26: =IF($B26="","",IF($C26="TANIMSIZ MÜŞTERİ","HATA",IF($G26="Pasif","PASİF",IF(AND(WEEKDAY($D26,2)=6,OR($E26="",WEEKDAY($E26,2)=6),$F26>0),"UYGUN","HATA")))) | N26: Haftalık ücret girilmeli
B27: M021 | C27: =IF($B27="","",IFERROR(INDEX(MUSTERILER!$C$7:$C$106,MATCH($B27,MUSTERILER!$B$7:$B$106,0)),"TANIMSIZ MÜŞTERİ")) | G27: Pasif | H27: =IF(OR($B27="",$D27="",$F27=""),0,$F27*MAX(0,INT((MIN(IF($E27="",TODAY(),$E27),TODAY())-$D27)/7)+1)) | I27: =IF(OR($B27="",$D27="",$F27=""),0,$F27*MAX(0,INT((MIN(IF($E27="",TODAY()-8,$E27),TODAY()-8)-$D27)/7)+1)) | J27: =IF(OR($B27="",$D27="",$F27=""),0,$F27*MAX(0,INT((MIN(IF($E27="",TODAY()-15,$E27),TODAY()-15)-$D27)/7)+1)) | K27: =IF(OR($B27="",$D27="",$F27=""),0,$F27*MAX(0,INT((MIN(IF($E27="",TODAY()-29,$E27),TODAY()-29)-$D27)/7)+1)) | L27: =IF($F27>0,$H27/$F27,0) | M27: =IF($B27="","",IF($C27="TANIMSIZ MÜŞTERİ","HATA",IF($G27="Pasif","PASİF",IF(AND(WEEKDAY($D27,2)=6,OR($E27="",WEEKDAY($E27,2)=6),$F27>0),"UYGUN","HATA")))) | N27: Haftalık ücret girilmeli
C28: =IF($B28="","",IFERROR(INDEX(MUSTERILER!$C$7:$C$106,MATCH($B28,MUSTERILER!$B$7:$B$106,0)),"TANIMSIZ MÜŞTERİ")) | H28: =IF(OR($B28="",$D28="",$F28=""),0,$F28*MAX(0,INT((MIN(IF($E28="",TODAY(),$E28),TODAY())-$D28)/7)+1)) | I28: =IF(OR($B28="",$D28="",$F28=""),0,$F28*MAX(0,INT((MIN(IF($E28="",TODAY()-8,$E28),TODAY()-8)-$D28)/7)+1)) | J28: =IF(OR($B28="",$D28="",$F28=""),0,$F28*MAX(0,INT((MIN(IF($E28="",TODAY()-15,$E28),TODAY()-15)-$D28)/7)+1)) | K28: =IF(OR($B28="",$D28="",$F28=""),0,$F28*MAX(0,INT((MIN(IF($E28="",TODAY()-29,$E28),TODAY()-29)-$D28)/7)+1)) | L28: =IF($F28>0,$H28/$F28,0) | M28: =IF($B28="","",IF($C28="TANIMSIZ MÜŞTERİ","HATA",IF($G28="Pasif","PASİF",IF(AND(WEEKDAY($D28,2)=6,OR($E28="",WEEKDAY($E28,2)=6),$F28>0),"UYGUN","HATA"))))
C29: =IF($B29="","",IFERROR(INDEX(MUSTERILER!$C$7:$C$106,MATCH($B29,MUSTERILER!$B$7:$B$106,0)),"TANIMSIZ MÜŞTERİ")) | H29: =IF(OR($B29="",$D29="",$F29=""),0,$F29*MAX(0,INT((MIN(IF($E29="",TODAY(),$E29),TODAY())-$D29)/7)+1)) | I29: =IF(OR($B29="",$D29="",$F29=""),0,$F29*MAX(0,INT((MIN(IF($E29="",TODAY()-8,$E29),TODAY()-8)-$D29)/7)+1)) | J29: =IF(OR($B29="",$D29="",$F29=""),0,$F29*MAX(0,INT((MIN(IF($E29="",TODAY()-15,$E29),TODAY()-15)-$D29)/7)+1)) | K29: =IF(OR($B29="",$D29="",$F29=""),0,$F29*MAX(0,INT((MIN(IF($E29="",TODAY()-29,$E29),TODAY()-29)-$D29)/7)+1)) | L29: =IF($F29>0,$H29/$F29,0) | M29: =IF($B29="","",IF($C29="TANIMSIZ MÜŞTERİ","HATA",IF($G29="Pasif","PASİF",IF(AND(WEEKDAY($D29,2)=6,OR($E29="",WEEKDAY($E29,2)=6),$F29>0),"UYGUN","HATA"))))
C30: =IF($B30="","",IFERROR(INDEX(MUSTERILER!$C$7:$C$106,MATCH($B30,MUSTERILER!$B$7:$B$106,0)),"TANIMSIZ MÜŞTERİ")) | H30: =IF(OR($B30="",$D30="",$F30=""),0,$F30*MAX(0,INT((MIN(IF($E30="",TODAY(),$E30),TODAY())-$D30)/7)+1)) | I30: =IF(OR($B30="",$D30="",$F30=""),0,$F30*MAX(0,INT((MIN(IF($E30="",TODAY()-8,$E30),TODAY()-8)-$D30)/7)+1)) | J30: =IF(OR($B30="",$D30="",$F30=""),0,$F30*MAX(0,INT((MIN(IF($E30="",TODAY()-15,$E30),TODAY()-15)-$D30)/7)+1)) | K30: =IF(OR($B30="",$D30="",$F30=""),0,$F30*MAX(0,INT((MIN(IF($E30="",TODAY()-29,$E30),TODAY()-29)-$D30)/7)+1)) | L30: =IF($F30>0,$H30/$F30,0) | M30: =IF($B30="","",IF($C30="TANIMSIZ MÜŞTERİ","HATA",IF($G30="Pasif","PASİF",IF(AND(WEEKDAY($D30,2)=6,OR($E30="",WEEKDAY($E30,2)=6),$F30>0),"UYGUN","HATA"))))
C31: =IF($B31="","",IFERROR(INDEX(MUSTERILER!$C$7:$C$106,MATCH($B31,MUSTERILER!$B$7:$B$106,0)),"TANIMSIZ MÜŞTERİ")) | H31: =IF(OR($B31="",$D31="",$F31=""),0,$F31*MAX(0,INT((MIN(IF($E31="",TODAY(),$E31),TODAY())-$D31)/7)+1)) | I31: =IF(OR($B31="",$D31="",$F31=""),0,$F31*MAX(0,INT((MIN(IF($E31="",TODAY()-8,$E31),TODAY()-8)-$D31)/7)+1)) | J31: =IF(OR($B31="",$D31="",$F31=""),0,$F31*MAX(0,INT((MIN(IF($E31="",TODAY()-15,$E31),TODAY()-15)-$D31)/7)+1)) | K31: =IF(OR($B31="",$D31="",$F31=""),0,$F31*MAX(0,INT((MIN(IF($E31="",TODAY()-29,$E31),TODAY()-29)-$D31)/7)+1)) | L31: =IF($F31>0,$H31/$F31,0) | M31: =IF($B31="","",IF($C31="TANIMSIZ MÜŞTERİ","HATA",IF($G31="Pasif","PASİF",IF(AND(WEEKDAY($D31,2)=6,OR($E31="",WEEKDAY($E31,2)=6),$F31>0),"UYGUN","HATA"))))
C32: =IF($B32="","",IFERROR(INDEX(MUSTERILER!$C$7:$C$106,MATCH($B32,MUSTERILER!$B$7:$B$106,0)),"TANIMSIZ MÜŞTERİ")) | H32: =IF(OR($B32="",$D32="",$F32=""),0,$F32*MAX(0,INT((MIN(IF($E32="",TODAY(),$E32),TODAY())-$D32)/7)+1)) | I32: =IF(OR($B32="",$D32="",$F32=""),0,$F32*MAX(0,INT((MIN(IF($E32="",TODAY()-8,$E32),TODAY()-8)-$D32)/7)+1)) | J32: =IF(OR($B32="",$D32="",$F32=""),0,$F32*MAX(0,INT((MIN(IF($E32="",TODAY()-15,$E32),TODAY()-15)-$D32)/7)+1)) | K32: =IF(OR($B32="",$D32="",$F32=""),0,$F32*MAX(0,INT((MIN(IF($E32="",TODAY()-29,$E32),TODAY()-29)-$D32)/7)+1)) | L32: =IF($F32>0,$H32/$F32,0) | M32: =IF($B32="","",IF($C32="TANIMSIZ MÜŞTERİ","HATA",IF($G32="Pasif","PASİF",IF(AND(WEEKDAY($D32,2)=6,OR($E32="",WEEKDAY($E32,2)=6),$F32>0),"UYGUN","HATA"))))
C33: =IF($B33="","",IFERROR(INDEX(MUSTERILER!$C$7:$C$106,MATCH($B33,MUSTERILER!$B$7:$B$106,0)),"TANIMSIZ MÜŞTERİ")) | H33: =IF(OR($B33="",$D33="",$F33=""),0,$F33*MAX(0,INT((MIN(IF($E33="",TODAY(),$E33),TODAY())-$D33)/7)+1)) | I33: =IF(OR($B33="",$D33="",$F33=""),0,$F33*MAX(0,INT((MIN(IF($E33="",TODAY()-8,$E33),TODAY()-8)-$D33)/7)+1)) | J33: =IF(OR($B33="",$D33="",$F33=""),0,$F33*MAX(0,INT((MIN(IF($E33="",TODAY()-15,$E33),TODAY()-15)-$D33)/7)+1)) | K33: =IF(OR($B33="",$D33="",$F33=""),0,$F33*MAX(0,INT((MIN(IF($E33="",TODAY()-29,$E33),TODAY()-29)-$D33)/7)+1)) | L33: =IF($F33>0,$H33/$F33,0) | M33: =IF($B33="","",IF($C33="TANIMSIZ MÜŞTERİ","HATA",IF($G33="Pasif","PASİF",IF(AND(WEEKDAY($D33,2)=6,OR($E33="",WEEKDAY($E33,2)=6),$F33>0),"UYGUN","HATA"))))
C34: =IF($B34="","",IFERROR(INDEX(MUSTERILER!$C$7:$C$106,MATCH($B34,MUSTERILER!$B$7:$B$106,0)),"TANIMSIZ MÜŞTERİ")) | H34: =IF(OR($B34="",$D34="",$F34=""),0,$F34*MAX(0,INT((MIN(IF($E34="",TODAY(),$E34),TODAY())-$D34)/7)+1)) | I34: =IF(OR($B34="",$D34="",$F34=""),0,$F34*MAX(0,INT((MIN(IF($E34="",TODAY()-8,$E34),TODAY()-8)-$D34)/7)+1)) | J34: =IF(OR($B34="",$D34="",$F34=""),0,$F34*MAX(0,INT((MIN(IF($E34="",TODAY()-15,$E34),TODAY()-15)-$D34)/7)+1)) | K34: =IF(OR($B34="",$D34="",$F34=""),0,$F34*MAX(0,INT((MIN(IF($E34="",TODAY()-29,$E34),TODAY()-29)-$D34)/7)+1)) | L34: =IF($F34>0,$H34/$F34,0) | M34: =IF($B34="","",IF($C34="TANIMSIZ MÜŞTERİ","HATA",IF($G34="Pasif","PASİF",IF(AND(WEEKDAY($D34,2)=6,OR($E34="",WEEKDAY($E34,2)=6),$F34>0),"UYGUN","HATA"))))
C35: =IF($B35="","",IFERROR(INDEX(MUSTERILER!$C$7:$C$106,MATCH($B35,MUSTERILER!$B$7:$B$106,0)),"TANIMSIZ MÜŞTERİ")) | H35: =IF(OR($B35="",$D35="",$F35=""),0,$F35*MAX(0,INT((MIN(IF($E35="",TODAY(),$E35),TODAY())-$D35)/7)+1)) | I35: =IF(OR($B35="",$D35="",$F35=""),0,$F35*MAX(0,INT((MIN(IF($E35="",TODAY()-8,$E35),TODAY()-8)-$D35)/7)+1)) | J35: =IF(OR($B35="",$D35="",$F35=""),0,$F35*MAX(0,INT((MIN(IF($E35="",TODAY()-15,$E35),TODAY()-15)-$D35)/7)+1)) | K35: =IF(OR($B35="",$D35="",$F35=""),0,$F35*MAX(0,INT((MIN(IF($E35="",TODAY()-29,$E35),TODAY()-29)-$D35)/7)+1)) | L35: =IF($F35>0,$H35/$F35,0) | M35: =IF($B35="","",IF($C35="TANIMSIZ MÜŞTERİ","HATA",IF($G35="Pasif","PASİF",IF(AND(WEEKDAY($D35,2)=6,OR($E35="",WEEKDAY($E35,2)=6),$F35>0),"UYGUN","HATA"))))
C36: =IF($B36="","",IFERROR(INDEX(MUSTERILER!$C$7:$C$106,MATCH($B36,MUSTERILER!$B$7:$B$106,0)),"TANIMSIZ MÜŞTERİ")) | H36: =IF(OR($B36="",$D36="",$F36=""),0,$F36*MAX(0,INT((MIN(IF($E36="",TODAY(),$E36),TODAY())-$D36)/7)+1)) | I36: =IF(OR($B36="",$D36="",$F36=""),0,$F36*MAX(0,INT((MIN(IF($E36="",TODAY()-8,$E36),TODAY()-8)-$D36)/7)+1)) | J36: =IF(OR($B36="",$D36="",$F36=""),0,$F36*MAX(0,INT((MIN(IF($E36="",TODAY()-15,$E36),TODAY()-15)-$D36)/7)+1)) | K36: =IF(OR($B36="",$D36="",$F36=""),0,$F36*MAX(0,INT((MIN(IF($E36="",TODAY()-29,$E36),TODAY()-29)-$D36)/7)+1)) | L36: =IF($F36>0,$H36/$F36,0) | M36: =IF($B36="","",IF($C36="TANIMSIZ MÜŞTERİ","HATA",IF($G36="Pasif","PASİF",IF(AND(WEEKDAY($D36,2)=6,OR($E36="",WEEKDAY($E36,2)=6),$F36>0),"UYGUN","HATA"))))
C37: =IF($B37="","",IFERROR(INDEX(MUSTERILER!$C$7:$C$106,MATCH($B37,MUSTERILER!$B$7:$B$106,0)),"TANIMSIZ MÜŞTERİ")) | H37: =IF(OR($B37="",$D37="",$F37=""),0,$F37*MAX(0,INT((MIN(IF($E37="",TODAY(),$E37),TODAY())-$D37)/7)+1)) | I37: =IF(OR($B37="",$D37="",$F37=""),0,$F37*MAX(0,INT((MIN(IF($E37="",TODAY()-8,$E37),TODAY()-8)-$D37)/7)+1)) | J37: =IF(OR($B37="",$D37="",$F37=""),0,$F37*MAX(0,INT((MIN(IF($E37="",TODAY()-15,$E37),TODAY()-15)-$D37)/7)+1)) | K37: =IF(OR($B37="",$D37="",$F37=""),0,$F37*MAX(0,INT((MIN(IF($E37="",TODAY()-29,$E37),TODAY()-29)-$D37)/7)+1)) | L37: =IF($F37>0,$H37/$F37,0) | M37: =IF($B37="","",IF($C37="TANIMSIZ MÜŞTERİ","HATA",IF($G37="Pasif","PASİF",IF(AND(WEEKDAY($D37,2)=6,OR($E37="",WEEKDAY($E37,2)=6),$F37>0),"UYGUN","HATA"))))
C38: =IF($B38="","",IFERROR(INDEX(MUSTERILER!$C$7:$C$106,MATCH($B38,MUSTERILER!$B$7:$B$106,0)),"TANIMSIZ MÜŞTERİ")) | H38: =IF(OR($B38="",$D38="",$F38=""),0,$F38*MAX(0,INT((MIN(IF($E38="",TODAY(),$E38),TODAY())-$D38)/7)+1)) | I38: =IF(OR($B38="",$D38="",$F38=""),0,$F38*MAX(0,INT((MIN(IF($E38="",TODAY()-8,$E38),TODAY()-8)-$D38)/7)+1)) | J38: =IF(OR($B38="",$D38="",$F38=""),0,$F38*MAX(0,INT((MIN(IF($E38="",TODAY()-15,$E38),TODAY()-15)-$D38)/7)+1)) | K38: =IF(OR($B38="",$D38="",$F38=""),0,$F38*MAX(0,INT((MIN(IF($E38="",TODAY()-29,$E38),TODAY()-29)-$D38)/7)+1)) | L38: =IF($F38>0,$H38/$F38,0) | M38: =IF($B38="","",IF($C38="TANIMSIZ MÜŞTERİ","HATA",IF($G38="Pasif","PASİF",IF(AND(WEEKDAY($D38,2)=6,OR($E38="",WEEKDAY($E38,2)=6),$F38>0),"UYGUN","HATA"))))
C39: =IF($B39="","",IFERROR(INDEX(MUSTERILER!$C$7:$C$106,MATCH($B39,MUSTERILER!$B$7:$B$106,0)),"TANIMSIZ MÜŞTERİ")) | H39: =IF(OR($B39="",$D39="",$F39=""),0,$F39*MAX(0,INT((MIN(IF($E39="",TODAY(),$E39),TODAY())-$D39)/7)+1)) | I39: =IF(OR($B39="",$D39="",$F39=""),0,$F39*MAX(0,INT((MIN(IF($E39="",TODAY()-8,$E39),TODAY()-8)-$D39)/7)+1)) | J39: =IF(OR($B39="",$D39="",$F39=""),0,$F39*MAX(0,INT((MIN(IF($E39="",TODAY()-15,$E39),TODAY()-15)-$D39)/7)+1)) | K39: =IF(OR($B39="",$D39="",$F39=""),0,$F39*MAX(0,INT((MIN(IF($E39="",TODAY()-29,$E39),TODAY()-29)-$D39)/7)+1)) | L39: =IF($F39>0,$H39/$F39,0) | M39: =IF($B39="","",IF($C39="TANIMSIZ MÜŞTERİ","HATA",IF($G39="Pasif","PASİF",IF(AND(WEEKDAY($D39,2)=6,OR($E39="",WEEKDAY($E39,2)=6),$F39>0),"UYGUN","HATA"))))
... C406: =IF($B406="","",IFERROR(INDEX(MUSTERILER!$C$7:$C$106,MATCH($B406,MUSTERILER!$B$7:$B$106,0)),"TANIMSIZ MÜŞTERİ")) | H406: =IF(OR($B406="",$D406="",$F406=""),0,$F406*MAX(0,INT((MIN(IF($E406="",TODAY(),$E406),TODAY())-$D406)/7)+1)) | I406: =IF(OR($B406="",$D406="",$F406=""),0,$F406*MAX(0,INT((MIN(IF($E406="",TODAY()-8,$E406),TODAY()-8)-$D406)/7)+1)) | J406: =IF(OR($B406="",$D406="",$F406=""),0,$F406*MAX(0,INT((MIN(IF($E406="",TODAY()-15,$E406),TODAY()-15)-$D406)/7)+1)) | K406: =IF(OR($B406="",$D406="",$F406=""),0,$F406*MAX(0,INT((MIN(IF($E406="",TODAY()-29,$E406),TODAY()-29)-$D406)/7)+1)) | L406: =IF($F406>0,$H406/$F406,0) | M406: =IF($B406="","",IF($C406="TANIMSIZ MÜŞTERİ","HATA",IF($G406="Pasif","PASİF",IF(AND(WEEKDAY($D406,2)=6,OR($E406="",WEEKDAY($E406,2)=6),$F406>0),"UYGUN","HATA"))))

Sheet TAHSILAT
A1: NECATİBEY OFİS YÖNETİM SİSTEMİ │ MÜŞTERİ TAHSİLATI
A2: Bir ödeme yalnız buraya girilir │ Cari, kasa, aylık kapanış ve nakit kâr otomatik güncellenir
B4: =HYPERLINK("#PANO!A1","← PANO") | D4: =HYPERLINK("#MUSTERI_360!A1","Müşteri 360") | F4: =HYPERLINK("#HESAPLAR!A1","Hesaplar") | H4: Sarı hücreler veri girişidir. Beyaz hücreler sistem tarafından hesaplanır ve kilitlidir. Aynı ödemeyi başka bir ekrana tekrar girmeyin.
B5: =COUNTIF($C$7:$C$1506,"<>") | C5: TOPLAM │ Kayıtlı tahsilat | F5: =SUM($F$7:$F$1506)
B6: Tahsilat No | C6: Müşteri No | D6: Müşteri | E6: Tarih | F6: Tutar | G6: Kasa / Banka | H6: Ödeme Türü | I6: Belge No | J6: Açıklama | K6: İşlemi Giren | L6: Ay | M6: Kayıt Kontrolü
B7: =IF($C7="","","T"&TEXT(ROW()-6,"00000")) | D7: =IF($C7="","",IFERROR(INDEX(MUSTERILER!$C$7:$C$106,MATCH($C7,MUSTERILER!$B$7:$B$106,0)),"TANIMSIZ MÜŞTERİ")) | L7: =IF($E7="","",DATE(YEAR($E7),MONTH($E7),1)) | M7: =IF($C7="","",IF($D7="TANIMSIZ MÜŞTERİ","HATA",IF(OR($E7="",$F7<=0,$G7=""),"EKSİK",IF($E7>TODAY(),"İLERİ TARİH","UYGUN"))))
B8: =IF($C8="","","T"&TEXT(ROW()-6,"00000")) | D8: =IF($C8="","",IFERROR(INDEX(MUSTERILER!$C$7:$C$106,MATCH($C8,MUSTERILER!$B$7:$B$106,0)),"TANIMSIZ MÜŞTERİ")) | L8: =IF($E8="","",DATE(YEAR($E8),MONTH($E8),1)) | M8: =IF($C8="","",IF($D8="TANIMSIZ MÜŞTERİ","HATA",IF(OR($E8="",$F8<=0,$G8=""),"EKSİK",IF($E8>TODAY(),"İLERİ TARİH","UYGUN"))))
B9: =IF($C9="","","T"&TEXT(ROW()-6,"00000")) | D9: =IF($C9="","",IFERROR(INDEX(MUSTERILER!$C$7:$C$106,MATCH($C9,MUSTERILER!$B$7:$B$106,0)),"TANIMSIZ MÜŞTERİ")) | L9: =IF($E9="","",DATE(YEAR($E9),MONTH($E9),1)) | M9: =IF($C9="","",IF($D9="TANIMSIZ MÜŞTERİ","HATA",IF(OR($E9="",$F9<=0,$G9=""),"EKSİK",IF($E9>TODAY(),"İLERİ TARİH","UYGUN"))))
B10: =IF($C10="","","T"&TEXT(ROW()-6,"00000")) | D10: =IF($C10="","",IFERROR(INDEX(MUSTERILER!$C$7:$C$106,MATCH($C10,MUSTERILER!$B$7:$B$106,0)),"TANIMSIZ MÜŞTERİ")) | L10: =IF($E10="","",DATE(YEAR($E10),MONTH($E10),1)) | M10: =IF($C10="","",IF($D10="TANIMSIZ MÜŞTERİ","HATA",IF(OR($E10="",$F10<=0,$G10=""),"EKSİK",IF($E10>TODAY(),"İLERİ TARİH","UYGUN"))))
B11: =IF($C11="","","T"&TEXT(ROW()-6,"00000")) | D11: =IF($C11="","",IFERROR(INDEX(MUSTERILER!$C$7:$C$106,MATCH($C11,MUSTERILER!$B$7:$B$106,0)),"TANIMSIZ MÜŞTERİ")) | L11: =IF($E11="","",DATE(YEAR($E11),MONTH($E11),1)) | M11: =IF($C11="","",IF($D11="TANIMSIZ MÜŞTERİ","HATA",IF(OR($E11="",$F11<=0,$G11=""),"EKSİK",IF($E11>TODAY(),"İLERİ TARİH","UYGUN"))))
B12: =IF($C12="","","T"&TEXT(ROW()-6,"00000")) | D12: =IF($C12="","",IFERROR(INDEX(MUSTERILER!$C$7:$C$106,MATCH($C12,MUSTERILER!$B$7:$B$106,0)),"TANIMSIZ MÜŞTERİ")) | L12: =IF($E12="","",DATE(YEAR($E12),MONTH($E12),1)) | M12: =IF($C12="","",IF($D12="TANIMSIZ MÜŞTERİ","HATA",IF(OR($E12="",$F12<=0,$G12=""),"EKSİK",IF($E12>TODAY(),"İLERİ TARİH","UYGUN"))))
B13: =IF($C13="","","T"&TEXT(ROW()-6,"00000")) | D13: =IF($C13="","",IFERROR(INDEX(MUSTERILER!$C$7:$C$106,MATCH($C13,MUSTERILER!$B$7:$B$106,0)),"TANIMSIZ MÜŞTERİ")) | L13: =IF($E13="","",DATE(YEAR($E13),MONTH($E13),1)) | M13: =IF($C13="","",IF($D13="TANIMSIZ MÜŞTERİ","HATA",IF(OR($E13="",$F13<=0,$G13=""),"EKSİK",IF($E13>TODAY(),"İLERİ TARİH","UYGUN"))))
B14: =IF($C14="","","T"&TEXT(ROW()-6,"00000")) | D14: =IF($C14="","",IFERROR(INDEX(MUSTERILER!$C$7:$C$106,MATCH($C14,MUSTERILER!$B$7:$B$106,0)),"TANIMSIZ MÜŞTERİ")) | L14: =IF($E14="","",DATE(YEAR($E14),MONTH($E14),1)) | M14: =IF($C14="","",IF($D14="TANIMSIZ MÜŞTERİ","HATA",IF(OR($E14="",$F14<=0,$G14=""),"EKSİK",IF($E14>TODAY(),"İLERİ TARİH","UYGUN"))))
B15: =IF($C15="","","T"&TEXT(ROW()-6,"00000")) | D15: =IF($C15="","",IFERROR(INDEX(MUSTERILER!$C$7:$C$106,MATCH($C15,MUSTERILER!$B$7:$B$106,0)),"TANIMSIZ MÜŞTERİ")) | L15: =IF($E15="","",DATE(YEAR($E15),MONTH($E15),1)) | M15: =IF($C15="","",IF($D15="TANIMSIZ MÜŞTERİ","HATA",IF(OR($E15="",$F15<=0,$G15=""),"EKSİK",IF($E15>TODAY(),"İLERİ TARİH","UYGUN"))))
B16: =IF($C16="","","T"&TEXT(ROW()-6,"00000")) | D16: =IF($C16="","",IFERROR(INDEX(MUSTERILER!$C$7:$C$106,MATCH($C16,MUSTERILER!$B$7:$B$106,0)),"TANIMSIZ MÜŞTERİ")) | L16: =IF($E16="","",DATE(YEAR($E16),MONTH($E16),1)) | M16: =IF($C16="","",IF($D16="TANIMSIZ MÜŞTERİ","HATA",IF(OR($E16="",$F16<=0,$G16=""),"EKSİK",IF($E16>TODAY(),"İLERİ TARİH","UYGUN"))))
B17: =IF($C17="","","T"&TEXT(ROW()-6,"00000")) | D17: =IF($C17="","",IFERROR(INDEX(MUSTERILER!$C$7:$C$106,MATCH($C17,MUSTERILER!$B$7:$B$106,0)),"TANIMSIZ MÜŞTERİ")) | L17: =IF($E17="","",DATE(YEAR($E17),MONTH($E17),1)) | M17: =IF($C17="","",IF($D17="TANIMSIZ MÜŞTERİ","HATA",IF(OR($E17="",$F17<=0,$G17=""),"EKSİK",IF($E17>TODAY(),"İLERİ TARİH","UYGUN"))))
B18: =IF($C18="","","T"&TEXT(ROW()-6,"00000")) | D18: =IF($C18="","",IFERROR(INDEX(MUSTERILER!$C$7:$C$106,MATCH($C18,MUSTERILER!$B$7:$B$106,0)),"TANIMSIZ MÜŞTERİ")) | L18: =IF($E18="","",DATE(YEAR($E18),MONTH($E18),1)) | M18: =IF($C18="","",IF($D18="TANIMSIZ MÜŞTERİ","HATA",IF(OR($E18="",$F18<=0,$G18=""),"EKSİK",IF($E18>TODAY(),"İLERİ TARİH","UYGUN"))))
... B1506: =IF($C1506="","","T"&TEXT(ROW()-6,"00000")) | D1506: =IF($C1506="","",IFERROR(INDEX(MUSTERILER!$C$7:$C$106,MATCH($C1506,MUSTERILER!$B$7:$B$106,0)),"TANIMSIZ MÜŞTERİ")) | L1506: =IF($E1506="","",DATE(YEAR($E1506),MONTH($E1506),1)) | M1506: =IF($C1506="","",IF($D1506="TANIMSIZ MÜŞTERİ","HATA",IF(OR($E1506="",$F1506<=0,$G1506=""),"EKSİK",IF($E1506>TODAY(),"İLERİ TARİH","UYGUN"))))

Sheet GELIR_GIDER
A1: NECATİBEY OFİS YÖNETİM SİSTEMİ │ OFİS GELİR VE GİDERLERİ
A2: Müşteri tahsilatı dışındaki tüm nakit hareketleri │ Hesaplar arası transfer buraya gİRMEZ
B4: =HYPERLINK("#PANO!A1","← PANO") | D4: =HYPERLINK("#VIRMAN!A1","Virman") | F4: =HYPERLINK("#AY_SONU!A1","Ay Sonu") | H4: Sarı hücreler veri girişidir. Beyaz hücreler sistem tarafından hesaplanır ve kilitlidir. Ödemenin gerçekleştiğini işaretlemezseniz nakit kâra yansımaz.
C5: TOPLAM │ Gerçekleşmiş gelir ve gider | G5: =SUMIFS($G$7:$G$1206,$D$7:$D$1206,"Gelir",$I$7:$I$1206,"Evet")-SUMIFS($G$7:$G$1206,$D$7:$D$1206,"Gider",$I$7:$I$1206,"Evet")
B6: Kayıt No | C6: Tarih | D6: Tür | E6: Kategori | F6: Açıklama | G6: Tutar | H6: Kasa / Banka | I6: Gerçekleşti | J6: Belge No | K6: Sorumlu | L6: Ay | M6: Kayıt Kontrolü
B7: =IF($C7="","","GG"&TEXT(ROW()-6,"00000")) | L7: =IF($C7="","",DATE(YEAR($C7),MONTH($C7),1)) | M7: =IF($C7="","",IF(AND($D7<>"",$E7<>"",$G7>0,$H7<>"",$I7<>""),IF($C7>TODAY(),"İLERİ TARİH","UYGUN"),"EKSİK"))
B8: =IF($C8="","","GG"&TEXT(ROW()-6,"00000")) | L8: =IF($C8="","",DATE(YEAR($C8),MONTH($C8),1)) | M8: =IF($C8="","",IF(AND($D8<>"",$E8<>"",$G8>0,$H8<>"",$I8<>""),IF($C8>TODAY(),"İLERİ TARİH","UYGUN"),"EKSİK"))
B9: =IF($C9="","","GG"&TEXT(ROW()-6,"00000")) | L9: =IF($C9="","",DATE(YEAR($C9),MONTH($C9),1)) | M9: =IF($C9="","",IF(AND($D9<>"",$E9<>"",$G9>0,$H9<>"",$I9<>""),IF($C9>TODAY(),"İLERİ TARİH","UYGUN"),"EKSİK"))
B10: =IF($C10="","","GG"&TEXT(ROW()-6,"00000")) | L10: =IF($C10="","",DATE(YEAR($C10),MONTH($C10),1)) | M10: =IF($C10="","",IF(AND($D10<>"",$E10<>"",$G10>0,$H10<>"",$I10<>""),IF($C10>TODAY(),"İLERİ TARİH","UYGUN"),"EKSİK"))
B11: =IF($C11="","","GG"&TEXT(ROW()-6,"00000")) | L11: =IF($C11="","",DATE(YEAR($C11),MONTH($C11),1)) | M11: =IF($C11="","",IF(AND($D11<>"",$E11<>"",$G11>0,$H11<>"",$I11<>""),IF($C11>TODAY(),"İLERİ TARİH","UYGUN"),"EKSİK"))
B12: =IF($C12="","","GG"&TEXT(ROW()-6,"00000")) | L12: =IF($C12="","",DATE(YEAR($C12),MONTH($C12),1)) | M12: =IF($C12="","",IF(AND($D12<>"",$E12<>"",$G12>0,$H12<>"",$I12<>""),IF($C12>TODAY(),"İLERİ TARİH","UYGUN"),"EKSİK"))
B13: =IF($C13="","","GG"&TEXT(ROW()-6,"00000")) | L13: =IF($C13="","",DATE(YEAR($C13),MONTH($C13),1)) | M13: =IF($C13="","",IF(AND($D13<>"",$E13<>"",$G13>0,$H13<>"",$I13<>""),IF($C13>TODAY(),"İLERİ TARİH","UYGUN"),"EKSİK"))
B14: =IF($C14="","","GG"&TEXT(ROW()-6,"00000")) | L14: =IF($C14="","",DATE(YEAR($C14),MONTH($C14),1)) | M14: =IF($C14="","",IF(AND($D14<>"",$E14<>"",$G14>0,$H14<>"",$I14<>""),IF($C14>TODAY(),"İLERİ TARİH","UYGUN"),"EKSİK"))
B15: =IF($C15="","","GG"&TEXT(ROW()-6,"00000")) | L15: =IF($C15="","",DATE(YEAR($C15),MONTH($C15),1)) | M15: =IF($C15="","",IF(AND($D15<>"",$E15<>"",$G15>0,$H15<>"",$I15<>""),IF($C15>TODAY(),"İLERİ TARİH","UYGUN"),"EKSİK"))
B16: =IF($C16="","","GG"&TEXT(ROW()-6,"00000")) | L16: =IF($C16="","",DATE(YEAR($C16),MONTH($C16),1)) | M16: =IF($C16="","",IF(AND($D16<>"",$E16<>"",$G16>0,$H16<>"",$I16<>""),IF($C16>TODAY(),"İLERİ TARİH","UYGUN"),"EKSİK"))
B17: =IF($C17="","","GG"&TEXT(ROW()-6,"00000")) | L17: =IF($C17="","",DATE(YEAR($C17),MONTH($C17),1)) | M17: =IF($C17="","",IF(AND($D17<>"",$E17<>"",$G17>0,$H17<>"",$I17<>""),IF($C17>TODAY(),"İLERİ TARİH","UYGUN"),"EKSİK"))
B18: =IF($C18="","","GG"&TEXT(ROW()-6,"00000")) | L18: =IF($C18="","",DATE(YEAR($C18),MONTH($C18),1)) | M18: =IF($C18="","",IF(AND($D18<>"",$E18<>"",$G18>0,$H18<>"",$I18<>""),IF($C18>TODAY(),"İLERİ TARİH","UYGUN"),"EKSİK"))
... B1206: =IF($C1206="","","GG"&TEXT(ROW()-6,"00000")) | L1206: =IF($C1206="","",DATE(YEAR($C1206),MONTH($C1206),1)) | M1206: =IF($C1206="","",IF(AND($D1206<>"",$E1206<>"",$G1206>0,$H1206<>"",$I1206<>""),IF($C1206>TODAY(),"İLERİ TARİH","UYGUN"),"EKSİK"))

Sheet VIRMAN
A1: NECATİBEY OFİS YÖNETİM SİSTEMİ │ KASA / BANKA ARASI VİRMAN
A2: Hesaplar arası para geçişi gelir veya gider değildir │ Toplam nakit değişmez
B4: =HYPERLINK("#PANO!A1","← PANO") | D4: =HYPERLINK("#HESAPLAR!A1","Hesaplar") | F4: Sarı hücreler veri girişidir. Beyaz hücreler sistem tarafından hesaplanır ve kilitlidir. Çıkan ve giren hesap aynı olamaz.
C5: TOPLAM │ Virman hacmi | F5: =SUM($F$7:$F$406)
B6: İşlem No | C6: Tarih | D6: Para Çıkan Hesap | E6: Para Giren Hesap | F6: Tutar | G6: Açıklama | H6: Belge No | I6: İşlemi Giren | J6: Sistem Kontrolü
B7: =IF($C7="","","V"&TEXT(ROW()-6,"00000")) | J7: =IF($C7="","",IF(AND($D7<>"",$E7<>"",$D7<>$E7,$F7>0),"UYGUN","HATA"))
B8: =IF($C8="","","V"&TEXT(ROW()-6,"00000")) | J8: =IF($C8="","",IF(AND($D8<>"",$E8<>"",$D8<>$E8,$F8>0),"UYGUN","HATA"))
B9: =IF($C9="","","V"&TEXT(ROW()-6,"00000")) | J9: =IF($C9="","",IF(AND($D9<>"",$E9<>"",$D9<>$E9,$F9>0),"UYGUN","HATA"))
B10: =IF($C10="","","V"&TEXT(ROW()-6,"00000")) | J10: =IF($C10="","",IF(AND($D10<>"",$E10<>"",$D10<>$E10,$F10>0),"UYGUN","HATA"))
B11: =IF($C11="","","V"&TEXT(ROW()-6,"00000")) | J11: =IF($C11="","",IF(AND($D11<>"",$E11<>"",$D11<>$E11,$F11>0),"UYGUN","HATA"))
B12: =IF($C12="","","V"&TEXT(ROW()-6,"00000")) | J12: =IF($C12="","",IF(AND($D12<>"",$E12<>"",$D12<>$E12,$F12>0),"UYGUN","HATA"))
