Workbook
Name LST_BORCLU_TARAF: SISTEM!$M$7:$M$63
Name LST_HESAP: SISTEM!$N$7:$N$20
Name LST_MUSTERI_ADI: MUSTERILER!$C$7:$C$156
Name LST_MUSTERI_NO: MUSTERILER!$B$7:$B$156
Name LST_ORTAK: SISTEM!$C$9:$C$10
Name LST_ORTAKLAR: ORTAKLAR!$B$7:$B$8
Name LST_VIRMAN_SINIF: SISTEM!$O$7:$O$10

Sheet MENU
B1: KILIÇ MUHASEBE │ OFİS YÖNETİM SİSTEMİ
B2: ◈ RAPOR / YÖNLENDİRME ALANI — VERİ GİRİŞİ YOK
B3: Yarı-ERP çalışma merkezi • sarı = veri girişi • beyaz = otomatik • kırmızı = müdahale gerekli
B5: YÖNETİM PANOSU | E5: BAŞUCU REHBERİ | H5: YÖNETİM RAPORU | K5: KONTROL MERKEZİ
B6: =IFERROR(HYPERLINK("#PANO!A1","AÇ"),"AÇ") -> AÇ | E6: =IFERROR(HYPERLINK("#BASLANGIC!A1","AÇ"),"AÇ") -> AÇ | H6: =IFERROR(HYPERLINK("#RAPOR!A1","AÇ"),"AÇ") -> AÇ | K6: =IFERROR(HYPERLINK("#KONTROL!A1","AÇ"),"AÇ") -> AÇ
B10: VERİ GİRİŞ EKRANLARI | I10: RAPOR / KONTROL EKRANLARI
B12: =IFERROR(HYPERLINK("#MUSTERILER!A1","MÜŞTERİLER"),"MÜŞTERİLER") -> MÜŞTERİLER | I12: =IFERROR(HYPERLINK("#MUSTERI_360!A1","MÜŞTERİ 360"),"MÜŞTERİ 360") -> MÜŞTERİ 360
B13: =IFERROR(HYPERLINK("#UCRETLER!A1","ÜCRETLER"),"ÜCRETLER") -> ÜCRETLER | I13: =IFERROR(HYPERLINK("#CARI_EKSTRE!A1","CARİ EKSTRE"),"CARİ EKSTRE") -> CARİ EKSTRE
B14: =IFERROR(HYPERLINK("#TAHSILAT!A1","TAHSİLAT"),"TAHSİLAT") -> TAHSİLAT | I14: =IFERROR(HYPERLINK("#ORTAK_EKSTRE!A1","ORTAK EKSTRE"),"ORTAK EKSTRE") -> ORTAK EKSTRE
B15: =IFERROR(HYPERLINK("#GELIR_GIDER!A1","GELİR / GİDER"),"GELİR / GİDER") -> GELİR / GİDER | I15: =IFERROR(HYPERLINK("#HESAPLAR!A1","HESAPLAR"),"HESAPLAR") -> HESAPLAR
B16: =IFERROR(HYPERLINK("#VIRMAN!A1","VİRMAN"),"VİRMAN") -> VİRMAN | I16: =IFERROR(HYPERLINK("#AY_SONU!A1","AY SONU"),"AY SONU") -> AY SONU
I17: =IFERROR(HYPERLINK("#ORTAKLAR!A1","ORTAKLAR"),"ORTAKLAR") -> ORTAKLAR
I18: =IFERROR(HYPERLINK("#KAR!A1","KÂR"),"KÂR") -> KÂR
B22: 4 ANA KURAL
B23: 1 Gerçek para hareketi yoksa VIRMAN yok.
B24: 2 Para Ömer'de kaldıysa TAHSİLAT hesabı ÖMER KARTAL; MERKEZ KASA değildir.
B25: 3 Para alınmadı, Ömer borcuna aldıysa: GELİR_GİDER → Gelir / Hayır / ÖMER KARTAL / Kasa boş.
B26: 4 Kâr payı / avans işletme gideri değildir; gerçek ödeme VIRMAN ile izlenir.
B28: RELEASE / KONTROL MERKEZİ
B29: 32 kontrol ailesi • ekran + konum + kullanıcı aksiyonu | N29: =IFERROR(HYPERLINK("#KONTROL!A1","AÇ"),"AÇ") -> AÇ

Sheet PANO
A1: =IFERROR(HYPERLINK("#MENU!A1","☰ MENÜ"),"☰ MENÜ") -> ☰ MENÜ | B1: =IFERROR(HYPERLINK("#MENU!A1","↗"),"↗") -> ↗ | C1: KILIÇ MUHASEBE │ YÖNETİM PANOSU
A2: ◈ RAPOR ALANI — VERİ GİRİŞİ YOK | C2: Bugünkü finansal durum, riskler ve hızlı geçişler tek ekranda.
A3: ANA EKRAN: Kırmızı/KALDI bir kontrol görürseniz ilgili hızlı aksiyondan kaynağa gidin.
A4: =IFERROR(HYPERLINK("#MENU!A1","← MENÜ │ PANO"),"← MENÜ │ PANO") -> ← MENÜ │ PANO | H4: =IFERROR(HYPERLINK("#TAHSILAT!A1","TAHSİLAT"),"TAHSİLAT") -> TAHSİLAT | J4: =IFERROR(HYPERLINK("#GELIR_GIDER!A1","GELİR / GİDER"),"GELİR / GİDER") -> GELİR / GİDER | L4: =IFERROR(HYPERLINK("#VIRMAN!A1","VİRMAN"),"VİRMAN") -> VİRMAN | N4: =IFERROR(HYPERLINK("#RAPOR!A1","RAPOR"),"RAPOR") -> RAPOR
A5: MENÜ | D5: AKTİF MÜŞTERİ | G5: TOPLAM CARİ ALACAK
A6: =IFERROR(HYPERLINK("#RAPOR!A1","Yönetim Raporu"),"Yönetim Raporu") -> Yönetim Raporu | B6: =IFERROR(HYPERLINK("#RAPOR!A1","›"),"›") -> › | D6: =COUNTIF(MUSTERILER!$D$7:$D$156,"Aktif") -> 52 | G6: =SUMIFS(MUSTERI_360!$J$7:$J$156,MUSTERI_360!$J$7:$J$156,">0") -> 1219008
A7: =IFERROR(HYPERLINK("#MUSTERILER!A1","Müşteriler"),"Müşteriler") -> Müşteriler | B7: =IFERROR(HYPERLINK("#MUSTERILER!A1","›"),"›") -> ›
A8: =IFERROR(HYPERLINK("#UCRETLER!A1","Ücretler"),"Ücretler") -> Ücretler | B8: =IFERROR(HYPERLINK("#UCRETLER!A1","›"),"›") -> ›
A9: =IFERROR(HYPERLINK("#TAHSILAT!A1","Tahsilat"),"Tahsilat") -> Tahsilat | B9: =IFERROR(HYPERLINK("#TAHSILAT!A1","›"),"›") -> › | D9: BU AY TAHSİLAT | G9: BU AY NAKİT KÂR | J9: NAKİTSİZ ÖMER TAHAKKUKU | M9: KRİTİK KALAN
A10: =IFERROR(HYPERLINK("#GELIR_GIDER!A1","Gelir / Gider"),"Gelir / Gider") -> Gelir / Gider | B10: =IFERROR(HYPERLINK("#GELIR_GIDER!A1","›"),"›") -> › | D10: =SUMIFS(AY_SONU!$C$7:$C$42,AY_SONU!$B$7:$B$42,DATE(YEAR(SISTEM!$C$17),MONTH(SISTEM!$C$17),1)) -> 327900 | G10: =SUMIFS(AY_SONU!$G$7:$G$42,AY_SONU!$B$7:$B$42,DATE(YEAR(SISTEM!$C$17),MONTH(SISTEM!$C$17),1)) -> 273600
A11: =IFERROR(HYPERLINK("#VIRMAN!A1","Virman"),"Virman") -> Virman | B11: =IFERROR(HYPERLINK("#VIRMAN!A1","›"),"›") -> ›
A12: =IFERROR(HYPERLINK("#MUSTERI_360!A1","Müşteri 360"),"Müşteri 360") -> Müşteri 360 | B12: =IFERROR(HYPERLINK("#MUSTERI_360!A1","›"),"›") -> ›
A13: =IFERROR(HYPERLINK("#CARI_EKSTRE!A1","Cari Ekstre"),"Cari Ekstre") -> Cari Ekstre | B13: =IFERROR(HYPERLINK("#CARI_EKSTRE!A1","›"),"›") -> › | D13: KONTROL & HIZLI AKSİYON
A14: =IFERROR(HYPERLINK("#ORTAK_EKSTRE!A1","Ortak Ekstre"),"Ortak Ekstre") -> Ortak Ekstre | B14: =IFERROR(HYPERLINK("#ORTAK_EKSTRE!A1","›"),"›") -> › | D14: =IFERROR(HYPERLINK("#KONTROL!A1","KRİTİK KONTROLLER — AÇ"),"KRİTİK KONTROLLER — AÇ") -> KRİTİK KONTROLLER — AÇ | G14: =IFERROR(HYPERLINK("#GELIR_GIDER!A1","ÖMER TAHAKKUKU — AÇ"),"ÖMER TAHAKKUKU — AÇ") -> ÖMER TAHAKKUKU — AÇ | J14: =HYPERLINK("#ORTAK_EKSTRE!A1","ÖMER CARİ: "&TEXT(ORTAKLAR!G8,"#,##0.00")&" TL — AÇ") -> ÖMER CARİ: 734650,000 TL — AÇ | M14: =IFERROR(HYPERLINK("#RAPOR!A1","YÖNETİM RAPORU — AÇ"),"YÖNETİM RAPORU — AÇ") -> YÖNETİM RAPORU — AÇ
A15: =IFERROR(HYPERLINK("#HESAPLAR!A1","Hesaplar"),"Hesaplar") -> Hesaplar | B15: =IFERROR(HYPERLINK("#HESAPLAR!A1","›"),"›") -> ›
A16: =IFERROR(HYPERLINK("#AY_SONU!A1","Ay Sonu"),"Ay Sonu") -> Ay Sonu | B16: =IFERROR(HYPERLINK("#AY_SONU!A1","›"),"›") -> ›
A17: =IFERROR(HYPERLINK("#ORTAKLAR!A1","Ortaklar"),"Ortaklar") -> Ortaklar | B17: =IFERROR(HYPERLINK("#ORTAKLAR!A1","›"),"›") -> ›
A18: =IFERROR(HYPERLINK("#KAR!A1","Kâr"),"Kâr") -> Kâr | B18: =IFERROR(HYPERLINK("#KAR!A1","›"),"›") -> › | D18: SİSTEM DURUMU — KALDI İSE KAYNAĞA GİT
A19: =IFERROR(HYPERLINK("#SISTEM!A1","Sistem"),"Sistem") -> Sistem | B19: =IFERROR(HYPERLINK("#SISTEM!A1","›"),"›") -> › | D19: =SISTEM!B19 -> Gelir/Gider tanımsız borçlu
A20: =IFERROR(HYPERLINK("#BASLANGIC!A1","Başucu Rehberi"),"Başucu Rehberi") -> Başucu Rehberi | B20: =IFERROR(HYPERLINK("#BASLANGIC!A1","›"),"›") -> › | D20: =SISTEM!B20 -> Nakitsiz tahakkukta kasa seçilmiş
A21: =IFERROR(HYPERLINK("#KONTROL!A1","Kontrol Merkezi"),"Kontrol Merkezi") -> Kontrol Merkezi | B21: =IFERROR(HYPERLINK("#KONTROL!A1","›"),"›") -> › | D21: =SISTEM!B21 -> Eski SGK/Muhasebe işlemi yanlış VIRMAN'da
D22: =SISTEM!B22 -> Yalıkent/Grand06 yapay kasa çifti | M22: =SISTEM!E22 -> GEÇTİ
D23: =SISTEM!B23 -> Eksik tarihli gerçek Gelir/Gider kaydı | M23: =SISTEM!E23 -> GEÇTİ
D24: =SISTEM!B24 -> Nakit olmayan mahsup kaydı fiziki kasada | M24: =SISTEM!E24 -> GEÇTİ
D26: MODÜL RENKLERİ
D27: VERİ GİRİŞİ | G27: RAPOR | J27: KONTROL | M27: KÂR / NAKİT
D28: 10/10 RELEASE DURUMU
D29: =COUNTIFS(KONTROL!$D$6:$D$53,"KRİTİK",KONTROL!$F$6:$F$53,"KALDI") -> 2 | I29: =COUNTIF(KONTROL!$F$6:$F$53,"UYARI") -> 1 | M29: =HYPERLINK("#'KONTROL'!A1","KONTROLÜ AÇ") -> KONTROLÜ AÇ
D31: KRİTİK KALDI | I31: UYARI | M31: 32 KONTROL AİLESİ

Sheet BASLANGIC
A1: =IFERROR(HYPERLINK("#MENU!A1","☰ MENÜ"),"☰ MENÜ") -> ☰ MENÜ | B1: =IFERROR(HYPERLINK("#MENU!A1","↗"),"↗") -> ↗ | C1: KILIÇ MUHASEBE │ BAŞLANGIÇ / BAŞUCU REHBERİ
A2: ✎ VERİ GİRİŞ / REHBER ALANI — YALNIZ SARI HÜCRELER | C2: Her işlem için ekran, adım, uyarı ve sorun giderme rehberi.
A3: KURAL: Sarı hücre görmüyorsanız o alana veri girmeyin.
A4: =IFERROR(HYPERLINK("#MENU!A1","← MENÜ │ BAŞLANGIÇ"),"← MENÜ │ BAŞLANGIÇ") -> ← MENÜ │ BAŞLANGIÇ | H4: =IFERROR(HYPERLINK("#TAHSILAT!A1","TAHSİLAT"),"TAHSİLAT") -> TAHSİLAT | J4: =IFERROR(HYPERLINK("#GELIR_GIDER!A1","GELİR / GİDER"),"GELİR / GİDER") -> GELİR / GİDER | L4: =IFERROR(HYPERLINK("#VIRMAN!A1","VİRMAN"),"VİRMAN") -> VİRMAN | N4: =IFERROR(HYPERLINK("#RAPOR!A1","RAPOR"),"RAPOR") -> RAPOR
B5: 1. 30 SANİYEDE BAŞLAYIN
B6: ADIM | C6: NE YAPACAĞIM? | D6: HANGİ EKRAN? | E6: KURAL / SON KONTROL | G6: =IFERROR(HYPERLINK("#BASLANGIC!B5","1 · 30 Saniyede Başlayın"),"1 · 30 Saniyede Başlayın") -> 1 · 30 Saniyede Başlayın | K6: =IFERROR(HYPERLINK("#BASLANGIC!B15","2 · Renk Kılavuzu"),"2 · Renk Kılavuzu") -> 2 · Renk Kılavuzu
B7: 1 | C7: Yeni müşteriyi bir kez açın | D7: MUSTERILER | E7: Müşteri No benzersiz olmalı; aynı müşteriyi ikinci kez açmayın. | G7: =IFERROR(HYPERLINK("#BASLANGIC!B25","3 · Ekran Haritası"),"3 · Ekran Haritası") -> 3 · Ekran Haritası | K7: =IFERROR(HYPERLINK("#BASLANGIC!B43","4 · Senaryo Kataloğu"),"4 · Senaryo Kataloğu") -> 4 · Senaryo Kataloğu
B8: 2 | C8: Haftalık/aylık ücretini tanımlayın | D8: UCRETLER | E8: Ücret değişirse eski satırı kapatıp yeni dönem açın. | G8: =IFERROR(HYPERLINK("#BASLANGIC!B70","5 · Uyarı Sözlüğü"),"5 · Uyarı Sözlüğü") -> 5 · Uyarı Sözlüğü | K8: =IFERROR(HYPERLINK("#BASLANGIC!B85","6 · Sorun Giderme"),"6 · Sorun Giderme") -> 6 · Sorun Giderme
B9: 3 | C9: Gerçek müşteri ödemesini kaydedin | D9: TAHSILAT | E9: Para kimde kaldıysa Kasa/Banka o hesap olmalı. | G9: =IFERROR(HYPERLINK("#BASLANGIC!B100","7 · Ömer Cari Akışı"),"7 · Ömer Cari Akışı") -> 7 · Ömer Cari Akışı | K9: =IFERROR(HYPERLINK("#BASLANGIC!B118","8 · Yedek / Güvenlik"),"8 · Yedek / Güvenlik") -> 8 · Yedek / Güvenlik
B10: 4 | C10: İşletme giderini veya ek geliri kaydedin | D10: GELIR_GIDER | E10: Gerçek para varsa Gerçekleşti=Evet ve Kasa/Banka seçilir. | G10: =HYPERLINK("#'BASLANGIC'!B100","None") -> None | K10: =HYPERLINK("#'BASLANGIC'!B118","None") -> None
B11: 5 | C11: Para alınmadı, Ömer borcuna aldıysa | D11: GELIR_GIDER | E11: Gelir + Hayır + Borçlu Taraf=ÖMER KARTAL + Kasa/Banka boş. | G11: EN ÇOK SORULAN 4 KURAL
B12: 6 | C12: Hesaplar arasında gerçekten para taşındıysa | D12: VIRMAN | E12: Gerçek para yoksa VIRMAN yok. | G12: 1. Gerçek para hareketi yoksa VIRMAN yok.
B13: 7 | C13: Sonucu kontrol edin | D13: PANO / RAPOR / SISTEM | E13: Kırmızı KALDI varsa müşteriye rapor vermeden kaynağı düzeltin. | G13: 2. Ömer borcuna yazılan nakitsiz iş: GELİR_GİDER / Hayır / ÖMER / Kasa boş.
G14: 3. Ömer parayı sonra kasaya verirse: VIRMAN ÖMER → MERKEZ KASA.
B15: 2. RENK KILAVUZU — DOSYA SİZE NE SÖYLÜYOR?
B16: RENK / İŞARET | C16: ANLAMI | D16: SİZ NE YAPACAKSINIZ? | E16: ÖRNEK
B17: SARI hücre | C17: Kullanıcı girişi | D17: Yalnız bu hücrelere yazın / seçim yapın. | E17: Tutar, tarih, müşteri, ortak seçimi
B18: BEYAZ hücre | C18: Otomatik hesap | D18: Elle değiştirmeyin. | E18: Cari bakiye, kâr, hesap bakiyesi
B19: MAVİ açık alan | C19: Toplam / bilgi | D19: Okuyun; kaynak defterden beslenir. | E19: Toplam tahsilat
B20: YEŞİL GEÇTİ | C20: Kontrol temiz | D20: İşlem gerekmez. | E20: Tanımsız borçlu = 0
B21: TURUNCU / UYARI | C21: Dikkat / eksik | D21: İlgili satırı kontrol edin. | E21: Eksik alan
B22: KIRMIZI / KALDI | C22: Kritik sorun | D22: Rapor/kapanış öncesi mutlaka düzeltin. | E22: Yanlış virman, nakitsiz işlem kasada
B23: ☰ MENÜ | C23: Ana ekrana dönüş | D23: Her sayfanın sol üstünden PANO'ya dönün. | E23: Tek tık navigasyon
B25: 3. EKRAN HARİTASI — NEREYE GİRECEĞİM?
B26: EKRAN | C26: MOD | D26: NE İÇİN? | E26: NEREYE YAZILIR? | F26: SAKIN YAPMAYIN
B27: PANO | C27: Rapor | D27: Ana karar ekranı | E27: Kayıt girilmez | F27: PANO'daki rakamı elle düzeltmeye çalışma
B28: MUSTERILER | C28: Giriş | D28: Müşteri ana kartı | E28: Sarı hücreler | F28: Aynı müşteriyi tekrar açma
B29: UCRETLER | C29: Giriş | D29: Ücret/tarife dönemleri | E29: Sarı hücreler | F29: Eski ücret tutarını geriye dönük değiştirme
B30: TAHSILAT | C30: Giriş | D30: Müşteri ödemeleri | E30: Sarı hücreler | F30: Gerçekte kasaya girmeyen parayı MERKEZ KASA yazma
B31: GELIR_GIDER | C31: Giriş | D31: Gelir/gider + nakitsiz tahakkuk | E31: Sarı hücreler | F31: Nakitsiz tahakkukta kasa seçme
B32: VIRMAN | C32: Giriş | D32: Gerçek hesap transferi | E32: Sarı hücreler | F32: Mahsup/hizmet kaydını para transferi gibi yazma
B33: MUSTERI_360 | C33: Rapor | D33: Tüm cari ve riskler | E33: Kayıt girilmez | F33: Raporu kaynak veri gibi kullanma
B34: CARI_EKSTRE | C34: Rapor | D34: Tek müşteri ekstresi | E34: Yalnız müşteri seçimi | F34: Ekstre satırlarına elle yazma
B35: ORTAK_EKSTRE | C35: Rapor | D35: Tek ortak ekstresi | E35: Yalnız ortak seçimi | F35: Ekstre satırlarını elle değiştirme
B36: HESAPLAR | C36: Karma | D36: Kasa/banka bakiyesi | E36: Yalnız açılış bakiyesi | F36: Otomatik bakiyeyi elle değiştirme
B37: AY_SONU | C37: Karma | D37: Aylık kâr/kapanış | E37: Yalnız dönem durumu | F37: Kâr payını gider yazma
... B41: RAPOR | C41: Rapor | D41: Yönetim sunum ekranı | E41: Kayıt girilmez | F41: Kaynak defter yerine kullanma
B43: 4. SENARYO KATALOĞU — 'ŞUNU YAPMAK İSTİYORUM'
B44: # | C44: NE YAPMAK İSTİYORUM? | D44: EKRAN | E44: ADIMLAR | F44: KONTROL / DİKKAT
B45: 1 | C45: Yeni müşteri açmak | D45: MUSTERILER | E45: Yeni satır → No → Unvan → Aktif → temel bilgiler | F45: Kayıt Kontrolü UYGUN olmalı.
...

Sheet RAPOR
A1: =IFERROR(HYPERLINK("#MENU!A1","☰ MENÜ"),"☰ MENÜ") -> ☰ MENÜ | B1: =IFERROR(HYPERLINK("#MENU!A1","↗"),"↗") -> ↗ | C1: KILIÇ MUHASEBE │ YÖNETİM RAPORU
A2: ◈ RAPOR ALANI — VERİ GİRİŞİ YOK | C2: KPI, aylık performans ve kritik kontroller.
A3: RAPOR: Bu sayfaya veri girilmez.
A4: =IFERROR(HYPERLINK("#MENU!A1","← MENÜ │ RAPOR"),"← MENÜ │ RAPOR") -> ← MENÜ │ RAPOR | H4: =IFERROR(HYPERLINK("#TAHSILAT!A1","TAHSİLAT"),"TAHSİLAT") -> TAHSİLAT | J4: =IFERROR(HYPERLINK("#GELIR_GIDER!A1","GELİR / GİDER"),"GELİR / GİDER") -> GELİR / GİDER | L4: =IFERROR(HYPERLINK("#VIRMAN!A1","VİRMAN"),"VİRMAN") -> VİRMAN | N4: =IFERROR(HYPERLINK("#RAPOR!A1","RAPOR"),"RAPOR") -> RAPOR
B5: YÖNETİM ÖZETİ
B6: NET NAKİT KÂR | E6: GERÇEK KASA/BANKA | H6: TOPLAM CARİ ALACAK | K6: ÖMER NET CARİ | N6: KRİTİK KALAN
B7: =KAR!C22 -> 1525862 | E7: =SUMIFS(HESAPLAR!$K$7:$K$16,HESAPLAR!$C$7:$C$16,"Kasa")+SUMIFS(HESAPLAR!$K$7:$K$16,HESAPLAR!$C$7:$C$16,"Banka") -> -440300.02 | H7: =PANO!G6 -> 1219008 | K7: =ORTAKLAR!I8 -> 634731.02 | N7: =COUNTIF(SISTEM!$E$19:$E$24,"KALDI") -> 0
B11: Ay | C11: Tahsilat | D11: Diğer Gelir | E11: Toplam Gelir | F11: Gider | G11: Nakit Kâr
B12: =AY_SONU!B7 -> 46023 | C12: =AY_SONU!C7 -> 320700 | D12: =AY_SONU!D7 -> 0 | E12: =AY_SONU!E7 -> 320700 | F12: =AY_SONU!F7 -> 82333.82 | G12: =AY_SONU!G7 -> 238366.18
B13: =AY_SONU!B8 -> 46054 | C13: =AY_SONU!C8 -> 205500 | D13: =AY_SONU!D8 -> 97200 | E13: =AY_SONU!E8 -> 302700 | F13: =AY_SONU!F8 -> 282078.19 | G13: =AY_SONU!G8 -> 20621.81
B14: =AY_SONU!B9 -> 46082 | C14: =AY_SONU!C9 -> 263250 | D14: =AY_SONU!D9 -> 50000 | E14: =AY_SONU!E9 -> 313250 | F14: =AY_SONU!F9 -> 158407.97 | G14: =AY_SONU!G9 -> 154842.03
B15: =AY_SONU!B10 -> 46113 | C15: =AY_SONU!C10 -> 281200 | D15: =AY_SONU!D10 -> 147600 | E15: =AY_SONU!E10 -> 428800 | F15: =AY_SONU!F10 -> 154094 | G15: =AY_SONU!G10 -> 274706
B16: =AY_SONU!B11 -> 46143 | C16: =AY_SONU!C11 -> 347650 | D16: =AY_SONU!D11 -> 67250 | E16: =AY_SONU!E11 -> 414900 | F16: =AY_SONU!F11 -> 195354 | G16: =AY_SONU!G11 -> 219546
B17: =AY_SONU!B12 -> 46174 | C17: =AY_SONU!C12 -> 288350 | D17: =AY_SONU!D12 -> 38200 | E17: =AY_SONU!E12 -> 326550 | F17: =AY_SONU!F12 -> 99110 | G17: =AY_SONU!G12 -> 227440
B18: =AY_SONU!B13 -> 46204 | C18: =AY_SONU!C13 -> 204250 | D18: =AY_SONU!D13 -> 20000 | E18: =AY_SONU!E13 -> 224250 | F18: =AY_SONU!F13 -> 107510 | G18: =AY_SONU!G13 -> 116740
B19: =AY_SONU!B14 -> 46235 | C19: =AY_SONU!C14 -> 327900 | D19: =AY_SONU!D14 -> 63000 | E19: =AY_SONU!E14 -> 390900 | F19: =AY_SONU!F14 -> 117300 | G19: =AY_SONU!G14 -> 273600
B20: =AY_SONU!B15 -> 46266 | C20: =AY_SONU!C15 -> 0 | D20: =AY_SONU!D15 -> 0 | E20: =AY_SONU!E15 -> 0 | F20: =AY_SONU!F15 -> 0 | G20: =AY_SONU!G15 -> 0
B21: =AY_SONU!B16 -> 46296 | C21: =AY_SONU!C16 -> 0 | D21: =AY_SONU!D16 -> 0 | E21: =AY_SONU!E16 -> 0 | F21: =AY_SONU!F16 -> 0 | G21: =AY_SONU!G16 -> 0
B22: =AY_SONU!B17 -> 46327 | C22: =AY_SONU!C17 -> 0 | D22: =AY_SONU!D17 -> 0 | E22: =AY_SONU!E17 -> 0 | F22: =AY_SONU!F17 -> 0 | G22: =AY_SONU!G17 -> 0
B23: =AY_SONU!B18 -> 46357 | C23: =AY_SONU!C18 -> 0 | D23: =AY_SONU!D18 -> 0 | E23: =AY_SONU!E18 -> 0 | F23: =AY_SONU!F18 -> 0 | G23: =AY_SONU!G18 -> 0
B26: KRİTİK KONTROLLER
B27: =SISTEM!B19 -> Gelir/Gider tanımsız borçlu | F27: =SISTEM!E19 -> GEÇTİ
B28: =SISTEM!B20 -> Nakitsiz tahakkukta kasa seçilmiş | F28: =SISTEM!E20 -> GEÇTİ
B29: =SISTEM!B21 -> Eski SGK/Muhasebe işlemi yanlış VIRMAN'da | F29: =SISTEM!E21 -> GEÇTİ
B30: =SISTEM!B22 -> Yalıkent/Grand06 yapay kasa çifti | F30: =SISTEM!E22 -> GEÇTİ
B31: =SISTEM!B23 -> Eksik tarihli gerçek Gelir/Gider kaydı | F31: =SISTEM!E23 -> GEÇTİ
B32: =SISTEM!B24 -> Nakit olmayan mahsup kaydı fiziki kasada | F32: =SISTEM!E24 -> GEÇTİ

Sheet MUSTERILER
A1: =IFERROR(HYPERLINK("#MENU!A1","☰ MENÜ"),"☰ MENÜ") -> ☰ MENÜ | B1: =IFERROR(HYPERLINK("#MENU!A1","↗"),"↗") -> ↗ | C1: KILIÇ MUHASEBE │ MÜŞTERİ KARTLARI
A2: ✎ VERİ GİRİŞ ALANI — YALNIZ SARI HÜCRELER | C2: Müşteri ana kartları — yalnız sarı hücrelere giriş.
A3: SAKIN: Aynı müşteriyi ikinci kez açmayın.
A4: =IFERROR(HYPERLINK("#MENU!A1","← MENÜ │ MÜŞTERİLER"),"← MENÜ │ MÜŞTERİLER") -> ← MENÜ │ MÜŞTERİLER | H4: =IFERROR(HYPERLINK("#TAHSILAT!A1","TAHSİLAT"),"TAHSİLAT") -> TAHSİLAT | J4: =IFERROR(HYPERLINK("#GELIR_GIDER!A1","GELİR / GİDER"),"GELİR / GİDER") -> GELİR / GİDER | L4: =IFERROR(HYPERLINK("#VIRMAN!A1","VİRMAN"),"VİRMAN") -> VİRMAN | N4: =IFERROR(HYPERLINK("#RAPOR!A1","RAPOR"),"RAPOR") -> RAPOR
B5: TOPLAM / DURUM | C5: =COUNTIF($B$7:$B$156,"<>") -> 55 | E5: AKTİF | F5: =COUNTIF($D$7:$D$156,"Aktif") -> 52 | H5: PASİF | I5: =COUNTIF($D$7:$D$156,"Pasif") -> 3 | K5: KAYIT KURALI │ Aynı müşteri bir kez açılır.
B6: Müşteri No | C6: Müşteri / Mükellef Unvanı | D6: Durum | E6: Sorumlu Kişi | F6: Telefon | G6: Vergi No | H6: Ödeme Şekli | I6: Başlangıç Tarihi | J6: Devir Alacağı | K6: Devir Alacak Tarihi | L6: Devir Kaynağı | M6: Özel Not | N6: Bilgi Durumu | O6: Kayıt Kontrolü
B7: M019 | C7: AC OTEL LTD.ŞTİ. | D7: Aktif | H7: Nakit | I7: 46023 | J7: 0 | O7: =IF(AND(B7="",C7=""),"",IF(OR(B7="",C7="",D7=""),"EKSİK",IF(COUNTIF($B$7:$B$156,B7)>1,"MÜKERRER NO","UYGUN"))) -> UYGUN
B8: M022 | C8: ADEM KARABENLİ | D8: Aktif | H8: Nakit | I8: 46023 | J8: 0 | O8: =IF(AND(B8="",C8=""),"",IF(OR(B8="",C8="",D8=""),"EKSİK",IF(COUNTIF($B$7:$B$156,B8)>1,"MÜKERRER NO","UYGUN"))) -> UYGUN
B9: M023 | C9: ALTINEL LTD.ŞTİ. | D9: Aktif | H9: Nakit | I9: 46023 | J9: 0 | O9: =IF(AND(B9="",C9=""),"",IF(OR(B9="",C9="",D9=""),"EKSİK",IF(COUNTIF($B$7:$B$156,B9)>1,"MÜKERRER NO","UYGUN"))) -> UYGUN
B10: M001 | C10: ANKARA HAVANA LTD.ŞTİ. | D10: Aktif | H10: Nakit | I10: 46023 | J10: 0 | O10: =IF(AND(B10="",C10=""),"",IF(OR(B10="",C10="",D10=""),"EKSİK",IF(COUNTIF($B$7:$B$156,B10)>1,"MÜKERRER NO","UYGUN"))) -> UYGUN
B11: M024 | C11: ARMAN DİK | D11: Aktif | H11: Nakit | I11: 46023 | J11: 0 | O11: =IF(AND(B11="",C11=""),"",IF(OR(B11="",C11="",D11=""),"EKSİK",IF(COUNTIF($B$7:$B$156,B11)>1,"MÜKERRER NO","UYGUN"))) -> UYGUN
B12: M021 | C12: ARON TOPTAN LTD.ŞTİ. | D12: Aktif | H12: Nakit | I12: 46023 | J12: 0 | O12: =IF(AND(B12="",C12=""),"",IF(OR(B12="",C12="",D12=""),"EKSİK",IF(COUNTIF($B$7:$B$156,B12)>1,"MÜKERRER NO","UYGUN"))) -> UYGUN
B13: M025 | C13: ASIM AÇIKGÖZ | D13: Aktif | H13: Nakit | I13: 46023 | J13: 0 | O13: =IF(AND(B13="",C13=""),"",IF(OR(B13="",C13="",D13=""),"EKSİK",IF(COUNTIF($B$7:$B$156,B13)>1,"MÜKERRER NO","UYGUN"))) -> UYGUN
B14: M017 | C14: ASM EĞLENCE LTD.ŞTİ. | D14: Aktif | H14: Nakit | I14: 46023 | J14: 0 | O14: =IF(AND(B14="",C14=""),"",IF(OR(B14="",C14="",D14=""),"EKSİK",IF(COUNTIF($B$7:$B$156,B14)>1,"MÜKERRER NO","UYGUN"))) -> UYGUN
B15: M026 | C15: AYDES LTD.ŞTİ. | D15: Aktif | H15: Nakit | I15: 46023 | J15: 0 | O15: =IF(AND(B15="",C15=""),"",IF(OR(B15="",C15="",D15=""),"EKSİK",IF(COUNTIF($B$7:$B$156,B15)>1,"MÜKERRER NO","UYGUN"))) -> UYGUN
B16: M015 | C16: ÇAYIRALAN LTD.ŞTİ. | D16: Aktif | H16: Nakit | I16: 46023 | J16: 0 | O16: =IF(AND(B16="",C16=""),"",IF(OR(B16="",C16="",D16=""),"EKSİK",IF(COUNTIF($B$7:$B$156,B16)>1,"MÜKERRER NO","UYGUN"))) -> UYGUN
B17: M027 | C17: CEREN DEMİRCİ | D17: Aktif | H17: Nakit | I17: 46023 | J17: 0 | O17: =IF(AND(B17="",C17=""),"",IF(OR(B17="",C17="",D17=""),"EKSİK",IF(COUNTIF($B$7:$B$156,B17)>1,"MÜKERRER NO","UYGUN"))) -> UYGUN
B18: M018 | C18: ÇINARHAN LTD.ŞTİ. | D18: Aktif | H18: Nakit | I18: 46023 | J18: 0 | O18: =IF(AND(B18="",C18=""),"",IF(OR(B18="",C18="",D18=""),"EKSİK",IF(COUNTIF($B$7:$B$156,B18)>1,"MÜKERRER NO","UYGUN"))) -> UYGUN
... B50: M016 | C50: RİX ŞOW LTD.ŞTİ. | D50: Aktif | H50: Nakit | I50: 46023 | J50: 0 | O50: =IF(AND(B50="",C50=""),"",IF(OR(B50="",C50="",D50=""),"EKSİK",IF(COUNTIF($B$7:$B$156,B50)>1,"MÜKERRER NO","UYGUN"))) -> UYGUN
B51: M055 | C51: SEMRA GÜMÜŞ | D51: Pasif | H51: Nakit | I51: 46023 | O51: =IF(AND(B51="",C51=""),"",IF(OR(B51="",C51="",D51=""),"EKSİK",IF(COUNTIF($B$7:$B$156,B51)>1,"MÜKERRER NO","UYGUN"))) -> UYGUN
B52: M049 | C52: STAR ŞOW LTD.ŞTİ. | D52: Aktif | H52: Nakit | I52: 46023 | J52: 0 | O52: =IF(AND(B52="",C52=""),"",IF(OR(B52="",C52="",D52=""),"EKSİK",IF(COUNTIF($B$7:$B$156,B52)>1,"MÜKERRER NO","UYGUN"))) -> UYGUN
B53: M050 | C53: TANAK LTD.ŞTİ. | D53: Aktif | H53: Nakit | I53: 46023 | J53: 0 | O53: =IF(AND(B53="",C53=""),"",IF(OR(B53="",C53="",D53=""),"EKSİK",IF(COUNTIF($B$7:$B$156,B53)>1,"MÜKERRER NO","UYGUN"))) -> UYGUN
B54: M003 | C54: TYANA LTD.ŞTİ. | D54: Aktif | H54: Nakit | I54: 46023 | J54: 0 | O54: =IF(AND(B54="",C54=""),"",IF(OR(B54="",C54="",D54=""),"EKSİK",IF(COUNTIF($B$7:$B$156,B54)>1,"MÜKERRER NO","UYGUN"))) -> UYGUN
B55: M051 | C55: UFUK YILMAZ | D55: Aktif | H55: Nakit | I55: 46023 | J55: 0 | O55: =IF(AND(B55="",C55=""),"",IF(OR(B55="",C55="",D55=""),"EKSİK",IF(COUNTIF($B$7:$B$156,B55)>1,"MÜKERRER NO","UYGUN"))) -> UYGUN
B56: M052 | C56: VANOLYA SU LTD.ŞTİ. | D56: Aktif | H56: Nakit | I56: 46023 | J56: 0 | O56: =IF(AND(B56="",C56=""),"",IF(OR(B56="",C56="",D56=""),"EKSİK",IF(COUNTIF($B$7:$B$156,B56)>1,"MÜKERRER NO","UYGUN"))) -> UYGUN
B57: M006 | C57: VOLKAN AÇIK | D57: Aktif | H57: Nakit | I57: 46023 | J57: 0 | O57: =IF(AND(B57="",C57=""),"",IF(OR(B57="",C57="",D57=""),"EKSİK",IF(COUNTIF($B$7:$B$156,B57)>1,"MÜKERRER NO","UYGUN"))) -> UYGUN
B58: M054 | C58: YALIKENT LTD.ŞTİ. | D58: Pasif | H58: Nakit | I58: 46023 | O58: =IF(AND(B58="",C58=""),"",IF(OR(B58="",C58="",D58=""),"EKSİK",IF(COUNTIF($B$7:$B$156,B58)>1,"MÜKERRER NO","UYGUN"))) -> UYGUN
B59: M053 | C59: YEDİYİRMİDÖRT LTD.ŞTİ. | D59: Aktif | H59: Nakit | I59: 46023 | J59: 0 | O59: =IF(AND(B59="",C59=""),"",IF(OR(B59="",C59="",D59=""),"EKSİK",IF(COUNTIF($B$7:$B$156,B59)>1,"MÜKERRER NO","UYGUN"))) -> UYGUN
B60: M004 | C60: ZÜMRÜT EĞLENCE LTD.ŞTİ. | D60: Aktif | H60: Nakit | I60: 46023 | J60: 0 | O60: =IF(AND(B60="",C60=""),"",IF(OR(B60="",C60="",D60=""),"EKSİK",IF(COUNTIF($B$7:$B$156,B60)>1,"MÜKERRER NO","UYGUN"))) -> UYGUN
B61: M005 | C61: ZÜMRÜT GRUP LTD.ŞTİ. | D61: Aktif | H61: Nakit | I61: 46023 | J61: 0 | O61: =IF(AND(B61="",C61=""),"",IF(OR(B61="",C61="",D61=""),"EKSİK",IF(COUNTIF($B$7:$B$156,B61)>1,"MÜKERRER NO","UYGUN"))) -> UYGUN
O62: =IF(AND(B62="",C62=""),"",IF(OR(B62="",C62="",D62=""),"EKSİK",IF(COUNTIF($B$7:$B$156,B62)>1,"MÜKERRER NO","UYGUN")))
O63: =IF(AND(B63="",C63=""),"",IF(OR(B63="",C63="",D63=""),"EKSİK",IF(COUNTIF($B$7:$B$156,B63)>1,"MÜKERRER NO","UYGUN")))
O64: =IF(AND(B64="",C64=""),"",IF(OR(B64="",C64="",D64=""),"EKSİK",IF(COUNTIF($B$7:$B$156,B64)>1,"MÜKERRER NO","UYGUN")))
O65: =IF(AND(B65="",C65=""),"",IF(OR(B65="",C65="",D65=""),"EKSİK",IF(COUNTIF($B$7:$B$156,B65)>1,"MÜKERRER NO","UYGUN")))
O66: =IF(AND(B66="",C66=""),"",IF(OR(B66="",C66="",D66=""),"EKSİK",IF(COUNTIF($B$7:$B$156,B66)>1,"MÜKERRER NO","UYGUN")))
O67: =IF(AND(B67="",C67=""),"",IF(OR(B67="",C67="",D67=""),"EKSİK",IF(COUNTIF($B$7:$B$156,B67)>1,"MÜKERRER NO","UYGUN")))
O68: =IF(AND(B68="",C68=""),"",IF(OR(B68="",C68="",D68=""),"EKSİK",IF(COUNTIF($B$7:$B$156,B68)>1,"MÜKERRER NO","UYGUN")))
O69: =IF(AND(B69="",C69=""),"",IF(OR(B69="",C69="",D69=""),"EKSİK",IF(COUNTIF($B$7:$B$156,B69)>1,"MÜKERRER NO","UYGUN")))
O70: =IF(AND(B70="",C70=""),"",IF(OR(B70="",C70="",D70=""),"EKSİK",IF(COUNTIF($B$7:$B$156,B70)>1,"MÜKERRER NO","UYGUN")))
O71: =IF(AND(B71="",C71=""),"",IF(OR(B71="",C71="",D71=""),"EKSİK",IF(COUNTIF($B$7:$B$156,B71)>1,"MÜKERRER NO","UYGUN")))
...

Sheet UCRETLER
A1: =IFERROR(HYPERLINK("#MENU!A1","☰ MENÜ"),"☰ MENÜ") -> ☰ MENÜ | B1: =IFERROR(HYPERLINK("#MENU!A1","↗"),"↗") -> ↗ | C1: KILIÇ MUHASEBE │ ÜCRET DÖNEMLERİ
A2: ✎ VERİ GİRİŞ ALANI — YALNIZ SARI HÜCRELER | C2: Ücret ve dönem tanımları — eski dönemi değiştirmeden yeni dönem açın.
A3: SAKIN: Ücret değişince eski satırdaki tutarı değiştirmeyin; yeni dönem açın.
A4: =IFERROR(HYPERLINK("#MENU!A1","← MENÜ │ ÜCRETLER"),"← MENÜ │ ÜCRETLER") -> ← MENÜ │ ÜCRETLER | H4: =IFERROR(HYPERLINK("#TAHSILAT!A1","TAHSİLAT"),"TAHSİLAT") -> TAHSİLAT | J4: =IFERROR(HYPERLINK("#GELIR_GIDER!A1","GELİR / GİDER"),"GELİR / GİDER") -> GELİR / GİDER | L4: =IFERROR(HYPERLINK("#VIRMAN!A1","VİRMAN"),"VİRMAN") -> VİRMAN | N4: =IFERROR(HYPERLINK("#RAPOR!A1","RAPOR"),"RAPOR") -> RAPOR
B5: AKTİF ÜCRET TANIMI | C5: =COUNTIF($H$7:$H$306,"Aktif") -> 53 | E5: ÜCRET TOPLAMI | F5: =SUMIFS($G$7:$G$306,$H$7:$H$306,"Aktif") -> 210751 | J5: DÖNEM KURALI │ Zamda eski satırı kapat, yeni satır aç.
B6: Müşteri No | C6: Müşteri | D6: Ücret Başlangıç Tarihi | E6: Ücret Bitiş Tarihi | F6: Tahakkuk Modeli | G6: Ücret Tutarı | H6: Dönem Durumu | I6: Bugüne Kadar Oluşan | J6: Oluşan Dönem | K6: Sistem Kontrolü | L6: İlk Tahakkuk Tarihi | M6: Not | N6: Teknik Hesap Tarihi | O6: Teknik İlk Tahakkuk | P6: Teknik Dönem Sayısı
B7: M019 | C7: AC OTEL LTD.ŞTİ. | D7: 46023 | F7: Aylık | G7: 4000 | H7: =IF(OR(B7="",D7="",F7="",G7=""),"",IF(AND(E7<>"",E7<SISTEM!$C$17),"Pasif","Aktif")) -> Aktif | I7: =IF(P7=0,0,P7*G7) -> 32000 | J7: =IF(OR(G7="",G7=0),"",I7/G7) -> 8 | K7: =IF(AND(B7="",C7=""),"",IF(OR(B7="",C7="",D7="",F7="",G7=""),"EKSİK",IF(COUNTIF(MUSTERILER!$B$7:$B$156,B7)=0,"TANIMSIZ MÜŞTERİ","UYGUN"))) -> UYGUN | L7: =IF(D7="","",IF(F7="Haftalık",D7+MOD(6-WEEKDAY(D7,2),7),EOMONTH(D7,0))) -> 46053 | M7: 7 | N7: =IF(B7="","",IF(E7="",SISTEM!$C$17,MIN(E7,SISTEM!$C$17))) -> 46261 | O7: =L7 -> 46053 | P7: =IF(OR(B7="",O7="",N7=""),0,IF(F7="Haftalık",MAX(0,INT((N7-O7)/7)+1),IF(F7="Aylık",MAX(0,(YEAR(N7)-YEAR(O7))*12+MONTH(N7)-MONTH(O7)+1),0))) -> 8
B8: M022 | C8: ADEM KARABENLİ | D8: 46023 | F8: Aylık | G8: 3000 | H8: =IF(OR(B8="",D8="",F8="",G8=""),"",IF(AND(E8<>"",E8<SISTEM!$C$17),"Pasif","Aktif")) -> Aktif | I8: =IF(P8=0,0,P8*G8) -> 24000 | J8: =IF(OR(G8="",G8=0),"",I8/G8) -> 8 | K8: =IF(AND(B8="",C8=""),"",IF(OR(B8="",C8="",D8="",F8="",G8=""),"EKSİK",IF(COUNTIF(MUSTERILER!$B$7:$B$156,B8)=0,"TANIMSIZ MÜŞTERİ","UYGUN"))) -> UYGUN | L8: =IF(D8="","",IF(F8="Haftalık",D8+MOD(6-WEEKDAY(D8,2),7),EOMONTH(D8,0))) -> 46053 | M8: 7 | N8: =IF(B8="","",IF(E8="",SISTEM!$C$17,MIN(E8,SISTEM!$C$17))) -> 46261 | O8: =L8 -> 46053 | P8: =IF(OR(B8="",O8="",N8=""),0,IF(F8="Haftalık",MAX(0,INT((N8-O8)/7)+1),IF(F8="Aylık",MAX(0,(YEAR(N8)-YEAR(O8))*12+MONTH(N8)-MONTH(O8)+1),0))) -> 8
B9: M023 | C9: ALTINEL LTD.ŞTİ. | D9: 46266 | F9: Aylık | G9: 10000 | H9: =IF(OR(B9="",D9="",F9="",G9=""),"",IF(AND(E9<>"",E9<SISTEM!$C$17),"Pasif","Aktif")) -> Aktif | I9: =IF(P9=0,0,P9*G9) -> 0 | J9: =IF(OR(G9="",G9=0),"",I9/G9) -> 0 | K9: =IF(AND(B9="",C9=""),"",IF(OR(B9="",C9="",D9="",F9="",G9=""),"EKSİK",IF(COUNTIF(MUSTERILER!$B$7:$B$156,B9)=0,"TANIMSIZ MÜŞTERİ","UYGUN"))) -> UYGUN | L9: =IF(D9="","",IF(F9="Haftalık",D9+MOD(6-WEEKDAY(D9,2),7),EOMONTH(D9,0))) -> 46295 | M9: 0 | N9: =IF(B9="","",IF(E9="",SISTEM!$C$17,MIN(E9,SISTEM!$C$17))) -> 46261 | O9: =L9 -> 46295 | P9: =IF(OR(B9="",O9="",N9=""),0,IF(F9="Haftalık",MAX(0,INT((N9-O9)/7)+1),IF(F9="Aylık",MAX(0,(YEAR(N9)-YEAR(O9))*12+MONTH(N9)-MONTH(O9)+1),0))) -> 0
B10: M001 | C10: ANKARA HAVANA LTD.ŞTİ. | D10: 46023 | F10: Haftalık | G10: 4000 | H10: =IF(OR(B10="",D10="",F10="",G10=""),"",IF(AND(E10<>"",E10<SISTEM!$C$17),"Pasif","Aktif")) -> Aktif | I10: =IF(P10=0,0,P10*G10) -> 136000 | J10: =IF(OR(G10="",G10=0),"",I10/G10) -> 34 | K10: =IF(AND(B10="",C10=""),"",IF(OR(B10="",C10="",D10="",F10="",G10=""),"EKSİK",IF(COUNTIF(MUSTERILER!$B$7:$B$156,B10)=0,"TANIMSIZ MÜŞTERİ","UYGUN"))) -> UYGUN | L10: =IF(D10="","",IF(F10="Haftalık",D10+MOD(6-WEEKDAY(D10,2),7),EOMONTH(D10,0))) -> 46025 | M10: 34 | N10: =IF(B10="","",IF(E10="",SISTEM!$C$17,MIN(E10,SISTEM!$C$17))) -> 46261 | O10: =L10 -> 46025 | P10: =IF(OR(B10="",O10="",N10=""),0,IF(F10="Haftalık",MAX(0,INT((N10-O10)/7)+1),IF(F10="Aylık",MAX(0,(YEAR(N10)-YEAR(O10))*12+MONTH(N10)-MONTH(O10)+1),0))) -> 34
B11: M024 | C11: ARMAN DİK | D11: 46023 | F11: Aylık | G11: 3000 | H11: =IF(OR(B11="",D11="",F11="",G11=""),"",IF(AND(E11<>"",E11<SISTEM!$C$17),"Pasif","Aktif")) -> Aktif | I11: =IF(P11=0,0,P11*G11) -> 24000 | J11: =IF(OR(G11="",G11=0),"",I11/G11) -> 8 | K11: =IF(AND(B11="",C11=""),"",IF(OR(B11="",C11="",D11="",F11="",G11=""),"EKSİK",IF(COUNTIF(MUSTERILER!$B$7:$B$156,B11)=0,"TANIMSIZ MÜŞTERİ","UYGUN"))) -> UYGUN | L11: =IF(D11="","",IF(F11="Haftalık",D11+MOD(6-WEEKDAY(D11,2),7),EOMONTH(D11,0))) -> 46053 | M11: 7 | N11: =IF(B11="","",IF(E11="",SISTEM!$C$17,MIN(E11,SISTEM!$C$17))) -> 46261 | O11: =L11 -> 46053 | P11: =IF(OR(B11="",O11="",N11=""),0,IF(F11="Haftalık",MAX(0,INT((N11-O11)/7)+1),IF(F11="Aylık",MAX(0,(YEAR(N11)-YEAR(O11))*12+MONTH(N11)-MONTH(O11)+1),0))) -> 8
B12: M021 | C12: ARON TOPTAN LTD.ŞTİ. | D12: 46023 | F12: Aylık | G12: 10000 | H12: =IF(OR(B12="",D12="",F12="",G12=""),"",IF(AND(E12<>"",E12<SISTEM!$C$17),"Pasif","Aktif")) -> Aktif | I12: =IF(P12=0,0,P12*G12) -> 80000 | J12: =IF(OR(G12="",G12=0),"",I12/G12) -> 8 | K12: =IF(AND(B12="",C12=""),"",IF(OR(B12="",C12="",D12="",F12="",G12=""),"EKSİK",IF(COUNTIF(MUSTERILER!$B$7:$B$156,B12)=0,"TANIMSIZ MÜŞTERİ","UYGUN"))) -> UYGUN | L12: =IF(D12="","",IF(F12="Haftalık",D12+MOD(6-WEEKDAY(D12,2),7),EOMONTH(D12,0))) -> 46053 | M12: 7 | N12: =IF(B12="","",IF(E12="",SISTEM!$C$17,MIN(E12,SISTEM!$C$17))) -> 46261 | O12: =L12 -> 46053 | P12: =IF(OR(B12="",O12="",N12=""),0,IF(F12="Haftalık",MAX(0,INT((N12-O12)/7)+1),IF(F12="Aylık",MAX(0,(YEAR(N12)-YEAR(O12))*12+MONTH(N12)-MONTH(O12)+1),0))) -> 8
B13: M025 | C13: ASIM AÇIKGÖZ | D13: 46023 | F13: Haftalık | G13: 2000 | H13: =IF(OR(B13="",D13="",F13="",G13=""),"",IF(AND(E13<>"",E13<SISTEM!$C$17),"Pasif","Aktif")) -> Aktif | I13: =IF(P13=0,0,P13*G13) -> 68000 | J13: =IF(OR(G13="",G13=0),"",I13/G13) -> 34 | K13: =IF(AND(B13="",C13=""),"",IF(OR(B13="",C13="",D13="",F13="",G13=""),"EKSİK",IF(COUNTIF(MUSTERILER!$B$7:$B$156,B13)=0,"TANIMSIZ MÜŞTERİ","UYGUN"))) -> UYGUN | L13: =IF(D13="","",IF(F13="Haftalık",D13+MOD(6-WEEKDAY(D13,2),7),EOMONTH(D13,0))) -> 46025 | M13: 34 | N13: =IF(B13="","",IF(E13="",SISTEM!$C$17,MIN(E13,SISTEM!$C$17))) -> 46261 | O13: =L13 -> 46025 | P13: =IF(OR(B13="",O13="",N13=""),0,IF(F13="Haftalık",MAX(0,INT((N13-O13)/7)+1),IF(F13="Aylık",MAX(0,(YEAR(N13)-YEAR(O13))*12+MONTH(N13)-MONTH(O13)+1),0))) -> 34
B14: M017 | C14: ASM EĞLENCE LTD.ŞTİ. | D14: 46023 | F14: Haftalık | G14: 2500 | H14: =IF(OR(B14="",D14="",F14="",G14=""),"",IF(AND(E14<>"",E14<SISTEM!$C$17),"Pasif","Aktif")) -> Aktif | I14: =IF(P14=0,0,P14*G14) -> 85000 | J14: =IF(OR(G14="",G14=0),"",I14/G14) -> 34 | K14: =IF(AND(B14="",C14=""),"",IF(OR(B14="",C14="",D14="",F14="",G14=""),"EKSİK",IF(COUNTIF(MUSTERILER!$B$7:$B$156,B14)=0,"TANIMSIZ MÜŞTERİ","UYGUN"))) -> UYGUN | L14: =IF(D14="","",IF(F14="Haftalık",D14+MOD(6-WEEKDAY(D14,2),7),EOMONTH(D14,0))) -> 46025 | M14: 34 | N14: =IF(B14="","",IF(E14="",SISTEM!$C$17,MIN(E14,SISTEM!$C$17))) -> 46261 | O14: =L14 -> 46025 | P14: =IF(OR(B14="",O14="",N14=""),0,IF(F14="Haftalık",MAX(0,INT((N14-O14)/7)+1),IF(F14="Aylık",MAX(0,(YEAR(N14)-YEAR(O14))*12+MONTH(N14)-MONTH(O14)+1),0))) -> 34
B15: M026 | C15: AYDES LTD.ŞTİ. | D15: 46023 | F15: Aylık | G15: 7500 | H15: =IF(OR(B15="",D15="",F15="",G15=""),"",IF(AND(E15<>"",E15<SISTEM!$C$17),"Pasif","Aktif")) -> Aktif | I15: =IF(P15=0,0,P15*G15) -> 60000 | J15: =IF(OR(G15="",G15=0),"",I15/G15) -> 8 | K15: =IF(AND(B15="",C15=""),"",IF(OR(B15="",C15="",D15="",F15="",G15=""),"EKSİK",IF(COUNTIF(MUSTERILER!$B$7:$B$156,B15)=0,"TANIMSIZ MÜŞTERİ","UYGUN"))) -> UYGUN | L15: =IF(D15="","",IF(F15="Haftalık",D15+MOD(6-WEEKDAY(D15,2),7),EOMONTH(D15,0))) -> 46053 | M15: 7 | N15: =IF(B15="","",IF(E15="",SISTEM!$C$17,MIN(E15,SISTEM!$C$17))) -> 46261 | O15: =L15 -> 46053 | P15: =IF(OR(B15="",O15="",N15=""),0,IF(F15="Haftalık",MAX(0,INT((N15-O15)/7)+1),IF(F15="Aylık",MAX(0,(YEAR(N15)-YEAR(O15))*12+MONTH(N15)-MONTH(O15)+1),0))) -> 8
B16: M027 | C16: CEREN DEMİRCİ | D16: 46023 | F16: Aylık | G16: 4000 | H16: =IF(OR(B16="",D16="",F16="",G16=""),"",IF(AND(E16<>"",E16<SISTEM!$C$17),"Pasif","Aktif")) -> Aktif | I16: =IF(P16=0,0,P16*G16) -> 32000 | J16: =IF(OR(G16="",G16=0),"",I16/G16) -> 8 | K16: =IF(AND(B16="",C16=""),"",IF(OR(B16="",C16="",D16="",F16="",G16=""),"EKSİK",IF(COUNTIF(MUSTERILER!$B$7:$B$156,B16)=0,"TANIMSIZ MÜŞTERİ","UYGUN"))) -> UYGUN | L16: =IF(D16="","",IF(F16="Haftalık",D16+MOD(6-WEEKDAY(D16,2),7),EOMONTH(D16,0))) -> 46053 | M16: 7 | N16: =IF(B16="","",IF(E16="",SISTEM!$C$17,MIN(E16,SISTEM!$C$17))) -> 46261 | O16: =L16 -> 46053 | P16: =IF(OR(B16="",O16="",N16=""),0,IF(F16="Haftalık",MAX(0,INT((N16-O16)/7)+1),IF(F16="Aylık",MAX(0,(YEAR(N16)-YEAR(O16))*12+MONTH(N16)-MONTH(O16)+1),0))) -> 8
B17: M015 | C17: ÇAYIRALAN LTD.ŞTİ. | D17: 46023 | F17: Haftalık | G17: 3000 | H17: =IF(OR(B17="",D17="",F17="",G17=""),"",IF(AND(E17<>"",E17<SISTEM!$C$17),"Pasif","Aktif")) -> Aktif | I17: =IF(P17=0,0,P17*G17) -> 102000 | J17: =IF(OR(G17="",G17=0),"",I17/G17) -> 34 | K17: =IF(AND(B17="",C17=""),"",IF(OR(B17="",C17="",D17="",F17="",G17=""),"EKSİK",IF(COUNTIF(MUSTERILER!$B$7:$B$156,B17)=0,"TANIMSIZ MÜŞTERİ","UYGUN"))) -> UYGUN | L17: =IF(D17="","",IF(F17="Haftalık",D17+MOD(6-WEEKDAY(D17,2),7),EOMONTH(D17,0))) -> 46025 | M17: 34 | N17: =IF(B17="","",IF(E17="",SISTEM!$C$17,MIN(E17,SISTEM!$C$17))) -> 46261 | O17: =L17 -> 46025 | P17: =IF(OR(B17="",O17="",N17=""),0,IF(F17="Haftalık",MAX(0,INT((N17-O17)/7)+1),IF(F17="Aylık",MAX(0,(YEAR(N17)-YEAR(O17))*12+MONTH(N17)-MONTH(O17)+1),0))) -> 34
B18: M018 | C18: ÇINARHAN LTD.ŞTİ. | D18: 46023 | E18: 46248 | F18: Haftalık | G18: 2500 | H18: =IF(OR(B18="",D18="",F18="",G18=""),"",IF(AND(E18<>"",E18<SISTEM!$C$17),"Pasif","Aktif")) -> Pasif | I18: =IF(P18=0,0,P18*G18) -> 80000 | J18: =IF(OR(G18="",G18=0),"",I18/G18) -> 32 | K18: =IF(AND(B18="",C18=""),"",IF(OR(B18="",C18="",D18="",F18="",G18=""),"EKSİK",IF(COUNTIF(MUSTERILER!$B$7:$B$156,B18)=0,"TANIMSIZ MÜŞTERİ","UYGUN"))) -> UYGUN | L18: =IF(D18="","",IF(F18="Haftalık",D18+MOD(6-WEEKDAY(D18,2),7),EOMONTH(D18,0))) -> 46025 | M18: 32 | N18: =IF(B18="","",IF(E18="",SISTEM!$C$17,MIN(E18,SISTEM!$C$17))) -> 46248 | O18: =L18 -> 46025 | P18: =IF(OR(B18="",O18="",N18=""),0,IF(F18="Haftalık",MAX(0,INT((N18-O18)/7)+1),IF(F18="Aylık",MAX(0,(YEAR(N18)-YEAR(O18))*12+MONTH(N18)-MONTH(O18)+1),0))) -> 32
B19: M028 | C19: DERVİŞHAN LTD.ŞTİ. | D19: 46023 | F19: Aylık | G19: 10000 | H19: =IF(OR(B19="",D19="",F19="",G19=""),"",IF(AND(E19<>"",E19<SISTEM!$C$17),"Pasif","Aktif")) -> Aktif | I19: =IF(P19=0,0,P19*G19) -> 80000 | J19: =IF(OR(G19="",G19=0),"",I19/G19) -> 8 | K19: =IF(AND(B19="",C19=""),"",IF(OR(B19="",C19="",D19="",F19="",G19=""),"EKSİK",IF(COUNTIF(MUSTERILER!$B$7:$B$156,B19)=0,"TANIMSIZ MÜŞTERİ","UYGUN"))) -> UYGUN | L19: =IF(D19="","",IF(F19="Haftalık",D19+MOD(6-WEEKDAY(D19,2),7),EOMONTH(D19,0))) -> 46053 | M19: 7 | N19: =IF(B19="","",IF(E19="",SISTEM!$C$17,MIN(E19,SISTEM!$C$17))) -> 46261 | O19: =L19 -> 46053 | P19: =IF(OR(B19="",O19="",N19=""),0,IF(F19="Haftalık",MAX(0,INT((N19-O19)/7)+1),IF(F19="Aylık",MAX(0,(YEAR(N19)-YEAR(O19))*12+MONTH(N19)-MONTH(O19)+1),0))) -> 8
B20: M011 | C20: EĞLENGÖR LTD.ŞTİ. | D20: 46039 | E20: 46109 | F20: Haftalık | G20: 3000 | H20: =IF(OR(B20="",D20="",F20="",G20=""),"",IF(AND(E20<>"",E20<SISTEM!$C$17),"Pasif","Aktif")) -> Pasif | I20: =IF(P20=0,0,P20*G20) -> 33000 | J20: =IF(OR(G20="",G20=0),"",I20/G20) -> 11 | K20: =IF(AND(B20="",C20=""),"",IF(OR(B20="",C20="",D20="",F20="",G20=""),"EKSİK",IF(COUNTIF(MUSTERILER!$B$7:$B$156,B20)=0,"TANIMSIZ MÜŞTERİ","UYGUN"))) -> UYGUN | L20: =IF(D20="","",IF(F20="Haftalık",D20+MOD(6-WEEKDAY(D20,2),7),EOMONTH(D20,0))) -> 46039 | M20: 11 | N20: =IF(B20="","",IF(E20="",SISTEM!$C$17,MIN(E20,SISTEM!$C$17))) -> 46109 | O20: =L20 -> 46039 | P20: =IF(OR(B20="",O20="",N20=""),0,IF(F20="Haftalık",MAX(0,INT((N20-O20)/7)+1),IF(F20="Aylık",MAX(0,(YEAR(N20)-YEAR(O20))*12+MONTH(N20)-MONTH(O20)+1),0))) -> 11
B21: M029 | C21: EMRAH SAVURKAN | D21: 46023 | F21: Aylık | G21: 2000 | H21: =IF(OR(B21="",D21="",F21="",G21=""),"",IF(AND(E21<>"",E21<SISTEM!$C$17),"Pasif","Aktif")) -> Aktif | I21: =IF(P21=0,0,P21*G21) -> 16000 | J21: =IF(OR(G21="",G21=0),"",I21/G21) -> 8 | K21: =IF(AND(B21="",C21=""),"",IF(OR(B21="",C21="",D21="",F21="",G21=""),"EKSİK",IF(COUNTIF(MUSTERILER!$B$7:$B$156,B21)=0,"TANIMSIZ MÜŞTERİ","UYGUN"))) -> UYGUN | L21: =IF(D21="","",IF(F21="Haftalık",D21+MOD(6-WEEKDAY(D21,2),7),EOMONTH(D21,0))) -> 46053 | M21: 7 | N21: =IF(B21="","",IF(E21="",SISTEM!$C$17,MIN(E21,SISTEM!$C$17))) -> 46261 | O21: =L21 -> 46053 | P21: =IF(OR(B21="",O21="",N21=""),0,IF(F21="Haftalık",MAX(0,INT((N21-O21)/7)+1),IF(F21="Aylık",MAX(0,(YEAR(N21)-YEAR(O21))*12+MONTH(N21)-MONTH(O21)+1),0))) -> 8
B22: M002 | C22: ESERLİ LTD.ŞTİ. | D22: 46023 | F22: Haftalık | G22: 3500 | H22: =IF(OR(B22="",D22="",F22="",G22=""),"",IF(AND(E22<>"",E22<SISTEM!$C$17),"Pasif","Aktif")) -> Aktif | I22: =IF(P22=0,0,P22*G22) -> 119000 | J22: =IF(OR(G22="",G22=0),"",I22/G22) -> 34 | K22: =IF(AND(B22="",C22=""),"",IF(OR(B22="",C22="",D22="",F22="",G22=""),"EKSİK",IF(COUNTIF(MUSTERILER!$B$7:$B$156,B22)=0,"TANIMSIZ MÜŞTERİ","UYGUN"))) -> UYGUN | L22: =IF(D22="","",IF(F22="Haftalık",D22+MOD(6-WEEKDAY(D22,2),7),EOMONTH(D22,0))) -> 46025 | M22: 34 | N22: =IF(B22="","",IF(E22="",SISTEM!$C$17,MIN(E22,SISTEM!$C$17))) -> 46261 | O22: =L22 -> 46025 | P22: =IF(OR(B22="",O22="",N22=""),0,IF(F22="Haftalık",MAX(0,INT((N22-O22)/7)+1),IF(F22="Aylık",MAX(0,(YEAR(N22)-YEAR(O22))*12+MONTH(N22)-MONTH(O22)+1),0))) -> 34
B23: M030 | C23: FARUK DEMİRCİ | D23: 46023 | F23: Aylık | G23: 2000 | H23: =IF(OR(B23="",D23="",F23="",G23=""),"",IF(AND(E23<>"",E23<SISTEM!$C$17),"Pasif","Aktif")) -> Aktif | I23: =IF(P23=0,0,P23*G23) -> 16000 | J23: =IF(OR(G23="",G23=0),"",I23/G23) -> 8 | K23: =IF(AND(B23="",C23=""),"",IF(OR(B23="",C23="",D23="",F23="",G23=""),"EKSİK",IF(COUNTIF(MUSTERILER!$B$7:$B$156,B23)=0,"TANIMSIZ MÜŞTERİ","UYGUN"))) -> UYGUN | L23: =IF(D23="","",IF(F23="Haftalık",D23+MOD(6-WEEKDAY(D23,2),7),EOMONTH(D23,0))) -> 46053 | M23: 7 | N23: =IF(B23="","",IF(E23="",SISTEM!$C$17,MIN(E23,SISTEM!$C$17))) -> 46261 | O23: =L23 -> 46053 | P23: =IF(OR(B23="",O23="",N23=""),0,IF(F23="Haftalık",MAX(0,INT((N23-O23)/7)+1),IF(F23="Aylık",MAX(0,(YEAR(N23)-YEAR(O23))*12+MONTH(N23)-MONTH(O23)+1),0))) -> 8
B24: M014 | C24: FİNAL SİYAH BEYAZ LTD.ŞTİ. | D24: 46023 | E24: 46115 | F24: Haftalık | G24: 2000 | H24: =IF(OR(B24="",D24="",F24="",G24=""),"",IF(AND(E24<>"",E24<SISTEM!$C$17),"Pasif","Aktif")) -> Pasif | I24: =IF(P24=0,0,P24*G24) -> 26000 | J24: =IF(OR(G24="",G24=0),"",I24/G24) -> 13 | K24: =IF(AND(B24="",C24=""),"",IF(OR(B24="",C24="",D24="",F24="",G24=""),"EKSİK",IF(COUNTIF(MUSTERILER!$B$7:$B$156,B24)=0,"TANIMSIZ MÜŞTERİ","UYGUN"))) -> UYGUN | L24: =IF(D24="","",IF(F24="Haftalık",D24+MOD(6-WEEKDAY(D24,2),7),EOMONTH(D24,0))) -> 46025 | M24: 13 | N24: =IF(B24="","",IF(E24="",SISTEM!$C$17,MIN(E24,SISTEM!$C$17))) -> 46115 | O24: =L24 -> 46025 | P24: =IF(OR(B24="",O24="",N24=""),0,IF(F24="Haftalık",MAX(0,INT((N24-O24)/7)+1),IF(F24="Aylık",MAX(0,(YEAR(N24)-YEAR(O24))*12+MONTH(N24)-MONTH(O24)+1),0))) -> 13
B25: M031 | C25: HALİL AVŞAR | D25: 46023 | F25: Aylık | G25: 3000 | H25: =IF(OR(B25="",D25="",F25="",G25=""),"",IF(AND(E25<>"",E25<SISTEM!$C$17),"Pasif","Aktif")) -> Aktif | I25: =IF(P25=0,0,P25*G25) -> 24000 | J25: =IF(OR(G25="",G25=0),"",I25/G25) -> 8 | K25: =IF(AND(B25="",C25=""),"",IF(OR(B25="",C25="",D25="",F25="",G25=""),"EKSİK",IF(COUNTIF(MUSTERILER!$B$7:$B$156,B25)=0,"TANIMSIZ MÜŞTERİ","UYGUN"))) -> UYGUN | L25: =IF(D25="","",IF(F25="Haftalık",D25+MOD(6-WEEKDAY(D25,2),7),EOMONTH(D25,0))) -> 46053 | M25: 7 | N25: =IF(B25="","",IF(E25="",SISTEM!$C$17,MIN(E25,SISTEM!$C$17))) -> 46261 | O25: =L25 -> 46053 | P25: =IF(OR(B25="",O25="",N25=""),0,IF(F25="Haftalık",MAX(0,INT((N25-O25)/7)+1),IF(F25="Aylık",MAX(0,(YEAR(N25)-YEAR(O25))*12+MONTH(N25)-MONTH(O25)+1),0))) -> 8
B26: M032 | C26: HAYDAR KAYA | D26: 46023 | F26: Aylık | G26: 1000 | H26: =IF(OR(B26="",D26="",F26="",G26=""),"",IF(AND(E26<>"",E26<SISTEM!$C$17),"Pasif","Aktif")) -> Aktif | I26: =IF(P26=0,0,P26*G26) -> 8000 | J26: =IF(OR(G26="",G26=0),"",I26/G26) -> 8 | K26: =IF(AND(B26="",C26=""),"",IF(OR(B26="",C26="",D26="",F26="",G26=""),"EKSİK",IF(COUNTIF(MUSTERILER!$B$7:$B$156,B26)=0,"TANIMSIZ MÜŞTERİ","UYGUN"))) -> UYGUN | L26: =IF(D26="","",IF(F26="Haftalık",D26+MOD(6-WEEKDAY(D26,2),7),EOMONTH(D26,0))) -> 46053 | M26: 7 | N26: =IF(B26="","",IF(E26="",SISTEM!$C$17,MIN(E26,SISTEM!$C$17))) -> 46261 | O26: =L26 -> 46053 | P26: =IF(OR(B26="",O26="",N26=""),0,IF(F26="Haftalık",MAX(0,INT((N26-O26)/7)+1),IF(F26="Aylık",MAX(0,(YEAR(N26)-YEAR(O26))*12+MONTH(N26)-MONTH(O26)+1),0))) -> 8
B27: M033 | C27: IŞIL GRUP LTD.ŞTİ. | D27: 46023 | F27: Aylık | G27: 7500 | H27: =IF(OR(B27="",D27="",F27="",G27=""),"",IF(AND(E27<>"",E27<SISTEM!$C$17),"Pasif","Aktif")) -> Aktif | I27: =IF(P27=0,0,P27*G27) -> 60000 | J27: =IF(OR(G27="",G27=0),"",I27/G27) -> 8 | K27: =IF(AND(B27="",C27=""),"",IF(OR(B27="",C27="",D27="",F27="",G27=""),"EKSİK",IF(COUNTIF(MUSTERILER!$B$7:$B$156,B27)=0,"TANIMSIZ MÜŞTERİ","UYGUN"))) -> UYGUN | L27: =IF(D27="","",IF(F27="Haftalık",D27+MOD(6-WEEKDAY(D27,2),7),EOMONTH(D27,0))) -> 46053 | M27: 7 | N27: =IF(B27="","",IF(E27="",SISTEM!$C$17,MIN(E27,SISTEM!$C$17))) -> 46261 | O27: =L27 -> 46053 | P27: =IF(OR(B27="",O27="",N27=""),0,IF(F27="Haftalık",MAX(0,INT((N27-O27)/7)+1),IF(F27="Aylık",MAX(0,(YEAR(N27)-YEAR(O27))*12+MONTH(N27)-MONTH(O27)+1),0))) -> 8
B28: M034 | C28: İBRAHİM MALDAN | D28: 46023 | E28: 46081 | F28: Haftalık | G28: 1500 | H28: =IF(OR(B28="",D28="",F28="",G28=""),"",IF(AND(E28<>"",E28<SISTEM!$C$17),"Pasif","Aktif")) -> Pasif | I28: =IF(P28=0,0,P28*G28) -> 13500 | J28: =IF(OR(G28="",G28=0),"",I28/G28) -> 9 | K28: =IF(AND(B28="",C28=""),"",IF(OR(B28="",C28="",D28="",F28="",G28=""),"EKSİK",IF(COUNTIF(MUSTERILER!$B$7:$B$156,B28)=0,"TANIMSIZ MÜŞTERİ","UYGUN"))) -> UYGUN | L28: =IF(D28="","",IF(F28="Haftalık",D28+MOD(6-WEEKDAY(D28,2),7),EOMONTH(D28,0))) -> 46025 | M28: 9 | N28: =IF(B28="","",IF(E28="",SISTEM!$C$17,MIN(E28,SISTEM!$C$17))) -> 46081 | O28: =L28 -> 46025 | P28: =IF(OR(B28="",O28="",N28=""),0,IF(F28="Haftalık",MAX(0,INT((N28-O28)/7)+1),IF(F28="Aylık",MAX(0,(YEAR(N28)-YEAR(O28))*12+MONTH(N28)-MONTH(O28)+1),0))) -> 9
B29: M012 | C29: İLDEŞ LTD.ŞTİ. | D29: 46023 | E29: 46112 | F29: Haftalık | G29: 2000 | H29: =IF(OR(B29="",D29="",F29="",G29=""),"",IF(AND(E29<>"",E29<SISTEM!$C$17),"Pasif","Aktif")) -> Pasif | I29: =IF(P29=0,0,P29*G29) -> 26000 | J29: =IF(OR(G29="",G29=0),"",I29/G29) -> 13 | K29: =IF(AND(B29="",C29=""),"",IF(OR(B29="",C29="",D29="",F29="",G29=""),"EKSİK",IF(COUNTIF(MUSTERILER!$B$7:$B$156,B29)=0,"TANIMSIZ MÜŞTERİ","UYGUN"))) -> UYGUN | L29: =IF(D29="","",IF(F29="Haftalık",D29+MOD(6-WEEKDAY(D29,2),7),EOMONTH(D29,0))) -> 46025 | M29: 13 | N29: =IF(B29="","",IF(E29="",SISTEM!$C$17,MIN(E29,SISTEM!$C$17))) -> 46112 | O29: =L29 -> 46025 | P29: =IF(OR(B29="",O29="",N29=""),0,IF(F29="Haftalık",MAX(0,INT((N29-O29)/7)+1),IF(F29="Aylık",MAX(0,(YEAR(N29)-YEAR(O29))*12+MONTH(N29)-MONTH(O29)+1),0))) -> 13
B30: M035 | C30: İSA DEMİRCİ | D30: 46023 | F30: Aylık | G30: 3500 | H30: =IF(OR(B30="",D30="",F30="",G30=""),"",IF(AND(E30<>"",E30<SISTEM!$C$17),"Pasif","Aktif")) -> Aktif | I30: =IF(P30=0,0,P30*G30) -> 28000 | J30: =IF(OR(G30="",G30=0),"",I30/G30) -> 8 | K30: =IF(AND(B30="",C30=""),"",IF(OR(B30="",C30="",D30="",F30="",G30=""),"EKSİK",IF(COUNTIF(MUSTERILER!$B$7:$B$156,B30)=0,"TANIMSIZ MÜŞTERİ","UYGUN"))) -> UYGUN | L30: =IF(D30="","",IF(F30="Haftalık",D30+MOD(6-WEEKDAY(D30,2),7),EOMONTH(D30,0))) -> 46053 | M30: 7 | N30: =IF(B30="","",IF(E30="",SISTEM!$C$17,MIN(E30,SISTEM!$C$17))) -> 46261 | O30: =L30 -> 46053 | P30: =IF(OR(B30="",O30="",N30=""),0,IF(F30="Haftalık",MAX(0,INT((N30-O30)/7)+1),IF(F30="Aylık",MAX(0,(YEAR(N30)-YEAR(O30))*12+MONTH(N30)-MONTH(O30)+1),0))) -> 8
B31: M036 | C31: İSMAİL AKPINAR | D31: 46023 | F31: Aylık | G31: 4000 | H31: =IF(OR(B31="",D31="",F31="",G31=""),"",IF(AND(E31<>"",E31<SISTEM!$C$17),"Pasif","Aktif")) -> Aktif | I31: =IF(P31=0,0,P31*G31) -> 32000 | J31: =IF(OR(G31="",G31=0),"",I31/G31) -> 8 | K31: =IF(AND(B31="",C31=""),"",IF(OR(B31="",C31="",D31="",F31="",G31=""),"EKSİK",IF(COUNTIF(MUSTERILER!$B$7:$B$156,B31)=0,"TANIMSIZ MÜŞTERİ","UYGUN"))) -> UYGUN | L31: =IF(D31="","",IF(F31="Haftalık",D31+MOD(6-WEEKDAY(D31,2),7),EOMONTH(D31,0))) -> 46053 | M31: 7 | N31: =IF(B31="","",IF(E31="",SISTEM!$C$17,MIN(E31,SISTEM!$C$17))) -> 46261 | O31: =L31 -> 46053 | P31: =IF(OR(B31="",O31="",N31=""),0,IF(F31="Haftalık",MAX(0,INT((N31-O31)/7)+1),IF(F31="Aylık",MAX(0,(YEAR(N31)-YEAR(O31))*12+MONTH(N31)-MONTH(O31)+1),0))) -> 8
B32: M008 | C32: KÖŞK YÜKSELEN LTD.ŞTİ. | D32: 46023 | F32: Haftalık | G32: 2500 | H32: =IF(OR(B32="",D32="",F32="",G32=""),"",IF(AND(E32<>"",E32<SISTEM!$C$17),"Pasif","Aktif")) -> Aktif | I32: =IF(P32=0,0,P32*G32) -> 85000 | J32: =IF(OR(G32="",G32=0),"",I32/G32) -> 34 | K32: =IF(AND(B32="",C32=""),"",IF(OR(B32="",C32="",D32="",F32="",G32=""),"EKSİK",IF(COUNTIF(MUSTERILER!$B$7:$B$156,B32)=0,"TANIMSIZ MÜŞTERİ","UYGUN"))) -> UYGUN | L32: =IF(D32="","",IF(F32="Haftalık",D32+MOD(6-WEEKDAY(D32,2),7),EOMONTH(D32,0))) -> 46025 | M32: 34 | N32: =IF(B32="","",IF(E32="",SISTEM!$C$17,MIN(E32,SISTEM!$C$17))) -> 46261 | O32: =L32 -> 46025 | P32: =IF(OR(B32="",O32="",N32=""),0,IF(F32="Haftalık",MAX(0,INT((N32-O32)/7)+1),IF(F32="Aylık",MAX(0,(YEAR(N32)-YEAR(O32))*12+MONTH(N32)-MONTH(O32)+1),0))) -> 34
B33: M020 | C33: KRİSTAL LTD.ŞTİ. | D33: 46023 | F33: Haftalık | G33: 3000 | H33: =IF(OR(B33="",D33="",F33="",G33=""),"",IF(AND(E33<>"",E33<SISTEM!$C$17),"Pasif","Aktif")) -> Aktif | I33: =IF(P33=0,0,P33*G33) -> 102000 | J33: =IF(OR(G33="",G33=0),"",I33/G33) -> 34 | K33: =IF(AND(B33="",C33=""),"",IF(OR(B33="",C33="",D33="",F33="",G33=""),"EKSİK",IF(COUNTIF(MUSTERILER!$B$7:$B$156,B33)=0,"TANIMSIZ MÜŞTERİ","UYGUN"))) -> UYGUN | L33: =IF(D33="","",IF(F33="Haftalık",D33+MOD(6-WEEKDAY(D33,2),7),EOMONTH(D33,0))) -> 46025 | M33: 34 | N33: =IF(B33="","",IF(E33="",SISTEM!$C$17,MIN(E33,SISTEM!$C$17))) -> 46261 | O33: =L33 -> 46025 | P33: =IF(OR(B33="",O33="",N33=""),0,IF(F33="Haftalık",MAX(0,INT((N33-O33)/7)+1),IF(F33="Aylık",MAX(0,(YEAR(N33)-YEAR(O33))*12+MONTH(N33)-MONTH(O33)+1),0))) -> 34
B34: M037 | C34: MEHMET EVREN KILINÇ | D34: 46023 | F34: Aylık | G34: 2000 | H34: =IF(OR(B34="",D34="",F34="",G34=""),"",IF(AND(E34<>"",E34<SISTEM!$C$17),"Pasif","Aktif")) -> Aktif | I34: =IF(P34=0,0,P34*G34) -> 16000 | J34: =IF(OR(G34="",G34=0),"",I34/G34) -> 8 | K34: =IF(AND(B34="",C34=""),"",IF(OR(B34="",C34="",D34="",F34="",G34=""),"EKSİK",IF(COUNTIF(MUSTERILER!$B$7:$B$156,B34)=0,"TANIMSIZ MÜŞTERİ","UYGUN"))) -> UYGUN | L34: =IF(D34="","",IF(F34="Haftalık",D34+MOD(6-WEEKDAY(D34,2),7),EOMONTH(D34,0))) -> 46053 | M34: 7 | N34: =IF(B34="","",IF(E34="",SISTEM!$C$17,MIN(E34,SISTEM!$C$17))) -> 46261 | O34: =L34 -> 46053 | P34: =IF(OR(B34="",O34="",N34=""),0,IF(F34="Haftalık",MAX(0,INT((N34-O34)/7)+1),IF(F34="Aylık",MAX(0,(YEAR(N34)-YEAR(O34))*12+MONTH(N34)-MONTH(O34)+1),0))) -> 8
B35: M038 | C35: MELEK GÜLER | D35: 46023 | F35: Aylık | G35: 3000 | H35: =IF(OR(B35="",D35="",F35="",G35=""),"",IF(AND(E35<>"",E35<SISTEM!$C$17),"Pasif","Aktif")) -> Aktif | I35: =IF(P35=0,0,P35*G35) -> 24000 | J35: =IF(OR(G35="",G35=0),"",I35/G35) -> 8 | K35: =IF(AND(B35="",C35=""),"",IF(OR(B35="",C35="",D35="",F35="",G35=""),"EKSİK",IF(COUNTIF(MUSTERILER!$B$7:$B$156,B35)=0,"TANIMSIZ MÜŞTERİ","UYGUN"))) -> UYGUN | L35: =IF(D35="","",IF(F35="Haftalık",D35+MOD(6-WEEKDAY(D35,2),7),EOMONTH(D35,0))) -> 46053 | M35: 7 | N35: =IF(B35="","",IF(E35="",SISTEM!$C$17,MIN(E35,SISTEM!$C$17))) -> 46261 | O35: =L35 -> 46053 | P35: =IF(OR(B35="",O35="",N35=""),0,IF(F35="Haftalık",MAX(0,INT((N35-O35)/7)+1),IF(F35="Aylık",MAX(0,(YEAR(N35)-YEAR(O35))*12+MONTH(N35)-MONTH(O35)+1),0))) -> 8
B36: M039 | C36: MELİSA BEDİR | D36: 46023 | F36: Aylık | G36: 3000 | H36: =IF(OR(B36="",D36="",F36="",G36=""),"",IF(AND(E36<>"",E36<SISTEM!$C$17),"Pasif","Aktif")) -> Aktif | I36: =IF(P36=0,0,P36*G36) -> 24000 | J36: =IF(OR(G36="",G36=0),"",I36/G36) -> 8 | K36: =IF(AND(B36="",C36=""),"",IF(OR(B36="",C36="",D36="",F36="",G36=""),"EKSİK",IF(COUNTIF(MUSTERILER!$B$7:$B$156,B36)=0,"TANIMSIZ MÜŞTERİ","UYGUN"))) -> UYGUN | L36: =IF(D36="","",IF(F36="Haftalık",D36+MOD(6-WEEKDAY(D36,2),7),EOMONTH(D36,0))) -> 46053 | M36: 7 | N36: =IF(B36="","",IF(E36="",SISTEM!$C$17,MIN(E36,SISTEM!$C$17))) -> 46261 | O36: =L36 -> 46053 | P36: =IF(OR(B36="",O36="",N36=""),0,IF(F36="Haftalık",MAX(0,INT((N36-O36)/7)+1),IF(F36="Aylık",MAX(0,(YEAR(N36)-YEAR(O36))*12+MONTH(N36)-MONTH(O36)+1),0))) -> 8
B37: M040 | C37: MENEKŞE AKAN | D37: 46023 | F37: Aylık | G37: 1500 | H37: =IF(OR(B37="",D37="",F37="",G37=""),"",IF(AND(E37<>"",E37<SISTEM!$C$17),"Pasif","Aktif")) -> Aktif | I37: =IF(P37=0,0,P37*G37) -> 12000 | J37: =IF(OR(G37="",G37=0),"",I37/G37) -> 8 | K37: =IF(AND(B37="",C37=""),"",IF(OR(B37="",C37="",D37="",F37="",G37=""),"EKSİK",IF(COUNTIF(MUSTERILER!$B$7:$B$156,B37)=0,"TANIMSIZ MÜŞTERİ","UYGUN"))) -> UYGUN | L37: =IF(D37="","",IF(F37="Haftalık",D37+MOD(6-WEEKDAY(D37,2),7),EOMONTH(D37,0))) -> 46053 | M37: 7 | N37: =IF(B37="","",IF(E37="",SISTEM!$C$17,MIN(E37,SISTEM!$C$17))) -> 46261 | O37: =L37 -> 46053 | P37: =IF(OR(B37="",O37="",N37=""),0,IF(F37="Haftalık",MAX(0,INT((N37-O37)/7)+1),IF(F37="Aylık",MAX(0,(YEAR(N37)-YEAR(O37))*12+MONTH(N37)-MONTH(O37)+1),0))) -> 8
B38: M041 | C38: MESUT KÖKLÜ | D38: 46174 | F38: Aylık | G38: 5000 | H38: =IF(OR(B38="",D38="",F38="",G38=""),"",IF(AND(E38<>"",E38<SISTEM!$C$17),"Pasif","Aktif")) -> Aktif | I38: =IF(P38=0,0,P38*G38) -> 15000 | J38: =IF(OR(G38="",G38=0),"",I38/G38) -> 3 | K38: =IF(AND(B38="",C38=""),"",IF(OR(B38="",C38="",D38="",F38="",G38=""),"EKSİK",IF(COUNTIF(MUSTERILER!$B$7:$B$156,B38)=0,"TANIMSIZ MÜŞTERİ","UYGUN"))) -> UYGUN | L38: =IF(D38="","",IF(F38="Haftalık",D38+MOD(6-WEEKDAY(D38,2),7),EOMONTH(D38,0))) -> 46203 | M38: 2 | N38: =IF(B38="","",IF(E38="",SISTEM!$C$17,MIN(E38,SISTEM!$C$17))) -> 46261 | O38: =L38 -> 46203 | P38: =IF(OR(B38="",O38="",N38=""),0,IF(F38="Haftalık",MAX(0,INT((N38-O38)/7)+1),IF(F38="Aylık",MAX(0,(YEAR(N38)-YEAR(O38))*12+MONTH(N38)-MONTH(O38)+1),0))) -> 3
B39: M007 | C39: MONAMOUR LTD.ŞTİ. | D39: 46023 | F39: Haftalık | G39: 3500 | H39: =IF(OR(B39="",D39="",F39="",G39=""),"",IF(AND(E39<>"",E39<SISTEM!$C$17),"Pasif","Aktif")) -> Aktif | I39: =IF(P39=0,0,P39*G39) -> 119000 | J39: =IF(OR(G39="",G39=0),"",I39/G39) -> 34 | K39: =IF(AND(B39="",C39=""),"",IF(OR(B39="",C39="",D39="",F39="",G39=""),"EKSİK",IF(COUNTIF(MUSTERILER!$B$7:$B$156,B39)=0,"TANIMSIZ MÜŞTERİ","UYGUN"))) -> UYGUN | L39: =IF(D39="","",IF(F39="Haftalık",D39+MOD(6-WEEKDAY(D39,2),7),EOMONTH(D39,0))) -> 46025 | M39: 34 | N39: =IF(B39="","",IF(E39="",SISTEM!$C$17,MIN(E39,SISTEM!$C$17))) -> 46261 | O39: =L39 -> 46025 | P39: =IF(OR(B39="",O39="",N39=""),0,IF(F39="Haftalık",MAX(0,INT((N39-O39)/7)+1),IF(F39="Aylık",MAX(0,(YEAR(N39)-YEAR(O39))*12+MONTH(N39)-MONTH(O39)+1),0))) -> 34
B40: M042 | C40: MS TOPTAN LTD.ŞTİ. | D40: 46023 | F40: Aylık | G40: 1 | H40: =IF(OR(B40="",D40="",F40="",G40=""),"",IF(AND(E40<>"",E40<SISTEM!$C$17),"Pasif","Aktif")) -> Aktif | I40: =IF(P40=0,0,P40*G40) -> 8 | J40: =IF(OR(G40="",G40=0),"",I40/G40) -> 8 | K40: =IF(AND(B40="",C40=""),"",IF(OR(B40="",C40="",D40="",F40="",G40=""),"EKSİK",IF(COUNTIF(MUSTERILER!$B$7:$B$156,B40)=0,"TANIMSIZ MÜŞTERİ","UYGUN"))) -> UYGUN | L40: =IF(D40="","",IF(F40="Haftalık",D40+MOD(6-WEEKDAY(D40,2),7),EOMONTH(D40,0))) -> 46053 | M40: 7 | N40: =IF(B40="","",IF(E40="",SISTEM!$C$17,MIN(E40,SISTEM!$C$17))) -> 46261 | O40: =L40 -> 46053 | P40: =IF(OR(B40="",O40="",N40=""),0,IF(F40="Haftalık",MAX(0,INT((N40-O40)/7)+1),IF(F40="Aylık",MAX(0,(YEAR(N40)-YEAR(O40))*12+MONTH(N40)-MONTH(O40)+1),0))) -> 8
...

Sheet TAHSILAT
A1: =IFERROR(HYPERLINK("#MENU!A1","☰ MENÜ"),"☰ MENÜ") -> ☰ MENÜ | B1: =IFERROR(HYPERLINK("#MENU!A1","↗"),"↗") -> ↗ | C1: KILIÇ MUHASEBE │ TAHSİLAT DEFTERİ
A2: ✎ VERİ GİRİŞ ALANI — YALNIZ SARI HÜCRELER | C2: Gerçek tahsilat — para kimde kaldıysa ilgili hesabı seçin.
A3: SAKIN: Kasaya gerçekte girmeyen parayı MERKEZ KASA seçmeyin.
A4: =IFERROR(HYPERLINK("#MENU!A1","← MENÜ │ TAHSİLAT"),"← MENÜ │ TAHSİLAT") -> ← MENÜ │ TAHSİLAT | H4: =IFERROR(HYPERLINK("#TAHSILAT!A1","TAHSİLAT"),"TAHSİLAT") -> TAHSİLAT | J4: =IFERROR(HYPERLINK("#GELIR_GIDER!A1","GELİR / GİDER"),"GELİR / GİDER") -> GELİR / GİDER | L4: =IFERROR(HYPERLINK("#VIRMAN!A1","VİRMAN"),"VİRMAN") -> VİRMAN | N4: =IFERROR(HYPERLINK("#RAPOR!A1","RAPOR"),"RAPOR") -> RAPOR
B5: TAHSİLAT TOPLAMI | C5: =SUM($F$7:$F$1006) -> 2299500 | E5: KAYIT | F5: =COUNTIF($B$7:$B$1006,"<>") -> 1000 | H5: ÖMER'DE KALAN | I5: =SUMIFS($F$7:$F$1006,$G$7:$G$1006,"ÖMER KARTAL") -> 594650 | J5: NAKİT KURALI │ Para kimde kaldıysa hesap odur.
B6: Tahsilat No | C6: Müşteri No | D6: Müşteri | E6: Tarih | F6: Tutar | G6: Kasa / Banka | H6: Ödeme Türü | I6: Belge No | J6: Açıklama | K6: İşlemi Giren | L6: Ay | M6: Kayıt Kontrolü | N6: Teknik Müşteri Anahtarı | O6: Teknik Hesap Anahtarı
B7: T00001 | C7: M047 | D7: PALAOĞULLARI LTD.ŞTİ. | E7: 46023 | F7: 27000 | G7: CARİ MAHSUP | H7: Mahsup | J7: HESAP BAKİYE TASHİHİ KAPALI KALDIĞI DÖNEM | L7: =IF(E7="","",DATE(YEAR(E7),MONTH(E7),1)) -> 46023 | M7: =IF(AND(C7="",D7="",E7="",F7=""),"",IF(OR(C7="",D7="",E7="",F7="",G7=""),"EKSİK",IF(COUNTIF(MUSTERILER!$B$7:$B$156,C7)=0,"TANIMSIZ MÜŞTERİ","UYGUN"))) -> UYGUN | N7: =IF(D7="","",D7&"|"&TEXT(COUNTIF($D$7:D7,D7),"000")) -> PALAOĞULLARI LTD.ŞTİ.|001 | O7: =IF(G7="","",G7&"|"&TEXT(COUNTIF($G$7:G7,G7),"000")) -> CARİ MAHSUP|001
B8: T00002 | C8: M016 | D8: RİX ŞOW LTD.ŞTİ. | E8: 46023 | F8: 17200 | G8: CARİ MAHSUP | H8: Mahsup | J8: HESAP BAKİYE TASHİHİ KAPALI KALDIĞI DÖNEM | L8: =IF(E8="","",DATE(YEAR(E8),MONTH(E8),1)) -> 46023 | M8: =IF(AND(C8="",D8="",E8="",F8=""),"",IF(OR(C8="",D8="",E8="",F8="",G8=""),"EKSİK",IF(COUNTIF(MUSTERILER!$B$7:$B$156,C8)=0,"TANIMSIZ MÜŞTERİ","UYGUN"))) -> UYGUN | N8: =IF(D8="","",D8&"|"&TEXT(COUNTIF($D$7:D8,D8),"000")) -> RİX ŞOW LTD.ŞTİ.|001 | O8: =IF(G8="","",G8&"|"&TEXT(COUNTIF($G$7:G8,G8),"000")) -> CARİ MAHSUP|002
B9: T00003 | C9: M015 | D9: Çayıralan Ltd.Şti. | E9: 46023 | F9: 5000 | G9: MERKEZ KASA | H9: Nakit | J9: NAKİT ÖDENEN | L9: =IF(E9="","",DATE(YEAR(E9),MONTH(E9),1)) -> 46023 | M9: =IF(AND(C9="",D9="",E9="",F9=""),"",IF(OR(C9="",D9="",E9="",F9="",G9=""),"EKSİK",IF(COUNTIF(MUSTERILER!$B$7:$B$156,C9)=0,"TANIMSIZ MÜŞTERİ","UYGUN"))) -> UYGUN | N9: =IF(D9="","",D9&"|"&TEXT(COUNTIF($D$7:D9,D9),"000")) -> Çayıralan Ltd.Şti.|001 | O9: =IF(G9="","",G9&"|"&TEXT(COUNTIF($G$7:G9,G9),"000")) -> MERKEZ KASA|001
B10: T00004 | C10: M012 | D10: İldeş Ltd.Şti. | E10: 46023 | F10: 3000 | G10: MERKEZ KASA | H10: Nakit | J10: NAKİT ÖDENEN | L10: =IF(E10="","",DATE(YEAR(E10),MONTH(E10),1)) -> 46023 | M10: =IF(AND(C10="",D10="",E10="",F10=""),"",IF(OR(C10="",D10="",E10="",F10="",G10=""),"EKSİK",IF(COUNTIF(MUSTERILER!$B$7:$B$156,C10)=0,"TANIMSIZ MÜŞTERİ","UYGUN"))) -> UYGUN | N10: =IF(D10="","",D10&"|"&TEXT(COUNTIF($D$7:D10,D10),"000")) -> İldeş Ltd.Şti.|001 | O10: =IF(G10="","",G10&"|"&TEXT(COUNTIF($G$7:G10,G10),"000")) -> MERKEZ KASA|002
B11: T00005 | C11: M025 | D11: ASIM AÇIKGÖZ | E11: 46023 | F11: 8000 | G11: MERKEZ KASA | H11: Nakit | J11: NAKİT ÖDENEN | L11: =IF(E11="","",DATE(YEAR(E11),MONTH(E11),1)) -> 46023 | M11: =IF(AND(C11="",D11="",E11="",F11=""),"",IF(OR(C11="",D11="",E11="",F11="",G11=""),"EKSİK",IF(COUNTIF(MUSTERILER!$B$7:$B$156,C11)=0,"TANIMSIZ MÜŞTERİ","UYGUN"))) -> UYGUN | N11: =IF(D11="","",D11&"|"&TEXT(COUNTIF($D$7:D11,D11),"000")) -> ASIM AÇIKGÖZ|001 | O11: =IF(G11="","",G11&"|"&TEXT(COUNTIF($G$7:G11,G11),"000")) -> MERKEZ KASA|003
B12: T00006 | C12: M017 | D12: ASM EĞLENCE LTD.ŞTİ. | E12: 46023 | F12: 10000 | G12: MERKEZ KASA | H12: Nakit | J12: NAKİT ÖDENEN | L12: =IF(E12="","",DATE(YEAR(E12),MONTH(E12),1)) -> 46023 | M12: =IF(AND(C12="",D12="",E12="",F12=""),"",IF(OR(C12="",D12="",E12="",F12="",G12=""),"EKSİK",IF(COUNTIF(MUSTERILER!$B$7:$B$156,C12)=0,"TANIMSIZ MÜŞTERİ","UYGUN"))) -> UYGUN | N12: =IF(D12="","",D12&"|"&TEXT(COUNTIF($D$7:D12,D12),"000")) -> ASM EĞLENCE LTD.ŞTİ.|001 | O12: =IF(G12="","",G12&"|"&TEXT(COUNTIF($G$7:G12,G12),"000")) -> MERKEZ KASA|004
B13: T00007 | C13: M018 | D13: ÇINARHAN LTD.ŞTİ. | E13: 46023 | F13: 4500 | G13: MERKEZ KASA | H13: Nakit | J13: NAKİT ÖDENEN | L13: =IF(E13="","",DATE(YEAR(E13),MONTH(E13),1)) -> 46023 | M13: =IF(AND(C13="",D13="",E13="",F13=""),"",IF(OR(C13="",D13="",E13="",F13="",G13=""),"EKSİK",IF(COUNTIF(MUSTERILER!$B$7:$B$156,C13)=0,"TANIMSIZ MÜŞTERİ","UYGUN"))) -> UYGUN | N13: =IF(D13="","",D13&"|"&TEXT(COUNTIF($D$7:D13,D13),"000")) -> ÇINARHAN LTD.ŞTİ.|001 | O13: =IF(G13="","",G13&"|"&TEXT(COUNTIF($G$7:G13,G13),"000")) -> MERKEZ KASA|005
B14: T00008 | C14: M005 | D14: Zümrüt Grup Ltd.Şti. | E14: 46023 | F14: 15750 | G14: MERKEZ KASA | H14: Nakit | J14: NAKİT ÖDENEN | L14: =IF(E14="","",DATE(YEAR(E14),MONTH(E14),1)) -> 46023 | M14: =IF(AND(C14="",D14="",E14="",F14=""),"",IF(OR(C14="",D14="",E14="",F14="",G14=""),"EKSİK",IF(COUNTIF(MUSTERILER!$B$7:$B$156,C14)=0,"TANIMSIZ MÜŞTERİ","UYGUN"))) -> UYGUN | N14: =IF(D14="","",D14&"|"&TEXT(COUNTIF($D$7:D14,D14),"000")) -> Zümrüt Grup Ltd.Şti.|001 | O14: =IF(G14="","",G14&"|"&TEXT(COUNTIF($G$7:G14,G14),"000")) -> MERKEZ KASA|006
B15: T00009 | C15: M011 | D15: EĞLENGÖR LTD.ŞTİ. | E15: 46025 | F15: 3000 | G15: ÖMER KARTAL | H15: Nakit | J15: ÖMER KARTALA ÖDENEN | L15: =IF(E15="","",DATE(YEAR(E15),MONTH(E15),1)) -> 46023 | M15: =IF(AND(C15="",D15="",E15="",F15=""),"",IF(OR(C15="",D15="",E15="",F15="",G15=""),"EKSİK",IF(COUNTIF(MUSTERILER!$B$7:$B$156,C15)=0,"TANIMSIZ MÜŞTERİ","UYGUN"))) -> UYGUN | N15: =IF(D15="","",D15&"|"&TEXT(COUNTIF($D$7:D15,D15),"000")) -> EĞLENGÖR LTD.ŞTİ.|001 | O15: =IF(G15="","",G15&"|"&TEXT(COUNTIF($G$7:G15,G15),"000")) -> ÖMER KARTAL|001
B16: T00010 | C16: M010 | D16: ÖZFİDANLAR LTD.ŞTİ. | E16: 46025 | F16: 2000 | G16: ÖMER KARTAL | H16: Nakit | J16: ÖMER KARTALA ÖDENEN | L16: =IF(E16="","",DATE(YEAR(E16),MONTH(E16),1)) -> 46023 | M16: =IF(AND(C16="",D16="",E16="",F16=""),"",IF(OR(C16="",D16="",E16="",F16="",G16=""),"EKSİK",IF(COUNTIF(MUSTERILER!$B$7:$B$156,C16)=0,"TANIMSIZ MÜŞTERİ","UYGUN"))) -> UYGUN | N16: =IF(D16="","",D16&"|"&TEXT(COUNTIF($D$7:D16,D16),"000")) -> ÖZFİDANLAR LTD.ŞTİ.|001 | O16: =IF(G16="","",G16&"|"&TEXT(COUNTIF($G$7:G16,G16),"000")) -> ÖMER KARTAL|002
B17: T00011 | C17: M009 | D17: PAKYILDIZ LTD.ŞTİ. | E17: 46025 | F17: 2000 | G17: ÖMER KARTAL | H17: Nakit | J17: ÖMER KARTALA ÖDENEN | L17: =IF(E17="","",DATE(YEAR(E17),MONTH(E17),1)) -> 46023 | M17: =IF(AND(C17="",D17="",E17="",F17=""),"",IF(OR(C17="",D17="",E17="",F17="",G17=""),"EKSİK",IF(COUNTIF(MUSTERILER!$B$7:$B$156,C17)=0,"TANIMSIZ MÜŞTERİ","UYGUN"))) -> UYGUN | N17: =IF(D17="","",D17&"|"&TEXT(COUNTIF($D$7:D17,D17),"000")) -> PAKYILDIZ LTD.ŞTİ.|001 | O17: =IF(G17="","",G17&"|"&TEXT(COUNTIF($G$7:G17,G17),"000")) -> ÖMER KARTAL|003
B18: T00012 | C18: M005 | D18: ZÜMRÜT GRUP LTD.ŞTİ. | E18: 46025 | F18: 1750 | G18: ÖMER KARTAL | H18: Nakit | J18: ÖMER KARTALA ÖDENEN | L18: =IF(E18="","",DATE(YEAR(E18),MONTH(E18),1)) -> 46023 | M18: =IF(AND(C18="",D18="",E18="",F18=""),"",IF(OR(C18="",D18="",E18="",F18="",G18=""),"EKSİK",IF(COUNTIF(MUSTERILER!$B$7:$B$156,C18)=0,"TANIMSIZ MÜŞTERİ","UYGUN"))) -> UYGUN | N18: =IF(D18="","",D18&"|"&TEXT(COUNTIF($D$7:D18,D18),"000")) -> ZÜMRÜT GRUP LTD.ŞTİ.|002 | O18: =IF(G18="","",G18&"|"&TEXT(COUNTIF($G$7:G18,G18),"000")) -> ÖMER KARTAL|004
