Workbook
Name CARI_BAKIYE: MUSTERI_360!$J$7:$J$156
Name EKSTRE: OFFSET(CARI_EKSTRE!$A$1,0,0,15+COUNT(CARI_EKSTRE!$C$12:$C$311)+4,8)
Name EKSTRE_BAKIYE: CARI_EKSTRE!$F$9
Name EKSTRE_TABLO: OFFSET(CARI_EKSTRE!$B$11,0,0,1+COUNT(CARI_EKSTRE!$C$12:$C$311),7)
Name GECIKMIS_29: MUSTERI_360!$N$7:$N$156
Name Gelir: SISTEM!$K$36:$K$60
Name Gider: SISTEM!$K$8:$K$32
Name LST_HESAP: HESAPLAR!$B$7:$B$16
Name LST_MUSTERI_ADI: MUSTERILER!$C$7:$C$156
Name LST_ORTAK: ORTAKLAR!$B$7:$B$10
Name NAKIT_POZISYON: HESAPLAR!$K$18
Name SISTEM_SONUC: SISTEM!$F$23:$F$70

Sheet PANO
A1: ◈ RAPOR EKRANI — KAYIT GİRİLMEZ | F1: KILIÇ MUHASEBE │ YÖNETİM PANOSU
A2: ="BU EKRANA KAYIT GİRİLMEZ │ SİSTEM DURUMU: "&IF(COUNTIFS(SISTEM!$C$23:$C$70,"KRİTİK",SISTEM!$F$23:$F$70,"KALDI")>0,"KRİTİK HATA – AY KAPATILAMAZ",IF(COUNTIF(SISTEM!$F$23:$F$70,"KALDI")=0,"KULLANIMA UYGUN","UYARI VAR – İNCELEYİN"))&" │ "&COUNTIF(SISTEM!$F$23:$F$70,"GEÇTİ")&" / "&COUNTIF(SISTEM!$F$23:$F$70,"<>BİLGİ")&" kontrol geçti" -> BU EKRANA KAYIT GİRİLMEZ │ SİSTEM DURUMU: KRİTİK HATA – AY KAPATILAMAZ │ 32 / 37 kontrol geçti
B4: =RIGHT("0"&DAY(TODAY()),2)&"."&RIGHT("0"&MONTH(TODAY()),2)&"."&YEAR(TODAY())&" │ "&SISTEM!$C$7 -> 24.08.2026 │ KILIÇ MUHASEBE
B5: MENÜ | D5: AKTİF MÜŞTERİ | G5: TOPLAM CARİ ALACAK | J5: 29+ GÜN GECİKMİŞ | M5: KASA + BANKA
B6: =HYPERLINK("#PANO!A1"," PANO") -> PANO | D6: =COUNTIF(MUSTERILER!$D$7:$D$156,"Aktif") -> 55 | G6: =SUM(MUSTERI_360!$J$7:$J$156) -> 1521150 | J6: =SUM(MUSTERI_360!$N$7:$N$156) -> 976000 | M6: =HESAPLAR!$K$18 -> 1020612
B7: =HYPERLINK("#MUSTERILER!A1"," Müşteriler") -> Müşteriler | D7: =COUNTA(MUSTERILER!$C$7:$C$156)&" kayıtlı müşteri" -> 55 kayıtlı müşteri | G7: =COUNTIF(MUSTERI_360!$J$7:$J$156,">0")&" müşteride açık bakiye" -> 48 müşteride açık bakiye | J7: =ROUND(IFERROR(SUM(MUSTERI_360!$N$7:$N$156)/SUM(MUSTERI_360!$J$7:$J$156),0)*100,1)&"% toplam alacağın payı" -> 64,2% toplam alacağın payı | M7: =COUNTIF(HESAPLAR!$D$7:$D$16,"Aktif")&" aktif hesap" -> 5 aktif hesap
B8: =HYPERLINK("#UCRETLER!A1"," Haftalık Ücretler") -> Haftalık Ücretler
B9: =HYPERLINK("#TAHSILAT!A1"," Tahsilat") -> Tahsilat | D9: BU AY NAKİT KÂR | G9: BU AY TAHSİLAT | J9: HAFTALIK TAHAKKUK | M9: GECİKMİŞ İŞ
B10: =HYPERLINK("#GELIR_GIDER!A1"," Gelir / Gider") -> Gelir / Gider | D10: =SUMIFS(AY_SONU!$I$7:$I$42,AY_SONU!$B$7:$B$42,">="&EOMONTH(TODAY(),-1)+1,AY_SONU!$B$7:$B$42,"<="&EOMONTH(TODAY(),0)) -> 187350 | G10: =SUMIFS(AY_SONU!$D$7:$D$42,AY_SONU!$B$7:$B$42,">="&EOMONTH(TODAY(),-1)+1,AY_SONU!$B$7:$B$42,"<="&EOMONTH(TODAY(),0)) -> 277150 | J10: =SUMIFS(UCRETLER!$G$7:$G$606,UCRETLER!$H$7:$H$606,"Aktif",UCRETLER!$F$7:$F$606,"Haftalık") -> 78750 | M10: =COUNTIF(AKTIVITE!$Q$7:$Q$1006,"GECİKMİŞ") -> 0
B11: =HYPERLINK("#VIRMAN!A1"," Virman") -> Virman | D11: =CHOOSE(MONTH(TODAY()),"Ocak","Şubat","Mart","Nisan","Mayıs","Haziran","Temmuz","Ağustos","Eylül","Ekim","Kasım","Aralık")&" "&YEAR(TODAY())&" dönemi" -> Ağustos 2026 dönemi | G11: ="Ay tahakkuku "&TEXT(SUMIFS(AY_SONU!$C$7:$C$42,AY_SONU!$B$7:$B$42,">="&EOMONTH(TODAY(),-1)+1,AY_SONU!$B$7:$B$42,"<="&EOMONTH(TODAY(),0)),"#,##0")&" ₺" -> Ay tahakkuku 511750,0 ₺ | J11: ="Aylık: "&TEXT(SUMIFS(UCRETLER!$G$7:$G$606,UCRETLER!$H$7:$H$606,"Aktif",UCRETLER!$F$7:$F$606,"Aylık"),"#,##0")&" ₺ │ "&COUNTIFS(UCRETLER!$H$7:$H$606,"Aktif")&" aktif dönem" -> Aylık: 131000,0 ₺ │ 53 aktif dönem | M11: =COUNTIF(AKTIVITE!$Q$7:$Q$1006,"BUGÜN")&" iş bugün teslim" -> 0 iş bugün teslim
B12: =HYPERLINK("#AKTIVITE!A1"," Aktivite") -> Aktivite
B13: =HYPERLINK("#MUSTERI_360!A1"," Müşteri 360") -> Müşteri 360 | D13: AYLIK NAKİT KÂR EĞRİSİ | H13: TAHAKKUK ↔ TAHSİLAT | L13: ALACAK YAŞLANDIRMASI
B14: =HYPERLINK("#CARI_EKSTRE!A1"," Cari Ekstre") -> Cari Ekstre
B15: =HYPERLINK("#HESAPLAR!A1"," Hesaplar") -> Hesaplar
B16: =HYPERLINK("#ORTAKLAR!A1"," Ortaklar") -> Ortaklar
B17: =HYPERLINK("#AY_SONU!A1"," Ay Sonu") -> Ay Sonu
B18: =HYPERLINK("#SISTEM!A1"," Sistem & Kontrol") -> Sistem & Kontrol
B19: =HYPERLINK("#BASLANGIC!A1"," Başlangıç") -> Başlangıç
D23: MÜŞTERİ HIZLI KARTI | J23: BUGÜNÜN UYARILARI
D24: Müşteri seçin | F24: ANKARA HAVANA LTD.ŞTİ. | J24: Gecikmiş müşteri işi | O24: =COUNTIF(AKTIVITE!$Q$7:$Q$1006,"GECİKMİŞ") -> 0
D25: Müşteri No | F25: =IF($F$24="","",IFERROR(INDEX(MUSTERI_360!$B$7:$B$156,MATCH($F$24,MUSTERI_360!$C$7:$C$156,0)),"")) -> M001 | J25: Bugün teslim edilecek iş | O25: =COUNTIF(AKTIVITE!$Q$7:$Q$1006,"BUGÜN") -> 0
D26: Borç Durumu | F26: =IF($F$24="","",IFERROR(INDEX(MUSTERI_360!$Q$7:$Q$156,MATCH($F$24,MUSTERI_360!$C$7:$C$156,0)),"")) -> KRİTİK | J26: 7 gün içindeki işler | O26: =COUNTIF(AKTIVITE!$Q$7:$Q$1006,"7 GÜN İÇİNDE") -> 0
D27: Haftalık Ücret | F27: =IF($F$24="","",IFERROR(INDEX(MUSTERI_360!$D$7:$D$156,MATCH($F$24,MUSTERI_360!$C$7:$C$156,0)),"")) -> 4000 | J27: Gecikmiş müşteri teması | O27: =COUNTIFS(AKTIVITE!$C$7:$C$1006,"Görüşme",AKTIVITE!$Q$7:$Q$1006,"GECİKMİŞ") -> 0
D28: Aylık Ücret | F28: =IF($F$24="","",IFERROR(INDEX(MUSTERI_360!$E$7:$E$156,MATCH($F$24,MUSTERI_360!$C$7:$C$156,0)),"")) -> 0 | J28: Kritik borç durumundaki müşteri | O28: =COUNTIF(MUSTERI_360!$Q$7:$Q$156,"KRİTİK") -> 32
D29: Devir Alacağı | F29: =IF($F$24="","",IFERROR(INDEX(MUSTERI_360!$F$7:$F$156,MATCH($F$24,MUSTERI_360!$C$7:$C$156,0)),"")) -> 0 | J29: Bilgisi eksik müşteri kaydı | O29: =COUNTIF(MUSTERILER!$P$7:$P$156,"EKSİK") -> 0
D30: Yeni Tahakkuk | F30: =IF($F$24="","",IFERROR(INDEX(MUSTERI_360!$G$7:$G$156,MATCH($F$24,MUSTERI_360!$C$7:$C$156,0)),"")) -> 140200 | J30: Aktif ama ücretsiz müşteri | O30: =COUNTIFS(MUSTERILER!$D$7:$D$156,"Aktif",MUSTERILER!$O$7:$O$156,"HAYIR") -> 2
D31: Toplam Borç | F31: =IF($F$24="","",IFERROR(INDEX(MUSTERI_360!$H$7:$H$156,MATCH($F$24,MUSTERI_360!$C$7:$C$156,0)),"")) -> 140200 | J31: Eksik tahsilat kaydı | O31: =COUNTIF(TAHSILAT!$M$7:$M$2506,"EKSİK") -> 0
D32: Toplam Tahsilat | F32: =IF($F$24="","",IFERROR(INDEX(MUSTERI_360!$I$7:$I$156,MATCH($F$24,MUSTERI_360!$C$7:$C$156,0)),"")) -> 112000 | J32: Eksik gelir/gider kaydı | O32: =COUNTIF(GELIR_GIDER!$P$7:$P$3006,"EKSİK") -> 0
D33: Cari Bakiye | F33: =IF($F$24="","",IFERROR(INDEX(MUSTERI_360!$J$7:$J$156,MATCH($F$24,MUSTERI_360!$C$7:$C$156,0)),"")) -> 28200 | J33: Fazla ödeme yapan müşteri (avans) | O33: =COUNTIF(MUSTERI_360!$V$7:$V$156,">0") -> 3
D34: 0–7 Gün | F34: =IF($F$24="","",IFERROR(INDEX(MUSTERI_360!$K$7:$K$156,MATCH($F$24,MUSTERI_360!$C$7:$C$156,0)),"")) -> 8200 | J34: Mükerrer kayıt şüphesi | O34: =COUNTIF(TAHSILAT!$M$7:$M$2506,"MÜKERRER?")+COUNTIF(GELIR_GIDER!$P$7:$P$3006,"MÜKERRER?") -> 22
D35: 8–14 Gün | F35: =IF($F$24="","",IFERROR(INDEX(MUSTERI_360!$L$7:$L$156,MATCH($F$24,MUSTERI_360!$C$7:$C$156,0)),"")) -> 4000 | J35: Ödenmemiş gider kaydı | O35: =COUNTIF(GELIR_GIDER!$P$7:$P$3006,"ÖDENECEK") -> 0
D36: 15–28 Gün | F36: =IF($F$24="","",IFERROR(INDEX(MUSTERI_360!$M$7:$M$156,MATCH($F$24,MUSTERI_360!$C$7:$C$156,0)),"")) -> 8000 | J36: Sistem kontrolünde KALDI satırı | O36: =COUNTIF(SISTEM!$F$23:$F$70,"KALDI") -> 5
D37: 29+ Gün | F37: =IF($F$24="","",IFERROR(INDEX(MUSTERI_360!$N$7:$N$156,MATCH($F$24,MUSTERI_360!$C$7:$C$156,0)),"")) -> 8000
D38: Tahsilat Oranı | F38: =IF($F$24="","",IFERROR(INDEX(MUSTERI_360!$O$7:$O$156,MATCH($F$24,MUSTERI_360!$C$7:$C$156,0)),"")) -> 0.79885877
D39: Son Tahsilat | F39: =IF($F$24="","",IFERROR(INDEX(MUSTERI_360!$P$7:$P$156,MATCH($F$24,MUSTERI_360!$C$7:$C$156,0)),"")) -> 46249
D40: Önerilen İşlem | F40: =IF($F$24="","",IFERROR(INDEX(MUSTERI_360!$R$7:$R$156,MATCH($F$24,MUSTERI_360!$C$7:$C$156,0)),"")) -> Acil tahsilat görüşmesi ve cari mutabakat

Sheet BASLANGIC
A1: ◈ RAPOR EKRANI — KAYIT GİRİLMEZ | F1: KILIÇ MUHASEBE │ BAŞLANGIÇ │ AMAÇ, RENK KİLAVUZU, KULLANIM VE RİSKLER
A2: BU EKRANA KAYIT GİRİLMEZ │ Bu ekran sistemin kimlik kartıdır │ İlk kez açıyorsanız baştan sona okuyun
B4: =HYPERLINK("#PANO!A1","⌂") -> ⌂ | C4: =HYPERLINK("#PANO!A1","M E N Ü") -> M E N Ü
B5: KILIÇ MUHASEBE │ OFİS YÖNETİM SİSTEMİ
B6: Enterprise Exclusive sürüm │ Haftalık ve aylık ücretle çalışan muhasebe ofisleri için müşteri, tahakkuk, tahsilat, cari, kasa ve ortak payı yönetimi
B8: İÇİNDEKİLER │ başlığa tıklayın, doğrudan o bölüme gidersiniz
B9: =HYPERLINK("#BASLANGIC!B17","▸ 1. BU EXCEL NE İÇİN ÜRETİLDİ?") -> ▸ 1. BU EXCEL NE İÇİN ÜRETİLDİ? | F9: =HYPERLINK("#BASLANGIC!B88","▸ 7. SENARYO KATALOĞU") -> ▸ 7. SENARYO KATALOĞU
B10: =HYPERLINK("#BASLANGIC!B26","▸ 2. RENK KİLAVUZU") -> ▸ 2. RENK KİLAVUZU | F10: =HYPERLINK("#BASLANGIC!B115","▸ 8. UYARI SÖZLÜĞÜ") -> ▸ 8. UYARI SÖZLÜĞÜ
B11: =HYPERLINK("#BASLANGIC!B40","▸ 3. SEKME HARİTASI") -> ▸ 3. SEKME HARİTASI | F11: =HYPERLINK("#BASLANGIC!B142","▸ 9. EN SIK YAPILAN HATALAR") -> ▸ 9. EN SIK YAPILAN HATALAR
B12: =HYPERLINK("#BASLANGIC!B57","▸ 4. EKRAN MODLARI") -> ▸ 4. EKRAN MODLARI | F12: =HYPERLINK("#BASLANGIC!B155","▸ 10. SORUN GİDERME") -> ▸ 10. SORUN GİDERME
B13: =HYPERLINK("#BASLANGIC!B63","▸ 5. ADIM ADIM KULLANIM") -> ▸ 5. ADIM ADIM KULLANIM | F13: =HYPERLINK("#BASLANGIC!B173","▸ 11. DEĞİŞMEZ KURALLAR") -> ▸ 11. DEĞİŞMEZ KURALLAR
B14: =HYPERLINK("#BASLANGIC!B78","▸ 6. TAHAKKUK MODELLERİ, ZAM VE PARA GİRİŞİ") -> ▸ 6. TAHAKKUK MODELLERİ, ZAM VE PARA GİRİŞİ | F14: =HYPERLINK("#BASLANGIC!B183","▸ 12. KORUMA, YEDEK VE GÜVENLİK") -> ▸ 12. KORUMA, YEDEK VE GÜVENLİK
B17: 1. BU EXCEL NE İÇİN ÜRETİLDİ?
B18: Başlık | D18: Açıklama
B19: Amaç | D19: Haftalık veya aylık ücretle çalışan bir muhasebe ofisinin tüm ticari işleyişini tek dosyada, tek veri girişiyle ve kendi kendini denetleyen bir yapıyla yönetmek.
B20: Neyi çözer? | D20: “Kim ne kadar borçlu, bu borç kaç günlük, kasada ne kadar param var, bu ay gerçekten ne kazandım, ortaklara ne dağıtabilirim” sorularını tahmine dayanmadan cevaplar.
B21: Nasıl çalışır? | D21: Siz yalnızca SARI hücrelere gerçek işlemi girersiniz. Cari hesap, yaşlandırma, kasa bakiyesi, aylık kapanış, ortak payı ve ekstreler otomatik hesaplanır.
B22: Neden güvenilir? | D22: Sistem her açılışta 50 otomatik kontrol çalıştırır ve hatanın hangi satırda olduğunu yazar. Bir KRİTİK kontrol KALDI verirse ay kapatılamaz.
B23: Tahakkuk esası | D23: Haftalık ücret her hafta aynı günde, aylık ücret her ayın son gününde otomatik tahakkuk eder. Ücret değiştiğinde eski dönem kapatılır, yeni dönem açılır.
B24: Kâr esası | D24: Dağıtım yalnız tahsil edilmiş nakit kârdan yapılır. Tahsil edilmemiş alacak kâr sayılmaz. Zararlı ay olursa sonraki kârdan mahsup edilir.
B26: 2. RENK KİLAVUZU │ EKRANDAKİ RENKLER NE ANLAMA GELİR?
B27: Renk | C27: Ne görünür | E27: Anlamı | G27: Ne yapmanız gerekir
B28: ■ | C28: SARI ZEMİN / MAVİ YAZI | E28: SİZ YAZARSINIZ | G28: Sistemin tek besleme kaynağı bu hücrelerdir. Başka hiçbir yere veri girilmez.
B29: ■ | C29: BEYAZ ZEMİN / SİYAH YAZI | E29: SİSTEM HESAPLAR | G29: Kilitlidir, elle değiştirilemez. Değeri yanlışsa burayı değil KAYNAK defteri düzeltin.
B30: ■ | C30: LACİVERT BANT ✎ | E30: VERİ GİRİŞ EKRANI | G30: Sayfanın üstü LACİVERT ise buraya kayıt girilir. Sağ üstte sarı “VERİ GİRİŞ EKRANI” rozeti vardır.
B31: ■ | C31: SARI/ALTIN ROZET ⚙ | E31: KARMA EKRAN — YALNIZ SARI ALANLAR | G31: SİSTEM, AY SONU ve ORTAKLAR ekranları karmadır: bir kısmı girilir, bir kısmı salt okunur. Her bloğun başlığında ✎ GİRİLEBİLİR veya ◈ SALT OKUNUR yazar.
B32: ■ | C32: KOYU GRİ BANT ◈ | E32: RAPOR EKRANI — KAYIT GİRİLMEZ | G32: Sayfanın üstü KOYU GRİ ise o ekrana KAYIT GİRİLMEZ. Sağ üstte beyaz “RAPOR EKRANI” rozeti vardır. Yalnız müşteri/ortak seçim kutusu yazılabilir.
B33: ■ | C33: SARI HÜCRE YOKSA | E33: O EKRANA VERİ GİRİLMEZ | G33: Kural: bir ekranda hiç sarı hücre görmüyorsanız, o ekran salt okunurdur.
B34: ■ | C34: AÇIK MAVİ SATIR | E34: TOPLAM satırı | G34: Tablo başlığının üstünde durur, aşağı kaydırsanız da ekranda kalır.
B35: ■ | C35: YEŞİL ROZET | E35: UYGUN / GEÇTİ / TEMİZ | G35: Kayıt eksiksiz, kontrol başarılı. İşlem gerekmiyor.
B36: ■ | C36: TURUNCU ROZET | E36: EKSİK / BUGÜN / UYARI | G36: Dikkat gerektirir ama ayı kilitlemez. En kısa sürede tamamlayın.
B37: ■ | C37: KIRMIZI ROZET | E37: HATA / KALDI / KRİTİK | G37: ACIL. Kırmızı KRİTİK satır varken ay sonu kapatılamaz — sistem engeller.
B38: ■ | C38: GRİ ROZET | E38: PASİF / PLANLI / İZLE | G38: Bilgi amaçlıdır, işlem gerektirmez.
B40: 3. SEKME HARİTASI │ HANGİ SEKMEDE NE YAPILIR, NE YAPILMAZ
B41: Renk | C41: Sekme | D41: BURADA NE YAPARSINIZ | G41: ⚠ SAKIN YAPMAYIN — RİSK
B42: ■ | C42: =HYPERLINK("#PANO!A1","PANO") -> PANO | D42: Güne buradan başlayın. Özet rakamlar, grafikler, uyarı listesi ve müşteri hızlı kartı burada. | G42: ⚠ Buraya veri girmeye çalışmayın. Yalnız müşteri seçim kutusu yazılabilir.
B43: ■ | C43: =HYPERLINK("#BASLANGIC!A1","BASLANGIC") -> BASLANGIC | D43: Şu an okuduğunuz ekran. Kural, renk ve riskleri buradan öğrenin. | G43: ⚠ Kuralları okumadan sisteme veri girmeyin. En pahalı hatalar buradan önlenir.
B44: ■ | C44: =HYPERLINK("#MUSTERILER!A1","MUSTERILER") -> MUSTERILER | D44: Yeni müşteri açın: no, unvan, durum ve varsa devir alacağı. | G44: ⚠ AYNI UNVANI İKİ KEZ AÇMAYIN. Tahsilat yanlış müşteriye gider ve cari bozulur.
B45: ■ | C45: =HYPERLINK("#UCRETLER!A1","UCRETLER") -> UCRETLER | D45: Ücret dönemi tanımlayın: başlangıç, model (haftalık/aylık), tutar. | G45: ⚠ ÜCRET DEĞİŞİNCE TUTARI DEĞİŞTİRMEYİN. Eski satırı kapatıp yeni satır açın; yoksa geçmiş tüm aylar geriye dönük bozulur ve GERİ ALINAMAZ.
B46: ■ | C46: =HYPERLINK("#TAHSILAT!A1","TAHSILAT") -> TAHSILAT | D46: Müşteriden gelen her ödemeyi buraya girin. Cari, kasa, ekstre ve ay sonu otomatik güncellenir. | G46: ⚠ AYNI ÖDEMEYİ GELİR/GİDER'E DE YAZMAYIN. Gelir iki kez sayılır, ortak payı şişer.
...

Sheet MUSTERILER
A1: ✎ VERİ GİRİŞ EKRANI — SARI HÜCRELER | F1: KILIÇ MUHASEBE │ MÜŞTERİLER
A2: SARI HÜCRELERE YAZIN │ Ana müşteri kartı │ Her müşteri için tek kayıt │ Devir alacağı bu ekranda tanımlanır
B3: ⚠ SAKIN: aynı müşteriyi iki kez açmayın; unvanı sonradan elle değiştirmeyin — geçmiş tahsilatlar kopar.
B4: =HYPERLINK("#PANO!A1","⌂") -> ⌂ | C4: =HYPERLINK("#PANO!A1","M E N Ü") -> M E N Ü | D4: =HYPERLINK("#UCRETLER!A1","Haftalık Ücretler") -> Haftalık Ücretler | F4: =HYPERLINK("#MUSTERI_360!A1","Müşteri 360") -> Müşteri 360 | H4: Sarı = giriş, beyaz = otomatik (kilitli). Devir Alacak Tarihi yaşlandırmayı belirler — boş bırakılırsa tutar 29+ gün kabul edilir.
C5: TOPLAM │ Aktif müşteri ve devir alacağı | D5: =COUNTIF($D$7:$D$156,"Aktif") -> 55 | J5: =SUM($J$7:$J$156) -> 0
B6: Müşteri No | C6: Müşteri / Mükellef Unvanı | D6: Durum | E6: Sorumlu Kişi | F6: Telefon | G6: Vergi No | H6: Ödeme Şekli | I6: Başlangıç Tarihi | J6: Devir Alacağı | K6: Devir Alacak Tarihi | L6: Devir Kaynağı | M6: Özel Not | N6: Bilgi Durumu | O6: Aktif Ücret Tanımı | P6: Kayıt Kontrolü
B7: M019 | C7: AC OTEL LTD.ŞTİ. | D7: Aktif | H7: Nakit | I7: 46023 | J7: 0 | O7: =IF($C7="","",IF(COUNTIFS(UCRETLER!$B$7:$B$606,$B7,UCRETLER!$H$7:$H$606,"Aktif")>0,"EVET","HAYIR")) -> EVET | P7: =IF($C7="","",IF($B7="","NO EKSİK",IF(COUNTIF($B$7:$B$156,$B7)>1,"NO TEKRARI",IF(COUNTIF($C$7:$C$156,$C7)>1,"UNVAN TEKRARI",IF($D7="","DURUM EKSİK",IF(AND($J7>0,$K7=""),"DEVİR TARİHİ EKSİK","UYGUN")))))) -> UYGUN | T7: =IF($C7="","",UPPER(SUBSTITUTE(SUBSTITUTE(SUBSTITUTE(SUBSTITUTE(SUBSTITUTE(SUBSTITUTE(SUBSTITUTE(SUBSTITUTE(SUBSTITUTE(SUBSTITUTE(SUBSTITUTE(SUBSTITUTE(SUBSTITUTE(SUBSTITUTE(SUBSTITUTE(SUBSTITUTE(SUBSTITUTE(SUBSTITUTE(TRIM($C7),"'",""),"İ","I"),"ı","I"),"i","I"),"Ş","S"),"ş","S"),"Ğ","G"),"ğ","G"),"Ü","U"),"ü","U"),"Ö","O"),"ö","O"),"Ç","C"),"ç","C"),".",""),",","")," ",""),"-",""))) -> ACOTELLTDSTI | U7: =IF($C7="","",COUNTIF($C$7:$C$156,"<"&$C7)+COUNTIF($C$7:$C7,$C7)) -> 1
B8: M022 | C8: ADEM KARABENLİ | D8: Aktif | H8: Nakit | I8: 46023 | J8: 0 | O8: =IF($C8="","",IF(COUNTIFS(UCRETLER!$B$7:$B$606,$B8,UCRETLER!$H$7:$H$606,"Aktif")>0,"EVET","HAYIR")) -> EVET | P8: =IF($C8="","",IF($B8="","NO EKSİK",IF(COUNTIF($B$7:$B$156,$B8)>1,"NO TEKRARI",IF(COUNTIF($C$7:$C$156,$C8)>1,"UNVAN TEKRARI",IF($D8="","DURUM EKSİK",IF(AND($J8>0,$K8=""),"DEVİR TARİHİ EKSİK","UYGUN")))))) -> UYGUN | T8: =IF($C8="","",UPPER(SUBSTITUTE(SUBSTITUTE(SUBSTITUTE(SUBSTITUTE(SUBSTITUTE(SUBSTITUTE(SUBSTITUTE(SUBSTITUTE(SUBSTITUTE(SUBSTITUTE(SUBSTITUTE(SUBSTITUTE(SUBSTITUTE(SUBSTITUTE(SUBSTITUTE(SUBSTITUTE(SUBSTITUTE(SUBSTITUTE(TRIM($C8),"'",""),"İ","I"),"ı","I"),"i","I"),"Ş","S"),"ş","S"),"Ğ","G"),"ğ","G"),"Ü","U"),"ü","U"),"Ö","O"),"ö","O"),"Ç","C"),"ç","C"),".",""),",","")," ",""),"-",""))) -> ADEMKARABENLI | U8: =IF($C8="","",COUNTIF($C$7:$C$156,"<"&$C8)+COUNTIF($C$7:$C8,$C8)) -> 2
B9: M023 | C9: ALTINEL LTD.ŞTİ. | D9: Aktif | H9: Nakit | I9: 46023 | J9: 0 | O9: =IF($C9="","",IF(COUNTIFS(UCRETLER!$B$7:$B$606,$B9,UCRETLER!$H$7:$H$606,"Aktif")>0,"EVET","HAYIR")) -> EVET | P9: =IF($C9="","",IF($B9="","NO EKSİK",IF(COUNTIF($B$7:$B$156,$B9)>1,"NO TEKRARI",IF(COUNTIF($C$7:$C$156,$C9)>1,"UNVAN TEKRARI",IF($D9="","DURUM EKSİK",IF(AND($J9>0,$K9=""),"DEVİR TARİHİ EKSİK","UYGUN")))))) -> UYGUN | T9: =IF($C9="","",UPPER(SUBSTITUTE(SUBSTITUTE(SUBSTITUTE(SUBSTITUTE(SUBSTITUTE(SUBSTITUTE(SUBSTITUTE(SUBSTITUTE(SUBSTITUTE(SUBSTITUTE(SUBSTITUTE(SUBSTITUTE(SUBSTITUTE(SUBSTITUTE(SUBSTITUTE(SUBSTITUTE(SUBSTITUTE(SUBSTITUTE(TRIM($C9),"'",""),"İ","I"),"ı","I"),"i","I"),"Ş","S"),"ş","S"),"Ğ","G"),"ğ","G"),"Ü","U"),"ü","U"),"Ö","O"),"ö","O"),"Ç","C"),"ç","C"),".",""),",","")," ",""),"-",""))) -> ALTINELLTDSTI | U9: =IF($C9="","",COUNTIF($C$7:$C$156,"<"&$C9)+COUNTIF($C$7:$C9,$C9)) -> 3
B10: M001 | C10: ANKARA HAVANA LTD.ŞTİ. | D10: Aktif | H10: Nakit | I10: 46023 | J10: 0 | O10: =IF($C10="","",IF(COUNTIFS(UCRETLER!$B$7:$B$606,$B10,UCRETLER!$H$7:$H$606,"Aktif")>0,"EVET","HAYIR")) -> EVET | P10: =IF($C10="","",IF($B10="","NO EKSİK",IF(COUNTIF($B$7:$B$156,$B10)>1,"NO TEKRARI",IF(COUNTIF($C$7:$C$156,$C10)>1,"UNVAN TEKRARI",IF($D10="","DURUM EKSİK",IF(AND($J10>0,$K10=""),"DEVİR TARİHİ EKSİK","UYGUN")))))) -> UYGUN | T10: =IF($C10="","",UPPER(SUBSTITUTE(SUBSTITUTE(SUBSTITUTE(SUBSTITUTE(SUBSTITUTE(SUBSTITUTE(SUBSTITUTE(SUBSTITUTE(SUBSTITUTE(SUBSTITUTE(SUBSTITUTE(SUBSTITUTE(SUBSTITUTE(SUBSTITUTE(SUBSTITUTE(SUBSTITUTE(SUBSTITUTE(SUBSTITUTE(TRIM($C10),"'",""),"İ","I"),"ı","I"),"i","I"),"Ş","S"),"ş","S"),"Ğ","G"),"ğ","G"),"Ü","U"),"ü","U"),"Ö","O"),"ö","O"),"Ç","C"),"ç","C"),".",""),",","")," ",""),"-",""))) -> ANKARAHAVANALTDSTI | U10: =IF($C10="","",COUNTIF($C$7:$C$156,"<"&$C10)+COUNTIF($C$7:$C10,$C10)) -> 4
B11: M024 | C11: ARMAN DİK | D11: Aktif | H11: Nakit | I11: 46023 | J11: 0 | O11: =IF($C11="","",IF(COUNTIFS(UCRETLER!$B$7:$B$606,$B11,UCRETLER!$H$7:$H$606,"Aktif")>0,"EVET","HAYIR")) -> EVET | P11: =IF($C11="","",IF($B11="","NO EKSİK",IF(COUNTIF($B$7:$B$156,$B11)>1,"NO TEKRARI",IF(COUNTIF($C$7:$C$156,$C11)>1,"UNVAN TEKRARI",IF($D11="","DURUM EKSİK",IF(AND($J11>0,$K11=""),"DEVİR TARİHİ EKSİK","UYGUN")))))) -> UYGUN | T11: =IF($C11="","",UPPER(SUBSTITUTE(SUBSTITUTE(SUBSTITUTE(SUBSTITUTE(SUBSTITUTE(SUBSTITUTE(SUBSTITUTE(SUBSTITUTE(SUBSTITUTE(SUBSTITUTE(SUBSTITUTE(SUBSTITUTE(SUBSTITUTE(SUBSTITUTE(SUBSTITUTE(SUBSTITUTE(SUBSTITUTE(SUBSTITUTE(TRIM($C11),"'",""),"İ","I"),"ı","I"),"i","I"),"Ş","S"),"ş","S"),"Ğ","G"),"ğ","G"),"Ü","U"),"ü","U"),"Ö","O"),"ö","O"),"Ç","C"),"ç","C"),".",""),",","")," ",""),"-",""))) -> ARMANDIK | U11: =IF($C11="","",COUNTIF($C$7:$C$156,"<"&$C11)+COUNTIF($C$7:$C11,$C11)) -> 5
B12: M021 | C12: ARON TOPTAN LTD.ŞTİ. | D12: Aktif | H12: Nakit | I12: 46023 | J12: 0 | O12: =IF($C12="","",IF(COUNTIFS(UCRETLER!$B$7:$B$606,$B12,UCRETLER!$H$7:$H$606,"Aktif")>0,"EVET","HAYIR")) -> EVET | P12: =IF($C12="","",IF($B12="","NO EKSİK",IF(COUNTIF($B$7:$B$156,$B12)>1,"NO TEKRARI",IF(COUNTIF($C$7:$C$156,$C12)>1,"UNVAN TEKRARI",IF($D12="","DURUM EKSİK",IF(AND($J12>0,$K12=""),"DEVİR TARİHİ EKSİK","UYGUN")))))) -> UYGUN | T12: =IF($C12="","",UPPER(SUBSTITUTE(SUBSTITUTE(SUBSTITUTE(SUBSTITUTE(SUBSTITUTE(SUBSTITUTE(SUBSTITUTE(SUBSTITUTE(SUBSTITUTE(SUBSTITUTE(SUBSTITUTE(SUBSTITUTE(SUBSTITUTE(SUBSTITUTE(SUBSTITUTE(SUBSTITUTE(SUBSTITUTE(SUBSTITUTE(TRIM($C12),"'",""),"İ","I"),"ı","I"),"i","I"),"Ş","S"),"ş","S"),"Ğ","G"),"ğ","G"),"Ü","U"),"ü","U"),"Ö","O"),"ö","O"),"Ç","C"),"ç","C"),".",""),",","")," ",""),"-",""))) -> ARONTOPTANLTDSTI | U12: =IF($C12="","",COUNTIF($C$7:$C$156,"<"&$C12)+COUNTIF($C$7:$C12,$C12)) -> 6
B13: M025 | C13: ASIM AÇIKGÖZ | D13: Aktif | H13: Nakit | I13: 46023 | J13: 0 | O13: =IF($C13="","",IF(COUNTIFS(UCRETLER!$B$7:$B$606,$B13,UCRETLER!$H$7:$H$606,"Aktif")>0,"EVET","HAYIR")) -> EVET | P13: =IF($C13="","",IF($B13="","NO EKSİK",IF(COUNTIF($B$7:$B$156,$B13)>1,"NO TEKRARI",IF(COUNTIF($C$7:$C$156,$C13)>1,"UNVAN TEKRARI",IF($D13="","DURUM EKSİK",IF(AND($J13>0,$K13=""),"DEVİR TARİHİ EKSİK","UYGUN")))))) -> UYGUN | T13: =IF($C13="","",UPPER(SUBSTITUTE(SUBSTITUTE(SUBSTITUTE(SUBSTITUTE(SUBSTITUTE(SUBSTITUTE(SUBSTITUTE(SUBSTITUTE(SUBSTITUTE(SUBSTITUTE(SUBSTITUTE(SUBSTITUTE(SUBSTITUTE(SUBSTITUTE(SUBSTITUTE(SUBSTITUTE(SUBSTITUTE(SUBSTITUTE(TRIM($C13),"'",""),"İ","I"),"ı","I"),"i","I"),"Ş","S"),"ş","S"),"Ğ","G"),"ğ","G"),"Ü","U"),"ü","U"),"Ö","O"),"ö","O"),"Ç","C"),"ç","C"),".",""),",","")," ",""),"-",""))) -> ASIMACIKGOZ | U13: =IF($C13="","",COUNTIF($C$7:$C$156,"<"&$C13)+COUNTIF($C$7:$C13,$C13)) -> 7
B14: M017 | C14: ASM EĞLENCE LTD.ŞTİ. | D14: Aktif | H14: Nakit | I14: 46023 | J14: 0 | O14: =IF($C14="","",IF(COUNTIFS(UCRETLER!$B$7:$B$606,$B14,UCRETLER!$H$7:$H$606,"Aktif")>0,"EVET","HAYIR")) -> EVET | P14: =IF($C14="","",IF($B14="","NO EKSİK",IF(COUNTIF($B$7:$B$156,$B14)>1,"NO TEKRARI",IF(COUNTIF($C$7:$C$156,$C14)>1,"UNVAN TEKRARI",IF($D14="","DURUM EKSİK",IF(AND($J14>0,$K14=""),"DEVİR TARİHİ EKSİK","UYGUN")))))) -> UYGUN | T14: =IF($C14="","",UPPER(SUBSTITUTE(SUBSTITUTE(SUBSTITUTE(SUBSTITUTE(SUBSTITUTE(SUBSTITUTE(SUBSTITUTE(SUBSTITUTE(SUBSTITUTE(SUBSTITUTE(SUBSTITUTE(SUBSTITUTE(SUBSTITUTE(SUBSTITUTE(SUBSTITUTE(SUBSTITUTE(SUBSTITUTE(SUBSTITUTE(TRIM($C14),"'",""),"İ","I"),"ı","I"),"i","I"),"Ş","S"),"ş","S"),"Ğ","G"),"ğ","G"),"Ü","U"),"ü","U"),"Ö","O"),"ö","O"),"Ç","C"),"ç","C"),".",""),",","")," ",""),"-",""))) -> ASMEGLENCELTDSTI | U14: =IF($C14="","",COUNTIF($C$7:$C$156,"<"&$C14)+COUNTIF($C$7:$C14,$C14)) -> 8
B15: M026 | C15: AYDES LTD.ŞTİ. | D15: Aktif | H15: Nakit | I15: 46023 | J15: 0 | O15: =IF($C15="","",IF(COUNTIFS(UCRETLER!$B$7:$B$606,$B15,UCRETLER!$H$7:$H$606,"Aktif")>0,"EVET","HAYIR")) -> EVET | P15: =IF($C15="","",IF($B15="","NO EKSİK",IF(COUNTIF($B$7:$B$156,$B15)>1,"NO TEKRARI",IF(COUNTIF($C$7:$C$156,$C15)>1,"UNVAN TEKRARI",IF($D15="","DURUM EKSİK",IF(AND($J15>0,$K15=""),"DEVİR TARİHİ EKSİK","UYGUN")))))) -> UYGUN | T15: =IF($C15="","",UPPER(SUBSTITUTE(SUBSTITUTE(SUBSTITUTE(SUBSTITUTE(SUBSTITUTE(SUBSTITUTE(SUBSTITUTE(SUBSTITUTE(SUBSTITUTE(SUBSTITUTE(SUBSTITUTE(SUBSTITUTE(SUBSTITUTE(SUBSTITUTE(SUBSTITUTE(SUBSTITUTE(SUBSTITUTE(SUBSTITUTE(TRIM($C15),"'",""),"İ","I"),"ı","I"),"i","I"),"Ş","S"),"ş","S"),"Ğ","G"),"ğ","G"),"Ü","U"),"ü","U"),"Ö","O"),"ö","O"),"Ç","C"),"ç","C"),".",""),",","")," ",""),"-",""))) -> AYDESLTDSTI | U15: =IF($C15="","",COUNTIF($C$7:$C$156,"<"&$C15)+COUNTIF($C$7:$C15,$C15)) -> 9
B16: M015 | C16: ÇAYIRALAN LTD.ŞTİ. | D16: Aktif | H16: Nakit | I16: 46023 | J16: 0 | O16: =IF($C16="","",IF(COUNTIFS(UCRETLER!$B$7:$B$606,$B16,UCRETLER!$H$7:$H$606,"Aktif")>0,"EVET","HAYIR")) -> EVET | P16: =IF($C16="","",IF($B16="","NO EKSİK",IF(COUNTIF($B$7:$B$156,$B16)>1,"NO TEKRARI",IF(COUNTIF($C$7:$C$156,$C16)>1,"UNVAN TEKRARI",IF($D16="","DURUM EKSİK",IF(AND($J16>0,$K16=""),"DEVİR TARİHİ EKSİK","UYGUN")))))) -> UYGUN | T16: =IF($C16="","",UPPER(SUBSTITUTE(SUBSTITUTE(SUBSTITUTE(SUBSTITUTE(SUBSTITUTE(SUBSTITUTE(SUBSTITUTE(SUBSTITUTE(SUBSTITUTE(SUBSTITUTE(SUBSTITUTE(SUBSTITUTE(SUBSTITUTE(SUBSTITUTE(SUBSTITUTE(SUBSTITUTE(SUBSTITUTE(SUBSTITUTE(TRIM($C16),"'",""),"İ","I"),"ı","I"),"i","I"),"Ş","S"),"ş","S"),"Ğ","G"),"ğ","G"),"Ü","U"),"ü","U"),"Ö","O"),"ö","O"),"Ç","C"),"ç","C"),".",""),",","")," ",""),"-",""))) -> CAYIRALANLTDSTI | U16: =IF($C16="","",COUNTIF($C$7:$C$156,"<"&$C16)+COUNTIF($C$7:$C16,$C16)) -> 11
B17: M027 | C17: CEREN DEMİRCİ | D17: Aktif | H17: Nakit | I17: 46023 | J17: 0 | O17: =IF($C17="","",IF(COUNTIFS(UCRETLER!$B$7:$B$606,$B17,UCRETLER!$H$7:$H$606,"Aktif")>0,"EVET","HAYIR")) -> EVET | P17: =IF($C17="","",IF($B17="","NO EKSİK",IF(COUNTIF($B$7:$B$156,$B17)>1,"NO TEKRARI",IF(COUNTIF($C$7:$C$156,$C17)>1,"UNVAN TEKRARI",IF($D17="","DURUM EKSİK",IF(AND($J17>0,$K17=""),"DEVİR TARİHİ EKSİK","UYGUN")))))) -> UYGUN | T17: =IF($C17="","",UPPER(SUBSTITUTE(SUBSTITUTE(SUBSTITUTE(SUBSTITUTE(SUBSTITUTE(SUBSTITUTE(SUBSTITUTE(SUBSTITUTE(SUBSTITUTE(SUBSTITUTE(SUBSTITUTE(SUBSTITUTE(SUBSTITUTE(SUBSTITUTE(SUBSTITUTE(SUBSTITUTE(SUBSTITUTE(SUBSTITUTE(TRIM($C17),"'",""),"İ","I"),"ı","I"),"i","I"),"Ş","S"),"ş","S"),"Ğ","G"),"ğ","G"),"Ü","U"),"ü","U"),"Ö","O"),"ö","O"),"Ç","C"),"ç","C"),".",""),",","")," ",""),"-",""))) -> CERENDEMIRCI | U17: =IF($C17="","",COUNTIF($C$7:$C$156,"<"&$C17)+COUNTIF($C$7:$C17,$C17)) -> 10
B18: M018 | C18: ÇINARHAN LTD.ŞTİ. | D18: Aktif | H18: Nakit | I18: 46023 | J18: 0 | O18: =IF($C18="","",IF(COUNTIFS(UCRETLER!$B$7:$B$606,$B18,UCRETLER!$H$7:$H$606,"Aktif")>0,"EVET","HAYIR")) -> EVET | P18: =IF($C18="","",IF($B18="","NO EKSİK",IF(COUNTIF($B$7:$B$156,$B18)>1,"NO TEKRARI",IF(COUNTIF($C$7:$C$156,$C18)>1,"UNVAN TEKRARI",IF($D18="","DURUM EKSİK",IF(AND($J18>0,$K18=""),"DEVİR TARİHİ EKSİK","UYGUN")))))) -> UYGUN | T18: =IF($C18="","",UPPER(SUBSTITUTE(SUBSTITUTE(SUBSTITUTE(SUBSTITUTE(SUBSTITUTE(SUBSTITUTE(SUBSTITUTE(SUBSTITUTE(SUBSTITUTE(SUBSTITUTE(SUBSTITUTE(SUBSTITUTE(SUBSTITUTE(SUBSTITUTE(SUBSTITUTE(SUBSTITUTE(SUBSTITUTE(SUBSTITUTE(TRIM($C18),"'",""),"İ","I"),"ı","I"),"i","I"),"Ş","S"),"ş","S"),"Ğ","G"),"ğ","G"),"Ü","U"),"ü","U"),"Ö","O"),"ö","O"),"Ç","C"),"ç","C"),".",""),",","")," ",""),"-",""))) -> CINARHANLTDSTI | U18: =IF($C18="","",COUNTIF($C$7:$C$156,"<"&$C18)+COUNTIF($C$7:$C18,$C18)) -> 12
... B50: M016 | C50: RİX ŞOW LTD.ŞTİ. | D50: Aktif | H50: Nakit | I50: 46023 | J50: 0 | O50: =IF($C50="","",IF(COUNTIFS(UCRETLER!$B$7:$B$606,$B50,UCRETLER!$H$7:$H$606,"Aktif")>0,"EVET","HAYIR")) -> EVET | P50: =IF($C50="","",IF($B50="","NO EKSİK",IF(COUNTIF($B$7:$B$156,$B50)>1,"NO TEKRARI",IF(COUNTIF($C$7:$C$156,$C50)>1,"UNVAN TEKRARI",IF($D50="","DURUM EKSİK",IF(AND($J50>0,$K50=""),"DEVİR TARİHİ EKSİK","UYGUN")))))) -> UYGUN | T50: =IF($C50="","",UPPER(SUBSTITUTE(SUBSTITUTE(SUBSTITUTE(SUBSTITUTE(SUBSTITUTE(SUBSTITUTE(SUBSTITUTE(SUBSTITUTE(SUBSTITUTE(SUBSTITUTE(SUBSTITUTE(SUBSTITUTE(SUBSTITUTE(SUBSTITUTE(SUBSTITUTE(SUBSTITUTE(SUBSTITUTE(SUBSTITUTE(TRIM($C50),"'",""),"İ","I"),"ı","I"),"i","I"),"Ş","S"),"ş","S"),"Ğ","G"),"ğ","G"),"Ü","U"),"ü","U"),"Ö","O"),"ö","O"),"Ç","C"),"ç","C"),".",""),",","")," ",""),"-",""))) -> RIXSOWLTDSTI | U50: =IF($C50="","",COUNTIF($C$7:$C$156,"<"&$C50)+COUNTIF($C$7:$C50,$C50)) -> 44
B51: M055 | C51: SEMRA GÜMÜŞ | D51: Aktif | H51: Nakit | I51: 46023 | O51: =IF($C51="","",IF(COUNTIFS(UCRETLER!$B$7:$B$606,$B51,UCRETLER!$H$7:$H$606,"Aktif")>0,"EVET","HAYIR")) -> HAYIR | P51: =IF($C51="","",IF($B51="","NO EKSİK",IF(COUNTIF($B$7:$B$156,$B51)>1,"NO TEKRARI",IF(COUNTIF($C$7:$C$156,$C51)>1,"UNVAN TEKRARI",IF($D51="","DURUM EKSİK",IF(AND($J51>0,$K51=""),"DEVİR TARİHİ EKSİK","UYGUN")))))) -> UYGUN | T51: =IF($C51="","",UPPER(SUBSTITUTE(SUBSTITUTE(SUBSTITUTE(SUBSTITUTE(SUBSTITUTE(SUBSTITUTE(SUBSTITUTE(SUBSTITUTE(SUBSTITUTE(SUBSTITUTE(SUBSTITUTE(SUBSTITUTE(SUBSTITUTE(SUBSTITUTE(SUBSTITUTE(SUBSTITUTE(SUBSTITUTE(SUBSTITUTE(TRIM($C51),"'",""),"İ","I"),"ı","I"),"i","I"),"Ş","S"),"ş","S"),"Ğ","G"),"ğ","G"),"Ü","U"),"ü","U"),"Ö","O"),"ö","O"),"Ç","C"),"ç","C"),".",""),",","")," ",""),"-",""))) -> SEMRAGUMUS | U51: =IF($C51="","",COUNTIF($C$7:$C$156,"<"&$C51)+COUNTIF($C$7:$C51,$C51)) -> 45
B52: M049 | C52: STAR ŞOW LTD.ŞTİ. | D52: Aktif | H52: Nakit | I52: 46023 | J52: 0 | O52: =IF($C52="","",IF(COUNTIFS(UCRETLER!$B$7:$B$606,$B52,UCRETLER!$H$7:$H$606,"Aktif")>0,"EVET","HAYIR")) -> EVET | P52: =IF($C52="","",IF($B52="","NO EKSİK",IF(COUNTIF($B$7:$B$156,$B52)>1,"NO TEKRARI",IF(COUNTIF($C$7:$C$156,$C52)>1,"UNVAN TEKRARI",IF($D52="","DURUM EKSİK",IF(AND($J52>0,$K52=""),"DEVİR TARİHİ EKSİK","UYGUN")))))) -> UYGUN | T52: =IF($C52="","",UPPER(SUBSTITUTE(SUBSTITUTE(SUBSTITUTE(SUBSTITUTE(SUBSTITUTE(SUBSTITUTE(SUBSTITUTE(SUBSTITUTE(SUBSTITUTE(SUBSTITUTE(SUBSTITUTE(SUBSTITUTE(SUBSTITUTE(SUBSTITUTE(SUBSTITUTE(SUBSTITUTE(SUBSTITUTE(SUBSTITUTE(TRIM($C52),"'",""),"İ","I"),"ı","I"),"i","I"),"Ş","S"),"ş","S"),"Ğ","G"),"ğ","G"),"Ü","U"),"ü","U"),"Ö","O"),"ö","O"),"Ç","C"),"ç","C"),".",""),",","")," ",""),"-",""))) -> STARSOWLTDSTI | U52: =IF($C52="","",COUNTIF($C$7:$C$156,"<"&$C52)+COUNTIF($C$7:$C52,$C52)) -> 46
B53: M050 | C53: TANAK LTD.ŞTİ. | D53: Aktif | H53: Nakit | I53: 46023 | J53: 0 | O53: =IF($C53="","",IF(COUNTIFS(UCRETLER!$B$7:$B$606,$B53,UCRETLER!$H$7:$H$606,"Aktif")>0,"EVET","HAYIR")) -> EVET | P53: =IF($C53="","",IF($B53="","NO EKSİK",IF(COUNTIF($B$7:$B$156,$B53)>1,"NO TEKRARI",IF(COUNTIF($C$7:$C$156,$C53)>1,"UNVAN TEKRARI",IF($D53="","DURUM EKSİK",IF(AND($J53>0,$K53=""),"DEVİR TARİHİ EKSİK","UYGUN")))))) -> UYGUN | T53: =IF($C53="","",UPPER(SUBSTITUTE(SUBSTITUTE(SUBSTITUTE(SUBSTITUTE(SUBSTITUTE(SUBSTITUTE(SUBSTITUTE(SUBSTITUTE(SUBSTITUTE(SUBSTITUTE(SUBSTITUTE(SUBSTITUTE(SUBSTITUTE(SUBSTITUTE(SUBSTITUTE(SUBSTITUTE(SUBSTITUTE(SUBSTITUTE(TRIM($C53),"'",""),"İ","I"),"ı","I"),"i","I"),"Ş","S"),"ş","S"),"Ğ","G"),"ğ","G"),"Ü","U"),"ü","U"),"Ö","O"),"ö","O"),"Ç","C"),"ç","C"),".",""),",","")," ",""),"-",""))) -> TANAKLTDSTI | U53: =IF($C53="","",COUNTIF($C$7:$C$156,"<"&$C53)+COUNTIF($C$7:$C53,$C53)) -> 47
B54: M003 | C54: TYANA LTD.ŞTİ. | D54: Aktif | H54: Nakit | I54: 46023 | J54: 0 | O54: =IF($C54="","",IF(COUNTIFS(UCRETLER!$B$7:$B$606,$B54,UCRETLER!$H$7:$H$606,"Aktif")>0,"EVET","HAYIR")) -> EVET | P54: =IF($C54="","",IF($B54="","NO EKSİK",IF(COUNTIF($B$7:$B$156,$B54)>1,"NO TEKRARI",IF(COUNTIF($C$7:$C$156,$C54)>1,"UNVAN TEKRARI",IF($D54="","DURUM EKSİK",IF(AND($J54>0,$K54=""),"DEVİR TARİHİ EKSİK","UYGUN")))))) -> UYGUN | T54: =IF($C54="","",UPPER(SUBSTITUTE(SUBSTITUTE(SUBSTITUTE(SUBSTITUTE(SUBSTITUTE(SUBSTITUTE(SUBSTITUTE(SUBSTITUTE(SUBSTITUTE(SUBSTITUTE(SUBSTITUTE(SUBSTITUTE(SUBSTITUTE(SUBSTITUTE(SUBSTITUTE(SUBSTITUTE(SUBSTITUTE(SUBSTITUTE(TRIM($C54),"'",""),"İ","I"),"ı","I"),"i","I"),"Ş","S"),"ş","S"),"Ğ","G"),"ğ","G"),"Ü","U"),"ü","U"),"Ö","O"),"ö","O"),"Ç","C"),"ç","C"),".",""),",","")," ",""),"-",""))) -> TYANALTDSTI | U54: =IF($C54="","",COUNTIF($C$7:$C$156,"<"&$C54)+COUNTIF($C$7:$C54,$C54)) -> 48
B55: M051 | C55: UFUK YILMAZ | D55: Aktif | H55: Nakit | I55: 46023 | J55: 0 | O55: =IF($C55="","",IF(COUNTIFS(UCRETLER!$B$7:$B$606,$B55,UCRETLER!$H$7:$H$606,"Aktif")>0,"EVET","HAYIR")) -> EVET | P55: =IF($C55="","",IF($B55="","NO EKSİK",IF(COUNTIF($B$7:$B$156,$B55)>1,"NO TEKRARI",IF(COUNTIF($C$7:$C$156,$C55)>1,"UNVAN TEKRARI",IF($D55="","DURUM EKSİK",IF(AND($J55>0,$K55=""),"DEVİR TARİHİ EKSİK","UYGUN")))))) -> UYGUN | T55: =IF($C55="","",UPPER(SUBSTITUTE(SUBSTITUTE(SUBSTITUTE(SUBSTITUTE(SUBSTITUTE(SUBSTITUTE(SUBSTITUTE(SUBSTITUTE(SUBSTITUTE(SUBSTITUTE(SUBSTITUTE(SUBSTITUTE(SUBSTITUTE(SUBSTITUTE(SUBSTITUTE(SUBSTITUTE(SUBSTITUTE(SUBSTITUTE(TRIM($C55),"'",""),"İ","I"),"ı","I"),"i","I"),"Ş","S"),"ş","S"),"Ğ","G"),"ğ","G"),"Ü","U"),"ü","U"),"Ö","O"),"ö","O"),"Ç","C"),"ç","C"),".",""),",","")," ",""),"-",""))) -> UFUKYILMAZ | U55: =IF($C55="","",COUNTIF($C$7:$C$156,"<"&$C55)+COUNTIF($C$7:$C55,$C55)) -> 49
B56: M052 | C56: VANOLYA SU LTD.ŞTİ. | D56: Aktif | H56: Nakit | I56: 46023 | J56: 0 | O56: =IF($C56="","",IF(COUNTIFS(UCRETLER!$B$7:$B$606,$B56,UCRETLER!$H$7:$H$606,"Aktif")>0,"EVET","HAYIR")) -> EVET | P56: =IF($C56="","",IF($B56="","NO EKSİK",IF(COUNTIF($B$7:$B$156,$B56)>1,"NO TEKRARI",IF(COUNTIF($C$7:$C$156,$C56)>1,"UNVAN TEKRARI",IF($D56="","DURUM EKSİK",IF(AND($J56>0,$K56=""),"DEVİR TARİHİ EKSİK","UYGUN")))))) -> UYGUN | T56: =IF($C56="","",UPPER(SUBSTITUTE(SUBSTITUTE(SUBSTITUTE(SUBSTITUTE(SUBSTITUTE(SUBSTITUTE(SUBSTITUTE(SUBSTITUTE(SUBSTITUTE(SUBSTITUTE(SUBSTITUTE(SUBSTITUTE(SUBSTITUTE(SUBSTITUTE(SUBSTITUTE(SUBSTITUTE(SUBSTITUTE(SUBSTITUTE(TRIM($C56),"'",""),"İ","I"),"ı","I"),"i","I"),"Ş","S"),"ş","S"),"Ğ","G"),"ğ","G"),"Ü","U"),"ü","U"),"Ö","O"),"ö","O"),"Ç","C"),"ç","C"),".",""),",","")," ",""),"-",""))) -> VANOLYASULTDSTI | U56: =IF($C56="","",COUNTIF($C$7:$C$156,"<"&$C56)+COUNTIF($C$7:$C56,$C56)) -> 50
B57: M006 | C57: VOLKAN AÇIK | D57: Aktif | H57: Nakit | I57: 46023 | J57: 0 | O57: =IF($C57="","",IF(COUNTIFS(UCRETLER!$B$7:$B$606,$B57,UCRETLER!$H$7:$H$606,"Aktif")>0,"EVET","HAYIR")) -> EVET | P57: =IF($C57="","",IF($B57="","NO EKSİK",IF(COUNTIF($B$7:$B$156,$B57)>1,"NO TEKRARI",IF(COUNTIF($C$7:$C$156,$C57)>1,"UNVAN TEKRARI",IF($D57="","DURUM EKSİK",IF(AND($J57>0,$K57=""),"DEVİR TARİHİ EKSİK","UYGUN")))))) -> UYGUN | T57: =IF($C57="","",UPPER(SUBSTITUTE(SUBSTITUTE(SUBSTITUTE(SUBSTITUTE(SUBSTITUTE(SUBSTITUTE(SUBSTITUTE(SUBSTITUTE(SUBSTITUTE(SUBSTITUTE(SUBSTITUTE(SUBSTITUTE(SUBSTITUTE(SUBSTITUTE(SUBSTITUTE(SUBSTITUTE(SUBSTITUTE(SUBSTITUTE(TRIM($C57),"'",""),"İ","I"),"ı","I"),"i","I"),"Ş","S"),"ş","S"),"Ğ","G"),"ğ","G"),"Ü","U"),"ü","U"),"Ö","O"),"ö","O"),"Ç","C"),"ç","C"),".",""),",","")," ",""),"-",""))) -> VOLKANACIK | U57: =IF($C57="","",COUNTIF($C$7:$C$156,"<"&$C57)+COUNTIF($C$7:$C57,$C57)) -> 51
B58: M054 | C58: YALIKENT LTD.ŞTİ. | D58: Aktif | H58: Nakit | I58: 46023 | O58: =IF($C58="","",IF(COUNTIFS(UCRETLER!$B$7:$B$606,$B58,UCRETLER!$H$7:$H$606,"Aktif")>0,"EVET","HAYIR")) -> HAYIR | P58: =IF($C58="","",IF($B58="","NO EKSİK",IF(COUNTIF($B$7:$B$156,$B58)>1,"NO TEKRARI",IF(COUNTIF($C$7:$C$156,$C58)>1,"UNVAN TEKRARI",IF($D58="","DURUM EKSİK",IF(AND($J58>0,$K58=""),"DEVİR TARİHİ EKSİK","UYGUN")))))) -> UYGUN | T58: =IF($C58="","",UPPER(SUBSTITUTE(SUBSTITUTE(SUBSTITUTE(SUBSTITUTE(SUBSTITUTE(SUBSTITUTE(SUBSTITUTE(SUBSTITUTE(SUBSTITUTE(SUBSTITUTE(SUBSTITUTE(SUBSTITUTE(SUBSTITUTE(SUBSTITUTE(SUBSTITUTE(SUBSTITUTE(SUBSTITUTE(SUBSTITUTE(TRIM($C58),"'",""),"İ","I"),"ı","I"),"i","I"),"Ş","S"),"ş","S"),"Ğ","G"),"ğ","G"),"Ü","U"),"ü","U"),"Ö","O"),"ö","O"),"Ç","C"),"ç","C"),".",""),",","")," ",""),"-",""))) -> YALIKENTLTDSTI | U58: =IF($C58="","",COUNTIF($C$7:$C$156,"<"&$C58)+COUNTIF($C$7:$C58,$C58)) -> 52
B59: M053 | C59: YEDİYİRMİDÖRT LTD.ŞTİ. | D59: Aktif | H59: Nakit | I59: 46023 | J59: 0 | O59: =IF($C59="","",IF(COUNTIFS(UCRETLER!$B$7:$B$606,$B59,UCRETLER!$H$7:$H$606,"Aktif")>0,"EVET","HAYIR")) -> EVET | P59: =IF($C59="","",IF($B59="","NO EKSİK",IF(COUNTIF($B$7:$B$156,$B59)>1,"NO TEKRARI",IF(COUNTIF($C$7:$C$156,$C59)>1,"UNVAN TEKRARI",IF($D59="","DURUM EKSİK",IF(AND($J59>0,$K59=""),"DEVİR TARİHİ EKSİK","UYGUN")))))) -> UYGUN | T59: =IF($C59="","",UPPER(SUBSTITUTE(SUBSTITUTE(SUBSTITUTE(SUBSTITUTE(SUBSTITUTE(SUBSTITUTE(SUBSTITUTE(SUBSTITUTE(SUBSTITUTE(SUBSTITUTE(SUBSTITUTE(SUBSTITUTE(SUBSTITUTE(SUBSTITUTE(SUBSTITUTE(SUBSTITUTE(SUBSTITUTE(SUBSTITUTE(TRIM($C59),"'",""),"İ","I"),"ı","I"),"i","I"),"Ş","S"),"ş","S"),"Ğ","G"),"ğ","G"),"Ü","U"),"ü","U"),"Ö","O"),"ö","O"),"Ç","C"),"ç","C"),".",""),",","")," ",""),"-",""))) -> YEDIYIRMIDORTLTDSTI | U59: =IF($C59="","",COUNTIF($C$7:$C$156,"<"&$C59)+COUNTIF($C$7:$C59,$C59)) -> 53
B60: M004 | C60: ZÜMRÜT EĞLENCE LTD.ŞTİ. | D60: Aktif | H60: Nakit | I60: 46023 | J60: 0 | O60: =IF($C60="","",IF(COUNTIFS(UCRETLER!$B$7:$B$606,$B60,UCRETLER!$H$7:$H$606,"Aktif")>0,"EVET","HAYIR")) -> EVET | P60: =IF($C60="","",IF($B60="","NO EKSİK",IF(COUNTIF($B$7:$B$156,$B60)>1,"NO TEKRARI",IF(COUNTIF($C$7:$C$156,$C60)>1,"UNVAN TEKRARI",IF($D60="","DURUM EKSİK",IF(AND($J60>0,$K60=""),"DEVİR TARİHİ EKSİK","UYGUN")))))) -> UYGUN | T60: =IF($C60="","",UPPER(SUBSTITUTE(SUBSTITUTE(SUBSTITUTE(SUBSTITUTE(SUBSTITUTE(SUBSTITUTE(SUBSTITUTE(SUBSTITUTE(SUBSTITUTE(SUBSTITUTE(SUBSTITUTE(SUBSTITUTE(SUBSTITUTE(SUBSTITUTE(SUBSTITUTE(SUBSTITUTE(SUBSTITUTE(SUBSTITUTE(TRIM($C60),"'",""),"İ","I"),"ı","I"),"i","I"),"Ş","S"),"ş","S"),"Ğ","G"),"ğ","G"),"Ü","U"),"ü","U"),"Ö","O"),"ö","O"),"Ç","C"),"ç","C"),".",""),",","")," ",""),"-",""))) -> ZUMRUTEGLENCELTDSTI | U60: =IF($C60="","",COUNTIF($C$7:$C$156,"<"&$C60)+COUNTIF($C$7:$C60,$C60)) -> 54
B61: M005 | C61: ZÜMRÜT GRUP LTD.ŞTİ. | D61: Aktif | H61: Nakit | I61: 46023 | J61: 0 | O61: =IF($C61="","",IF(COUNTIFS(UCRETLER!$B$7:$B$606,$B61,UCRETLER!$H$7:$H$606,"Aktif")>0,"EVET","HAYIR")) -> EVET | P61: =IF($C61="","",IF($B61="","NO EKSİK",IF(COUNTIF($B$7:$B$156,$B61)>1,"NO TEKRARI",IF(COUNTIF($C$7:$C$156,$C61)>1,"UNVAN TEKRARI",IF($D61="","DURUM EKSİK",IF(AND($J61>0,$K61=""),"DEVİR TARİHİ EKSİK","UYGUN")))))) -> UYGUN | T61: =IF($C61="","",UPPER(SUBSTITUTE(SUBSTITUTE(SUBSTITUTE(SUBSTITUTE(SUBSTITUTE(SUBSTITUTE(SUBSTITUTE(SUBSTITUTE(SUBSTITUTE(SUBSTITUTE(SUBSTITUTE(SUBSTITUTE(SUBSTITUTE(SUBSTITUTE(SUBSTITUTE(SUBSTITUTE(SUBSTITUTE(SUBSTITUTE(TRIM($C61),"'",""),"İ","I"),"ı","I"),"i","I"),"Ş","S"),"ş","S"),"Ğ","G"),"ğ","G"),"Ü","U"),"ü","U"),"Ö","O"),"ö","O"),"Ç","C"),"ç","C"),".",""),",","")," ",""),"-",""))) -> ZUMRUTGRUPLTDSTI | U61: =IF($C61="","",COUNTIF($C$7:$C$156,"<"&$C61)+COUNTIF($C$7:$C61,$C61)) -> 55
O62: =IF($C62="","",IF(COUNTIFS(UCRETLER!$B$7:$B$606,$B62,UCRETLER!$H$7:$H$606,"Aktif")>0,"EVET","HAYIR")) | P62: =IF($C62="","",IF($B62="","NO EKSİK",IF(COUNTIF($B$7:$B$156,$B62)>1,"NO TEKRARI",IF(COUNTIF($C$7:$C$156,$C62)>1,"UNVAN TEKRARI",IF($D62="","DURUM EKSİK",IF(AND($J62>0,$K62=""),"DEVİR TARİHİ EKSİK","UYGUN")))))) | T62: =IF($C62="","",UPPER(SUBSTITUTE(SUBSTITUTE(SUBSTITUTE(SUBSTITUTE(SUBSTITUTE(SUBSTITUTE(SUBSTITUTE(SUBSTITUTE(SUBSTITUTE(SUBSTITUTE(SUBSTITUTE(SUBSTITUTE(SUBSTITUTE(SUBSTITUTE(SUBSTITUTE(SUBSTITUTE(SUBSTITUTE(SUBSTITUTE(TRIM($C62),"'",""),"İ","I"),"ı","I"),"i","I"),"Ş","S"),"ş","S"),"Ğ","G"),"ğ","G"),"Ü","U"),"ü","U"),"Ö","O"),"ö","O"),"Ç","C"),"ç","C"),".",""),",","")," ",""),"-",""))) | U62: =IF($C62="","",COUNTIF($C$7:$C$156,"<"&$C62)+COUNTIF($C$7:$C62,$C62))
O63: =IF($C63="","",IF(COUNTIFS(UCRETLER!$B$7:$B$606,$B63,UCRETLER!$H$7:$H$606,"Aktif")>0,"EVET","HAYIR")) | P63: =IF($C63="","",IF($B63="","NO EKSİK",IF(COUNTIF($B$7:$B$156,$B63)>1,"NO TEKRARI",IF(COUNTIF($C$7:$C$156,$C63)>1,"UNVAN TEKRARI",IF($D63="","DURUM EKSİK",IF(AND($J63>0,$K63=""),"DEVİR TARİHİ EKSİK","UYGUN")))))) | T63: =IF($C63="","",UPPER(SUBSTITUTE(SUBSTITUTE(SUBSTITUTE(SUBSTITUTE(SUBSTITUTE(SUBSTITUTE(SUBSTITUTE(SUBSTITUTE(SUBSTITUTE(SUBSTITUTE(SUBSTITUTE(SUBSTITUTE(SUBSTITUTE(SUBSTITUTE(SUBSTITUTE(SUBSTITUTE(SUBSTITUTE(SUBSTITUTE(TRIM($C63),"'",""),"İ","I"),"ı","I"),"i","I"),"Ş","S"),"ş","S"),"Ğ","G"),"ğ","G"),"Ü","U"),"ü","U"),"Ö","O"),"ö","O"),"Ç","C"),"ç","C"),".",""),",","")," ",""),"-",""))) | U63: =IF($C63="","",COUNTIF($C$7:$C$156,"<"&$C63)+COUNTIF($C$7:$C63,$C63))
O64: =IF($C64="","",IF(COUNTIFS(UCRETLER!$B$7:$B$606,$B64,UCRETLER!$H$7:$H$606,"Aktif")>0,"EVET","HAYIR")) | P64: =IF($C64="","",IF($B64="","NO EKSİK",IF(COUNTIF($B$7:$B$156,$B64)>1,"NO TEKRARI",IF(COUNTIF($C$7:$C$156,$C64)>1,"UNVAN TEKRARI",IF($D64="","DURUM EKSİK",IF(AND($J64>0,$K64=""),"DEVİR TARİHİ EKSİK","UYGUN")))))) | T64: =IF($C64="","",UPPER(SUBSTITUTE(SUBSTITUTE(SUBSTITUTE(SUBSTITUTE(SUBSTITUTE(SUBSTITUTE(SUBSTITUTE(SUBSTITUTE(SUBSTITUTE(SUBSTITUTE(SUBSTITUTE(SUBSTITUTE(SUBSTITUTE(SUBSTITUTE(SUBSTITUTE(SUBSTITUTE(SUBSTITUTE(SUBSTITUTE(TRIM($C64),"'",""),"İ","I"),"ı","I"),"i","I"),"Ş","S"),"ş","S"),"Ğ","G"),"ğ","G"),"Ü","U"),"ü","U"),"Ö","O"),"ö","O"),"Ç","C"),"ç","C"),".",""),",","")," ",""),"-",""))) | U64: =IF($C64="","",COUNTIF($C$7:$C$156,"<"&$C64)+COUNTIF($C$7:$C64,$C64))
O65: =IF($C65="","",IF(COUNTIFS(UCRETLER!$B$7:$B$606,$B65,UCRETLER!$H$7:$H$606,"Aktif")>0,"EVET","HAYIR")) | P65: =IF($C65="","",IF($B65="","NO EKSİK",IF(COUNTIF($B$7:$B$156,$B65)>1,"NO TEKRARI",IF(COUNTIF($C$7:$C$156,$C65)>1,"UNVAN TEKRARI",IF($D65="","DURUM EKSİK",IF(AND($J65>0,$K65=""),"DEVİR TARİHİ EKSİK","UYGUN")))))) | T65: =IF($C65="","",UPPER(SUBSTITUTE(SUBSTITUTE(SUBSTITUTE(SUBSTITUTE(SUBSTITUTE(SUBSTITUTE(SUBSTITUTE(SUBSTITUTE(SUBSTITUTE(SUBSTITUTE(SUBSTITUTE(SUBSTITUTE(SUBSTITUTE(SUBSTITUTE(SUBSTITUTE(SUBSTITUTE(SUBSTITUTE(SUBSTITUTE(TRIM($C65),"'",""),"İ","I"),"ı","I"),"i","I"),"Ş","S"),"ş","S"),"Ğ","G"),"ğ","G"),"Ü","U"),"ü","U"),"Ö","O"),"ö","O"),"Ç","C"),"ç","C"),".",""),",","")," ",""),"-",""))) | U65: =IF($C65="","",COUNTIF($C$7:$C$156,"<"&$C65)+COUNTIF($C$7:$C65,$C65))
O66: =IF($C66="","",IF(COUNTIFS(UCRETLER!$B$7:$B$606,$B66,UCRETLER!$H$7:$H$606,"Aktif")>0,"EVET","HAYIR")) | P66: =IF($C66="","",IF($B66="","NO EKSİK",IF(COUNTIF($B$7:$B$156,$B66)>1,"NO TEKRARI",IF(COUNTIF($C$7:$C$156,$C66)>1,"UNVAN TEKRARI",IF($D66="","DURUM EKSİK",IF(AND($J66>0,$K66=""),"DEVİR TARİHİ EKSİK","UYGUN")))))) | T66: =IF($C66="","",UPPER(SUBSTITUTE(SUBSTITUTE(SUBSTITUTE(SUBSTITUTE(SUBSTITUTE(SUBSTITUTE(SUBSTITUTE(SUBSTITUTE(SUBSTITUTE(SUBSTITUTE(SUBSTITUTE(SUBSTITUTE(SUBSTITUTE(SUBSTITUTE(SUBSTITUTE(SUBSTITUTE(SUBSTITUTE(SUBSTITUTE(TRIM($C66),"'",""),"İ","I"),"ı","I"),"i","I"),"Ş","S"),"ş","S"),"Ğ","G"),"ğ","G"),"Ü","U"),"ü","U"),"Ö","O"),"ö","O"),"Ç","C"),"ç","C"),".",""),",","")," ",""),"-",""))) | U66: =IF($C66="","",COUNTIF($C$7:$C$156,"<"&$C66)+COUNTIF($C$7:$C66,$C66))
O67: =IF($C67="","",IF(COUNTIFS(UCRETLER!$B$7:$B$606,$B67,UCRETLER!$H$7:$H$606,"Aktif")>0,"EVET","HAYIR")) | P67: =IF($C67="","",IF($B67="","NO EKSİK",IF(COUNTIF($B$7:$B$156,$B67)>1,"NO TEKRARI",IF(COUNTIF($C$7:$C$156,$C67)>1,"UNVAN TEKRARI",IF($D67="","DURUM EKSİK",IF(AND($J67>0,$K67=""),"DEVİR TARİHİ EKSİK","UYGUN")))))) | T67: =IF($C67="","",UPPER(SUBSTITUTE(SUBSTITUTE(SUBSTITUTE(SUBSTITUTE(SUBSTITUTE(SUBSTITUTE(SUBSTITUTE(SUBSTITUTE(SUBSTITUTE(SUBSTITUTE(SUBSTITUTE(SUBSTITUTE(SUBSTITUTE(SUBSTITUTE(SUBSTITUTE(SUBSTITUTE(SUBSTITUTE(SUBSTITUTE(TRIM($C67),"'",""),"İ","I"),"ı","I"),"i","I"),"Ş","S"),"ş","S"),"Ğ","G"),"ğ","G"),"Ü","U"),"ü","U"),"Ö","O"),"ö","O"),"Ç","C"),"ç","C"),".",""),",","")," ",""),"-",""))) | U67: =IF($C67="","",COUNTIF($C$7:$C$156,"<"&$C67)+COUNTIF($C$7:$C67,$C67))
O68: =IF($C68="","",IF(COUNTIFS(UCRETLER!$B$7:$B$606,$B68,UCRETLER!$H$7:$H$606,"Aktif")>0,"EVET","HAYIR")) | P68: =IF($C68="","",IF($B68="","NO EKSİK",IF(COUNTIF($B$7:$B$156,$B68)>1,"NO TEKRARI",IF(COUNTIF($C$7:$C$156,$C68)>1,"UNVAN TEKRARI",IF($D68="","DURUM EKSİK",IF(AND($J68>0,$K68=""),"DEVİR TARİHİ EKSİK","UYGUN")))))) | T68: =IF($C68="","",UPPER(SUBSTITUTE(SUBSTITUTE(SUBSTITUTE(SUBSTITUTE(SUBSTITUTE(SUBSTITUTE(SUBSTITUTE(SUBSTITUTE(SUBSTITUTE(SUBSTITUTE(SUBSTITUTE(SUBSTITUTE(SUBSTITUTE(SUBSTITUTE(SUBSTITUTE(SUBSTITUTE(SUBSTITUTE(SUBSTITUTE(TRIM($C68),"'",""),"İ","I"),"ı","I"),"i","I"),"Ş","S"),"ş","S"),"Ğ","G"),"ğ","G"),"Ü","U"),"ü","U"),"Ö","O"),"ö","O"),"Ç","C"),"ç","C"),".",""),",","")," ",""),"-",""))) | U68: =IF($C68="","",COUNTIF($C$7:$C$156,"<"&$C68)+COUNTIF($C$7:$C68,$C68))
O69: =IF($C69="","",IF(COUNTIFS(UCRETLER!$B$7:$B$606,$B69,UCRETLER!$H$7:$H$606,"Aktif")>0,"EVET","HAYIR")) | P69: =IF($C69="","",IF($B69="","NO EKSİK",IF(COUNTIF($B$7:$B$156,$B69)>1,"NO TEKRARI",IF(COUNTIF($C$7:$C$156,$C69)>1,"UNVAN TEKRARI",IF($D69="","DURUM EKSİK",IF(AND($J69>0,$K69=""),"DEVİR TARİHİ EKSİK","UYGUN")))))) | T69: =IF($C69="","",UPPER(SUBSTITUTE(SUBSTITUTE(SUBSTITUTE(SUBSTITUTE(SUBSTITUTE(SUBSTITUTE(SUBSTITUTE(SUBSTITUTE(SUBSTITUTE(SUBSTITUTE(SUBSTITUTE(SUBSTITUTE(SUBSTITUTE(SUBSTITUTE(SUBSTITUTE(SUBSTITUTE(SUBSTITUTE(SUBSTITUTE(TRIM($C69),"'",""),"İ","I"),"ı","I"),"i","I"),"Ş","S"),"ş","S"),"Ğ","G"),"ğ","G"),"Ü","U"),"ü","U"),"Ö","O"),"ö","O"),"Ç","C"),"ç","C"),".",""),",","")," ",""),"-",""))) | U69: =IF($C69="","",COUNTIF($C$7:$C$156,"<"&$C69)+COUNTIF($C$7:$C69,$C69))
O70: =IF($C70="","",IF(COUNTIFS(UCRETLER!$B$7:$B$606,$B70,UCRETLER!$H$7:$H$606,"Aktif")>0,"EVET","HAYIR")) | P70: =IF($C70="","",IF($B70="","NO EKSİK",IF(COUNTIF($B$7:$B$156,$B70)>1,"NO TEKRARI",IF(COUNTIF($C$7:$C$156,$C70)>1,"UNVAN TEKRARI",IF($D70="","DURUM EKSİK",IF(AND($J70>0,$K70=""),"DEVİR TARİHİ EKSİK","UYGUN")))))) | T70: =IF($C70="","",UPPER(SUBSTITUTE(SUBSTITUTE(SUBSTITUTE(SUBSTITUTE(SUBSTITUTE(SUBSTITUTE(SUBSTITUTE(SUBSTITUTE(SUBSTITUTE(SUBSTITUTE(SUBSTITUTE(SUBSTITUTE(SUBSTITUTE(SUBSTITUTE(SUBSTITUTE(SUBSTITUTE(SUBSTITUTE(SUBSTITUTE(TRIM($C70),"'",""),"İ","I"),"ı","I"),"i","I"),"Ş","S"),"ş","S"),"Ğ","G"),"ğ","G"),"Ü","U"),"ü","U"),"Ö","O"),"ö","O"),"Ç","C"),"ç","C"),".",""),",","")," ",""),"-",""))) | U70: =IF($C70="","",COUNTIF($C$7:$C$156,"<"&$C70)+COUNTIF($C$7:$C70,$C70))
O71: =IF($C71="","",IF(COUNTIFS(UCRETLER!$B$7:$B$606,$B71,UCRETLER!$H$7:$H$606,"Aktif")>0,"EVET","HAYIR")) | P71: =IF($C71="","",IF($B71="","NO EKSİK",IF(COUNTIF($B$7:$B$156,$B71)>1,"NO TEKRARI",IF(COUNTIF($C$7:$C$156,$C71)>1,"UNVAN TEKRARI",IF($D71="","DURUM EKSİK",IF(AND($J71>0,$K71=""),"DEVİR TARİHİ EKSİK","UYGUN")))))) | T71: =IF($C71="","",UPPER(SUBSTITUTE(SUBSTITUTE(SUBSTITUTE(SUBSTITUTE(SUBSTITUTE(SUBSTITUTE(SUBSTITUTE(SUBSTITUTE(SUBSTITUTE(SUBSTITUTE(SUBSTITUTE(SUBSTITUTE(SUBSTITUTE(SUBSTITUTE(SUBSTITUTE(SUBSTITUTE(SUBSTITUTE(SUBSTITUTE(TRIM($C71),"'",""),"İ","I"),"ı","I"),"i","I"),"Ş","S"),"ş","S"),"Ğ","G"),"ğ","G"),"Ü","U"),"ü","U"),"Ö","O"),"ö","O"),"Ç","C"),"ç","C"),".",""),",","")," ",""),"-",""))) | U71: =IF($C71="","",COUNTIF($C$7:$C$156,"<"&$C71)+COUNTIF($C$7:$C71,$C71))
...

Sheet UCRETLER
A1: ✎ VERİ GİRİŞ EKRANI — SARI HÜCRELER | F1: KILIÇ MUHASEBE │ ÜCRET DÖNEMLERİ │ HAFTALIK VE AYLIK TAHAKKUK
A2: SARI HÜCRELERE YAZIN │ Ücret değişinde eski dönemi kapat, yeni satır aç │ Geçmiş tahakkuk asla bozulmaz
B3: ⚠ SAKIN: ücret değişinde TUTARI DEĞİŞTİRMEYİN. Eski satırı kapatıp yeni satır açın — aksi halde geçmiş aylar bozulur ve GERİ ALINAMAZ.
B4: =HYPERLINK("#PANO!A1","⌂") -> ⌂ | C4: =HYPERLINK("#PANO!A1","M E N Ü") -> M E N Ü | D4: =HYPERLINK("#MUSTERILER!A1","Müşteriler") -> Müşteriler | F4: =HYPERLINK("#MUSTERI_360!A1","Müşteri 360") -> Müşteri 360 | H4: Sarı = giriş, beyaz = otomatik (kilitli). Başlangıç tarihi serbesttir: haftalık modelde ilk tahakkuk bu tarihten sonraki ilk tahakkuk gününde, aylık modelde ayın son gününde oluşur.
C5: TOPLAM │ Aktif haftalık + aylık tahakkuk ve oluşan ücret | G5: =SUMIFS($G$7:$G$606,$H$7:$H$606,"Aktif") -> 209750 | I5: =SUM($I$7:$I$606) -> 3311000
B6: Müşteri No | C6: Müşteri (yazın veya seçin) | D6: Ücret Başlangıç Tarihi | E6: Ücret Bitiş Tarihi (bu tarih DAHİL — boş = süresiz) | F6: Tahakkuk Modeli | G6: Ücret Tutarı | H6: Dönem Durumu | I6: Bugüne Kadar Oluşan | J6: 8 Gün Öncesine Kadar | K6: 15 Gün Öncesine Kadar | L6: 29 Gün Öncesine Kadar | M6: Oluşan Dönem | N6: Sistem Kontrolü | O6: İlk Tahakkuk Tarihi | P6: Not
B7: =IF($C7="","",IFERROR(INDEX(MUSTERILER!$B$7:$B$156,MATCH($T7,MUSTERILER!$T$7:$T$156,0)),IFERROR(INDEX(MUSTERILER!$B$7:$B$156,MATCH($C7,MUSTERILER!$B$7:$B$156,0)),IFERROR(INDEX(MUSTERILER!$B$7:$B$156,MATCH($T7&"*",MUSTERILER!$T$7:$T$156,0)),"TANIMSIZ MÜŞTERİ")))) -> M019 | C7: AC OTEL LTD.ŞTİ. | D7: 46023 | F7: Aylık | G7: 4000 | H7: Aktif | I7: =IF(OR($C7="",$D7="",$G7="",$F7=""),0,$G7*(($W7=1)*($U7>0)*(($V7+(TODAY()-$V7)*(TODAY()<$V7))>=$U7)*(INT((($V7+(TODAY()-$V7)*(TODAY()<$V7))-$U7)/7)+1)+($W7=2)*($U7>0)*((($V7<=TODAY())*$Y7+($V7>TODAY())*((YEAR(TODAY())-1900)*12+MONTH(TODAY())))>=$X7)*(((($V7<=TODAY())*$Y7+($V7>TODAY())*((YEAR(TODAY())-1900)*12+MONTH(TODAY())))-$X7+1)-(1-(($V7<=TODAY())*$Z7+($V7>TODAY())*((TODAY())=EOMONTH(TODAY(),0))*1))))) -> 28000 | J7: =IF(OR($C7="",$D7="",$G7="",$F7=""),0,$G7*(($W7=1)*($U7>0)*(($V7+(TODAY()-8-$V7)*(TODAY()-8<$V7))>=$U7)*(INT((($V7+(TODAY()-8-$V7)*(TODAY()-8<$V7))-$U7)/7)+1)+($W7=2)*($U7>0)*((($V7<=TODAY()-8)*$Y7+($V7>TODAY()-8)*((YEAR(TODAY()-8)-1900)*12+MONTH(TODAY()-8)))>=$X7)*(((($V7<=TODAY()-8)*$Y7+($V7>TODAY()-8)*((YEAR(TODAY()-8)-1900)*12+MONTH(TODAY()-8)))-$X7+1)-(1-(($V7<=TODAY()-8)*$Z7+($V7>TODAY()-8)*((TODAY()-8)=EOMONTH(TODAY()-8,0))*1))))) -> 28000 | K7: =IF(OR($C7="",$D7="",$G7="",$F7=""),0,$G7*(($W7=1)*($U7>0)*(($V7+(TODAY()-15-$V7)*(TODAY()-15<$V7))>=$U7)*(INT((($V7+(TODAY()-15-$V7)*(TODAY()-15<$V7))-$U7)/7)+1)+($W7=2)*($U7>0)*((($V7<=TODAY()-15)*$Y7+($V7>TODAY()-15)*((YEAR(TODAY()-15)-1900)*12+MONTH(TODAY()-15)))>=$X7)*(((($V7<=TODAY()-15)*$Y7+($V7>TODAY()-15)*((YEAR(TODAY()-15)-1900)*12+MONTH(TODAY()-15)))-$X7+1)-(1-(($V7<=TODAY()-15)*$Z7+($V7>TODAY()-15)*((TODAY()-15)=EOMONTH(TODAY()-15,0))*1))))) -> 28000 | L7: =IF(OR($C7="",$D7="",$G7="",$F7=""),0,$G7*(($W7=1)*($U7>0)*(($V7+(TODAY()-29-$V7)*(TODAY()-29<$V7))>=$U7)*(INT((($V7+(TODAY()-29-$V7)*(TODAY()-29<$V7))-$U7)/7)+1)+($W7=2)*($U7>0)*((($V7<=TODAY()-29)*$Y7+($V7>TODAY()-29)*((YEAR(TODAY()-29)-1900)*12+MONTH(TODAY()-29)))>=$X7)*(((($V7<=TODAY()-29)*$Y7+($V7>TODAY()-29)*((YEAR(TODAY()-29)-1900)*12+MONTH(TODAY()-29)))-$X7+1)-(1-(($V7<=TODAY()-29)*$Z7+($V7>TODAY()-29)*((TODAY()-29)=EOMONTH(TODAY()-29,0))*1))))) -> 24000 | M7: =IF($G7>0,$I7/$G7,0) -> 7 | N7: =IF($C7="","",IF($B7="TANIMSIZ MÜŞTERİ","TANIMSIZ MÜŞTERİ",IF($F7="","MODEL SEÇİN",IF(OR($D7="",$G7<=0),"EKSİK",IF(AND($E7<>"",$E7<$D7),"TARİH HATASI",IF($H7="Pasif","KAPALI DÖNEM","UYGUN")))))) -> UYGUN | O7: =IF(OR($C7="",$D7="",$F7=""),"",IF($F7="Aylık",EOMONTH($D7,0),($D7+MOD(SISTEM!$F$8-WEEKDAY($D7,2),7)))) -> 46053 | S7: =IF($B7="","",$B7&"|"&COUNTIFS($B$7:$B7,$B7)) -> M019|1 | T7: =IF($C7="","",UPPER(SUBSTITUTE(SUBSTITUTE(SUBSTITUTE(SUBSTITUTE(SUBSTITUTE(SUBSTITUTE(SUBSTITUTE(SUBSTITUTE(SUBSTITUTE(SUBSTITUTE(SUBSTITUTE(SUBSTITUTE(SUBSTITUTE(SUBSTITUTE(SUBSTITUTE(SUBSTITUTE(SUBSTITUTE(SUBSTITUTE(TRIM($C7),"'",""),"İ","I"),"ı","I"),"i","I"),"Ş","S"),"ş","S"),"Ğ","G"),"ğ","G"),"Ü","U"),"ü","U"),"Ö","O"),"ö","O"),"Ç","C"),"ç","C"),".",""),",","")," ",""),"-",""))) -> ACOTELLTDSTI | U7: =IF($O7="",0,$O7) -> 46053 | V7: =IF($E7="",2958465,$E7) -> 2958465 | W7: =IF($F7="Haftalık",1,IF($F7="Aylık",2,0)) -> 2 | X7: =IF($U7=0,0,(YEAR($U7)-1900)*12+MONTH($U7)) -> 1513 | Y7: =(YEAR($V7)-1900)*12+MONTH($V7) -> 97200 | Z7: =IF($V7=EOMONTH($V7,0),1,0) -> 1
B8: =IF($C8="","",IFERROR(INDEX(MUSTERILER!$B$7:$B$156,MATCH($T8,MUSTERILER!$T$7:$T$156,0)),IFERROR(INDEX(MUSTERILER!$B$7:$B$156,MATCH($C8,MUSTERILER!$B$7:$B$156,0)),IFERROR(INDEX(MUSTERILER!$B$7:$B$156,MATCH($T8&"*",MUSTERILER!$T$7:$T$156,0)),"TANIMSIZ MÜŞTERİ")))) -> M022 | C8: ADEM KARABENLİ | D8: 46023 | F8: Aylık | G8: 3000 | H8: Aktif | I8: =IF(OR($C8="",$D8="",$G8="",$F8=""),0,$G8*(($W8=1)*($U8>0)*(($V8+(TODAY()-$V8)*(TODAY()<$V8))>=$U8)*(INT((($V8+(TODAY()-$V8)*(TODAY()<$V8))-$U8)/7)+1)+($W8=2)*($U8>0)*((($V8<=TODAY())*$Y8+($V8>TODAY())*((YEAR(TODAY())-1900)*12+MONTH(TODAY())))>=$X8)*(((($V8<=TODAY())*$Y8+($V8>TODAY())*((YEAR(TODAY())-1900)*12+MONTH(TODAY())))-$X8+1)-(1-(($V8<=TODAY())*$Z8+($V8>TODAY())*((TODAY())=EOMONTH(TODAY(),0))*1))))) -> 21000 | J8: =IF(OR($C8="",$D8="",$G8="",$F8=""),0,$G8*(($W8=1)*($U8>0)*(($V8+(TODAY()-8-$V8)*(TODAY()-8<$V8))>=$U8)*(INT((($V8+(TODAY()-8-$V8)*(TODAY()-8<$V8))-$U8)/7)+1)+($W8=2)*($U8>0)*((($V8<=TODAY()-8)*$Y8+($V8>TODAY()-8)*((YEAR(TODAY()-8)-1900)*12+MONTH(TODAY()-8)))>=$X8)*(((($V8<=TODAY()-8)*$Y8+($V8>TODAY()-8)*((YEAR(TODAY()-8)-1900)*12+MONTH(TODAY()-8)))-$X8+1)-(1-(($V8<=TODAY()-8)*$Z8+($V8>TODAY()-8)*((TODAY()-8)=EOMONTH(TODAY()-8,0))*1))))) -> 21000 | K8: =IF(OR($C8="",$D8="",$G8="",$F8=""),0,$G8*(($W8=1)*($U8>0)*(($V8+(TODAY()-15-$V8)*(TODAY()-15<$V8))>=$U8)*(INT((($V8+(TODAY()-15-$V8)*(TODAY()-15<$V8))-$U8)/7)+1)+($W8=2)*($U8>0)*((($V8<=TODAY()-15)*$Y8+($V8>TODAY()-15)*((YEAR(TODAY()-15)-1900)*12+MONTH(TODAY()-15)))>=$X8)*(((($V8<=TODAY()-15)*$Y8+($V8>TODAY()-15)*((YEAR(TODAY()-15)-1900)*12+MONTH(TODAY()-15)))-$X8+1)-(1-(($V8<=TODAY()-15)*$Z8+($V8>TODAY()-15)*((TODAY()-15)=EOMONTH(TODAY()-15,0))*1))))) -> 21000 | L8: =IF(OR($C8="",$D8="",$G8="",$F8=""),0,$G8*(($W8=1)*($U8>0)*(($V8+(TODAY()-29-$V8)*(TODAY()-29<$V8))>=$U8)*(INT((($V8+(TODAY()-29-$V8)*(TODAY()-29<$V8))-$U8)/7)+1)+($W8=2)*($U8>0)*((($V8<=TODAY()-29)*$Y8+($V8>TODAY()-29)*((YEAR(TODAY()-29)-1900)*12+MONTH(TODAY()-29)))>=$X8)*(((($V8<=TODAY()-29)*$Y8+($V8>TODAY()-29)*((YEAR(TODAY()-29)-1900)*12+MONTH(TODAY()-29)))-$X8+1)-(1-(($V8<=TODAY()-29)*$Z8+($V8>TODAY()-29)*((TODAY()-29)=EOMONTH(TODAY()-29,0))*1))))) -> 18000 | M8: =IF($G8>0,$I8/$G8,0) -> 7 | N8: =IF($C8="","",IF($B8="TANIMSIZ MÜŞTERİ","TANIMSIZ MÜŞTERİ",IF($F8="","MODEL SEÇİN",IF(OR($D8="",$G8<=0),"EKSİK",IF(AND($E8<>"",$E8<$D8),"TARİH HATASI",IF($H8="Pasif","KAPALI DÖNEM","UYGUN")))))) -> UYGUN | O8: =IF(OR($C8="",$D8="",$F8=""),"",IF($F8="Aylık",EOMONTH($D8,0),($D8+MOD(SISTEM!$F$8-WEEKDAY($D8,2),7)))) -> 46053 | S8: =IF($B8="","",$B8&"|"&COUNTIFS($B$7:$B8,$B8)) -> M022|1 | T8: =IF($C8="","",UPPER(SUBSTITUTE(SUBSTITUTE(SUBSTITUTE(SUBSTITUTE(SUBSTITUTE(SUBSTITUTE(SUBSTITUTE(SUBSTITUTE(SUBSTITUTE(SUBSTITUTE(SUBSTITUTE(SUBSTITUTE(SUBSTITUTE(SUBSTITUTE(SUBSTITUTE(SUBSTITUTE(SUBSTITUTE(SUBSTITUTE(TRIM($C8),"'",""),"İ","I"),"ı","I"),"i","I"),"Ş","S"),"ş","S"),"Ğ","G"),"ğ","G"),"Ü","U"),"ü","U"),"Ö","O"),"ö","O"),"Ç","C"),"ç","C"),".",""),",","")," ",""),"-",""))) -> ADEMKARABENLI | U8: =IF($O8="",0,$O8) -> 46053 | V8: =IF($E8="",2958465,$E8) -> 2958465 | W8: =IF($F8="Haftalık",1,IF($F8="Aylık",2,0)) -> 2 | X8: =IF($U8=0,0,(YEAR($U8)-1900)*12+MONTH($U8)) -> 1513 | Y8: =(YEAR($V8)-1900)*12+MONTH($V8) -> 97200 | Z8: =IF($V8=EOMONTH($V8,0),1,0) -> 1
B9: =IF($C9="","",IFERROR(INDEX(MUSTERILER!$B$7:$B$156,MATCH($T9,MUSTERILER!$T$7:$T$156,0)),IFERROR(INDEX(MUSTERILER!$B$7:$B$156,MATCH($C9,MUSTERILER!$B$7:$B$156,0)),IFERROR(INDEX(MUSTERILER!$B$7:$B$156,MATCH($T9&"*",MUSTERILER!$T$7:$T$156,0)),"TANIMSIZ MÜŞTERİ")))) -> M023 | C9: ALTINEL LTD.ŞTİ. | D9: 46266 | F9: Aylık | G9: 10000 | H9: Aktif | I9: =IF(OR($C9="",$D9="",$G9="",$F9=""),0,$G9*(($W9=1)*($U9>0)*(($V9+(TODAY()-$V9)*(TODAY()<$V9))>=$U9)*(INT((($V9+(TODAY()-$V9)*(TODAY()<$V9))-$U9)/7)+1)+($W9=2)*($U9>0)*((($V9<=TODAY())*$Y9+($V9>TODAY())*((YEAR(TODAY())-1900)*12+MONTH(TODAY())))>=$X9)*(((($V9<=TODAY())*$Y9+($V9>TODAY())*((YEAR(TODAY())-1900)*12+MONTH(TODAY())))-$X9+1)-(1-(($V9<=TODAY())*$Z9+($V9>TODAY())*((TODAY())=EOMONTH(TODAY(),0))*1))))) -> 0 | J9: =IF(OR($C9="",$D9="",$G9="",$F9=""),0,$G9*(($W9=1)*($U9>0)*(($V9+(TODAY()-8-$V9)*(TODAY()-8<$V9))>=$U9)*(INT((($V9+(TODAY()-8-$V9)*(TODAY()-8<$V9))-$U9)/7)+1)+($W9=2)*($U9>0)*((($V9<=TODAY()-8)*$Y9+($V9>TODAY()-8)*((YEAR(TODAY()-8)-1900)*12+MONTH(TODAY()-8)))>=$X9)*(((($V9<=TODAY()-8)*$Y9+($V9>TODAY()-8)*((YEAR(TODAY()-8)-1900)*12+MONTH(TODAY()-8)))-$X9+1)-(1-(($V9<=TODAY()-8)*$Z9+($V9>TODAY()-8)*((TODAY()-8)=EOMONTH(TODAY()-8,0))*1))))) -> 0 | K9: =IF(OR($C9="",$D9="",$G9="",$F9=""),0,$G9*(($W9=1)*($U9>0)*(($V9+(TODAY()-15-$V9)*(TODAY()-15<$V9))>=$U9)*(INT((($V9+(TODAY()-15-$V9)*(TODAY()-15<$V9))-$U9)/7)+1)+($W9=2)*($U9>0)*((($V9<=TODAY()-15)*$Y9+($V9>TODAY()-15)*((YEAR(TODAY()-15)-1900)*12+MONTH(TODAY()-15)))>=$X9)*(((($V9<=TODAY()-15)*$Y9+($V9>TODAY()-15)*((YEAR(TODAY()-15)-1900)*12+MONTH(TODAY()-15)))-$X9+1)-(1-(($V9<=TODAY()-15)*$Z9+($V9>TODAY()-15)*((TODAY()-15)=EOMONTH(TODAY()-15,0))*1))))) -> 0 | L9: =IF(OR($C9="",$D9="",$G9="",$F9=""),0,$G9*(($W9=1)*($U9>0)*(($V9+(TODAY()-29-$V9)*(TODAY()-29<$V9))>=$U9)*(INT((($V9+(TODAY()-29-$V9)*(TODAY()-29<$V9))-$U9)/7)+1)+($W9=2)*($U9>0)*((($V9<=TODAY()-29)*$Y9+($V9>TODAY()-29)*((YEAR(TODAY()-29)-1900)*12+MONTH(TODAY()-29)))>=$X9)*(((($V9<=TODAY()-29)*$Y9+($V9>TODAY()-29)*((YEAR(TODAY()-29)-1900)*12+MONTH(TODAY()-29)))-$X9+1)-(1-(($V9<=TODAY()-29)*$Z9+($V9>TODAY()-29)*((TODAY()-29)=EOMONTH(TODAY()-29,0))*1))))) -> 0 | M9: =IF($G9>0,$I9/$G9,0) -> 0 | N9: =IF($C9="","",IF($B9="TANIMSIZ MÜŞTERİ","TANIMSIZ MÜŞTERİ",IF($F9="","MODEL SEÇİN",IF(OR($D9="",$G9<=0),"EKSİK",IF(AND($E9<>"",$E9<$D9),"TARİH HATASI",IF($H9="Pasif","KAPALI DÖNEM","UYGUN")))))) -> UYGUN | O9: =IF(OR($C9="",$D9="",$F9=""),"",IF($F9="Aylık",EOMONTH($D9,0),($D9+MOD(SISTEM!$F$8-WEEKDAY($D9,2),7)))) -> 46295 | S9: =IF($B9="","",$B9&"|"&COUNTIFS($B$7:$B9,$B9)) -> M023|1 | T9: =IF($C9="","",UPPER(SUBSTITUTE(SUBSTITUTE(SUBSTITUTE(SUBSTITUTE(SUBSTITUTE(SUBSTITUTE(SUBSTITUTE(SUBSTITUTE(SUBSTITUTE(SUBSTITUTE(SUBSTITUTE(SUBSTITUTE(SUBSTITUTE(SUBSTITUTE(SUBSTITUTE(SUBSTITUTE(SUBSTITUTE(SUBSTITUTE(TRIM($C9),"'",""),"İ","I"),"ı","I"),"i","I"),"Ş","S"),"ş","S"),"Ğ","G"),"ğ","G"),"Ü","U"),"ü","U"),"Ö","O"),"ö","O"),"Ç","C"),"ç","C"),".",""),",","")," ",""),"-",""))) -> ALTINELLTDSTI | U9: =IF($O9="",0,$O9) -> 46295 | V9: =IF($E9="",2958465,$E9) -> 2958465 | W9: =IF($F9="Haftalık",1,IF($F9="Aylık",2,0)) -> 2 | X9: =IF($U9=0,0,(YEAR($U9)-1900)*12+MONTH($U9)) -> 1521 | Y9: =(YEAR($V9)-1900)*12+MONTH($V9) -> 97200 | Z9: =IF($V9=EOMONTH($V9,0),1,0) -> 1
B10: =IF($C10="","",IFERROR(INDEX(MUSTERILER!$B$7:$B$156,MATCH($T10,MUSTERILER!$T$7:$T$156,0)),IFERROR(INDEX(MUSTERILER!$B$7:$B$156,MATCH($C10,MUSTERILER!$B$7:$B$156,0)),IFERROR(INDEX(MUSTERILER!$B$7:$B$156,MATCH($T10&"*",MUSTERILER!$T$7:$T$156,0)),"TANIMSIZ MÜŞTERİ")))) -> M001 | C10: ANKARA HAVANA LTD.ŞTİ. | D10: 46023 | F10: Haftalık | G10: 4000 | H10: Aktif | I10: =IF(OR($C10="",$D10="",$G10="",$F10=""),0,$G10*(($W10=1)*($U10>0)*(($V10+(TODAY()-$V10)*(TODAY()<$V10))>=$U10)*(INT((($V10+(TODAY()-$V10)*(TODAY()<$V10))-$U10)/7)+1)+($W10=2)*($U10>0)*((($V10<=TODAY())*$Y10+($V10>TODAY())*((YEAR(TODAY())-1900)*12+MONTH(TODAY())))>=$X10)*(((($V10<=TODAY())*$Y10+($V10>TODAY())*((YEAR(TODAY())-1900)*12+MONTH(TODAY())))-$X10+1)-(1-(($V10<=TODAY())*$Z10+($V10>TODAY())*((TODAY())=EOMONTH(TODAY(),0))*1))))) -> 136000 | J10: =IF(OR($C10="",$D10="",$G10="",$F10=""),0,$G10*(($W10=1)*($U10>0)*(($V10+(TODAY()-8-$V10)*(TODAY()-8<$V10))>=$U10)*(INT((($V10+(TODAY()-8-$V10)*(TODAY()-8<$V10))-$U10)/7)+1)+($W10=2)*($U10>0)*((($V10<=TODAY()-8)*$Y10+($V10>TODAY()-8)*((YEAR(TODAY()-8)-1900)*12+MONTH(TODAY()-8)))>=$X10)*(((($V10<=TODAY()-8)*$Y10+($V10>TODAY()-8)*((YEAR(TODAY()-8)-1900)*12+MONTH(TODAY()-8)))-$X10+1)-(1-(($V10<=TODAY()-8)*$Z10+($V10>TODAY()-8)*((TODAY()-8)=EOMONTH(TODAY()-8,0))*1))))) -> 132000 | K10: =IF(OR($C10="",$D10="",$G10="",$F10=""),0,$G10*(($W10=1)*($U10>0)*(($V10+(TODAY()-15-$V10)*(TODAY()-15<$V10))>=$U10)*(INT((($V10+(TODAY()-15-$V10)*(TODAY()-15<$V10))-$U10)/7)+1)+($W10=2)*($U10>0)*((($V10<=TODAY()-15)*$Y10+($V10>TODAY()-15)*((YEAR(TODAY()-15)-1900)*12+MONTH(TODAY()-15)))>=$X10)*(((($V10<=TODAY()-15)*$Y10+($V10>TODAY()-15)*((YEAR(TODAY()-15)-1900)*12+MONTH(TODAY()-15)))-$X10+1)-(1-(($V10<=TODAY()-15)*$Z10+($V10>TODAY()-15)*((TODAY()-15)=EOMONTH(TODAY()-15,0))*1))))) -> 128000 | L10: =IF(OR($C10="",$D10="",$G10="",$F10=""),0,$G10*(($W10=1)*($U10>0)*(($V10+(TODAY()-29-$V10)*(TODAY()-29<$V10))>=$U10)*(INT((($V10+(TODAY()-29-$V10)*(TODAY()-29<$V10))-$U10)/7)+1)+($W10=2)*($U10>0)*((($V10<=TODAY()-29)*$Y10+($V10>TODAY()-29)*((YEAR(TODAY()-29)-1900)*12+MONTH(TODAY()-29)))>=$X10)*(((($V10<=TODAY()-29)*$Y10+($V10>TODAY()-29)*((YEAR(TODAY()-29)-1900)*12+MONTH(TODAY()-29)))-$X10+1)-(1-(($V10<=TODAY()-29)*$Z10+($V10>TODAY()-29)*((TODAY()-29)=EOMONTH(TODAY()-29,0))*1))))) -> 120000 | M10: =IF($G10>0,$I10/$G10,0) -> 34 | N10: =IF($C10="","",IF($B10="TANIMSIZ MÜŞTERİ","TANIMSIZ MÜŞTERİ",IF($F10="","MODEL SEÇİN",IF(OR($D10="",$G10<=0),"EKSİK",IF(AND($E10<>"",$E10<$D10),"TARİH HATASI",IF($H10="Pasif","KAPALI DÖNEM","UYGUN")))))) -> UYGUN | O10: =IF(OR($C10="",$D10="",$F10=""),"",IF($F10="Aylık",EOMONTH($D10,0),($D10+MOD(SISTEM!$F$8-WEEKDAY($D10,2),7)))) -> 46025 | S10: =IF($B10="","",$B10&"|"&COUNTIFS($B$7:$B10,$B10)) -> M001|1 | T10: =IF($C10="","",UPPER(SUBSTITUTE(SUBSTITUTE(SUBSTITUTE(SUBSTITUTE(SUBSTITUTE(SUBSTITUTE(SUBSTITUTE(SUBSTITUTE(SUBSTITUTE(SUBSTITUTE(SUBSTITUTE(SUBSTITUTE(SUBSTITUTE(SUBSTITUTE(SUBSTITUTE(SUBSTITUTE(SUBSTITUTE(SUBSTITUTE(TRIM($C10),"'",""),"İ","I"),"ı","I"),"i","I"),"Ş","S"),"ş","S"),"Ğ","G"),"ğ","G"),"Ü","U"),"ü","U"),"Ö","O"),"ö","O"),"Ç","C"),"ç","C"),".",""),",","")," ",""),"-",""))) -> ANKARAHAVANALTDSTI | U10: =IF($O10="",0,$O10) -> 46025 | V10: =IF($E10="",2958465,$E10) -> 2958465 | W10: =IF($F10="Haftalık",1,IF($F10="Aylık",2,0)) -> 1 | X10: =IF($U10=0,0,(YEAR($U10)-1900)*12+MONTH($U10)) -> 1513 | Y10: =(YEAR($V10)-1900)*12+MONTH($V10) -> 97200 | Z10: =IF($V10=EOMONTH($V10,0),1,0) -> 1
