Workbook

Sheet PANO
A1: BANKALAR BANA TOPLAM NE KADAR KREDİ VERİR?
A3: Limit Boşluk ve Kredi Kapasitesi Karar Sistemi • v1.0 • Amaç: kredi başvurusundan önce gerçek kullanılabilir limit, yeni tahsis potansiyeli ve kritik riskleri görmek.
A4: ☰ MENÜ / PANO | D4: Sarı = veri girişi • Beyaz = otomatik hesap • Kırmızı = işlem öncesi düzelt
A6: 1 | YÖNETİCİ ÖZETİ
B7: TOPLAM ONAYLI LİMİT | G7: TOPLAM KULLANILAN RİSK | L7: HEMEN KULLANILABİLİR BOŞLUK
B8: =SUM(LIMITLER!H8:H207) -> 0 | G8: =SUM(LIMITLER!I8:I207) -> 0 | L8: =SUM(LIMITLER!M8:M207) -> 0
B11: MODEL YENİ TAHSİS POTANSİYELİ | G11: TOPLAM FİNANSMAN GÖRÜNÜRLÜĞÜ | L11: KRİTİK UYARI SAYISI
B12: =KREDI_KAPASITE!F26 -> 0 | G12: =KREDI_KAPASITE!F28 -> 0 | L12: =COUNTIF(SISTEM!F8:F36,"KALDI") -> 0
A17: 2 | BANKA YOĞUNLAŞMASI VE LİMİT KALİTESİ
B19: En Büyük Banka Payı | G19: Limit Kullanım Oranı | L19: Teminat Bağımlılığı
B20: =IFERROR(MAX(BANKA_OZET!I8:I57),0) -> 0 | G20: =IFERROR(SUM(LIMITLER!I8:I207)/SUM(LIMITLER!H8:H207),0) -> 0 | L20: =IFERROR(SUM(TEMINATLAR!J8:J107)/SUM(LIMITLER!H8:H207),0) -> 0
A25: 3 | HIZLI KARAR
B27: =IF(COUNTIF(SISTEM!F8:F36,"KALDI")>0,"VERİ/KONTROL EKSİĞİ VAR. SİSTEM sayfasındaki KALDI satırlarını düzeltin.",IF(KREDI_KAPASITE!F26<=0,"Yeni tahsis potansiyeli görünmüyor. Önce borçluluk veya borç servis kapasitesini iyileştirin.","Başvuruya hazırlık uygun. Mevcut onaylı boşluğu ve yeni tahsis potansiyelini ayrı yönetin.")) -> 0
A33: 4 | ANA MODÜLLER
B35: FİRMA VERİLERİ | G35: LİMİT & RİSK GİRİŞİ | L35: LİMİT BOŞLUK
B39: KREDİ KAPASİTE | G39: RİSK KONTROL | L39: YÖNETİCİ RAPORU

Sheet KULLANIM_REHBERI
A1: KULLANIM REHBERİ
A3: Dosyayı 5 dakikada kullanıma alın. Formül hücrelerine dokunmayın; sarı alanları doldurun.
A4: ☰ MENÜ / PANO | D4: Sarı = veri girişi • Beyaz = otomatik hesap • Kırmızı = işlem öncesi düzelt
A6: 3 ADIMDA SONUÇ
B8: Adım | C8: Ekran | D8: Ne yapacaksınız? | E8: Bittiğinde ne görmelisiniz?
B9: 1 | C9: FIRMA | D9: Son 12 ay net satış, FAVÖK, özkaynak, finansal borç, nakit ve yıllık borç servisini sarı alanlara girin. | E9: Kritik firma alanları boş değil.
B10: 2 | C10: LIMITLER | D10: Her bankadaki ürün bazlı tahsis edilmiş limit, kullanılan risk, bloke ve vade bilgisini girin. | E10: Kullanım+bloke hiçbir satırda limitten büyük değil.
B11: 3 | C11: SONUÇ | D11: PANO, LIMIT_BOSLUK ve KREDI_KAPASITE sayfalarını okuyun. Kırmızı uyarı varsa SISTEM'i düzeltin. | E11: SISTEM kritik kontroller = GEÇTİ.
A14: RENK SÖZLÜĞÜ
B16: Sarı | C16: Kullanıcı veri girişi
B17: Mavi yazı | C17: Değiştirilebilir hardcode
B18: Beyaz | C18: Formül / otomatik hesap
B19: Yeşil | C19: Uygun / kapasite / boşluk
B20: Turuncu | C20: İzlenmeli
B21: Kırmızı | C21: Kritik hata / kapasite engeli
A24: ÖNEMLİ SINIR
B26: Bu sistem bankanın kesin kredi kararını tahmin etmez. Banka kararı; mali analiz, grup riski, sektör, ödeme davranışı, teminat, politika ve istihbarata göre değişir. Sistem mevcut onaylı kullanılabilir limiti ve ihtiyatlı yeni tahsis potansiyelini ayrı gösterir.

Sheet FIRMA
A1: FİRMA / MALİ GÖRÜNÜM
A3: Kredi kapasitesi modelinin finansal girdileri. Tutarlar TL. Son 12 ay / güncel bilanço kullanın.
A4: ☰ MENÜ / PANO | D4: Sarı = veri girişi • Beyaz = otomatik hesap • Kırmızı = işlem öncesi düzelt
A6: A | TEMEL FİRMA BİLGİLERİ
B8: Firma Unvanı | C8: TEST SANAYİ A.Ş.
B9: Vergi No / İç Kod | C9: TEST-001
B10: Sektör | C10: İmalat
B11: Çalışan Sayısı | C11: 85
B12: Rapor Tarihi | C12: 24.08.2026
A15: B | FİNANSAL GİRDİLER
B17: Son 12 Ay Net Satış | C17: 120000000
B18: Son 12 Ay FAVÖK | C18: 18000000
B19: Özkaynak | C19: 25000000
B20: Toplam Finansal Borç | C20: 22000000
B21: Nakit ve Benzeri | C21: 5000000
B22: Yıllık Faaliyet Nakit Akışı | C22: 15000000
B23: Yıllık Anapara + Faiz Servisi | C23: 10000000
B24: Dönen Varlıklar | C24: 45000000
B25: Kısa Vadeli Yükümlülükler | C25: 30000000
A28: C | OTOMATİK MALİ ORANLAR
B30: FAVÖK Marjı | C30: =IFERROR(C18/C17,0) -> 0
B31: Net Borç | C31: =MAX(0,C20-C21) -> 0
B32: Net Borç / FAVÖK | C32: =IFERROR(C31/C18,0) -> 0
B33: Borç Servis Karşılama (DSCR) | C33: =IFERROR(C22/C23,0) -> 0
B34: Cari Oran | C34: =IFERROR(C24/C25,0) -> 0
B35: Finansal Borç / Özkaynak | C35: =IFERROR(C20/C19,0) -> 0
A38: D | VERİ KAYNAĞI / DOĞRULAMA
B40: Alan | C40: Tercih edilen kaynak | D40: Güncellik | E40: Kontrol
B41: Net satış / FAVÖK | C41: Son 12 ay mizan / yönetim mali tablosu | D41: ≤ 60 gün | E41: Tek seferlik gelirleri ayır
B42: Finansal borç | C42: Banka risk dökümü + muhasebe | D42: Güncel | E42: Leasing/faktoring dahil mi kontrol et
B43: Borç servisi | C43: Önümüzdeki 12 ay taksit planları | D43: Güncel | E43: Anapara + faiz
B44: Nakit akışı | C44: Yönetim nakit akış tablosu | D44: Son 12 ay | E44: Tek seferlik nakitleri ayır

Sheet BANKALAR
A1: BANKA TANIMLARI
A3: Limit ve kullanım kayıtlarında kullanılacak banka kartları. Banka adı tekilleştirilir.
A4: ☰ MENÜ / PANO | D4: Sarı = veri girişi • Beyaz = otomatik hesap • Kırmızı = işlem öncesi düzelt
A6: BANKA KARTLARI
B8: Banka ID | C8: Banka Adı | D8: Ana Çalışma? | E8: İlişki Süresi (Yıl) | F8: İç Risk Notu | G8: Teminat Esnekliği | H8: Son Görüşme | I8: Not
B9: B001 | C9: Akbank | D9: Evet | E9: 8 | F9: A | G9: Orta | H9: 2026-08-10 | I9: TEST
B10: B002 | C10: Türkiye İş Bankası | D10: Evet | E10: 10 | F10: A | G10: Yüksek | H10: 2026-08-05 | I10: TEST
B11: B003 | C11: Garanti BBVA | D11: Hayır | E11: 5 | F11: B | G11: Orta | H11: 2026-07-25 | I11: TEST
B12: B004 | C12: Yapı Kredi | D12: Hayır | E12: 4 | F12: B | G12: Orta | H12: 2026-07-20 | I12: TEST
B13: B005 | C13: QNB | D13: Hayır | E13: 3 | F13: B | G13: Düşük | H13: 2026-07-15 | I13: TEST

Sheet LIMITLER
A1: LİMİTLER / RİSK DAĞILIMI
A3: Her tahsis kararını ürün bazında ayrı satıra girin. Aynı üst limit altındaki alt limitleri Ana Limit Grubu ile bağlayın.
A4: ☰ MENÜ / PANO | D4: Sarı = veri girişi • Beyaz = otomatik hesap • Kırmızı = işlem öncesi düzelt
A6: LİMİT KAYITLARI
B7: Kayıt ID | C7: Banka | D7: Ürün | E7: Limit Türü | F7: Ana Limit Grubu | G7: Para Birimi | H7: Kur | I7: Onaylı Limit (TL) | J7: Kullanılan Risk (TL) | K7: Bloke / Rehin (TL) | L7: Vade Sonu | M7: Durum | N7: Kullanılabilir Boşluk | O7: Kullanım % | P7: Hata / Uyarı
B8: L001 | C8: Akbank | D8: Rotatif Kredi | E8: Nakit | F8: AKB_NAKIT | G8: TRY | H8: 1 | I8: 10000000 | J8: 7000000 | K8: 0 | L8: 2027-06-30 | M8: Aktif | N8: =IF(OR(M8<>"Aktif",I8<=0),0,MAX(0,I8-J8-K8)) | O8: =IFERROR(J8/I8,0) | P8: =IF(B8="","",IF(I8<0,"DÜZELT: Onaylı limit negatif olamaz.",IF(J8<0,"DÜZELT: Kullanılan kredi negatif olamaz.",IF(H8<=0,"DÜZELT: Kur sıfır veya negatif olamaz.",IF(J8+K8>I8,"DÜZELT: "&C8&" - "&D8&" kaydında kullanılan risk + bloke ("&TEXT(J8+K8,"#,##0")&" TL), onaylı limiti ("&TEXT(I8,"#,##0")&" TL) aşıyor. Kullanılan Risk ve Bloke/Rehin tutarlarını kontrol edin.",IF(AND(M8="Aktif",L8<TODAY()),"KONTROL ET: "&C8&" - "&D8&" limitinin vadesi "&TEXT(L8,"dd.mm.yyyy")&" tarihinde bitmiş görünüyor. Bankadan güncel vade/durum bilgisini kontrol edip sarı hücreleri güncelleyin.","TAMAM"))))))
B9: L002 | C9: Akbank | D9: Teminat Mektubu | E9: Gayrinakdi | F9: AKB_GN | G9: TRY | H9: 1 | I9: 5000000 | J9: 2500000 | K9: 0 | L9: 2027-03-31 | M9: Aktif | N9: =IF(OR(M9<>"Aktif",I9<=0),0,MAX(0,I9-J9-K9)) | O9: =IFERROR(J9/I9,0) | P9: =IF(B9="","",IF(I9<0,"DÜZELT: Onaylı limit negatif olamaz.",IF(J9<0,"DÜZELT: Kullanılan kredi negatif olamaz.",IF(H9<=0,"DÜZELT: Kur sıfır veya negatif olamaz.",IF(J9+K9>I9,"DÜZELT: "&C9&" - "&D9&" kaydında kullanılan risk + bloke ("&TEXT(J9+K9,"#,##0")&" TL), onaylı limiti ("&TEXT(I9,"#,##0")&" TL) aşıyor. Kullanılan Risk ve Bloke/Rehin tutarlarını kontrol edin.",IF(AND(M9="Aktif",L9<TODAY()),"KONTROL ET: "&C9&" - "&D9&" limitinin vadesi "&TEXT(L9,"dd.mm.yyyy")&" tarihinde bitmiş görünüyor. Bankadan güncel vade/durum bilgisini kontrol edip sarı hücreleri güncelleyin.","TAMAM"))))))
B10: L003 | C10: Türkiye İş Bankası | D10: Taksitli Ticari Kredi | E10: Nakit | F10: ISB_NAKIT | G10: TRY | H10: 1 | I10: 12000000 | J10: 8500000 | K10: 0 | L10: 2028-01-31 | M10: Aktif | N10: =IF(OR(M10<>"Aktif",I10<=0),0,MAX(0,I10-J10-K10)) | O10: =IFERROR(J10/I10,0) | P10: =IF(B10="","",IF(I10<0,"DÜZELT: Onaylı limit negatif olamaz.",IF(J10<0,"DÜZELT: Kullanılan kredi negatif olamaz.",IF(H10<=0,"DÜZELT: Kur sıfır veya negatif olamaz.",IF(J10+K10>I10,"DÜZELT: "&C10&" - "&D10&" kaydında kullanılan risk + bloke ("&TEXT(J10+K10,"#,##0")&" TL), onaylı limiti ("&TEXT(I10,"#,##0")&" TL) aşıyor. Kullanılan Risk ve Bloke/Rehin tutarlarını kontrol edin.",IF(AND(M10="Aktif",L10<TODAY()),"KONTROL ET: "&C10&" - "&D10&" limitinin vadesi "&TEXT(L10,"dd.mm.yyyy")&" tarihinde bitmiş görünüyor. Bankadan güncel vade/durum bilgisini kontrol edip sarı hücreleri güncelleyin.","TAMAM"))))))
B11: L004 | C11: Türkiye İş Bankası | D11: Ticari Kart | E11: Nakit | F11: ISB_KART | G11: TRY | H11: 1 | I11: 2500000 | J11: 900000 | K11: 0 | L11: 2027-01-31 | M11: Aktif | N11: =IF(OR(M11<>"Aktif",I11<=0),0,MAX(0,I11-J11-K11)) | O11: =IFERROR(J11/I11,0) | P11: =IF(B11="","",IF(I11<0,"DÜZELT: Onaylı limit negatif olamaz.",IF(J11<0,"DÜZELT: Kullanılan kredi negatif olamaz.",IF(H11<=0,"DÜZELT: Kur sıfır veya negatif olamaz.",IF(J11+K11>I11,"DÜZELT: "&C11&" - "&D11&" kaydında kullanılan risk + bloke ("&TEXT(J11+K11,"#,##0")&" TL), onaylı limiti ("&TEXT(I11,"#,##0")&" TL) aşıyor. Kullanılan Risk ve Bloke/Rehin tutarlarını kontrol edin.",IF(AND(M11="Aktif",L11<TODAY()),"KONTROL ET: "&C11&" - "&D11&" limitinin vadesi "&TEXT(L11,"dd.mm.yyyy")&" tarihinde bitmiş görünüyor. Bankadan güncel vade/durum bilgisini kontrol edip sarı hücreleri güncelleyin.","TAMAM"))))))
B12: L005 | C12: Garanti BBVA | D12: Rotatif Kredi | E12: Nakit | F12: GAR_NAKIT | G12: TRY | H12: 1 | I12: 8000000 | J12: 6000000 | K12: 0 | L12: 2027-05-31 | M12: Aktif | N12: =IF(OR(M12<>"Aktif",I12<=0),0,MAX(0,I12-J12-K12)) | O12: =IFERROR(J12/I12,0) | P12: =IF(B12="","",IF(I12<0,"DÜZELT: Onaylı limit negatif olamaz.",IF(J12<0,"DÜZELT: Kullanılan kredi negatif olamaz.",IF(H12<=0,"DÜZELT: Kur sıfır veya negatif olamaz.",IF(J12+K12>I12,"DÜZELT: "&C12&" - "&D12&" kaydında kullanılan risk + bloke ("&TEXT(J12+K12,"#,##0")&" TL), onaylı limiti ("&TEXT(I12,"#,##0")&" TL) aşıyor. Kullanılan Risk ve Bloke/Rehin tutarlarını kontrol edin.",IF(AND(M12="Aktif",L12<TODAY()),"KONTROL ET: "&C12&" - "&D12&" limitinin vadesi "&TEXT(L12,"dd.mm.yyyy")&" tarihinde bitmiş görünüyor. Bankadan güncel vade/durum bilgisini kontrol edip sarı hücreleri güncelleyin.","TAMAM"))))))
B13: L006 | C13: Yapı Kredi | D13: KMH | E13: Nakit | F13: YKB_KMH | G13: TRY | H13: 1 | I13: 3500000 | J13: 2700000 | K13: 0 | L13: 2026-12-31 | M13: Aktif | N13: =IF(OR(M13<>"Aktif",I13<=0),0,MAX(0,I13-J13-K13)) | O13: =IFERROR(J13/I13,0) | P13: =IF(B13="","",IF(I13<0,"DÜZELT: Onaylı limit negatif olamaz.",IF(J13<0,"DÜZELT: Kullanılan kredi negatif olamaz.",IF(H13<=0,"DÜZELT: Kur sıfır veya negatif olamaz.",IF(J13+K13>I13,"DÜZELT: "&C13&" - "&D13&" kaydında kullanılan risk + bloke ("&TEXT(J13+K13,"#,##0")&" TL), onaylı limiti ("&TEXT(I13,"#,##0")&" TL) aşıyor. Kullanılan Risk ve Bloke/Rehin tutarlarını kontrol edin.",IF(AND(M13="Aktif",L13<TODAY()),"KONTROL ET: "&C13&" - "&D13&" limitinin vadesi "&TEXT(L13,"dd.mm.yyyy")&" tarihinde bitmiş görünüyor. Bankadan güncel vade/durum bilgisini kontrol edip sarı hücreleri güncelleyin.","TAMAM"))))))
B14: L007 | C14: QNB | D14: Teminat Mektubu | E14: Gayrinakdi | F14: QNB_GN | G14: TRY | H14: 1 | I14: 4000000 | J14: 1000000 | K14: 0 | L14: 2027-09-30 | M14: Aktif | N14: =IF(OR(M14<>"Aktif",I14<=0),0,MAX(0,I14-J14-K14)) | O14: =IFERROR(J14/I14,0) | P14: =IF(B14="","",IF(I14<0,"DÜZELT: Onaylı limit negatif olamaz.",IF(J14<0,"DÜZELT: Kullanılan kredi negatif olamaz.",IF(H14<=0,"DÜZELT: Kur sıfır veya negatif olamaz.",IF(J14+K14>I14,"DÜZELT: "&C14&" - "&D14&" kaydında kullanılan risk + bloke ("&TEXT(J14+K14,"#,##0")&" TL), onaylı limiti ("&TEXT(I14,"#,##0")&" TL) aşıyor. Kullanılan Risk ve Bloke/Rehin tutarlarını kontrol edin.",IF(AND(M14="Aktif",L14<TODAY()),"KONTROL ET: "&C14&" - "&D14&" limitinin vadesi "&TEXT(L14,"dd.mm.yyyy")&" tarihinde bitmiş görünüyor. Bankadan güncel vade/durum bilgisini kontrol edip sarı hücreleri güncelleyin.","TAMAM"))))))
N15: =IF(OR(M15<>"Aktif",I15<=0),0,MAX(0,I15-J15-K15)) | O15: =IFERROR(J15/I15,0) | P15: =IF(B15="","",IF(I15<0,"DÜZELT: Onaylı limit negatif olamaz.",IF(J15<0,"DÜZELT: Kullanılan kredi negatif olamaz.",IF(H15<=0,"DÜZELT: Kur sıfır veya negatif olamaz.",IF(J15+K15>I15,"DÜZELT: "&C15&" - "&D15&" kaydında kullanılan risk + bloke ("&TEXT(J15+K15,"#,##0")&" TL), onaylı limiti ("&TEXT(I15,"#,##0")&" TL) aşıyor. Kullanılan Risk ve Bloke/Rehin tutarlarını kontrol edin.",IF(AND(M15="Aktif",L15<TODAY()),"KONTROL ET: "&C15&" - "&D15&" limitinin vadesi "&TEXT(L15,"dd.mm.yyyy")&" tarihinde bitmiş görünüyor. Bankadan güncel vade/durum bilgisini kontrol edip sarı hücreleri güncelleyin.","TAMAM"))))))
N16: =IF(OR(M16<>"Aktif",I16<=0),0,MAX(0,I16-J16-K16)) | O16: =IFERROR(J16/I16,0) | P16: =IF(B16="","",IF(I16<0,"DÜZELT: Onaylı limit negatif olamaz.",IF(J16<0,"DÜZELT: Kullanılan kredi negatif olamaz.",IF(H16<=0,"DÜZELT: Kur sıfır veya negatif olamaz.",IF(J16+K16>I16,"DÜZELT: "&C16&" - "&D16&" kaydında kullanılan risk + bloke ("&TEXT(J16+K16,"#,##0")&" TL), onaylı limiti ("&TEXT(I16,"#,##0")&" TL) aşıyor. Kullanılan Risk ve Bloke/Rehin tutarlarını kontrol edin.",IF(AND(M16="Aktif",L16<TODAY()),"KONTROL ET: "&C16&" - "&D16&" limitinin vadesi "&TEXT(L16,"dd.mm.yyyy")&" tarihinde bitmiş görünüyor. Bankadan güncel vade/durum bilgisini kontrol edip sarı hücreleri güncelleyin.","TAMAM"))))))
N17: =IF(OR(M17<>"Aktif",I17<=0),0,MAX(0,I17-J17-K17)) | O17: =IFERROR(J17/I17,0) | P17: =IF(B17="","",IF(I17<0,"DÜZELT: Onaylı limit negatif olamaz.",IF(J17<0,"DÜZELT: Kullanılan kredi negatif olamaz.",IF(H17<=0,"DÜZELT: Kur sıfır veya negatif olamaz.",IF(J17+K17>I17,"DÜZELT: "&C17&" - "&D17&" kaydında kullanılan risk + bloke ("&TEXT(J17+K17,"#,##0")&" TL), onaylı limiti ("&TEXT(I17,"#,##0")&" TL) aşıyor. Kullanılan Risk ve Bloke/Rehin tutarlarını kontrol edin.",IF(AND(M17="Aktif",L17<TODAY()),"KONTROL ET: "&C17&" - "&D17&" limitinin vadesi "&TEXT(L17,"dd.mm.yyyy")&" tarihinde bitmiş görünüyor. Bankadan güncel vade/durum bilgisini kontrol edip sarı hücreleri güncelleyin.","TAMAM"))))))
N18: =IF(OR(M18<>"Aktif",I18<=0),0,MAX(0,I18-J18-K18)) | O18: =IFERROR(J18/I18,0) | P18: =IF(B18="","",IF(I18<0,"DÜZELT: Onaylı limit negatif olamaz.",IF(J18<0,"DÜZELT: Kullanılan kredi negatif olamaz.",IF(H18<=0,"DÜZELT: Kur sıfır veya negatif olamaz.",IF(J18+K18>I18,"DÜZELT: "&C18&" - "&D18&" kaydında kullanılan risk + bloke ("&TEXT(J18+K18,"#,##0")&" TL), onaylı limiti ("&TEXT(I18,"#,##0")&" TL) aşıyor. Kullanılan Risk ve Bloke/Rehin tutarlarını kontrol edin.",IF(AND(M18="Aktif",L18<TODAY()),"KONTROL ET: "&C18&" - "&D18&" limitinin vadesi "&TEXT(L18,"dd.mm.yyyy")&" tarihinde bitmiş görünüyor. Bankadan güncel vade/durum bilgisini kontrol edip sarı hücreleri güncelleyin.","TAMAM"))))))
N19: =IF(OR(M19<>"Aktif",I19<=0),0,MAX(0,I19-J19-K19)) | O19: =IFERROR(J19/I19,0) | P19: =IF(B19="","",IF(I19<0,"DÜZELT: Onaylı limit negatif olamaz.",IF(J19<0,"DÜZELT: Kullanılan kredi negatif olamaz.",IF(H19<=0,"DÜZELT: Kur sıfır veya negatif olamaz.",IF(J19+K19>I19,"DÜZELT: "&C19&" - "&D19&" kaydında kullanılan risk + bloke ("&TEXT(J19+K19,"#,##0")&" TL), onaylı limiti ("&TEXT(I19,"#,##0")&" TL) aşıyor. Kullanılan Risk ve Bloke/Rehin tutarlarını kontrol edin.",IF(AND(M19="Aktif",L19<TODAY()),"KONTROL ET: "&C19&" - "&D19&" limitinin vadesi "&TEXT(L19,"dd.mm.yyyy")&" tarihinde bitmiş görünüyor. Bankadan güncel vade/durum bilgisini kontrol edip sarı hücreleri güncelleyin.","TAMAM"))))))
N20: =IF(OR(M20<>"Aktif",I20<=0),0,MAX(0,I20-J20-K20)) | O20: =IFERROR(J20/I20,0) | P20: =IF(B20="","",IF(I20<0,"DÜZELT: Onaylı limit negatif olamaz.",IF(J20<0,"DÜZELT: Kullanılan kredi negatif olamaz.",IF(H20<=0,"DÜZELT: Kur sıfır veya negatif olamaz.",IF(J20+K20>I20,"DÜZELT: "&C20&" - "&D20&" kaydında kullanılan risk + bloke ("&TEXT(J20+K20,"#,##0")&" TL), onaylı limiti ("&TEXT(I20,"#,##0")&" TL) aşıyor. Kullanılan Risk ve Bloke/Rehin tutarlarını kontrol edin.",IF(AND(M20="Aktif",L20<TODAY()),"KONTROL ET: "&C20&" - "&D20&" limitinin vadesi "&TEXT(L20,"dd.mm.yyyy")&" tarihinde bitmiş görünüyor. Bankadan güncel vade/durum bilgisini kontrol edip sarı hücreleri güncelleyin.","TAMAM"))))))
N21: =IF(OR(M21<>"Aktif",I21<=0),0,MAX(0,I21-J21-K21)) | O21: =IFERROR(J21/I21,0) | P21: =IF(B21="","",IF(I21<0,"DÜZELT: Onaylı limit negatif olamaz.",IF(J21<0,"DÜZELT: Kullanılan kredi negatif olamaz.",IF(H21<=0,"DÜZELT: Kur sıfır veya negatif olamaz.",IF(J21+K21>I21,"DÜZELT: "&C21&" - "&D21&" kaydında kullanılan risk + bloke ("&TEXT(J21+K21,"#,##0")&" TL), onaylı limiti ("&TEXT(I21,"#,##0")&" TL) aşıyor. Kullanılan Risk ve Bloke/Rehin tutarlarını kontrol edin.",IF(AND(M21="Aktif",L21<TODAY()),"KONTROL ET: "&C21&" - "&D21&" limitinin vadesi "&TEXT(L21,"dd.mm.yyyy")&" tarihinde bitmiş görünüyor. Bankadan güncel vade/durum bilgisini kontrol edip sarı hücreleri güncelleyin.","TAMAM"))))))
N22: =IF(OR(M22<>"Aktif",I22<=0),0,MAX(0,I22-J22-K22)) | O22: =IFERROR(J22/I22,0) | P22: =IF(B22="","",IF(I22<0,"DÜZELT: Onaylı limit negatif olamaz.",IF(J22<0,"DÜZELT: Kullanılan kredi negatif olamaz.",IF(H22<=0,"DÜZELT: Kur sıfır veya negatif olamaz.",IF(J22+K22>I22,"DÜZELT: "&C22&" - "&D22&" kaydında kullanılan risk + bloke ("&TEXT(J22+K22,"#,##0")&" TL), onaylı limiti ("&TEXT(I22,"#,##0")&" TL) aşıyor. Kullanılan Risk ve Bloke/Rehin tutarlarını kontrol edin.",IF(AND(M22="Aktif",L22<TODAY()),"KONTROL ET: "&C22&" - "&D22&" limitinin vadesi "&TEXT(L22,"dd.mm.yyyy")&" tarihinde bitmiş görünüyor. Bankadan güncel vade/durum bilgisini kontrol edip sarı hücreleri güncelleyin.","TAMAM"))))))
N23: =IF(OR(M23<>"Aktif",I23<=0),0,MAX(0,I23-J23-K23)) | O23: =IFERROR(J23/I23,0) | P23: =IF(B23="","",IF(I23<0,"DÜZELT: Onaylı limit negatif olamaz.",IF(J23<0,"DÜZELT: Kullanılan kredi negatif olamaz.",IF(H23<=0,"DÜZELT: Kur sıfır veya negatif olamaz.",IF(J23+K23>I23,"DÜZELT: "&C23&" - "&D23&" kaydında kullanılan risk + bloke ("&TEXT(J23+K23,"#,##0")&" TL), onaylı limiti ("&TEXT(I23,"#,##0")&" TL) aşıyor. Kullanılan Risk ve Bloke/Rehin tutarlarını kontrol edin.",IF(AND(M23="Aktif",L23<TODAY()),"KONTROL ET: "&C23&" - "&D23&" limitinin vadesi "&TEXT(L23,"dd.mm.yyyy")&" tarihinde bitmiş görünüyor. Bankadan güncel vade/durum bilgisini kontrol edip sarı hücreleri güncelleyin.","TAMAM"))))))
N24: =IF(OR(M24<>"Aktif",I24<=0),0,MAX(0,I24-J24-K24)) | O24: =IFERROR(J24/I24,0) | P24: =IF(B24="","",IF(I24<0,"DÜZELT: Onaylı limit negatif olamaz.",IF(J24<0,"DÜZELT: Kullanılan kredi negatif olamaz.",IF(H24<=0,"DÜZELT: Kur sıfır veya negatif olamaz.",IF(J24+K24>I24,"DÜZELT: "&C24&" - "&D24&" kaydında kullanılan risk + bloke ("&TEXT(J24+K24,"#,##0")&" TL), onaylı limiti ("&TEXT(I24,"#,##0")&" TL) aşıyor. Kullanılan Risk ve Bloke/Rehin tutarlarını kontrol edin.",IF(AND(M24="Aktif",L24<TODAY()),"KONTROL ET: "&C24&" - "&D24&" limitinin vadesi "&TEXT(L24,"dd.mm.yyyy")&" tarihinde bitmiş görünüyor. Bankadan güncel vade/durum bilgisini kontrol edip sarı hücreleri güncelleyin.","TAMAM"))))))
N25: =IF(OR(M25<>"Aktif",I25<=0),0,MAX(0,I25-J25-K25)) | O25: =IFERROR(J25/I25,0) | P25: =IF(B25="","",IF(I25<0,"DÜZELT: Onaylı limit negatif olamaz.",IF(J25<0,"DÜZELT: Kullanılan kredi negatif olamaz.",IF(H25<=0,"DÜZELT: Kur sıfır veya negatif olamaz.",IF(J25+K25>I25,"DÜZELT: "&C25&" - "&D25&" kaydında kullanılan risk + bloke ("&TEXT(J25+K25,"#,##0")&" TL), onaylı limiti ("&TEXT(I25,"#,##0")&" TL) aşıyor. Kullanılan Risk ve Bloke/Rehin tutarlarını kontrol edin.",IF(AND(M25="Aktif",L25<TODAY()),"KONTROL ET: "&C25&" - "&D25&" limitinin vadesi "&TEXT(L25,"dd.mm.yyyy")&" tarihinde bitmiş görünüyor. Bankadan güncel vade/durum bilgisini kontrol edip sarı hücreleri güncelleyin.","TAMAM"))))))
N26: =IF(OR(M26<>"Aktif",I26<=0),0,MAX(0,I26-J26-K26)) | O26: =IFERROR(J26/I26,0) | P26: =IF(B26="","",IF(I26<0,"DÜZELT: Onaylı limit negatif olamaz.",IF(J26<0,"DÜZELT: Kullanılan kredi negatif olamaz.",IF(H26<=0,"DÜZELT: Kur sıfır veya negatif olamaz.",IF(J26+K26>I26,"DÜZELT: "&C26&" - "&D26&" kaydında kullanılan risk + bloke ("&TEXT(J26+K26,"#,##0")&" TL), onaylı limiti ("&TEXT(I26,"#,##0")&" TL) aşıyor. Kullanılan Risk ve Bloke/Rehin tutarlarını kontrol edin.",IF(AND(M26="Aktif",L26<TODAY()),"KONTROL ET: "&C26&" - "&D26&" limitinin vadesi "&TEXT(L26,"dd.mm.yyyy")&" tarihinde bitmiş görünüyor. Bankadan güncel vade/durum bilgisini kontrol edip sarı hücreleri güncelleyin.","TAMAM"))))))
... N207: =IF(OR(M207<>"Aktif",I207<=0),0,MAX(0,I207-J207-K207)) | O207: =IFERROR(J207/I207,0) | P207: =IF(B207="","",IF(I207<0,"DÜZELT: Onaylı limit negatif olamaz.",IF(J207<0,"DÜZELT: Kullanılan kredi negatif olamaz.",IF(H207<=0,"DÜZELT: Kur sıfır veya negatif olamaz.",IF(J207+K207>I207,"DÜZELT: "&C207&" - "&D207&" kaydında kullanılan risk + bloke ("&TEXT(J207+K207,"#,##0")&" TL), onaylı limiti ("&TEXT(I207,"#,##0")&" TL) aşıyor. Kullanılan Risk ve Bloke/Rehin tutarlarını kontrol edin.",IF(AND(M207="Aktif",L207<TODAY()),"KONTROL ET: "&C207&" - "&D207&" limitinin vadesi "&TEXT(L207,"dd.mm.yyyy")&" tarihinde bitmiş görünüyor. Bankadan güncel vade/durum bilgisini kontrol edip sarı hücreleri güncelleyin.","TAMAM"))))))

Sheet KREDI_KULLANIM
A1: KREDİ KULLANIM / BORÇ SERVİSİ
A3: Mevcut kredilerin taksit, vade ve yıllık servis yükünü görün. Kapasite modeli için kontrol katmanı.
A4: ☰ MENÜ / PANO | D4: Sarı = veri girişi • Beyaz = otomatik hesap • Kırmızı = işlem öncesi düzelt
A6: KREDİ KAYITLARI
B7: Kredi ID | C7: Banka | D7: Ürün | E7: Başlangıç Anapara | F7: Güncel Anapara | G7: Aylık Taksit | H7: Yıllık Borç Servisi | I7: Başlangıç | J7: Vade | K7: Faiz Türü | L7: Para Birimi | M7: Kur | N7: Not
B8: K001 | C8: Akbank | D8: Rotatif Kredi | E8: 7000000 | F8: 7000000 | G8: 450000 | H8: 5400000 | I8: 2026-01-15 | J8: 2027-01-15 | K8: Değişken | L8: TRY | M8: 1 | N8: TEST
B9: K002 | C9: Türkiye İş Bankası | D9: Taksitli Ticari Kredi | E9: 10000000 | F9: 8500000 | G9: 410000 | H9: 4920000 | I9: 2025-08-01 | J9: 2028-08-01 | K9: Sabit | L9: TRY | M9: 1 | N9: TEST
B10: K003 | C10: Garanti BBVA | D10: Rotatif Kredi | E10: 6000000 | F10: 6000000 | G10: 350000 | H10: 4200000 | I10: 2026-03-01 | J10: 2027-03-01 | K10: Değişken | L10: TRY | M10: 1 | N10: TEST

Sheet TEMINATLAR
A1: TEMİNAT ENVANTERİ
A3: Aynı teminat birden fazla bankada kullanılıyorsa mükerrerlik uyarısı verir. Tutarlar ihtiyatlı net değer üzerinden izlenir.
A4: ☰ MENÜ / PANO | D4: Sarı = veri girişi • Beyaz = otomatik hesap • Kırmızı = işlem öncesi düzelt
A6: TEMİNAT KAYITLARI
B7: Teminat ID | C7: Tür | D7: Banka | E7: Açıklama | F7: Brüt Değer | G7: Haircut % | H7: Net Değer | I7: Rehin/Tahsis Tutarı | J7: Serbest Değer | K7: Son Değerleme | L7: Durum | M7: Uyarı
B8: T001 | C8: Gayrimenkul | D8: Akbank | E8: Fabrika Binası | F8: 30000000 | G8: 0.3 | H8: =IFERROR(F8*(1-G8),0) -> 0 | I8: 12000000 | J8: =MAX(0,H8-I8) -> 0 | K8: 2026-06-30 | L8: Aktif | M8: =IF(B8="","",IF(COUNTIF($B$8:$B$107,B8)>1,"UYARI: Teminat ID mükerrer",IF(I8>H8,"KRİTİK: Tahsis net değeri aşıyor","OK"))) -> 0
B9: T002 | C9: Nakit Bloke | D9: Türkiye İş Bankası | E9: Vadeli Mevduat | F9: 2500000 | G9: 0 | H9: =IFERROR(F9*(1-G9),0) -> 0 | I9: 2500000 | J9: =MAX(0,H9-I9) -> 0 | K9: 2026-08-01 | L9: Aktif | M9: =IF(B9="","",IF(COUNTIF($B$8:$B$107,B9)>1,"UYARI: Teminat ID mükerrer",IF(I9>H9,"KRİTİK: Tahsis net değeri aşıyor","OK"))) -> 0
B10: T003 | C10: Makine | D10: Garanti BBVA | E10: Üretim Hattı | F10: 10000000 | G10: 0.5 | H10: =IFERROR(F10*(1-G10),0) -> 0 | I10: 4000000 | J10: =MAX(0,H10-I10) -> 0 | K10: 2026-05-15 | L10: Aktif | M10: =IF(B10="","",IF(COUNTIF($B$8:$B$107,B10)>1,"UYARI: Teminat ID mükerrer",IF(I10>H10,"KRİTİK: Tahsis net değeri aşıyor","OK"))) -> 0
H11: =IFERROR(F11*(1-G11),0) -> 0 | J11: =MAX(0,H11-I11) -> 0 | M11: =IF(B11="","",IF(COUNTIF($B$8:$B$107,B11)>1,"UYARI: Teminat ID mükerrer",IF(I11>H11,"KRİTİK: Tahsis net değeri aşıyor","OK"))) -> 0
H12: =IFERROR(F12*(1-G12),0) -> 0 | J12: =MAX(0,H12-I12) -> 0 | M12: =IF(B12="","",IF(COUNTIF($B$8:$B$107,B12)>1,"UYARI: Teminat ID mükerrer",IF(I12>H12,"KRİTİK: Tahsis net değeri aşıyor","OK"))) -> 0
H13: =IFERROR(F13*(1-G13),0) -> 0 | J13: =MAX(0,H13-I13) -> 0 | M13: =IF(B13="","",IF(COUNTIF($B$8:$B$107,B13)>1,"UYARI: Teminat ID mükerrer",IF(I13>H13,"KRİTİK: Tahsis net değeri aşıyor","OK"))) -> 0
H14: =IFERROR(F14*(1-G14),0) -> 0 | J14: =MAX(0,H14-I14) -> 0 | M14: =IF(B14="","",IF(COUNTIF($B$8:$B$107,B14)>1,"UYARI: Teminat ID mükerrer",IF(I14>H14,"KRİTİK: Tahsis net değeri aşıyor","OK"))) -> 0
H15: =IFERROR(F15*(1-G15),0) -> 0 | J15: =MAX(0,H15-I15) -> 0 | M15: =IF(B15="","",IF(COUNTIF($B$8:$B$107,B15)>1,"UYARI: Teminat ID mükerrer",IF(I15>H15,"KRİTİK: Tahsis net değeri aşıyor","OK"))) -> 0
H16: =IFERROR(F16*(1-G16),0) -> 0 | J16: =MAX(0,H16-I16) -> 0 | M16: =IF(B16="","",IF(COUNTIF($B$8:$B$107,B16)>1,"UYARI: Teminat ID mükerrer",IF(I16>H16,"KRİTİK: Tahsis net değeri aşıyor","OK"))) -> 0
H17: =IFERROR(F17*(1-G17),0) -> 0 | J17: =MAX(0,H17-I17) -> 0 | M17: =IF(B17="","",IF(COUNTIF($B$8:$B$107,B17)>1,"UYARI: Teminat ID mükerrer",IF(I17>H17,"KRİTİK: Tahsis net değeri aşıyor","OK"))) -> 0
H18: =IFERROR(F18*(1-G18),0) -> 0 | J18: =MAX(0,H18-I18) -> 0 | M18: =IF(B18="","",IF(COUNTIF($B$8:$B$107,B18)>1,"UYARI: Teminat ID mükerrer",IF(I18>H18,"KRİTİK: Tahsis net değeri aşıyor","OK"))) -> 0
H19: =IFERROR(F19*(1-G19),0) -> 0 | J19: =MAX(0,H19-I19) -> 0 | M19: =IF(B19="","",IF(COUNTIF($B$8:$B$107,B19)>1,"UYARI: Teminat ID mükerrer",IF(I19>H19,"KRİTİK: Tahsis net değeri aşıyor","OK"))) -> 0
H20: =IFERROR(F20*(1-G20),0) -> 0 | J20: =MAX(0,H20-I20) -> 0 | M20: =IF(B20="","",IF(COUNTIF($B$8:$B$107,B20)>1,"UYARI: Teminat ID mükerrer",IF(I20>H20,"KRİTİK: Tahsis net değeri aşıyor","OK"))) -> 0
H21: =IFERROR(F21*(1-G21),0) -> 0 | J21: =MAX(0,H21-I21) -> 0 | M21: =IF(B21="","",IF(COUNTIF($B$8:$B$107,B21)>1,"UYARI: Teminat ID mükerrer",IF(I21>H21,"KRİTİK: Tahsis net değeri aşıyor","OK"))) -> 0
H22: =IFERROR(F22*(1-G22),0) -> 0 | J22: =MAX(0,H22-I22) -> 0 | M22: =IF(B22="","",IF(COUNTIF($B$8:$B$107,B22)>1,"UYARI: Teminat ID mükerrer",IF(I22>H22,"KRİTİK: Tahsis net değeri aşıyor","OK"))) -> 0
... H107: =IFERROR(F107*(1-G107),0) -> 0 | J107: =MAX(0,H107-I107) -> 0 | M107: =IF(B107="","",IF(COUNTIF($B$8:$B$107,B107)>1,"UYARI: Teminat ID mükerrer",IF(I107>H107,"KRİTİK: Tahsis net değeri aşıyor","OK"))) -> 0

Sheet BANKA_OZET
A1: BANKA BAZLI ÖZET
A3: Banka başına limit, kullanım, boşluk, kullanım oranı ve yoğunlaşma. Otomatik hesap.
A4: ☰ MENÜ / PANO | D4: Sarı = veri girişi • Beyaz = otomatik hesap • Kırmızı = işlem öncesi düzelt
A6: BANKA ÖZETİ
B7: Banka | C7: Nakit Limit | D7: Gayrinakdi Limit | E7: Toplam Limit | F7: Kullanılan Risk | G7: Bloke | H7: Kullanılabilir Boşluk | I7: Toplam İçindeki Pay | J7: Kullanım % | K7: Aktif Limit Adedi | L7: Vadesi Geçmiş | M7: Durum
B8: =IF(BANKALAR!C9="","",BANKALAR!C9) -> 0 | C8: =IF(B8="",0,SUMIFS(LIMITLER!$H$8:$H$207,LIMITLER!$C$8:$C$207,B8,LIMITLER!$E$8:$E$207,"Nakit")) -> 0 | D8: =IF(B8="",0,SUMIFS(LIMITLER!$H$8:$H$207,LIMITLER!$C$8:$C$207,B8,LIMITLER!$E$8:$E$207,"Gayrinakdi")) -> 0 | E8: =IF(B8="",0,SUMIFS(LIMITLER!$H$8:$H$207,LIMITLER!$C$8:$C$207,B8)) -> 0 | F8: =IF(B8="",0,SUMIFS(LIMITLER!$I$8:$I$207,LIMITLER!$C$8:$C$207,B8)) -> 0 | G8: =IF(B8="",0,SUMIFS(LIMITLER!$J$8:$J$207,LIMITLER!$C$8:$C$207,B8)) -> 0 | H8: =IF(B8="",0,SUMIFS(LIMITLER!$M$8:$M$207,LIMITLER!$C$8:$C$207,B8)) -> 0 | I8: =IFERROR(E8/SUM($E$8:$E$57),0) -> 0 | J8: =IFERROR(F8/E8,0) -> 0 | K8: =COUNTIFS(LIMITLER!$C$8:$C$207,B8,LIMITLER!$L$8:$L$207,"Aktif") -> 0 | L8: =COUNTIFS(LIMITLER!$C$8:$C$207,B8,LIMITLER!$L$8:$L$207,"Aktif",LIMITLER!$K$8:$K$207,"<"&TODAY()) -> 0 | M8: =IF(B8="","",IF(L8>0,"VADE UYARISI",IF(J8>0.9,"ÇOK DOLU",IF(J8>0.75,"YÜKSEK KULLANIM","UYGUN")))) -> 0
B9: =IF(BANKALAR!C10="","",BANKALAR!C10) -> 0 | C9: =IF(B9="",0,SUMIFS(LIMITLER!$H$8:$H$207,LIMITLER!$C$8:$C$207,B9,LIMITLER!$E$8:$E$207,"Nakit")) -> 0 | D9: =IF(B9="",0,SUMIFS(LIMITLER!$H$8:$H$207,LIMITLER!$C$8:$C$207,B9,LIMITLER!$E$8:$E$207,"Gayrinakdi")) -> 0 | E9: =IF(B9="",0,SUMIFS(LIMITLER!$H$8:$H$207,LIMITLER!$C$8:$C$207,B9)) -> 0 | F9: =IF(B9="",0,SUMIFS(LIMITLER!$I$8:$I$207,LIMITLER!$C$8:$C$207,B9)) -> 0 | G9: =IF(B9="",0,SUMIFS(LIMITLER!$J$8:$J$207,LIMITLER!$C$8:$C$207,B9)) -> 0 | H9: =IF(B9="",0,SUMIFS(LIMITLER!$M$8:$M$207,LIMITLER!$C$8:$C$207,B9)) -> 0 | I9: =IFERROR(E9/SUM($E$8:$E$57),0) -> 0 | J9: =IFERROR(F9/E9,0) -> 0 | K9: =COUNTIFS(LIMITLER!$C$8:$C$207,B9,LIMITLER!$L$8:$L$207,"Aktif") -> 0 | L9: =COUNTIFS(LIMITLER!$C$8:$C$207,B9,LIMITLER!$L$8:$L$207,"Aktif",LIMITLER!$K$8:$K$207,"<"&TODAY()) -> 0 | M9: =IF(B9="","",IF(L9>0,"VADE UYARISI",IF(J9>0.9,"ÇOK DOLU",IF(J9>0.75,"YÜKSEK KULLANIM","UYGUN")))) -> 0
B10: =IF(BANKALAR!C11="","",BANKALAR!C11) -> 0 | C10: =IF(B10="",0,SUMIFS(LIMITLER!$H$8:$H$207,LIMITLER!$C$8:$C$207,B10,LIMITLER!$E$8:$E$207,"Nakit")) -> 0 | D10: =IF(B10="",0,SUMIFS(LIMITLER!$H$8:$H$207,LIMITLER!$C$8:$C$207,B10,LIMITLER!$E$8:$E$207,"Gayrinakdi")) -> 0 | E10: =IF(B10="",0,SUMIFS(LIMITLER!$H$8:$H$207,LIMITLER!$C$8:$C$207,B10)) -> 0 | F10: =IF(B10="",0,SUMIFS(LIMITLER!$I$8:$I$207,LIMITLER!$C$8:$C$207,B10)) -> 0 | G10: =IF(B10="",0,SUMIFS(LIMITLER!$J$8:$J$207,LIMITLER!$C$8:$C$207,B10)) -> 0 | H10: =IF(B10="",0,SUMIFS(LIMITLER!$M$8:$M$207,LIMITLER!$C$8:$C$207,B10)) -> 0 | I10: =IFERROR(E10/SUM($E$8:$E$57),0) -> 0 | J10: =IFERROR(F10/E10,0) -> 0 | K10: =COUNTIFS(LIMITLER!$C$8:$C$207,B10,LIMITLER!$L$8:$L$207,"Aktif") -> 0 | L10: =COUNTIFS(LIMITLER!$C$8:$C$207,B10,LIMITLER!$L$8:$L$207,"Aktif",LIMITLER!$K$8:$K$207,"<"&TODAY()) -> 0 | M10: =IF(B10="","",IF(L10>0,"VADE UYARISI",IF(J10>0.9,"ÇOK DOLU",IF(J10>0.75,"YÜKSEK KULLANIM","UYGUN")))) -> 0
B11: =IF(BANKALAR!C12="","",BANKALAR!C12) -> 0 | C11: =IF(B11="",0,SUMIFS(LIMITLER!$H$8:$H$207,LIMITLER!$C$8:$C$207,B11,LIMITLER!$E$8:$E$207,"Nakit")) -> 0 | D11: =IF(B11="",0,SUMIFS(LIMITLER!$H$8:$H$207,LIMITLER!$C$8:$C$207,B11,LIMITLER!$E$8:$E$207,"Gayrinakdi")) -> 0 | E11: =IF(B11="",0,SUMIFS(LIMITLER!$H$8:$H$207,LIMITLER!$C$8:$C$207,B11)) -> 0 | F11: =IF(B11="",0,SUMIFS(LIMITLER!$I$8:$I$207,LIMITLER!$C$8:$C$207,B11)) -> 0 | G11: =IF(B11="",0,SUMIFS(LIMITLER!$J$8:$J$207,LIMITLER!$C$8:$C$207,B11)) -> 0 | H11: =IF(B11="",0,SUMIFS(LIMITLER!$M$8:$M$207,LIMITLER!$C$8:$C$207,B11)) -> 0 | I11: =IFERROR(E11/SUM($E$8:$E$57),0) -> 0 | J11: =IFERROR(F11/E11,0) -> 0 | K11: =COUNTIFS(LIMITLER!$C$8:$C$207,B11,LIMITLER!$L$8:$L$207,"Aktif") -> 0 | L11: =COUNTIFS(LIMITLER!$C$8:$C$207,B11,LIMITLER!$L$8:$L$207,"Aktif",LIMITLER!$K$8:$K$207,"<"&TODAY()) -> 0 | M11: =IF(B11="","",IF(L11>0,"VADE UYARISI",IF(J11>0.9,"ÇOK DOLU",IF(J11>0.75,"YÜKSEK KULLANIM","UYGUN")))) -> 0
B12: =IF(BANKALAR!C13="","",BANKALAR!C13) -> 0 | C12: =IF(B12="",0,SUMIFS(LIMITLER!$H$8:$H$207,LIMITLER!$C$8:$C$207,B12,LIMITLER!$E$8:$E$207,"Nakit")) -> 0 | D12: =IF(B12="",0,SUMIFS(LIMITLER!$H$8:$H$207,LIMITLER!$C$8:$C$207,B12,LIMITLER!$E$8:$E$207,"Gayrinakdi")) -> 0 | E12: =IF(B12="",0,SUMIFS(LIMITLER!$H$8:$H$207,LIMITLER!$C$8:$C$207,B12)) -> 0 | F12: =IF(B12="",0,SUMIFS(LIMITLER!$I$8:$I$207,LIMITLER!$C$8:$C$207,B12)) -> 0 | G12: =IF(B12="",0,SUMIFS(LIMITLER!$J$8:$J$207,LIMITLER!$C$8:$C$207,B12)) -> 0 | H12: =IF(B12="",0,SUMIFS(LIMITLER!$M$8:$M$207,LIMITLER!$C$8:$C$207,B12)) -> 0 | I12: =IFERROR(E12/SUM($E$8:$E$57),0) -> 0 | J12: =IFERROR(F12/E12,0) -> 0 | K12: =COUNTIFS(LIMITLER!$C$8:$C$207,B12,LIMITLER!$L$8:$L$207,"Aktif") -> 0 | L12: =COUNTIFS(LIMITLER!$C$8:$C$207,B12,LIMITLER!$L$8:$L$207,"Aktif",LIMITLER!$K$8:$K$207,"<"&TODAY()) -> 0 | M12: =IF(B12="","",IF(L12>0,"VADE UYARISI",IF(J12>0.9,"ÇOK DOLU",IF(J12>0.75,"YÜKSEK KULLANIM","UYGUN")))) -> 0
B13: =IF(BANKALAR!C14="","",BANKALAR!C14) -> 0 | C13: =IF(B13="",0,SUMIFS(LIMITLER!$H$8:$H$207,LIMITLER!$C$8:$C$207,B13,LIMITLER!$E$8:$E$207,"Nakit")) -> 0 | D13: =IF(B13="",0,SUMIFS(LIMITLER!$H$8:$H$207,LIMITLER!$C$8:$C$207,B13,LIMITLER!$E$8:$E$207,"Gayrinakdi")) -> 0 | E13: =IF(B13="",0,SUMIFS(LIMITLER!$H$8:$H$207,LIMITLER!$C$8:$C$207,B13)) -> 0 | F13: =IF(B13="",0,SUMIFS(LIMITLER!$I$8:$I$207,LIMITLER!$C$8:$C$207,B13)) -> 0 | G13: =IF(B13="",0,SUMIFS(LIMITLER!$J$8:$J$207,LIMITLER!$C$8:$C$207,B13)) -> 0 | H13: =IF(B13="",0,SUMIFS(LIMITLER!$M$8:$M$207,LIMITLER!$C$8:$C$207,B13)) -> 0 | I13: =IFERROR(E13/SUM($E$8:$E$57),0) -> 0 | J13: =IFERROR(F13/E13,0) -> 0 | K13: =COUNTIFS(LIMITLER!$C$8:$C$207,B13,LIMITLER!$L$8:$L$207,"Aktif") -> 0 | L13: =COUNTIFS(LIMITLER!$C$8:$C$207,B13,LIMITLER!$L$8:$L$207,"Aktif",LIMITLER!$K$8:$K$207,"<"&TODAY()) -> 0 | M13: =IF(B13="","",IF(L13>0,"VADE UYARISI",IF(J13>0.9,"ÇOK DOLU",IF(J13>0.75,"YÜKSEK KULLANIM","UYGUN")))) -> 0
B14: =IF(BANKALAR!C15="","",BANKALAR!C15) -> 0 | C14: =IF(B14="",0,SUMIFS(LIMITLER!$H$8:$H$207,LIMITLER!$C$8:$C$207,B14,LIMITLER!$E$8:$E$207,"Nakit")) -> 0 | D14: =IF(B14="",0,SUMIFS(LIMITLER!$H$8:$H$207,LIMITLER!$C$8:$C$207,B14,LIMITLER!$E$8:$E$207,"Gayrinakdi")) -> 0 | E14: =IF(B14="",0,SUMIFS(LIMITLER!$H$8:$H$207,LIMITLER!$C$8:$C$207,B14)) -> 0 | F14: =IF(B14="",0,SUMIFS(LIMITLER!$I$8:$I$207,LIMITLER!$C$8:$C$207,B14)) -> 0 | G14: =IF(B14="",0,SUMIFS(LIMITLER!$J$8:$J$207,LIMITLER!$C$8:$C$207,B14)) -> 0 | H14: =IF(B14="",0,SUMIFS(LIMITLER!$M$8:$M$207,LIMITLER!$C$8:$C$207,B14)) -> 0 | I14: =IFERROR(E14/SUM($E$8:$E$57),0) -> 0 | J14: =IFERROR(F14/E14,0) -> 0 | K14: =COUNTIFS(LIMITLER!$C$8:$C$207,B14,LIMITLER!$L$8:$L$207,"Aktif") -> 0 | L14: =COUNTIFS(LIMITLER!$C$8:$C$207,B14,LIMITLER!$L$8:$L$207,"Aktif",LIMITLER!$K$8:$K$207,"<"&TODAY()) -> 0 | M14: =IF(B14="","",IF(L14>0,"VADE UYARISI",IF(J14>0.9,"ÇOK DOLU",IF(J14>0.75,"YÜKSEK KULLANIM","UYGUN")))) -> 0
B15: =IF(BANKALAR!C16="","",BANKALAR!C16) -> 0 | C15: =IF(B15="",0,SUMIFS(LIMITLER!$H$8:$H$207,LIMITLER!$C$8:$C$207,B15,LIMITLER!$E$8:$E$207,"Nakit")) -> 0 | D15: =IF(B15="",0,SUMIFS(LIMITLER!$H$8:$H$207,LIMITLER!$C$8:$C$207,B15,LIMITLER!$E$8:$E$207,"Gayrinakdi")) -> 0 | E15: =IF(B15="",0,SUMIFS(LIMITLER!$H$8:$H$207,LIMITLER!$C$8:$C$207,B15)) -> 0 | F15: =IF(B15="",0,SUMIFS(LIMITLER!$I$8:$I$207,LIMITLER!$C$8:$C$207,B15)) -> 0 | G15: =IF(B15="",0,SUMIFS(LIMITLER!$J$8:$J$207,LIMITLER!$C$8:$C$207,B15)) -> 0 | H15: =IF(B15="",0,SUMIFS(LIMITLER!$M$8:$M$207,LIMITLER!$C$8:$C$207,B15)) -> 0 | I15: =IFERROR(E15/SUM($E$8:$E$57),0) -> 0 | J15: =IFERROR(F15/E15,0) -> 0 | K15: =COUNTIFS(LIMITLER!$C$8:$C$207,B15,LIMITLER!$L$8:$L$207,"Aktif") -> 0 | L15: =COUNTIFS(LIMITLER!$C$8:$C$207,B15,LIMITLER!$L$8:$L$207,"Aktif",LIMITLER!$K$8:$K$207,"<"&TODAY()) -> 0 | M15: =IF(B15="","",IF(L15>0,"VADE UYARISI",IF(J15>0.9,"ÇOK DOLU",IF(J15>0.75,"YÜKSEK KULLANIM","UYGUN")))) -> 0
B16: =IF(BANKALAR!C17="","",BANKALAR!C17) -> 0 | C16: =IF(B16="",0,SUMIFS(LIMITLER!$H$8:$H$207,LIMITLER!$C$8:$C$207,B16,LIMITLER!$E$8:$E$207,"Nakit")) -> 0 | D16: =IF(B16="",0,SUMIFS(LIMITLER!$H$8:$H$207,LIMITLER!$C$8:$C$207,B16,LIMITLER!$E$8:$E$207,"Gayrinakdi")) -> 0 | E16: =IF(B16="",0,SUMIFS(LIMITLER!$H$8:$H$207,LIMITLER!$C$8:$C$207,B16)) -> 0 | F16: =IF(B16="",0,SUMIFS(LIMITLER!$I$8:$I$207,LIMITLER!$C$8:$C$207,B16)) -> 0 | G16: =IF(B16="",0,SUMIFS(LIMITLER!$J$8:$J$207,LIMITLER!$C$8:$C$207,B16)) -> 0 | H16: =IF(B16="",0,SUMIFS(LIMITLER!$M$8:$M$207,LIMITLER!$C$8:$C$207,B16)) -> 0 | I16: =IFERROR(E16/SUM($E$8:$E$57),0) -> 0 | J16: =IFERROR(F16/E16,0) -> 0 | K16: =COUNTIFS(LIMITLER!$C$8:$C$207,B16,LIMITLER!$L$8:$L$207,"Aktif") -> 0 | L16: =COUNTIFS(LIMITLER!$C$8:$C$207,B16,LIMITLER!$L$8:$L$207,"Aktif",LIMITLER!$K$8:$K$207,"<"&TODAY()) -> 0 | M16: =IF(B16="","",IF(L16>0,"VADE UYARISI",IF(J16>0.9,"ÇOK DOLU",IF(J16>0.75,"YÜKSEK KULLANIM","UYGUN")))) -> 0
B17: =IF(BANKALAR!C18="","",BANKALAR!C18) -> 0 | C17: =IF(B17="",0,SUMIFS(LIMITLER!$H$8:$H$207,LIMITLER!$C$8:$C$207,B17,LIMITLER!$E$8:$E$207,"Nakit")) -> 0 | D17: =IF(B17="",0,SUMIFS(LIMITLER!$H$8:$H$207,LIMITLER!$C$8:$C$207,B17,LIMITLER!$E$8:$E$207,"Gayrinakdi")) -> 0 | E17: =IF(B17="",0,SUMIFS(LIMITLER!$H$8:$H$207,LIMITLER!$C$8:$C$207,B17)) -> 0 | F17: =IF(B17="",0,SUMIFS(LIMITLER!$I$8:$I$207,LIMITLER!$C$8:$C$207,B17)) -> 0 | G17: =IF(B17="",0,SUMIFS(LIMITLER!$J$8:$J$207,LIMITLER!$C$8:$C$207,B17)) -> 0 | H17: =IF(B17="",0,SUMIFS(LIMITLER!$M$8:$M$207,LIMITLER!$C$8:$C$207,B17)) -> 0 | I17: =IFERROR(E17/SUM($E$8:$E$57),0) -> 0 | J17: =IFERROR(F17/E17,0) -> 0 | K17: =COUNTIFS(LIMITLER!$C$8:$C$207,B17,LIMITLER!$L$8:$L$207,"Aktif") -> 0 | L17: =COUNTIFS(LIMITLER!$C$8:$C$207,B17,LIMITLER!$L$8:$L$207,"Aktif",LIMITLER!$K$8:$K$207,"<"&TODAY()) -> 0 | M17: =IF(B17="","",IF(L17>0,"VADE UYARISI",IF(J17>0.9,"ÇOK DOLU",IF(J17>0.75,"YÜKSEK KULLANIM","UYGUN")))) -> 0
B18: =IF(BANKALAR!C19="","",BANKALAR!C19) -> 0 | C18: =IF(B18="",0,SUMIFS(LIMITLER!$H$8:$H$207,LIMITLER!$C$8:$C$207,B18,LIMITLER!$E$8:$E$207,"Nakit")) -> 0 | D18: =IF(B18="",0,SUMIFS(LIMITLER!$H$8:$H$207,LIMITLER!$C$8:$C$207,B18,LIMITLER!$E$8:$E$207,"Gayrinakdi")) -> 0 | E18: =IF(B18="",0,SUMIFS(LIMITLER!$H$8:$H$207,LIMITLER!$C$8:$C$207,B18)) -> 0 | F18: =IF(B18="",0,SUMIFS(LIMITLER!$I$8:$I$207,LIMITLER!$C$8:$C$207,B18)) -> 0 | G18: =IF(B18="",0,SUMIFS(LIMITLER!$J$8:$J$207,LIMITLER!$C$8:$C$207,B18)) -> 0 | H18: =IF(B18="",0,SUMIFS(LIMITLER!$M$8:$M$207,LIMITLER!$C$8:$C$207,B18)) -> 0 | I18: =IFERROR(E18/SUM($E$8:$E$57),0) -> 0 | J18: =IFERROR(F18/E18,0) -> 0 | K18: =COUNTIFS(LIMITLER!$C$8:$C$207,B18,LIMITLER!$L$8:$L$207,"Aktif") -> 0 | L18: =COUNTIFS(LIMITLER!$C$8:$C$207,B18,LIMITLER!$L$8:$L$207,"Aktif",LIMITLER!$K$8:$K$207,"<"&TODAY()) -> 0 | M18: =IF(B18="","",IF(L18>0,"VADE UYARISI",IF(J18>0.9,"ÇOK DOLU",IF(J18>0.75,"YÜKSEK KULLANIM","UYGUN")))) -> 0
B19: =IF(BANKALAR!C20="","",BANKALAR!C20) -> 0 | C19: =IF(B19="",0,SUMIFS(LIMITLER!$H$8:$H$207,LIMITLER!$C$8:$C$207,B19,LIMITLER!$E$8:$E$207,"Nakit")) -> 0 | D19: =IF(B19="",0,SUMIFS(LIMITLER!$H$8:$H$207,LIMITLER!$C$8:$C$207,B19,LIMITLER!$E$8:$E$207,"Gayrinakdi")) -> 0 | E19: =IF(B19="",0,SUMIFS(LIMITLER!$H$8:$H$207,LIMITLER!$C$8:$C$207,B19)) -> 0 | F19: =IF(B19="",0,SUMIFS(LIMITLER!$I$8:$I$207,LIMITLER!$C$8:$C$207,B19)) -> 0 | G19: =IF(B19="",0,SUMIFS(LIMITLER!$J$8:$J$207,LIMITLER!$C$8:$C$207,B19)) -> 0 | H19: =IF(B19="",0,SUMIFS(LIMITLER!$M$8:$M$207,LIMITLER!$C$8:$C$207,B19)) -> 0 | I19: =IFERROR(E19/SUM($E$8:$E$57),0) -> 0 | J19: =IFERROR(F19/E19,0) -> 0 | K19: =COUNTIFS(LIMITLER!$C$8:$C$207,B19,LIMITLER!$L$8:$L$207,"Aktif") -> 0 | L19: =COUNTIFS(LIMITLER!$C$8:$C$207,B19,LIMITLER!$L$8:$L$207,"Aktif",LIMITLER!$K$8:$K$207,"<"&TODAY()) -> 0 | M19: =IF(B19="","",IF(L19>0,"VADE UYARISI",IF(J19>0.9,"ÇOK DOLU",IF(J19>0.75,"YÜKSEK KULLANIM","UYGUN")))) -> 0
... B57: =IF(BANKALAR!C58="","",BANKALAR!C58) -> 0 | C57: =IF(B57="",0,SUMIFS(LIMITLER!$H$8:$H$207,LIMITLER!$C$8:$C$207,B57,LIMITLER!$E$8:$E$207,"Nakit")) -> 0 | D57: =IF(B57="",0,SUMIFS(LIMITLER!$H$8:$H$207,LIMITLER!$C$8:$C$207,B57,LIMITLER!$E$8:$E$207,"Gayrinakdi")) -> 0 | E57: =IF(B57="",0,SUMIFS(LIMITLER!$H$8:$H$207,LIMITLER!$C$8:$C$207,B57)) -> 0 | F57: =IF(B57="",0,SUMIFS(LIMITLER!$I$8:$I$207,LIMITLER!$C$8:$C$207,B57)) -> 0 | G57: =IF(B57="",0,SUMIFS(LIMITLER!$J$8:$J$207,LIMITLER!$C$8:$C$207,B57)) -> 0 | H57: =IF(B57="",0,SUMIFS(LIMITLER!$M$8:$M$207,LIMITLER!$C$8:$C$207,B57)) -> 0 | I57: =IFERROR(E57/SUM($E$8:$E$57),0) -> 0 | J57: =IFERROR(F57/E57,0) -> 0 | K57: =COUNTIFS(LIMITLER!$C$8:$C$207,B57,LIMITLER!$L$8:$L$207,"Aktif") -> 0 | L57: =COUNTIFS(LIMITLER!$C$8:$C$207,B57,LIMITLER!$L$8:$L$207,"Aktif",LIMITLER!$K$8:$K$207,"<"&TODAY()) -> 0 | M57: =IF(B57="","",IF(L57>0,"VADE UYARISI",IF(J57>0.9,"ÇOK DOLU",IF(J57>0.75,"YÜKSEK KULLANIM","UYGUN")))) -> 0

Sheet LIMIT_BOSLUK
A1: LİMİT BOŞLUK / BAŞVURU HARİTASI
A3: Hangi bankada ne kadar boşluk var? Hangi banka dolu? Başvuru sırasını operasyonel olarak görün.
A4: ☰ MENÜ / PANO | D4: Sarı = veri girişi • Beyaz = otomatik hesap • Kırmızı = işlem öncesi düzelt
A6: BANKA BAZLI LİMİT BOŞLUĞU
B7: Banka | C7: Toplam Limit | D7: Kullanılan Risk | E7: Bloke | F7: Brüt Boşluk | G7: Net Kullanılabilir Boşluk | H7: Kullanım % | I7: Yoğunlaşma Payı | J7: Öncelik Puanı | K7: Başvuru Kararı | L7: Açıklama | M7: Kaynak
B8: =BANKA_OZET!B8 -> 0 | C8: =BANKA_OZET!E8 -> 0 | D8: =BANKA_OZET!F8 -> 0 | E8: =BANKA_OZET!G8 -> 0 | F8: =MAX(0,C8-D8) -> 0 | G8: =BANKA_OZET!H8 -> 0 | H8: =BANKA_OZET!J8 -> 0 | I8: =BANKA_OZET!I8 -> 0 | J8: =IF(B8="",0,ROUND((1-H8)*50+(1-I8)*30+IF(BANKA_OZET!M8="UYGUN",20,0),0)) -> 0 | K8: =IF(B8="","",IF(BANKA_OZET!L8>0,"ÖNCE VADEYİ DÜZELT",IF(G8>0,"MEVCUT BOŞLUĞU KULLAN",IF(J8>=60,"YENİ TAHSİS GÖRÜŞ","DÜŞÜK ÖNCELİK")))) -> 0 | L8: =IF(B8="","",IF(G8>0,"Onaylı boşluk var; yeni tahsis talebinden önce mevcut limiti kullan.",IF(H8>0.9,"Limit dolu; tahsis artışı için mali kapasite + teminat hazırlığı gerekli.","İlişki ve limit yapısını teyit et."))) -> 0 | M8: BANKA_OZET!B8:M8
B9: =BANKA_OZET!B9 -> 0 | C9: =BANKA_OZET!E9 -> 0 | D9: =BANKA_OZET!F9 -> 0 | E9: =BANKA_OZET!G9 -> 0 | F9: =MAX(0,C9-D9) -> 0 | G9: =BANKA_OZET!H9 -> 0 | H9: =BANKA_OZET!J9 -> 0 | I9: =BANKA_OZET!I9 -> 0 | J9: =IF(B9="",0,ROUND((1-H9)*50+(1-I9)*30+IF(BANKA_OZET!M9="UYGUN",20,0),0)) -> 0 | K9: =IF(B9="","",IF(BANKA_OZET!L9>0,"ÖNCE VADEYİ DÜZELT",IF(G9>0,"MEVCUT BOŞLUĞU KULLAN",IF(J9>=60,"YENİ TAHSİS GÖRÜŞ","DÜŞÜK ÖNCELİK")))) -> 0 | L9: =IF(B9="","",IF(G9>0,"Onaylı boşluk var; yeni tahsis talebinden önce mevcut limiti kullan.",IF(H9>0.9,"Limit dolu; tahsis artışı için mali kapasite + teminat hazırlığı gerekli.","İlişki ve limit yapısını teyit et."))) -> 0 | M9: BANKA_OZET!B9:M9
B10: =BANKA_OZET!B10 -> 0 | C10: =BANKA_OZET!E10 -> 0 | D10: =BANKA_OZET!F10 -> 0 | E10: =BANKA_OZET!G10 -> 0 | F10: =MAX(0,C10-D10) -> 0 | G10: =BANKA_OZET!H10 -> 0 | H10: =BANKA_OZET!J10 -> 0 | I10: =BANKA_OZET!I10 -> 0 | J10: =IF(B10="",0,ROUND((1-H10)*50+(1-I10)*30+IF(BANKA_OZET!M10="UYGUN",20,0),0)) -> 0 | K10: =IF(B10="","",IF(BANKA_OZET!L10>0,"ÖNCE VADEYİ DÜZELT",IF(G10>0,"MEVCUT BOŞLUĞU KULLAN",IF(J10>=60,"YENİ TAHSİS GÖRÜŞ","DÜŞÜK ÖNCELİK")))) -> 0 | L10: =IF(B10="","",IF(G10>0,"Onaylı boşluk var; yeni tahsis talebinden önce mevcut limiti kullan.",IF(H10>0.9,"Limit dolu; tahsis artışı için mali kapasite + teminat hazırlığı gerekli.","İlişki ve limit yapısını teyit et."))) -> 0 | M10: BANKA_OZET!B10:M10
B11: =BANKA_OZET!B11 -> 0 | C11: =BANKA_OZET!E11 -> 0 | D11: =BANKA_OZET!F11 -> 0 | E11: =BANKA_OZET!G11 -> 0 | F11: =MAX(0,C11-D11) -> 0 | G11: =BANKA_OZET!H11 -> 0 | H11: =BANKA_OZET!J11 -> 0 | I11: =BANKA_OZET!I11 -> 0 | J11: =IF(B11="",0,ROUND((1-H11)*50+(1-I11)*30+IF(BANKA_OZET!M11="UYGUN",20,0),0)) -> 0 | K11: =IF(B11="","",IF(BANKA_OZET!L11>0,"ÖNCE VADEYİ DÜZELT",IF(G11>0,"MEVCUT BOŞLUĞU KULLAN",IF(J11>=60,"YENİ TAHSİS GÖRÜŞ","DÜŞÜK ÖNCELİK")))) -> 0 | L11: =IF(B11="","",IF(G11>0,"Onaylı boşluk var; yeni tahsis talebinden önce mevcut limiti kullan.",IF(H11>0.9,"Limit dolu; tahsis artışı için mali kapasite + teminat hazırlığı gerekli.","İlişki ve limit yapısını teyit et."))) -> 0 | M11: BANKA_OZET!B11:M11
B12: =BANKA_OZET!B12 -> 0 | C12: =BANKA_OZET!E12 -> 0 | D12: =BANKA_OZET!F12 -> 0 | E12: =BANKA_OZET!G12 -> 0 | F12: =MAX(0,C12-D12) -> 0 | G12: =BANKA_OZET!H12 -> 0 | H12: =BANKA_OZET!J12 -> 0 | I12: =BANKA_OZET!I12 -> 0 | J12: =IF(B12="",0,ROUND((1-H12)*50+(1-I12)*30+IF(BANKA_OZET!M12="UYGUN",20,0),0)) -> 0 | K12: =IF(B12="","",IF(BANKA_OZET!L12>0,"ÖNCE VADEYİ DÜZELT",IF(G12>0,"MEVCUT BOŞLUĞU KULLAN",IF(J12>=60,"YENİ TAHSİS GÖRÜŞ","DÜŞÜK ÖNCELİK")))) -> 0 | L12: =IF(B12="","",IF(G12>0,"Onaylı boşluk var; yeni tahsis talebinden önce mevcut limiti kullan.",IF(H12>0.9,"Limit dolu; tahsis artışı için mali kapasite + teminat hazırlığı gerekli.","İlişki ve limit yapısını teyit et."))) -> 0 | M12: BANKA_OZET!B12:M12
B13: =BANKA_OZET!B13 -> 0 | C13: =BANKA_OZET!E13 -> 0 | D13: =BANKA_OZET!F13 -> 0 | E13: =BANKA_OZET!G13 -> 0 | F13: =MAX(0,C13-D13) -> 0 | G13: =BANKA_OZET!H13 -> 0 | H13: =BANKA_OZET!J13 -> 0 | I13: =BANKA_OZET!I13 -> 0 | J13: =IF(B13="",0,ROUND((1-H13)*50+(1-I13)*30+IF(BANKA_OZET!M13="UYGUN",20,0),0)) -> 0 | K13: =IF(B13="","",IF(BANKA_OZET!L13>0,"ÖNCE VADEYİ DÜZELT",IF(G13>0,"MEVCUT BOŞLUĞU KULLAN",IF(J13>=60,"YENİ TAHSİS GÖRÜŞ","DÜŞÜK ÖNCELİK")))) -> 0 | L13: =IF(B13="","",IF(G13>0,"Onaylı boşluk var; yeni tahsis talebinden önce mevcut limiti kullan.",IF(H13>0.9,"Limit dolu; tahsis artışı için mali kapasite + teminat hazırlığı gerekli.","İlişki ve limit yapısını teyit et."))) -> 0 | M13: BANKA_OZET!B13:M13
B14: =BANKA_OZET!B14 -> 0 | C14: =BANKA_OZET!E14 -> 0 | D14: =BANKA_OZET!F14 -> 0 | E14: =BANKA_OZET!G14 -> 0 | F14: =MAX(0,C14-D14) -> 0 | G14: =BANKA_OZET!H14 -> 0 | H14: =BANKA_OZET!J14 -> 0 | I14: =BANKA_OZET!I14 -> 0 | J14: =IF(B14="",0,ROUND((1-H14)*50+(1-I14)*30+IF(BANKA_OZET!M14="UYGUN",20,0),0)) -> 0 | K14: =IF(B14="","",IF(BANKA_OZET!L14>0,"ÖNCE VADEYİ DÜZELT",IF(G14>0,"MEVCUT BOŞLUĞU KULLAN",IF(J14>=60,"YENİ TAHSİS GÖRÜŞ","DÜŞÜK ÖNCELİK")))) -> 0 | L14: =IF(B14="","",IF(G14>0,"Onaylı boşluk var; yeni tahsis talebinden önce mevcut limiti kullan.",IF(H14>0.9,"Limit dolu; tahsis artışı için mali kapasite + teminat hazırlığı gerekli.","İlişki ve limit yapısını teyit et."))) -> 0 | M14: BANKA_OZET!B14:M14
B15: =BANKA_OZET!B15 -> 0 | C15: =BANKA_OZET!E15 -> 0 | D15: =BANKA_OZET!F15 -> 0 | E15: =BANKA_OZET!G15 -> 0 | F15: =MAX(0,C15-D15) -> 0 | G15: =BANKA_OZET!H15 -> 0 | H15: =BANKA_OZET!J15 -> 0 | I15: =BANKA_OZET!I15 -> 0 | J15: =IF(B15="",0,ROUND((1-H15)*50+(1-I15)*30+IF(BANKA_OZET!M15="UYGUN",20,0),0)) -> 0 | K15: =IF(B15="","",IF(BANKA_OZET!L15>0,"ÖNCE VADEYİ DÜZELT",IF(G15>0,"MEVCUT BOŞLUĞU KULLAN",IF(J15>=60,"YENİ TAHSİS GÖRÜŞ","DÜŞÜK ÖNCELİK")))) -> 0 | L15: =IF(B15="","",IF(G15>0,"Onaylı boşluk var; yeni tahsis talebinden önce mevcut limiti kullan.",IF(H15>0.9,"Limit dolu; tahsis artışı için mali kapasite + teminat hazırlığı gerekli.","İlişki ve limit yapısını teyit et."))) -> 0 | M15: BANKA_OZET!B15:M15
B16: =BANKA_OZET!B16 -> 0 | C16: =BANKA_OZET!E16 -> 0 | D16: =BANKA_OZET!F16 -> 0 | E16: =BANKA_OZET!G16 -> 0 | F16: =MAX(0,C16-D16) -> 0 | G16: =BANKA_OZET!H16 -> 0 | H16: =BANKA_OZET!J16 -> 0 | I16: =BANKA_OZET!I16 -> 0 | J16: =IF(B16="",0,ROUND((1-H16)*50+(1-I16)*30+IF(BANKA_OZET!M16="UYGUN",20,0),0)) -> 0 | K16: =IF(B16="","",IF(BANKA_OZET!L16>0,"ÖNCE VADEYİ DÜZELT",IF(G16>0,"MEVCUT BOŞLUĞU KULLAN",IF(J16>=60,"YENİ TAHSİS GÖRÜŞ","DÜŞÜK ÖNCELİK")))) -> 0 | L16: =IF(B16="","",IF(G16>0,"Onaylı boşluk var; yeni tahsis talebinden önce mevcut limiti kullan.",IF(H16>0.9,"Limit dolu; tahsis artışı için mali kapasite + teminat hazırlığı gerekli.","İlişki ve limit yapısını teyit et."))) -> 0 | M16: BANKA_OZET!B16:M16
B17: =BANKA_OZET!B17 -> 0 | C17: =BANKA_OZET!E17 -> 0 | D17: =BANKA_OZET!F17 -> 0 | E17: =BANKA_OZET!G17 -> 0 | F17: =MAX(0,C17-D17) -> 0 | G17: =BANKA_OZET!H17 -> 0 | H17: =BANKA_OZET!J17 -> 0 | I17: =BANKA_OZET!I17 -> 0 | J17: =IF(B17="",0,ROUND((1-H17)*50+(1-I17)*30+IF(BANKA_OZET!M17="UYGUN",20,0),0)) -> 0 | K17: =IF(B17="","",IF(BANKA_OZET!L17>0,"ÖNCE VADEYİ DÜZELT",IF(G17>0,"MEVCUT BOŞLUĞU KULLAN",IF(J17>=60,"YENİ TAHSİS GÖRÜŞ","DÜŞÜK ÖNCELİK")))) -> 0 | L17: =IF(B17="","",IF(G17>0,"Onaylı boşluk var; yeni tahsis talebinden önce mevcut limiti kullan.",IF(H17>0.9,"Limit dolu; tahsis artışı için mali kapasite + teminat hazırlığı gerekli.","İlişki ve limit yapısını teyit et."))) -> 0 | M17: BANKA_OZET!B17:M17
B18: =BANKA_OZET!B18 -> 0 | C18: =BANKA_OZET!E18 -> 0 | D18: =BANKA_OZET!F18 -> 0 | E18: =BANKA_OZET!G18 -> 0 | F18: =MAX(0,C18-D18) -> 0 | G18: =BANKA_OZET!H18 -> 0 | H18: =BANKA_OZET!J18 -> 0 | I18: =BANKA_OZET!I18 -> 0 | J18: =IF(B18="",0,ROUND((1-H18)*50+(1-I18)*30+IF(BANKA_OZET!M18="UYGUN",20,0),0)) -> 0 | K18: =IF(B18="","",IF(BANKA_OZET!L18>0,"ÖNCE VADEYİ DÜZELT",IF(G18>0,"MEVCUT BOŞLUĞU KULLAN",IF(J18>=60,"YENİ TAHSİS GÖRÜŞ","DÜŞÜK ÖNCELİK")))) -> 0 | L18: =IF(B18="","",IF(G18>0,"Onaylı boşluk var; yeni tahsis talebinden önce mevcut limiti kullan.",IF(H18>0.9,"Limit dolu; tahsis artışı için mali kapasite + teminat hazırlığı gerekli.","İlişki ve limit yapısını teyit et."))) -> 0 | M18: BANKA_OZET!B18:M18
B19: =BANKA_OZET!B19 -> 0 | C19: =BANKA_OZET!E19 -> 0 | D19: =BANKA_OZET!F19 -> 0 | E19: =BANKA_OZET!G19 -> 0 | F19: =MAX(0,C19-D19) -> 0 | G19: =BANKA_OZET!H19 -> 0 | H19: =BANKA_OZET!J19 -> 0 | I19: =BANKA_OZET!I19 -> 0 | J19: =IF(B19="",0,ROUND((1-H19)*50+(1-I19)*30+IF(BANKA_OZET!M19="UYGUN",20,0),0)) -> 0 | K19: =IF(B19="","",IF(BANKA_OZET!L19>0,"ÖNCE VADEYİ DÜZELT",IF(G19>0,"MEVCUT BOŞLUĞU KULLAN",IF(J19>=60,"YENİ TAHSİS GÖRÜŞ","DÜŞÜK ÖNCELİK")))) -> 0 | L19: =IF(B19="","",IF(G19>0,"Onaylı boşluk var; yeni tahsis talebinden önce mevcut limiti kullan.",IF(H19>0.9,"Limit dolu; tahsis artışı için mali kapasite + teminat hazırlığı gerekli.","İlişki ve limit yapısını teyit et."))) -> 0 | M19: BANKA_OZET!B19:M19
... B57: =BANKA_OZET!B57 -> 0 | C57: =BANKA_OZET!E57 -> 0 | D57: =BANKA_OZET!F57 -> 0 | E57: =BANKA_OZET!G57 -> 0 | F57: =MAX(0,C57-D57) -> 0 | G57: =BANKA_OZET!H57 -> 0 | H57: =BANKA_OZET!J57 -> 0 | I57: =BANKA_OZET!I57 -> 0 | J57: =IF(B57="",0,ROUND((1-H57)*50+(1-I57)*30+IF(BANKA_OZET!M57="UYGUN",20,0),0)) -> 0 | K57: =IF(B57="","",IF(BANKA_OZET!L57>0,"ÖNCE VADEYİ DÜZELT",IF(G57>0,"MEVCUT BOŞLUĞU KULLAN",IF(J57>=60,"YENİ TAHSİS GÖRÜŞ","DÜŞÜK ÖNCELİK")))) -> 0 | L57: =IF(B57="","",IF(G57>0,"Onaylı boşluk var; yeni tahsis talebinden önce mevcut limiti kullan.",IF(H57>0.9,"Limit dolu; tahsis artışı için mali kapasite + teminat hazırlığı gerekli.","İlişki ve limit yapısını teyit et."))) -> 0 | M57: BANKA_OZET!B57:M57

Sheet SENARYO
A1: SENARYO / KREDİ POLİTİKASI VARSAYIMLARI
A3: Bankalar arasında standart tek kredi formülü yoktur. Bu katsayılar ihtiyatlı yönetim senaryosudur ve kullanıcı tarafından değiştirilebilir.
A4: ☰ MENÜ / PANO | D4: Sarı = veri girişi • Beyaz = otomatik hesap • Kırmızı = işlem öncesi düzelt
A6: MODEL VARSAYIMLARI
B8: Varsayım | C8: Baz | D8: Stres | E8: İyimser | F8: Açıklama
B9: Net Satışa Göre Azami Finansal Borç % | C9: 0.25 | D9: 0.18 | E9: 0.32 | F9: Ciro bazlı kaba üst sınır; banka politikası değildir.
B10: Net Borç / FAVÖK Azami | C10: 3 | D10: 2 | E10: 4 | F10: Borçluluk disiplin sınırı.
B11: Minimum DSCR | C11: 1.25 | D11: 1.5 | E11: 1.1 | F11: Faaliyet nakit akışı / yıllık borç servisi.
B12: Yeni Borç Yıllık Servis Katsayısı | C12: 0.35 | D12: 0.45 | E12: 0.3 | F12: Yeni kredi tutarını yaklaşık yıllık borç servisine çevirir.
B13: Likidite Tamponu | C13: 0.1 | D13: 0.15 | E13: 0.05 | F13: Yeni kapasiteden ayrılan ihtiyat payı.
B14: Banka Yoğunlaşma Üst Sınırı | C14: 0.35 | D14: 0.3 | E14: 0.4 | F14: Tek banka payı yükseldikçe kırılganlık artar.
A17: AKTİF SENARYO
B19: Seçili Senaryo | C19: Baz
B21: =B9 -> 0 | C21: =IF($C$19="Baz",C9,IF($C$19="Stres",D9,E9)) -> 0
B22: =B10 -> 0 | C22: =IF($C$19="Baz",C10,IF($C$19="Stres",D10,E10)) -> 0
B23: =B11 -> 0 | C23: =IF($C$19="Baz",C11,IF($C$19="Stres",D11,E11)) -> 0
B24: =B12 -> 0 | C24: =IF($C$19="Baz",C12,IF($C$19="Stres",D12,E12)) -> 0
B25: =B13 -> 0 | C25: =IF($C$19="Baz",C13,IF($C$19="Stres",D13,E13)) -> 0
B26: =B14 -> 0 | C26: =IF($C$19="Baz",C14,IF($C$19="Stres",D14,E14)) -> 0

Sheet KREDI_KAPASITE
A1: KREDİ KAPASİTESİ / İHTİYATLI MODEL
A3: Yeni tahsis potansiyelini ciro, FAVÖK ve borç servisi olmak üzere üç bağımsız kısıt ile test eder. En düşük sonuç kullanılır.
A4: ☰ MENÜ / PANO | D4: Sarı = veri girişi • Beyaz = otomatik hesap • Kırmızı = işlem öncesi düzelt
A6: KAPASİTE HESABI
B8: Mevcut Toplam Finansal Borç | C8: =FIRMA!C20 -> 0
B9: Mevcut Onaylı Kullanılabilir Boşluk | C9: =SUM(LIMITLER!M8:M207) -> 0
B11: A | Ciro Bazlı Azami Borç | C11: =FIRMA!C17*SENARYO!C21 -> 0
B12: A | Ciro Bazlı Yeni Borç Alanı | C12: =MAX(0,C11-C8) -> 0
B14: B | FAVÖK Bazlı Azami Net Borç | C14: =FIRMA!C18*SENARYO!C22 -> 0
B15: B | FAVÖK Bazlı Yeni Borç Alanı | C15: =MAX(0,C14-MAX(0,FIRMA!C20-FIRMA!C21)) -> 0
B17: C | Nakit Akışı Bazlı Azami Yıllık Borç Servisi | C17: =IFERROR(FIRMA!C22/SENARYO!C23,0) -> 0
B18: C | Ek Yıllık Borç Servisi Alanı | C18: =MAX(0,C17-FIRMA!C23) -> 0
B19: C | Nakit Akışı Bazlı Yeni Borç Alanı | C19: =IFERROR(C18/SENARYO!C24,0) -> 0
A22: SONUÇ
B24: Model Ham Yeni Tahsis Potansiyeli | F24: =MIN(C12,C15,C19) -> 0
B26: İhtiyat Tamponu Sonrası Yeni Tahsis Potansiyeli | F26: =MAX(0,F24*(1-SENARYO!C25)) -> 0
B28: Toplam Finansman Görünürlüğü | F28: =SUM(LIMITLER!M8:M207)+F26 -> 0
A31: MODELİN BAĞLAYICI KISITI
B33: =IF(F24=C12,"CİRO KISITI: Satış hacmine göre borç alanı en düşük.",IF(F24=C15,"FAVÖK KISITI: Borçluluk/FAVÖK sınırı en düşük kapasiteyi veriyor.","NAKİT AKIŞI KISITI: Borç servisi kapasitesi en düşük.")) -> 0

Sheet RISK_KONTROL
A1: RİSK KONTROL / KIRMIZI BAYRAKLAR
A3: Başvuru öncesi veri, vade, yoğunlaşma, limit doluluk ve borç servis risklerini tek ekranda görün.
A4: ☰ MENÜ / PANO | D4: Sarı = veri girişi • Beyaz = otomatik hesap • Kırmızı = işlem öncesi düzelt
A6: RİSK MATRİSİ
B7: Kod | C7: Kontrol | D7: Seviye | E7: Durum | F7: Değer | G7: Aksiyon | H7: Kaynak
B8: R01 | C8: Limit satırlarında kritik hata | D8: Kritik | E8: =IF(COUNTIF(LIMITLER!P8:P207,"KRİTİK*")>0,"KALDI","GEÇTİ") -> 0 | F8: =COUNTIF(LIMITLER!P8:P207,"KRİTİK*") -> 0 | G8: LIMITLER hatalarını düzelt | H8: LIMITLER!P8:P207
B9: R02 | C9: Vadesi geçmiş aktif limit | D9: Yüksek | E9: =IF(COUNTIF(LIMITLER!P8:P207,"*Vade geçmiş*")>0,"KALDI","GEÇTİ") -> 0 | F9: =COUNTIF(LIMITLER!P8:P207,"*Vade geçmiş*") -> 0 | G9: Bankayla yenileme teyidi | H9: LIMITLER!K8:K207
B10: R03 | C10: Tek banka yoğunlaşması | D10: Yüksek | E10: =IF(MAX(BANKA_OZET!I8:I57)>SENARYO!C26,"KALDI","GEÇTİ") -> 0 | F10: =MAX(BANKA_OZET!I8:I57) -> 0 | G10: Yoğunlaşmayı azalt / ikinci banka aç | H10: BANKA_OZET!I8:I57
B11: R04 | C11: Toplam limit kullanım oranı > %90 | D11: Yüksek | E11: =IF(IFERROR(SUM(LIMITLER!I8:I207)/SUM(LIMITLER!H8:H207),0)>0.9,"KALDI","GEÇTİ") -> 0 | F11: =IFERROR(SUM(LIMITLER!I8:I207)/SUM(LIMITLER!H8:H207),0) -> 0 | G11: Yeni tahsis / borç azaltma | H11: LIMITLER!H:I
B12: R05 | C12: DSCR minimum altında | D12: Kritik | E12: =IF(FIRMA!C33<SENARYO!C23,"KALDI","GEÇTİ") -> 0 | F12: =FIRMA!C33 -> 0 | G12: Borç servis yükünü azalt / nakit akışını güçlendir | H12: FIRMA!C33
B13: R06 | C13: Net Borç/FAVÖK limit üstünde | D13: Kritik | E13: =IF(FIRMA!C32>SENARYO!C22,"KALDI","GEÇTİ") -> 0 | F13: =FIRMA!C32 -> 0 | G13: Borç azalt / FAVÖK iyileştir | H13: FIRMA!C32
B14: R07 | C14: Teminat tahsisi net değeri aşıyor | D14: Kritik | E14: =IF(COUNTIF(TEMINATLAR!M8:M107,"KRİTİK*")>0,"KALDI","GEÇTİ") -> 0 | F14: =COUNTIF(TEMINATLAR!M8:M107,"KRİTİK*") -> 0 | G14: Teminat değer/tahsis kaydını düzelt | H14: TEMINATLAR!M8:M107
B15: R08 | C15: Yeni tahsis potansiyeli sıfır | D15: Orta | E15: =IF(KREDI_KAPASITE!F26<=0,"KALDI","GEÇTİ") -> 0 | F15: =KREDI_KAPASITE!F26 -> 0 | G15: Başvuru yerine mali yapı iyileştirme | H15: KREDI_KAPASITE!F26

Sheet RAPOR
A1: YÖNETİCİ RAPORU
A3: Kredi görüşmesine götürülebilecek tek sayfalık yönetici görünümü. Veriler otomatik gelir.
A4: ☰ MENÜ / PANO | D4: Sarı = veri girişi • Beyaz = otomatik hesap • Kırmızı = işlem öncesi düzelt
A6: KREDİ ÖN GÖRÜNÜM
B7: Mevcut Onaylı Limit | G7: Mevcut Kullanım
B8: =SUM(LIMITLER!H8:H207) -> 0 | G8: =SUM(LIMITLER!I8:I207) -> 0
B12: Onaylı Boşluk | G12: Yeni Tahsis Potansiyeli
B13: =SUM(LIMITLER!M8:M207) -> 0 | G13: =KREDI_KAPASITE!F26 -> 0
B17: Toplam Finansman Görünürlüğü | G17: Kritik Risk Sayısı
B18: =KREDI_KAPASITE!F28 -> 0 | G18: =COUNTIF(RISK_KONTROL!E8:E15,"KALDI") -> 0
A23: KREDİ GÖRÜŞMESİ ÖNCESİ NOT
B25: =IF(COUNTIF(RISK_KONTROL!E8:E15,"KALDI")>0,"ÖNCE RISK_KONTROL ekranındaki kırmızı bayrakları kapatın. Bankaya toplam kredi talebi söylemeden önce mevcut boşluğu, bağlayıcı kapasite kısıtını ve teminat durumunu ayrı sunun.","Veri kontrolleri geçti. Mevcut onaylı boşluk ile yeni tahsis talebini birbirinden ayırarak banka bazlı görüşme planı oluşturun.") -> 0

Sheet KURULUM
A1: KURULUM / MAKRO OTOMASYON KATMANI
A3: Bu .xlsx dosyası makrosuz tam çalışır. İsteğe bağlı VBA paketi günlük kullanım sürtünmesini azaltır.
A4: ☰ MENÜ / PANO | D4: Sarı = veri girişi • Beyaz = otomatik hesap • Kırmızı = işlem öncesi düzelt
A6: MAKROSUZ / MAKROLU FARK
B8: Özellik | C8: Makrosuz .xlsx | D8: Makrolu kurulum sonrası
B9: Tüm hesaplamalar | C9: Tam çalışır | D9: Tam çalışır
B10: Sayfa gezinme | C10: Hücre menü bağlantıları | D10: MENÜ butonu / gezinme
B11: Yedek / PDF / yenile | C11: Elle | D11: Tek tık otomasyon
A14: K1–K7 KURULUM
B16: K1 | C16: Dosya > sağ tık > Özellikler > Engellemeyi Kaldır | D16: Office internet dosyası blokajını kaldırır.
B17: K2 | C17: Güvenilir konuma taşı | D17: Her açılışta uyarıyı azaltır.
B18: K3 | C18: Excel sarı bant > İçeriği Etkinleştir | D18: Makroları etkinleştirir.
B19: K4 | C19: Alt+F11 > Dosya > Dosya Al > .bas modülleri | D19: VBA standart modülleri içe aktarılır.
B20: K5 | C20: ThisWorkbook metnini kod penceresine yapıştır | D20: Açılış/kapanış olaylarını kurar.
B21: K6 | C21: Farklı Kaydet > .xlsm | D21: Makroları korur.
B22: K7 | C22: MENÜ / PDF / YEDEK / YENİLE butonlarını test et | D22: Kurulum kabul testi.
A25: GÜVENLİK
B27: VBA paketi internete bağlanmaz, e-posta göndermez, harici API çağırmaz, dosya silmez. Yedekleme yalnızca çalışma kitabının aynı klasöründe kopya üretir. Makro kapalıyken hesap motoru ve sonuç ekranları çalışmaya devam eder.
A33: BUTON HARİTASI
B35: Buton | C35: Sayfa | D35: İşlev
B36: MENÜ | C36: Tüm sayfalar | D36: PANO’ya döner / navigasyon
B37: TAM HESAPLA | C37: PANO | D37: Tam hesap + kontrol yenile
B38: YEDEK AL | C38: PANO | D38: Zaman damgalı kopya
B39: PDF OLARAK KAYDET | C39: RAPOR | D39: Yönetici raporunu PDF yapar
B40: SÜRÜM | C40: KURULUM | D40: Sürüm bilgisini gösterir

Sheet SISTEM
A1: SİSTEM / HATA TEŞHİSİ
A3: Her hata hangi sayfa/hücreden kaynaklanıyor açıkça gösterilir. Kritik kontroller geçmeden sonuç temiz kabul edilmez.
A4: ☰ MENÜ / PANO | D4: Sarı = veri girişi • Beyaz = otomatik hesap • Kırmızı = işlem öncesi düzelt
A6: KONTROL MOTORU
B7: Kod | C7: Önem | D7: Ne kontrol ediliyor? | E7: Doğru olması gereken | F7: Sonuç | G7: Sorun nerede? | H7: Ne bulundu? | I7: Ne yapmalısınız?
B8: S01 | C8: KRİTİK | D8: Net satış rakamı girilmiş mi? | E8: > 0 | F8: =IF(FIRMA!C17>0,"TAMAM","DÜZELT") | G8: FIRMA → Son 12 Ay Net Satış | H8: =IF(FIRMA!C17>0,TEXT(FIRMA!C17,"#,##0")&" TL","Boş") | I8: FIRMA sayfasını açın ve Son 12 Ay Net Satış sarı hücresine gerçek tutarı girin.
B9: S02 | C9: KRİTİK | D9: FAVÖK rakamı girilmiş mi? | E9: > 0 | F9: =IF(FIRMA!C18>0,"TAMAM","DÜZELT") | G9: FIRMA → Son 12 Ay FAVÖK | H9: =IF(FIRMA!C18<>"",TEXT(FIRMA!C18,"#,##0")&" TL","Boş") | I9: FIRMA sayfasını açın ve Son 12 Ay FAVÖK sarı hücresine gerçek tutarı girin.
B10: S03 | C10: KRİTİK | D10: Finansal borç rakamı geçerli mi? | E10: >= 0 | F10: =IF(FIRMA!C20>=0,"TAMAM","DÜZELT") | G10: FIRMA → Toplam Finansal Borç | H10: =TEXT(FIRMA!C20,"#,##0")&" TL" | I10: FIRMA sayfasında Toplam Finansal Borç alanını kontrol edin. Negatif değer girmeyin.
B11: S04 | C11: KRİTİK | D11: 12 aylık borç ödeme yükü girilmiş mi? | E11: > 0 | F11: =IF(FIRMA!C23>0,"TAMAM","DÜZELT") | G11: FIRMA → Yıllık Anapara + Faiz Servisi | H11: =IF(FIRMA!C23>0,TEXT(FIRMA!C23,"#,##0")&" TL","Boş") | I11: FIRMA sayfasında Önümüzdeki 12 Ay Anapara + Faiz Servisi tutarını girin.
B12: S05 | C12: KRİTİK | D12: Limitlerde yanlış veya imkânsız bir rakam var mı? | E12: Kullanılan kredi + bloke, onaylı limiti aşmamalı; negatif tutar olmamalı. | F12: =IF(COUNTIF(LIMITLER!P8:P207,"DÜZELT*")=0,"TAMAM","DÜZELT") | G12: =IFERROR("LIMITLER → Satır "&(MATCH("DÜZELT*",LIMITLER!P8:P207,0)+7)&" → "&INDEX(LIMITLER!C8:C207,MATCH("DÜZELT*",LIMITLER!P8:P207,0))&" / "&INDEX(LIMITLER!D8:D207,MATCH("DÜZELT*",LIMITLER!P8:P207,0)),"Sorun yok") | H12: =IF(F12="TAMAM","Limit kayıtlarında kritik hata bulunmadı.",COUNTIF(LIMITLER!P8:P207,"DÜZELT*")&" kayıt düzeltilmeli. İlk sorun: "&INDEX(LIMITLER!P8:P207,MATCH("DÜZELT*",LIMITLER!P8:P207,0))) | I12: =IF(F12="TAMAM","Bir şey yapmanıza gerek yok.","1) LIMITLER sayfasını açın. 2) Hata / Uyarı alanında kırmızı görünen satırı bulun. 3) Mesajda yazan banka ve kredi kaydındaki sarı hücreleri bankanızdaki güncel rakamlarla karşılaştırıp düzeltin.")
