Workbook
Name LST_MUSTERI_ADI: MUSTERILER!$C$7:$C$106
Name LST_HESAP: HESAPLAR!$B$7:$B$16
Name LST_KATEGORI: SISTEM!$K$8:$K$37
Name CARI_BAKIYE: MUSTERI_360!$J$7:$J$106
Name GECIKMIS_29: MUSTERI_360!$N$7:$N$106
Name NAKIT_POZISYON: HESAPLAR!$K$18
Name SISTEM_SONUC: SISTEM!$F$23:$F$55
Name EKSTRE_BAKIYE: CARI_EKSTRE!$F$9
Name EKSTRE: OFFSET(CARI_EKSTRE!$A$1,0,0,15+COUNT(CARI_EKSTRE!$C$12:$C$311)+4,9)
Name EKSTRE_TABLO: OFFSET(CARI_EKSTRE!$B$11,0,0,1+COUNT(CARI_EKSTRE!$C$12:$C$311),8)

Sheet PANO
A1: KILIÇ MUHASEBE │ YÖNETİM PANOSU
A2: ="Bu ekran karar, alarm ve seçim ekranıdır │ SİSTEM DURUMU: "&IF(COUNTIFS(SISTEM!$C$23:$C$55,"KRİTİK",SISTEM!$F$23:$F$55,"KALDI")>0,"KRİTİK HATA – AY KAPATILAMAZ",IF(COUNTIF(SISTEM!$F$23:$F$55,"KALDI")=0,"KULLANIMA UYGUN","UYARI VAR – İNCELEYİN"))&" │ "&COUNTIF(SISTEM!$F$23:$F$55,"GEÇTİ")&" / "&COUNTIF(SISTEM!$F$23:$F$55,"<>BİLGİ")&" kontrol geçti"
B4: =TEXT(TODAY(),"dd.mm.yyyy")&" │ "&SISTEM!$C$7
B5: MENÜ | D5: AKTİF MÜŞTERİ | G5: TOPLAM CARİ ALACAK | J5: 29+ GÜN GECİKMİŞ | M5: KASA + BANKA
B6: =HYPERLINK("#PANO!A1"," PANO") | D6: =COUNTIF(MUSTERILER!$D$7:$D$106,"Aktif") | G6: =SUM(MUSTERI_360!$J$7:$J$106) | J6: =SUM(MUSTERI_360!$N$7:$N$106) | M6: =HESAPLAR!$K$18
B7: =HYPERLINK("#MUSTERILER!A1"," Müşteriler") | D7: =COUNTA(MUSTERILER!$B$7:$B$106)&" kayıtlı müşteri" | G7: =COUNTIF(MUSTERI_360!$J$7:$J$106,">0")&" müşteride açık bakiye" | J7: =TEXT(IFERROR(SUM(MUSTERI_360!$N$7:$N$106)/SUM(MUSTERI_360!$J$7:$J$106),0),"0,0%")&" toplam alacağın payı" | M7: =COUNTIF(HESAPLAR!$D$7:$D$16,"Aktif")&" aktif hesap"
B8: =HYPERLINK("#UCRETLER!A1"," Haftalık Ücretler")
B9: =HYPERLINK("#TAHSILAT!A1"," Tahsilat") | D9: BU AY NAKİT KÂR | G9: BU AY TAHSİLAT | J9: HAFTALIK TAHAKKUK | M9: GECİKMİŞ İŞ
B10: =HYPERLINK("#GELIR_GIDER!A1"," Gelir / Gider") | D10: =SUMIFS(AY_SONU!$I$7:$I$42,AY_SONU!$B$7:$B$42,">="&EOMONTH(TODAY(),-1)+1,AY_SONU!$B$7:$B$42,"<="&EOMONTH(TODAY(),0)) | G10: =SUMIFS(AY_SONU!$D$7:$D$42,AY_SONU!$B$7:$B$42,">="&EOMONTH(TODAY(),-1)+1,AY_SONU!$B$7:$B$42,"<="&EOMONTH(TODAY(),0)) | J10: =SUMIFS(UCRETLER!$G$7:$G$406,UCRETLER!$H$7:$H$406,"Aktif",UCRETLER!$F$7:$F$406,"Haftalık") | M10: =COUNTIF(AKTIVITE!$Q$7:$Q$1006,"GECİKMİŞ")
B11: =HYPERLINK("#VIRMAN!A1"," Virman") | D11: =TEXT(TODAY(),"mmmm yyyy")&" dönemi" | G11: ="Ay tahakkuku "&TEXT(SUMIFS(AY_SONU!$C$7:$C$42,AY_SONU!$B$7:$B$42,">="&EOMONTH(TODAY(),-1)+1,AY_SONU!$B$7:$B$42,"<="&EOMONTH(TODAY(),0)),"#,##0")&" ₺" | J11: ="Aylık: "&TEXT(SUMIFS(UCRETLER!$G$7:$G$406,UCRETLER!$H$7:$H$406,"Aktif",UCRETLER!$F$7:$F$406,"Aylık"),"#,##0")&" ₺ │ "&COUNTIFS(UCRETLER!$H$7:$H$406,"Aktif")&" aktif dönem" | M11: =COUNTIF(AKTIVITE!$Q$7:$Q$1006,"BUGÜN")&" iş bugün teslim"
B12: =HYPERLINK("#AKTIVITE!A1"," Aktivite")
B13: =HYPERLINK("#MUSTERI_360!A1"," Müşteri 360") | D13: AYLIK NAKİT KÂR EĞRİSİ | H13: TAHAKKUK ↔ TAHSİLAT | L13: ALACAK YAŞLANDIRMASI
B14: =HYPERLINK("#CARI_EKSTRE!A1"," Cari Ekstre")
B15: =HYPERLINK("#HESAPLAR!A1"," Hesaplar")
B16: =HYPERLINK("#AY_SONU!A1"," Ay Sonu")
B17: =HYPERLINK("#SISTEM!A1"," Sistem & Kontrol")
B18: =HYPERLINK("#BASLANGIC!A1"," Başlangıç")
D23: MÜŞTERİ HIZLI KARTI | J23: BUGÜNÜN UYARILARI
D24: Müşteri seçin | F24: ANKARA HAVANA LTD.ŞTİ. | J24: Gecikmiş müşteri işi | O24: =COUNTIF(AKTIVITE!$Q$7:$Q$1006,"GECİKMİŞ")
D25: Müşteri No | F25: =IF($F$24="","",IFERROR(INDEX(MUSTERI_360!$B$7:$B$106,MATCH($F$24,MUSTERI_360!$C$7:$C$106,0)),"")) | J25: Bugün teslim edilecek iş | O25: =COUNTIF(AKTIVITE!$Q$7:$Q$1006,"BUGÜN")
D26: Borç Durumu | F26: =IF($F$24="","",IFERROR(INDEX(MUSTERI_360!$Q$7:$Q$106,MATCH($F$24,MUSTERI_360!$C$7:$C$106,0)),"")) | J26: 7 gün içindeki işler | O26: =COUNTIF(AKTIVITE!$Q$7:$Q$1006,"7 GÜN İÇİNDE")
D27: Haftalık Ücret | F27: =IF($F$24="","",IFERROR(INDEX(MUSTERI_360!$D$7:$D$106,MATCH($F$24,MUSTERI_360!$C$7:$C$106,0)),"")) | J27: Gecikmiş müşteri teması | O27: =COUNTIFS(AKTIVITE!$C$7:$C$1006,"Görüşme",AKTIVITE!$Q$7:$Q$1006,"GECİKMİŞ")
D28: Aylık Ücret | F28: =IF($F$24="","",IFERROR(INDEX(MUSTERI_360!$E$7:$E$106,MATCH($F$24,MUSTERI_360!$C$7:$C$106,0)),"")) | J28: Kritik borç durumundaki müşteri | O28: =COUNTIF(MUSTERI_360!$Q$7:$Q$106,"KRİTİK")
D29: Devir Alacağı | F29: =IF($F$24="","",IFERROR(INDEX(MUSTERI_360!$F$7:$F$106,MATCH($F$24,MUSTERI_360!$C$7:$C$106,0)),"")) | J29: Bilgisi eksik müşteri kaydı | O29: =COUNTIF(MUSTERILER!$P$7:$P$106,"EKSİK")
D30: Yeni Tahakkuk | F30: =IF($F$24="","",IFERROR(INDEX(MUSTERI_360!$G$7:$G$106,MATCH($F$24,MUSTERI_360!$C$7:$C$106,0)),"")) | J30: Aktif ama ücretsiz müşteri | O30: =COUNTIFS(MUSTERILER!$D$7:$D$106,"Aktif",MUSTERILER!$O$7:$O$106,"HAYIR")
D31: Toplam Borç | F31: =IF($F$24="","",IFERROR(INDEX(MUSTERI_360!$H$7:$H$106,MATCH($F$24,MUSTERI_360!$C$7:$C$106,0)),"")) | J31: Eksik tahsilat kaydı | O31: =COUNTIF(TAHSILAT!$M$7:$M$1506,"EKSİK")
D32: Toplam Tahsilat | F32: =IF($F$24="","",IFERROR(INDEX(MUSTERI_360!$I$7:$I$106,MATCH($F$24,MUSTERI_360!$C$7:$C$106,0)),"")) | J32: Eksik gelir/gider kaydı | O32: =COUNTIF(GELIR_GIDER!$O$7:$O$1206,"EKSİK")
D33: Cari Bakiye | F33: =IF($F$24="","",IFERROR(INDEX(MUSTERI_360!$J$7:$J$106,MATCH($F$24,MUSTERI_360!$C$7:$C$106,0)),"")) | J33: Sistem kontrolünde KALDI satırı | O33: =COUNTIF(SISTEM!$F$23:$F$55,"KALDI")
D34: 0–7 Gün | F34: =IF($F$24="","",IFERROR(INDEX(MUSTERI_360!$K$7:$K$106,MATCH($F$24,MUSTERI_360!$C$7:$C$106,0)),""))
D35: 8–14 Gün | F35: =IF($F$24="","",IFERROR(INDEX(MUSTERI_360!$L$7:$L$106,MATCH($F$24,MUSTERI_360!$C$7:$C$106,0)),""))
D36: 15–28 Gün | F36: =IF($F$24="","",IFERROR(INDEX(MUSTERI_360!$M$7:$M$106,MATCH($F$24,MUSTERI_360!$C$7:$C$106,0)),""))
D37: 29+ Gün | F37: =IF($F$24="","",IFERROR(INDEX(MUSTERI_360!$N$7:$N$106,MATCH($F$24,MUSTERI_360!$C$7:$C$106,0)),""))
D38: Tahsilat Oranı | F38: =IF($F$24="","",IFERROR(INDEX(MUSTERI_360!$O$7:$O$106,MATCH($F$24,MUSTERI_360!$C$7:$C$106,0)),""))
D39: Son Tahsilat | F39: =IF($F$24="","",IFERROR(INDEX(MUSTERI_360!$P$7:$P$106,MATCH($F$24,MUSTERI_360!$C$7:$C$106,0)),""))
D40: Önerilen İşlem | F40: =IF($F$24="","",IFERROR(INDEX(MUSTERI_360!$R$7:$R$106,MATCH($F$24,MUSTERI_360!$C$7:$C$106,0)),""))

Sheet BASLANGIC
A1: KILIÇ MUHASEBE │ BAŞLANGIÇ │ AMAÇ, RENK KİLAVUZU VE KULLANIM
A2: Bu ekran sistemin kimlik kartıdır │ İlk kez açıyorsanız baştan sona okuyun
B4: =HYPERLINK("#PANO!A1","← PANO")
B5: KILIÇ MUHASEBE │ OFİS YÖNETİM SİSTEMİ
B6: Enterprise Exclusive sürüm │ Haftalık ücretle çalışan muhasebe ofisleri için müşteri, tahakkuk, tahsilat, cari, kasa ve ortak payı yönetimi
B8: 1. BU EXCEL NE İÇİN ÜRETİLDİ?
B9: Başlık | D9: Açıklama
B10: Amaç | D10: Haftalık ücretle çalışan bir muhasebe ofisinin tüm ticari işleyişini tek dosyada, tek veri girişiyle ve kendi kendini denetleyen bir yapıyla yönetmek.
B11: Kimin için? | D11: Müşterilerinden haftalık / dönemsel ücret tahsil eden, ortaklı veya tek kişilik muhasebe ve mali müşavirlik ofisleri için.
B12: Neyi çözer? | D12: “Kim ne kadar borçlu, bu borç kaç günlük, kasada ne kadar param var, bu ay gerçekten ne kazandım ve ortaklara ne dağıtabilirim” sorularını tahmine dayanmadan cevaplar.
B13: Nasıl çalışır? | D13: Siz yalnızca sarı hücrelere gerçek işlemi girersiniz. Cari hesap, yaşlandırma, kasa bakiyesi, aylık kapanış ve ortak payları otomatik olarak hesaplanır.
B14: Neden güvenilir? | D14: Sistem her açılışta 28 otomatik kontrol çalıştırır. Bir tanesi bile KALDI verirse ay kapatılamaz; hata sessizce geçmez.
B15: Tahakkuk esası | D15: Haftalık ücret her Cumartesi otomatik tahakkuk eder. Ücret değiştiğinde eski dönem kapatılır, yeni dönem açılır; geçmiş hesaplar asla bozulmaz.
B16: Kâr esası | D16: Dağıtım yalnız tahsil edilmiş nakit kârdan yapılır. Tahsil edilmemiş müşteri alacağı kâr sayılmaz ve ortaklara dağıtılmaz.
B18: 2. RENK KİLAVUZU │ EKRANDAKİ RENKLER NE ANLAMA GELİR?
B19: Renk | C19: Ne görünür | E19: Anlamı | G19: Ne yapmanız gerekir
B20: ■ | C20: SARI ZEMİN / MAVİ YAZI | E20: Veri giriş alanı | G20: Bu hücrelere siz yazarsınız. Sistemin tek besleme kaynağı bu alanlardır.
B21: ■ | C21: BEYAZ ZEMİN / SİYAH YAZI | E21: Otomatik hesaplanan alan | G21: Sistem hesaplar, kilitlidir. Elle değiştirilemez; değiştirmeye çalışırsanız uyarı alırsınız.
B22: ■ | C22: LACİVERT BANT | E22: Başlık ve tablo başlığı | G22: Ekran adı ve sütun başlıkları. Altındaki altın çizgi tablonun başladığı yeri gösterir.
B23: ■ | C23: AÇIK MAVİ SATIR | E23: TOPLAM satırı | G23: Tablo başlığının hemen üstünde durur ve aşağı kaydırsanız da ekranda kalır.
B24: ■ | C24: YEŞİL ROZET | E24: UYGUN / GEÇTİ / TEMİZ | G24: Kayıt eksiksiz, kontrol başarılı. Herhangi bir işlem gerekmiyor.
B25: ■ | C25: TURUNCU ROZET | E25: EKSİK / BUGÜN / ORTA | G25: Dikkat gerektirir. Kayıt tamamlanmalı veya iş bugün teslim edilmeli.
B26: ■ | C26: KIRMIZI ROZET | E26: HATA / KALDI / KRİTİK / GECİKMİŞ | G26: Acil müdahale. Kırmızı satır varken ay sonu kapatılmamalıdır.
B27: ■ | C27: GRİ ROZET | E27: PASİF / PLANLI / İZLE | G27: Bilgi amaçlıdır, işlem gerektirmez.
B29: 3. SEKME RENK HARİTASI │ ALTTAKİ SEKME RENKLERİ NE İŞE YARAR?
B30: Renk | C30: Sekme | D30: Ne için? | F30: Açıklama
B31: ■ | C31: =HYPERLINK("#PANO!A1","PANO") | D31: Yönetim panosu | F31: Günüe buradan başlayın: özet rakamlar, grafikler ve uyarılar.
B32: ■ | C32: =HYPERLINK("#BASLANGIC!A1","BASLANGIC") | D32: Kullanım kılavuzu | F32: Şu an okuduğunuz ekran. Amaç, renk kuralı ve adımlar.
B33: ■ | C33: =HYPERLINK("#MUSTERILER!A1","MUSTERILER") | D33: Ana müşteri kartı | F33: Her müşteri için tek kayıt. Devir alacağı burada tanımlanır.
B34: ■ | C34: =HYPERLINK("#UCRETLER!A1","UCRETLER") | D34: Haftalık ücret dönemleri | F34: Fiyat geçmişi. Tahakkuk motorunun kaynağı.
B35: ■ | C35: =HYPERLINK("#TAHSILAT!A1","TAHSILAT") | D35: Müşteri tahsilatı | F35: Müşteriden gelen her ödeme yalnız buraya girilir.
B36: ■ | C36: =HYPERLINK("#GELIR_GIDER!A1","GELIR_GIDER") | D36: Ofis gelir ve giderleri | F36: Kira, personel, fatura gibi müşteri dışı hareketler.
B37: ■ | C37: =HYPERLINK("#VIRMAN!A1","VIRMAN") | D37: Hesaplar arası transfer | F37: Kasadan bankaya para geçişi. Kârı etkilemez.
B38: ■ | C38: =HYPERLINK("#AKTIVITE!A1","AKTIVITE") | D38: İşler ve görüşmeler | F38: Beyanname, bildirim, telefon, toplantı ve son tarihler.
B39: ■ | C39: =HYPERLINK("#MUSTERI_360!A1","MUSTERI_360") | D39: Cari ve yaşlandırma | F39: Salt okunur karar ekranı. Kimden ne kadar alacaksınız?
B40: ■ | C40: =HYPERLINK("#CARI_EKSTRE!A1","CARI_EKSTRE") | D40: Müşteri cari ekstresi | F40: Seçilen müşterinin borç / alacak / bakiye hareketleri, tarih sırasıyla.
B41: ■ | C41: =HYPERLINK("#HESAPLAR!A1","HESAPLAR") | D41: Kasa ve banka | F41: Her hesabın güncel bakiyesi ve toplam nakit pozisyonu.
B42: ■ | C42: =HYPERLINK("#AY_SONU!A1","AY_SONU") | D42: Aylık kapanış | F42: Nakit kâr, dağıtılabilir kâr ve ortak payları.
B43: ■ | C43: =HYPERLINK("#SISTEM!A1","SISTEM") | D43: Ayarlar ve kontrol | F43: Ortak payları, kategoriler ve 28 otomatik denetim.
B45: 4. 11 ADIMDA KULLANIM │ HANGİ EKRANA NE GİRİLİR?
...

Sheet MUSTERILER
A1: KILIÇ MUHASEBE │ MÜŞTERİLER
A2: Ana müşteri kartı │ Her müşteri için tek kayıt │ Devir alacağı bu ekranda tanımlanır
B4: =HYPERLINK("#PANO!A1","← PANO") | D4: =HYPERLINK("#UCRETLER!A1","Haftalık Ücretler") | F4: =HYPERLINK("#MUSTERI_360!A1","Müşteri 360") | H4: Sarı hücreler veri girişidir. Beyaz hücreler sistem tarafından hesaplanır ve kilitlidir. Devir Alacak Tarihi yaşlandırmayı belirler — boş bırakılırsa tutar 29+ gün kabul edilir.
C5: TOPLAM │ Aktif müşteri ve devir alacağı | D5: =COUNTIF($D$7:$D$106,"Aktif") | J5: =SUM($J$7:$J$106)
B6: Müşteri No | C6: Müşteri / Mükellef Unvanı | D6: Durum | E6: Sorumlu Kişi | F6: Telefon | G6: Vergi No | H6: Ödeme Şekli | I6: Başlangıç Tarihi | J6: Devir Alacağı | K6: Devir Alacak Tarihi | L6: Devir Kaynağı | M6: Özel Not | N6: Bilgi Durumu | O6: Aktif Ücret Tanımı | P6: Kayıt Kontrolü
B7: M001 | C7: ANKARA HAVANA LTD.ŞTİ. | D7: Aktif | H7: Nakit | I7: 46023 | J7: 0 | O7: =IF($C7="","",IF(COUNTIFS(UCRETLER!$B$7:$B$406,$B7,UCRETLER!$H$7:$H$406,"Aktif")>0,"EVET","HAYIR")) | P7: =IF($C7="","",IF($B7="","NO EKSİK",IF(COUNTIF($B$7:$B$106,$B7)>1,"NO TEKRARI",IF(COUNTIF($C$7:$C$106,$C7)>1,"UNVAN TEKRARI",IF($D7="","DURUM EKSİK",IF(AND($J7>0,$K7=""),"DEVİR TARİHİ EKSİK","UYGUN"))))))
B8: M002 | C8: ESERLİ LTD.ŞTİ. | D8: Aktif | H8: Nakit | I8: 46023 | J8: 0 | O8: =IF($C8="","",IF(COUNTIFS(UCRETLER!$B$7:$B$406,$B8,UCRETLER!$H$7:$H$406,"Aktif")>0,"EVET","HAYIR")) | P8: =IF($C8="","",IF($B8="","NO EKSİK",IF(COUNTIF($B$7:$B$106,$B8)>1,"NO TEKRARI",IF(COUNTIF($C$7:$C$106,$C8)>1,"UNVAN TEKRARI",IF($D8="","DURUM EKSİK",IF(AND($J8>0,$K8=""),"DEVİR TARİHİ EKSİK","UYGUN"))))))
B9: M003 | C9: TYANA LTD.ŞTİ. | D9: Aktif | H9: Nakit | I9: 46023 | J9: 0 | O9: =IF($C9="","",IF(COUNTIFS(UCRETLER!$B$7:$B$406,$B9,UCRETLER!$H$7:$H$406,"Aktif")>0,"EVET","HAYIR")) | P9: =IF($C9="","",IF($B9="","NO EKSİK",IF(COUNTIF($B$7:$B$106,$B9)>1,"NO TEKRARI",IF(COUNTIF($C$7:$C$106,$C9)>1,"UNVAN TEKRARI",IF($D9="","DURUM EKSİK",IF(AND($J9>0,$K9=""),"DEVİR TARİHİ EKSİK","UYGUN"))))))
B10: M004 | C10: ZÜMRÜT EĞLENCE LTD.ŞTİ. | D10: Aktif | H10: Nakit | I10: 46023 | J10: 0 | O10: =IF($C10="","",IF(COUNTIFS(UCRETLER!$B$7:$B$406,$B10,UCRETLER!$H$7:$H$406,"Aktif")>0,"EVET","HAYIR")) | P10: =IF($C10="","",IF($B10="","NO EKSİK",IF(COUNTIF($B$7:$B$106,$B10)>1,"NO TEKRARI",IF(COUNTIF($C$7:$C$106,$C10)>1,"UNVAN TEKRARI",IF($D10="","DURUM EKSİK",IF(AND($J10>0,$K10=""),"DEVİR TARİHİ EKSİK","UYGUN"))))))
B11: M005 | C11: ZÜMRÜT GRUP LTD.ŞTİ. | D11: Aktif | H11: Nakit | I11: 46023 | J11: 0 | O11: =IF($C11="","",IF(COUNTIFS(UCRETLER!$B$7:$B$406,$B11,UCRETLER!$H$7:$H$406,"Aktif")>0,"EVET","HAYIR")) | P11: =IF($C11="","",IF($B11="","NO EKSİK",IF(COUNTIF($B$7:$B$106,$B11)>1,"NO TEKRARI",IF(COUNTIF($C$7:$C$106,$C11)>1,"UNVAN TEKRARI",IF($D11="","DURUM EKSİK",IF(AND($J11>0,$K11=""),"DEVİR TARİHİ EKSİK","UYGUN"))))))
B12: M006 | C12: VOLKAN AÇIK | D12: Aktif | H12: Nakit | I12: 46023 | J12: 0 | O12: =IF($C12="","",IF(COUNTIFS(UCRETLER!$B$7:$B$406,$B12,UCRETLER!$H$7:$H$406,"Aktif")>0,"EVET","HAYIR")) | P12: =IF($C12="","",IF($B12="","NO EKSİK",IF(COUNTIF($B$7:$B$106,$B12)>1,"NO TEKRARI",IF(COUNTIF($C$7:$C$106,$C12)>1,"UNVAN TEKRARI",IF($D12="","DURUM EKSİK",IF(AND($J12>0,$K12=""),"DEVİR TARİHİ EKSİK","UYGUN"))))))
B13: M007 | C13: MONAMOUR LTD.ŞTİ. | D13: Aktif | H13: Nakit | I13: 46023 | J13: 0 | O13: =IF($C13="","",IF(COUNTIFS(UCRETLER!$B$7:$B$406,$B13,UCRETLER!$H$7:$H$406,"Aktif")>0,"EVET","HAYIR")) | P13: =IF($C13="","",IF($B13="","NO EKSİK",IF(COUNTIF($B$7:$B$106,$B13)>1,"NO TEKRARI",IF(COUNTIF($C$7:$C$106,$C13)>1,"UNVAN TEKRARI",IF($D13="","DURUM EKSİK",IF(AND($J13>0,$K13=""),"DEVİR TARİHİ EKSİK","UYGUN"))))))
B14: M008 | C14: KÖŞK YÜKSELEN LTD.ŞTİ. | D14: Aktif | H14: Nakit | I14: 46023 | J14: 0 | O14: =IF($C14="","",IF(COUNTIFS(UCRETLER!$B$7:$B$406,$B14,UCRETLER!$H$7:$H$406,"Aktif")>0,"EVET","HAYIR")) | P14: =IF($C14="","",IF($B14="","NO EKSİK",IF(COUNTIF($B$7:$B$106,$B14)>1,"NO TEKRARI",IF(COUNTIF($C$7:$C$106,$C14)>1,"UNVAN TEKRARI",IF($D14="","DURUM EKSİK",IF(AND($J14>0,$K14=""),"DEVİR TARİHİ EKSİK","UYGUN"))))))
B15: M009 | C15: PAKYILDIZ LTD.ŞTİ. | D15: Aktif | H15: Nakit | I15: 46023 | J15: 0 | O15: =IF($C15="","",IF(COUNTIFS(UCRETLER!$B$7:$B$406,$B15,UCRETLER!$H$7:$H$406,"Aktif")>0,"EVET","HAYIR")) | P15: =IF($C15="","",IF($B15="","NO EKSİK",IF(COUNTIF($B$7:$B$106,$B15)>1,"NO TEKRARI",IF(COUNTIF($C$7:$C$106,$C15)>1,"UNVAN TEKRARI",IF($D15="","DURUM EKSİK",IF(AND($J15>0,$K15=""),"DEVİR TARİHİ EKSİK","UYGUN"))))))
B16: M010 | C16: ÖZFİDANLAR LTD.ŞTİ. | D16: Aktif | H16: Nakit | I16: 46023 | J16: 0 | O16: =IF($C16="","",IF(COUNTIFS(UCRETLER!$B$7:$B$406,$B16,UCRETLER!$H$7:$H$406,"Aktif")>0,"EVET","HAYIR")) | P16: =IF($C16="","",IF($B16="","NO EKSİK",IF(COUNTIF($B$7:$B$106,$B16)>1,"NO TEKRARI",IF(COUNTIF($C$7:$C$106,$C16)>1,"UNVAN TEKRARI",IF($D16="","DURUM EKSİK",IF(AND($J16>0,$K16=""),"DEVİR TARİHİ EKSİK","UYGUN"))))))
B17: M011 | C17: EĞLENGÖR LTD.ŞTİ. | D17: Aktif | H17: Nakit | I17: 46023 | J17: 0 | O17: =IF($C17="","",IF(COUNTIFS(UCRETLER!$B$7:$B$406,$B17,UCRETLER!$H$7:$H$406,"Aktif")>0,"EVET","HAYIR")) | P17: =IF($C17="","",IF($B17="","NO EKSİK",IF(COUNTIF($B$7:$B$106,$B17)>1,"NO TEKRARI",IF(COUNTIF($C$7:$C$106,$C17)>1,"UNVAN TEKRARI",IF($D17="","DURUM EKSİK",IF(AND($J17>0,$K17=""),"DEVİR TARİHİ EKSİK","UYGUN"))))))
B18: M012 | C18: İLDEŞ LTD.ŞTİ. | D18: Aktif | H18: Nakit | I18: 46023 | J18: 0 | O18: =IF($C18="","",IF(COUNTIFS(UCRETLER!$B$7:$B$406,$B18,UCRETLER!$H$7:$H$406,"Aktif")>0,"EVET","HAYIR")) | P18: =IF($C18="","",IF($B18="","NO EKSİK",IF(COUNTIF($B$7:$B$106,$B18)>1,"NO TEKRARI",IF(COUNTIF($C$7:$C$106,$C18)>1,"UNVAN TEKRARI",IF($D18="","DURUM EKSİK",IF(AND($J18>0,$K18=""),"DEVİR TARİHİ EKSİK","UYGUN"))))))
... B59: M053 | C59: YEDİYİRMİDÖRT LTD.ŞTİ. | D59: Aktif | H59: Nakit | I59: 46023 | J59: 0 | O59: =IF($C59="","",IF(COUNTIFS(UCRETLER!$B$7:$B$406,$B59,UCRETLER!$H$7:$H$406,"Aktif")>0,"EVET","HAYIR")) | P59: =IF($C59="","",IF($B59="","NO EKSİK",IF(COUNTIF($B$7:$B$106,$B59)>1,"NO TEKRARI",IF(COUNTIF($C$7:$C$106,$C59)>1,"UNVAN TEKRARI",IF($D59="","DURUM EKSİK",IF(AND($J59>0,$K59=""),"DEVİR TARİHİ EKSİK","UYGUN"))))))
B60: TST01 | C60: TEST HAFTALIK A.Ş. | D60: Aktif | J60: 5000 | K60: 46006 | L60: TEST devir | O60: =IF($C60="","",IF(COUNTIFS(UCRETLER!$B$7:$B$406,$B60,UCRETLER!$H$7:$H$406,"Aktif")>0,"EVET","HAYIR")) | P60: =IF($C60="","",IF($B60="","NO EKSİK",IF(COUNTIF($B$7:$B$106,$B60)>1,"NO TEKRARI",IF(COUNTIF($C$7:$C$106,$C60)>1,"UNVAN TEKRARI",IF($D60="","DURUM EKSİK",IF(AND($J60>0,$K60=""),"DEVİR TARİHİ EKSİK","UYGUN"))))))
B61: TST02 | C61: TEST AYLIK LTD. | D61: Aktif | O61: =IF($C61="","",IF(COUNTIFS(UCRETLER!$B$7:$B$406,$B61,UCRETLER!$H$7:$H$406,"Aktif")>0,"EVET","HAYIR")) | P61: =IF($C61="","",IF($B61="","NO EKSİK",IF(COUNTIF($B$7:$B$106,$B61)>1,"NO TEKRARI",IF(COUNTIF($C$7:$C$106,$C61)>1,"UNVAN TEKRARI",IF($D61="","DURUM EKSİK",IF(AND($J61>0,$K61=""),"DEVİR TARİHİ EKSİK","UYGUN"))))))
B62: M056 | O62: =IF($C62="","",IF(COUNTIFS(UCRETLER!$B$7:$B$406,$B62,UCRETLER!$H$7:$H$406,"Aktif")>0,"EVET","HAYIR")) | P62: =IF($C62="","",IF($B62="","NO EKSİK",IF(COUNTIF($B$7:$B$106,$B62)>1,"NO TEKRARI",IF(COUNTIF($C$7:$C$106,$C62)>1,"UNVAN TEKRARI",IF($D62="","DURUM EKSİK",IF(AND($J62>0,$K62=""),"DEVİR TARİHİ EKSİK","UYGUN"))))))
B63: M057 | O63: =IF($C63="","",IF(COUNTIFS(UCRETLER!$B$7:$B$406,$B63,UCRETLER!$H$7:$H$406,"Aktif")>0,"EVET","HAYIR")) | P63: =IF($C63="","",IF($B63="","NO EKSİK",IF(COUNTIF($B$7:$B$106,$B63)>1,"NO TEKRARI",IF(COUNTIF($C$7:$C$106,$C63)>1,"UNVAN TEKRARI",IF($D63="","DURUM EKSİK",IF(AND($J63>0,$K63=""),"DEVİR TARİHİ EKSİK","UYGUN"))))))
B64: M058 | O64: =IF($C64="","",IF(COUNTIFS(UCRETLER!$B$7:$B$406,$B64,UCRETLER!$H$7:$H$406,"Aktif")>0,"EVET","HAYIR")) | P64: =IF($C64="","",IF($B64="","NO EKSİK",IF(COUNTIF($B$7:$B$106,$B64)>1,"NO TEKRARI",IF(COUNTIF($C$7:$C$106,$C64)>1,"UNVAN TEKRARI",IF($D64="","DURUM EKSİK",IF(AND($J64>0,$K64=""),"DEVİR TARİHİ EKSİK","UYGUN"))))))
B65: M059 | O65: =IF($C65="","",IF(COUNTIFS(UCRETLER!$B$7:$B$406,$B65,UCRETLER!$H$7:$H$406,"Aktif")>0,"EVET","HAYIR")) | P65: =IF($C65="","",IF($B65="","NO EKSİK",IF(COUNTIF($B$7:$B$106,$B65)>1,"NO TEKRARI",IF(COUNTIF($C$7:$C$106,$C65)>1,"UNVAN TEKRARI",IF($D65="","DURUM EKSİK",IF(AND($J65>0,$K65=""),"DEVİR TARİHİ EKSİK","UYGUN"))))))
B66: M060 | O66: =IF($C66="","",IF(COUNTIFS(UCRETLER!$B$7:$B$406,$B66,UCRETLER!$H$7:$H$406,"Aktif")>0,"EVET","HAYIR")) | P66: =IF($C66="","",IF($B66="","NO EKSİK",IF(COUNTIF($B$7:$B$106,$B66)>1,"NO TEKRARI",IF(COUNTIF($C$7:$C$106,$C66)>1,"UNVAN TEKRARI",IF($D66="","DURUM EKSİK",IF(AND($J66>0,$K66=""),"DEVİR TARİHİ EKSİK","UYGUN"))))))
B67: M061 | O67: =IF($C67="","",IF(COUNTIFS(UCRETLER!$B$7:$B$406,$B67,UCRETLER!$H$7:$H$406,"Aktif")>0,"EVET","HAYIR")) | P67: =IF($C67="","",IF($B67="","NO EKSİK",IF(COUNTIF($B$7:$B$106,$B67)>1,"NO TEKRARI",IF(COUNTIF($C$7:$C$106,$C67)>1,"UNVAN TEKRARI",IF($D67="","DURUM EKSİK",IF(AND($J67>0,$K67=""),"DEVİR TARİHİ EKSİK","UYGUN"))))))
B68: M062 | O68: =IF($C68="","",IF(COUNTIFS(UCRETLER!$B$7:$B$406,$B68,UCRETLER!$H$7:$H$406,"Aktif")>0,"EVET","HAYIR")) | P68: =IF($C68="","",IF($B68="","NO EKSİK",IF(COUNTIF($B$7:$B$106,$B68)>1,"NO TEKRARI",IF(COUNTIF($C$7:$C$106,$C68)>1,"UNVAN TEKRARI",IF($D68="","DURUM EKSİK",IF(AND($J68>0,$K68=""),"DEVİR TARİHİ EKSİK","UYGUN"))))))
B69: M063 | O69: =IF($C69="","",IF(COUNTIFS(UCRETLER!$B$7:$B$406,$B69,UCRETLER!$H$7:$H$406,"Aktif")>0,"EVET","HAYIR")) | P69: =IF($C69="","",IF($B69="","NO EKSİK",IF(COUNTIF($B$7:$B$106,$B69)>1,"NO TEKRARI",IF(COUNTIF($C$7:$C$106,$C69)>1,"UNVAN TEKRARI",IF($D69="","DURUM EKSİK",IF(AND($J69>0,$K69=""),"DEVİR TARİHİ EKSİK","UYGUN"))))))
B70: M064 | O70: =IF($C70="","",IF(COUNTIFS(UCRETLER!$B$7:$B$406,$B70,UCRETLER!$H$7:$H$406,"Aktif")>0,"EVET","HAYIR")) | P70: =IF($C70="","",IF($B70="","NO EKSİK",IF(COUNTIF($B$7:$B$106,$B70)>1,"NO TEKRARI",IF(COUNTIF($C$7:$C$106,$C70)>1,"UNVAN TEKRARI",IF($D70="","DURUM EKSİK",IF(AND($J70>0,$K70=""),"DEVİR TARİHİ EKSİK","UYGUN"))))))
B71: M065 | O71: =IF($C71="","",IF(COUNTIFS(UCRETLER!$B$7:$B$406,$B71,UCRETLER!$H$7:$H$406,"Aktif")>0,"EVET","HAYIR")) | P71: =IF($C71="","",IF($B71="","NO EKSİK",IF(COUNTIF($B$7:$B$106,$B71)>1,"NO TEKRARI",IF(COUNTIF($C$7:$C$106,$C71)>1,"UNVAN TEKRARI",IF($D71="","DURUM EKSİK",IF(AND($J71>0,$K71=""),"DEVİR TARİHİ EKSİK","UYGUN"))))))
B72: M066 | O72: =IF($C72="","",IF(COUNTIFS(UCRETLER!$B$7:$B$406,$B72,UCRETLER!$H$7:$H$406,"Aktif")>0,"EVET","HAYIR")) | P72: =IF($C72="","",IF($B72="","NO EKSİK",IF(COUNTIF($B$7:$B$106,$B72)>1,"NO TEKRARI",IF(COUNTIF($C$7:$C$106,$C72)>1,"UNVAN TEKRARI",IF($D72="","DURUM EKSİK",IF(AND($J72>0,$K72=""),"DEVİR TARİHİ EKSİK","UYGUN"))))))
B73: M067 | O73: =IF($C73="","",IF(COUNTIFS(UCRETLER!$B$7:$B$406,$B73,UCRETLER!$H$7:$H$406,"Aktif")>0,"EVET","HAYIR")) | P73: =IF($C73="","",IF($B73="","NO EKSİK",IF(COUNTIF($B$7:$B$106,$B73)>1,"NO TEKRARI",IF(COUNTIF($C$7:$C$106,$C73)>1,"UNVAN TEKRARI",IF($D73="","DURUM EKSİK",IF(AND($J73>0,$K73=""),"DEVİR TARİHİ EKSİK","UYGUN"))))))
... B106: M100 | O106: =IF($C106="","",IF(COUNTIFS(UCRETLER!$B$7:$B$406,$B106,UCRETLER!$H$7:$H$406,"Aktif")>0,"EVET","HAYIR")) | P106: =IF($C106="","",IF($B106="","NO EKSİK",IF(COUNTIF($B$7:$B$106,$B106)>1,"NO TEKRARI",IF(COUNTIF($C$7:$C$106,$C106)>1,"UNVAN TEKRARI",IF($D106="","DURUM EKSİK",IF(AND($J106>0,$K106=""),"DEVİR TARİHİ EKSİK","UYGUN"))))))

Sheet UCRETLER
A1: KILIÇ MUHASEBE │ ÜCRET DÖNEMLERİ │ HAFTALIK VE AYLIK TAHAKKUK
A2: Ücret değişinde eski dönemi kapat, yeni satır aç │ Geçmiş tahakkuk asla bozulmaz
B4: =HYPERLINK("#PANO!A1","← PANO") | D4: =HYPERLINK("#MUSTERILER!A1","Müşteriler") | F4: =HYPERLINK("#MUSTERI_360!A1","Müşteri 360") | H4: Sarı hücreler veri girişidir. Beyaz hücreler sistem tarafından hesaplanır ve kilitlidir. Başlangıç tarihi serbesttir: haftalık modelde ilk tahakkuk bu tarihten sonraki ilk tahakkuk gününde, aylık modelde ayın son gününde oluşur.
C5: TOPLAM │ Aktif haftalık + aylık tahakkuk ve oluşan ücret | G5: =SUMIFS($G$7:$G$406,$H$7:$H$406,"Aktif") | I5: =SUM($I$7:$I$406)
B6: Müşteri No | C6: Müşteri (yazın veya seçin) | D6: Ücret Başlangıç Tarihi | E6: Ücret Bitiş Tarihi | F6: Tahakkuk Modeli | G6: Ücret Tutarı | H6: Dönem Durumu | I6: Bugüne Kadar Oluşan | J6: 8 Gün Öncesine Kadar | K6: 15 Gün Öncesine Kadar | L6: 29 Gün Öncesine Kadar | M6: Oluşan Dönem | N6: Sistem Kontrolü | O6: İlk Tahakkuk Tarihi | P6: Not
B7: =IF($C7="","",IFERROR(INDEX(MUSTERILER!$B$7:$B$106,MATCH($C7,MUSTERILER!$C$7:$C$106,0)),IFERROR(INDEX(MUSTERILER!$B$7:$B$106,MATCH($C7,MUSTERILER!$B$7:$B$106,0)),IFERROR(INDEX(MUSTERILER!$B$7:$B$106,MATCH($C7&"*",MUSTERILER!$C$7:$C$106,0)),"TANIMSIZ MÜŞTERİ")))) | C7: ANKARA HAVANA LTD.ŞTİ. | D7: 46023 | F7: Haftalık | G7: 4000 | H7: Aktif | I7: =IF(OR($C7="",$D7="",$G7="",$F7=""),0,$G7*IF($F7="Aylık",MAX(0,(YEAR(MIN(IF($E7="",TODAY(),$E7),TODAY()))-YEAR($D7))*12+MONTH(MIN(IF($E7="",TODAY(),$E7),TODAY()))-MONTH($D7)+IF(MIN(IF($E7="",TODAY(),$E7),TODAY())>=EOMONTH(MIN(IF($E7="",TODAY(),$E7),TODAY()),0),1,0)),MAX(0,INT((MIN(IF($E7="",TODAY(),$E7),TODAY())-($D7+MOD(SISTEM!$F$8-WEEKDAY($D7,2),7)))/7)+1))) | J7: =IF(OR($C7="",$D7="",$G7="",$F7=""),0,$G7*IF($F7="Aylık",MAX(0,(YEAR(MIN(IF($E7="",TODAY()-8,$E7),TODAY()-8))-YEAR($D7))*12+MONTH(MIN(IF($E7="",TODAY()-8,$E7),TODAY()-8))-MONTH($D7)+IF(MIN(IF($E7="",TODAY()-8,$E7),TODAY()-8)>=EOMONTH(MIN(IF($E7="",TODAY()-8,$E7),TODAY()-8),0),1,0)),MAX(0,INT((MIN(IF($E7="",TODAY()-8,$E7),TODAY()-8)-($D7+MOD(SISTEM!$F$8-WEEKDAY($D7,2),7)))/7)+1))) | K7: =IF(OR($C7="",$D7="",$G7="",$F7=""),0,$G7*IF($F7="Aylık",MAX(0,(YEAR(MIN(IF($E7="",TODAY()-15,$E7),TODAY()-15))-YEAR($D7))*12+MONTH(MIN(IF($E7="",TODAY()-15,$E7),TODAY()-15))-MONTH($D7)+IF(MIN(IF($E7="",TODAY()-15,$E7),TODAY()-15)>=EOMONTH(MIN(IF($E7="",TODAY()-15,$E7),TODAY()-15),0),1,0)),MAX(0,INT((MIN(IF($E7="",TODAY()-15,$E7),TODAY()-15)-($D7+MOD(SISTEM!$F$8-WEEKDAY($D7,2),7)))/7)+1))) | L7: =IF(OR($C7="",$D7="",$G7="",$F7=""),0,$G7*IF($F7="Aylık",MAX(0,(YEAR(MIN(IF($E7="",TODAY()-29,$E7),TODAY()-29))-YEAR($D7))*12+MONTH(MIN(IF($E7="",TODAY()-29,$E7),TODAY()-29))-MONTH($D7)+IF(MIN(IF($E7="",TODAY()-29,$E7),TODAY()-29)>=EOMONTH(MIN(IF($E7="",TODAY()-29,$E7),TODAY()-29),0),1,0)),MAX(0,INT((MIN(IF($E7="",TODAY()-29,$E7),TODAY()-29)-($D7+MOD(SISTEM!$F$8-WEEKDAY($D7,2),7)))/7)+1))) | M7: =IF($G7>0,$I7/$G7,0) | N7: =IF($C7="","",IF($B7="TANIMSIZ MÜŞTERİ","TANIMSIZ MÜŞTERİ",IF($F7="","MODEL SEÇİN",IF(OR($D7="",$G7<=0),"EKSİK",IF(AND($E7<>"",$E7<$D7),"TARİH HATASI",IF($H7="Pasif","KAPALI DÖNEM","UYGUN")))))) | O7: =IF(OR($C7="",$D7="",$F7=""),"",IF($F7="Aylık",EOMONTH($D7,0),($D7+MOD(SISTEM!$F$8-WEEKDAY($D7,2),7)))) | P7: Mevcut dosyadan aktarıldı | S7: =IF($B7="","",$B7&"|"&COUNTIFS($B$7:$B7,$B7))
B8: =IF($C8="","",IFERROR(INDEX(MUSTERILER!$B$7:$B$106,MATCH($C8,MUSTERILER!$C$7:$C$106,0)),IFERROR(INDEX(MUSTERILER!$B$7:$B$106,MATCH($C8,MUSTERILER!$B$7:$B$106,0)),IFERROR(INDEX(MUSTERILER!$B$7:$B$106,MATCH($C8&"*",MUSTERILER!$C$7:$C$106,0)),"TANIMSIZ MÜŞTERİ")))) | C8: ESERLİ LTD.ŞTİ. | D8: 46023 | F8: Haftalık | G8: 3500 | H8: Aktif | I8: =IF(OR($C8="",$D8="",$G8="",$F8=""),0,$G8*IF($F8="Aylık",MAX(0,(YEAR(MIN(IF($E8="",TODAY(),$E8),TODAY()))-YEAR($D8))*12+MONTH(MIN(IF($E8="",TODAY(),$E8),TODAY()))-MONTH($D8)+IF(MIN(IF($E8="",TODAY(),$E8),TODAY())>=EOMONTH(MIN(IF($E8="",TODAY(),$E8),TODAY()),0),1,0)),MAX(0,INT((MIN(IF($E8="",TODAY(),$E8),TODAY())-($D8+MOD(SISTEM!$F$8-WEEKDAY($D8,2),7)))/7)+1))) | J8: =IF(OR($C8="",$D8="",$G8="",$F8=""),0,$G8*IF($F8="Aylık",MAX(0,(YEAR(MIN(IF($E8="",TODAY()-8,$E8),TODAY()-8))-YEAR($D8))*12+MONTH(MIN(IF($E8="",TODAY()-8,$E8),TODAY()-8))-MONTH($D8)+IF(MIN(IF($E8="",TODAY()-8,$E8),TODAY()-8)>=EOMONTH(MIN(IF($E8="",TODAY()-8,$E8),TODAY()-8),0),1,0)),MAX(0,INT((MIN(IF($E8="",TODAY()-8,$E8),TODAY()-8)-($D8+MOD(SISTEM!$F$8-WEEKDAY($D8,2),7)))/7)+1))) | K8: =IF(OR($C8="",$D8="",$G8="",$F8=""),0,$G8*IF($F8="Aylık",MAX(0,(YEAR(MIN(IF($E8="",TODAY()-15,$E8),TODAY()-15))-YEAR($D8))*12+MONTH(MIN(IF($E8="",TODAY()-15,$E8),TODAY()-15))-MONTH($D8)+IF(MIN(IF($E8="",TODAY()-15,$E8),TODAY()-15)>=EOMONTH(MIN(IF($E8="",TODAY()-15,$E8),TODAY()-15),0),1,0)),MAX(0,INT((MIN(IF($E8="",TODAY()-15,$E8),TODAY()-15)-($D8+MOD(SISTEM!$F$8-WEEKDAY($D8,2),7)))/7)+1))) | L8: =IF(OR($C8="",$D8="",$G8="",$F8=""),0,$G8*IF($F8="Aylık",MAX(0,(YEAR(MIN(IF($E8="",TODAY()-29,$E8),TODAY()-29))-YEAR($D8))*12+MONTH(MIN(IF($E8="",TODAY()-29,$E8),TODAY()-29))-MONTH($D8)+IF(MIN(IF($E8="",TODAY()-29,$E8),TODAY()-29)>=EOMONTH(MIN(IF($E8="",TODAY()-29,$E8),TODAY()-29),0),1,0)),MAX(0,INT((MIN(IF($E8="",TODAY()-29,$E8),TODAY()-29)-($D8+MOD(SISTEM!$F$8-WEEKDAY($D8,2),7)))/7)+1))) | M8: =IF($G8>0,$I8/$G8,0) | N8: =IF($C8="","",IF($B8="TANIMSIZ MÜŞTERİ","TANIMSIZ MÜŞTERİ",IF($F8="","MODEL SEÇİN",IF(OR($D8="",$G8<=0),"EKSİK",IF(AND($E8<>"",$E8<$D8),"TARİH HATASI",IF($H8="Pasif","KAPALI DÖNEM","UYGUN")))))) | O8: =IF(OR($C8="",$D8="",$F8=""),"",IF($F8="Aylık",EOMONTH($D8,0),($D8+MOD(SISTEM!$F$8-WEEKDAY($D8,2),7)))) | P8: Mevcut dosyadan aktarıldı | S8: =IF($B8="","",$B8&"|"&COUNTIFS($B$7:$B8,$B8))
B9: =IF($C9="","",IFERROR(INDEX(MUSTERILER!$B$7:$B$106,MATCH($C9,MUSTERILER!$C$7:$C$106,0)),IFERROR(INDEX(MUSTERILER!$B$7:$B$106,MATCH($C9,MUSTERILER!$B$7:$B$106,0)),IFERROR(INDEX(MUSTERILER!$B$7:$B$106,MATCH($C9&"*",MUSTERILER!$C$7:$C$106,0)),"TANIMSIZ MÜŞTERİ")))) | C9: TYANA LTD.ŞTİ. | D9: 46023 | F9: Haftalık | G9: 4000 | H9: Aktif | I9: =IF(OR($C9="",$D9="",$G9="",$F9=""),0,$G9*IF($F9="Aylık",MAX(0,(YEAR(MIN(IF($E9="",TODAY(),$E9),TODAY()))-YEAR($D9))*12+MONTH(MIN(IF($E9="",TODAY(),$E9),TODAY()))-MONTH($D9)+IF(MIN(IF($E9="",TODAY(),$E9),TODAY())>=EOMONTH(MIN(IF($E9="",TODAY(),$E9),TODAY()),0),1,0)),MAX(0,INT((MIN(IF($E9="",TODAY(),$E9),TODAY())-($D9+MOD(SISTEM!$F$8-WEEKDAY($D9,2),7)))/7)+1))) | J9: =IF(OR($C9="",$D9="",$G9="",$F9=""),0,$G9*IF($F9="Aylık",MAX(0,(YEAR(MIN(IF($E9="",TODAY()-8,$E9),TODAY()-8))-YEAR($D9))*12+MONTH(MIN(IF($E9="",TODAY()-8,$E9),TODAY()-8))-MONTH($D9)+IF(MIN(IF($E9="",TODAY()-8,$E9),TODAY()-8)>=EOMONTH(MIN(IF($E9="",TODAY()-8,$E9),TODAY()-8),0),1,0)),MAX(0,INT((MIN(IF($E9="",TODAY()-8,$E9),TODAY()-8)-($D9+MOD(SISTEM!$F$8-WEEKDAY($D9,2),7)))/7)+1))) | K9: =IF(OR($C9="",$D9="",$G9="",$F9=""),0,$G9*IF($F9="Aylık",MAX(0,(YEAR(MIN(IF($E9="",TODAY()-15,$E9),TODAY()-15))-YEAR($D9))*12+MONTH(MIN(IF($E9="",TODAY()-15,$E9),TODAY()-15))-MONTH($D9)+IF(MIN(IF($E9="",TODAY()-15,$E9),TODAY()-15)>=EOMONTH(MIN(IF($E9="",TODAY()-15,$E9),TODAY()-15),0),1,0)),MAX(0,INT((MIN(IF($E9="",TODAY()-15,$E9),TODAY()-15)-($D9+MOD(SISTEM!$F$8-WEEKDAY($D9,2),7)))/7)+1))) | L9: =IF(OR($C9="",$D9="",$G9="",$F9=""),0,$G9*IF($F9="Aylık",MAX(0,(YEAR(MIN(IF($E9="",TODAY()-29,$E9),TODAY()-29))-YEAR($D9))*12+MONTH(MIN(IF($E9="",TODAY()-29,$E9),TODAY()-29))-MONTH($D9)+IF(MIN(IF($E9="",TODAY()-29,$E9),TODAY()-29)>=EOMONTH(MIN(IF($E9="",TODAY()-29,$E9),TODAY()-29),0),1,0)),MAX(0,INT((MIN(IF($E9="",TODAY()-29,$E9),TODAY()-29)-($D9+MOD(SISTEM!$F$8-WEEKDAY($D9,2),7)))/7)+1))) | M9: =IF($G9>0,$I9/$G9,0) | N9: =IF($C9="","",IF($B9="TANIMSIZ MÜŞTERİ","TANIMSIZ MÜŞTERİ",IF($F9="","MODEL SEÇİN",IF(OR($D9="",$G9<=0),"EKSİK",IF(AND($E9<>"",$E9<$D9),"TARİH HATASI",IF($H9="Pasif","KAPALI DÖNEM","UYGUN")))))) | O9: =IF(OR($C9="",$D9="",$F9=""),"",IF($F9="Aylık",EOMONTH($D9,0),($D9+MOD(SISTEM!$F$8-WEEKDAY($D9,2),7)))) | P9: Mevcut dosyadan aktarıldı | S9: =IF($B9="","",$B9&"|"&COUNTIFS($B$7:$B9,$B9))
B10: =IF($C10="","",IFERROR(INDEX(MUSTERILER!$B$7:$B$106,MATCH($C10,MUSTERILER!$C$7:$C$106,0)),IFERROR(INDEX(MUSTERILER!$B$7:$B$106,MATCH($C10,MUSTERILER!$B$7:$B$106,0)),IFERROR(INDEX(MUSTERILER!$B$7:$B$106,MATCH($C10&"*",MUSTERILER!$C$7:$C$106,0)),"TANIMSIZ MÜŞTERİ")))) | C10: ZÜMRÜT EĞLENCE LTD.ŞTİ. | D10: 46023 | F10: Haftalık | G10: 1750 | H10: Aktif | I10: =IF(OR($C10="",$D10="",$G10="",$F10=""),0,$G10*IF($F10="Aylık",MAX(0,(YEAR(MIN(IF($E10="",TODAY(),$E10),TODAY()))-YEAR($D10))*12+MONTH(MIN(IF($E10="",TODAY(),$E10),TODAY()))-MONTH($D10)+IF(MIN(IF($E10="",TODAY(),$E10),TODAY())>=EOMONTH(MIN(IF($E10="",TODAY(),$E10),TODAY()),0),1,0)),MAX(0,INT((MIN(IF($E10="",TODAY(),$E10),TODAY())-($D10+MOD(SISTEM!$F$8-WEEKDAY($D10,2),7)))/7)+1))) | J10: =IF(OR($C10="",$D10="",$G10="",$F10=""),0,$G10*IF($F10="Aylık",MAX(0,(YEAR(MIN(IF($E10="",TODAY()-8,$E10),TODAY()-8))-YEAR($D10))*12+MONTH(MIN(IF($E10="",TODAY()-8,$E10),TODAY()-8))-MONTH($D10)+IF(MIN(IF($E10="",TODAY()-8,$E10),TODAY()-8)>=EOMONTH(MIN(IF($E10="",TODAY()-8,$E10),TODAY()-8),0),1,0)),MAX(0,INT((MIN(IF($E10="",TODAY()-8,$E10),TODAY()-8)-($D10+MOD(SISTEM!$F$8-WEEKDAY($D10,2),7)))/7)+1))) | K10: =IF(OR($C10="",$D10="",$G10="",$F10=""),0,$G10*IF($F10="Aylık",MAX(0,(YEAR(MIN(IF($E10="",TODAY()-15,$E10),TODAY()-15))-YEAR($D10))*12+MONTH(MIN(IF($E10="",TODAY()-15,$E10),TODAY()-15))-MONTH($D10)+IF(MIN(IF($E10="",TODAY()-15,$E10),TODAY()-15)>=EOMONTH(MIN(IF($E10="",TODAY()-15,$E10),TODAY()-15),0),1,0)),MAX(0,INT((MIN(IF($E10="",TODAY()-15,$E10),TODAY()-15)-($D10+MOD(SISTEM!$F$8-WEEKDAY($D10,2),7)))/7)+1))) | L10: =IF(OR($C10="",$D10="",$G10="",$F10=""),0,$G10*IF($F10="Aylık",MAX(0,(YEAR(MIN(IF($E10="",TODAY()-29,$E10),TODAY()-29))-YEAR($D10))*12+MONTH(MIN(IF($E10="",TODAY()-29,$E10),TODAY()-29))-MONTH($D10)+IF(MIN(IF($E10="",TODAY()-29,$E10),TODAY()-29)>=EOMONTH(MIN(IF($E10="",TODAY()-29,$E10),TODAY()-29),0),1,0)),MAX(0,INT((MIN(IF($E10="",TODAY()-29,$E10),TODAY()-29)-($D10+MOD(SISTEM!$F$8-WEEKDAY($D10,2),7)))/7)+1))) | M10: =IF($G10>0,$I10/$G10,0) | N10: =IF($C10="","",IF($B10="TANIMSIZ MÜŞTERİ","TANIMSIZ MÜŞTERİ",IF($F10="","MODEL SEÇİN",IF(OR($D10="",$G10<=0),"EKSİK",IF(AND($E10<>"",$E10<$D10),"TARİH HATASI",IF($H10="Pasif","KAPALI DÖNEM","UYGUN")))))) | O10: =IF(OR($C10="",$D10="",$F10=""),"",IF($F10="Aylık",EOMONTH($D10,0),($D10+MOD(SISTEM!$F$8-WEEKDAY($D10,2),7)))) | P10: Mevcut dosyadan aktarıldı | S10: =IF($B10="","",$B10&"|"&COUNTIFS($B$7:$B10,$B10))
B11: =IF($C11="","",IFERROR(INDEX(MUSTERILER!$B$7:$B$106,MATCH($C11,MUSTERILER!$C$7:$C$106,0)),IFERROR(INDEX(MUSTERILER!$B$7:$B$106,MATCH($C11,MUSTERILER!$B$7:$B$106,0)),IFERROR(INDEX(MUSTERILER!$B$7:$B$106,MATCH($C11&"*",MUSTERILER!$C$7:$C$106,0)),"TANIMSIZ MÜŞTERİ")))) | C11: ZÜMRÜT GRUP LTD.ŞTİ. | D11: 46023 | F11: Haftalık | G11: 1750 | H11: Aktif | I11: =IF(OR($C11="",$D11="",$G11="",$F11=""),0,$G11*IF($F11="Aylık",MAX(0,(YEAR(MIN(IF($E11="",TODAY(),$E11),TODAY()))-YEAR($D11))*12+MONTH(MIN(IF($E11="",TODAY(),$E11),TODAY()))-MONTH($D11)+IF(MIN(IF($E11="",TODAY(),$E11),TODAY())>=EOMONTH(MIN(IF($E11="",TODAY(),$E11),TODAY()),0),1,0)),MAX(0,INT((MIN(IF($E11="",TODAY(),$E11),TODAY())-($D11+MOD(SISTEM!$F$8-WEEKDAY($D11,2),7)))/7)+1))) | J11: =IF(OR($C11="",$D11="",$G11="",$F11=""),0,$G11*IF($F11="Aylık",MAX(0,(YEAR(MIN(IF($E11="",TODAY()-8,$E11),TODAY()-8))-YEAR($D11))*12+MONTH(MIN(IF($E11="",TODAY()-8,$E11),TODAY()-8))-MONTH($D11)+IF(MIN(IF($E11="",TODAY()-8,$E11),TODAY()-8)>=EOMONTH(MIN(IF($E11="",TODAY()-8,$E11),TODAY()-8),0),1,0)),MAX(0,INT((MIN(IF($E11="",TODAY()-8,$E11),TODAY()-8)-($D11+MOD(SISTEM!$F$8-WEEKDAY($D11,2),7)))/7)+1))) | K11: =IF(OR($C11="",$D11="",$G11="",$F11=""),0,$G11*IF($F11="Aylık",MAX(0,(YEAR(MIN(IF($E11="",TODAY()-15,$E11),TODAY()-15))-YEAR($D11))*12+MONTH(MIN(IF($E11="",TODAY()-15,$E11),TODAY()-15))-MONTH($D11)+IF(MIN(IF($E11="",TODAY()-15,$E11),TODAY()-15)>=EOMONTH(MIN(IF($E11="",TODAY()-15,$E11),TODAY()-15),0),1,0)),MAX(0,INT((MIN(IF($E11="",TODAY()-15,$E11),TODAY()-15)-($D11+MOD(SISTEM!$F$8-WEEKDAY($D11,2),7)))/7)+1))) | L11: =IF(OR($C11="",$D11="",$G11="",$F11=""),0,$G11*IF($F11="Aylık",MAX(0,(YEAR(MIN(IF($E11="",TODAY()-29,$E11),TODAY()-29))-YEAR($D11))*12+MONTH(MIN(IF($E11="",TODAY()-29,$E11),TODAY()-29))-MONTH($D11)+IF(MIN(IF($E11="",TODAY()-29,$E11),TODAY()-29)>=EOMONTH(MIN(IF($E11="",TODAY()-29,$E11),TODAY()-29),0),1,0)),MAX(0,INT((MIN(IF($E11="",TODAY()-29,$E11),TODAY()-29)-($D11+MOD(SISTEM!$F$8-WEEKDAY($D11,2),7)))/7)+1))) | M11: =IF($G11>0,$I11/$G11,0) | N11: =IF($C11="","",IF($B11="TANIMSIZ MÜŞTERİ","TANIMSIZ MÜŞTERİ",IF($F11="","MODEL SEÇİN",IF(OR($D11="",$G11<=0),"EKSİK",IF(AND($E11<>"",$E11<$D11),"TARİH HATASI",IF($H11="Pasif","KAPALI DÖNEM","UYGUN")))))) | O11: =IF(OR($C11="",$D11="",$F11=""),"",IF($F11="Aylık",EOMONTH($D11,0),($D11+MOD(SISTEM!$F$8-WEEKDAY($D11,2),7)))) | P11: Mevcut dosyadan aktarıldı | S11: =IF($B11="","",$B11&"|"&COUNTIFS($B$7:$B11,$B11))
B12: =IF($C12="","",IFERROR(INDEX(MUSTERILER!$B$7:$B$106,MATCH($C12,MUSTERILER!$C$7:$C$106,0)),IFERROR(INDEX(MUSTERILER!$B$7:$B$106,MATCH($C12,MUSTERILER!$B$7:$B$106,0)),IFERROR(INDEX(MUSTERILER!$B$7:$B$106,MATCH($C12&"*",MUSTERILER!$C$7:$C$106,0)),"TANIMSIZ MÜŞTERİ")))) | C12: VOLKAN AÇIK | D12: 46023 | F12: Haftalık | G12: 1000 | H12: Aktif | I12: =IF(OR($C12="",$D12="",$G12="",$F12=""),0,$G12*IF($F12="Aylık",MAX(0,(YEAR(MIN(IF($E12="",TODAY(),$E12),TODAY()))-YEAR($D12))*12+MONTH(MIN(IF($E12="",TODAY(),$E12),TODAY()))-MONTH($D12)+IF(MIN(IF($E12="",TODAY(),$E12),TODAY())>=EOMONTH(MIN(IF($E12="",TODAY(),$E12),TODAY()),0),1,0)),MAX(0,INT((MIN(IF($E12="",TODAY(),$E12),TODAY())-($D12+MOD(SISTEM!$F$8-WEEKDAY($D12,2),7)))/7)+1))) | J12: =IF(OR($C12="",$D12="",$G12="",$F12=""),0,$G12*IF($F12="Aylık",MAX(0,(YEAR(MIN(IF($E12="",TODAY()-8,$E12),TODAY()-8))-YEAR($D12))*12+MONTH(MIN(IF($E12="",TODAY()-8,$E12),TODAY()-8))-MONTH($D12)+IF(MIN(IF($E12="",TODAY()-8,$E12),TODAY()-8)>=EOMONTH(MIN(IF($E12="",TODAY()-8,$E12),TODAY()-8),0),1,0)),MAX(0,INT((MIN(IF($E12="",TODAY()-8,$E12),TODAY()-8)-($D12+MOD(SISTEM!$F$8-WEEKDAY($D12,2),7)))/7)+1))) | K12: =IF(OR($C12="",$D12="",$G12="",$F12=""),0,$G12*IF($F12="Aylık",MAX(0,(YEAR(MIN(IF($E12="",TODAY()-15,$E12),TODAY()-15))-YEAR($D12))*12+MONTH(MIN(IF($E12="",TODAY()-15,$E12),TODAY()-15))-MONTH($D12)+IF(MIN(IF($E12="",TODAY()-15,$E12),TODAY()-15)>=EOMONTH(MIN(IF($E12="",TODAY()-15,$E12),TODAY()-15),0),1,0)),MAX(0,INT((MIN(IF($E12="",TODAY()-15,$E12),TODAY()-15)-($D12+MOD(SISTEM!$F$8-WEEKDAY($D12,2),7)))/7)+1))) | L12: =IF(OR($C12="",$D12="",$G12="",$F12=""),0,$G12*IF($F12="Aylık",MAX(0,(YEAR(MIN(IF($E12="",TODAY()-29,$E12),TODAY()-29))-YEAR($D12))*12+MONTH(MIN(IF($E12="",TODAY()-29,$E12),TODAY()-29))-MONTH($D12)+IF(MIN(IF($E12="",TODAY()-29,$E12),TODAY()-29)>=EOMONTH(MIN(IF($E12="",TODAY()-29,$E12),TODAY()-29),0),1,0)),MAX(0,INT((MIN(IF($E12="",TODAY()-29,$E12),TODAY()-29)-($D12+MOD(SISTEM!$F$8-WEEKDAY($D12,2),7)))/7)+1))) | M12: =IF($G12>0,$I12/$G12,0) | N12: =IF($C12="","",IF($B12="TANIMSIZ MÜŞTERİ","TANIMSIZ MÜŞTERİ",IF($F12="","MODEL SEÇİN",IF(OR($D12="",$G12<=0),"EKSİK",IF(AND($E12<>"",$E12<$D12),"TARİH HATASI",IF($H12="Pasif","KAPALI DÖNEM","UYGUN")))))) | O12: =IF(OR($C12="",$D12="",$F12=""),"",IF($F12="Aylık",EOMONTH($D12,0),($D12+MOD(SISTEM!$F$8-WEEKDAY($D12,2),7)))) | P12: Mevcut dosyadan aktarıldı | S12: =IF($B12="","",$B12&"|"&COUNTIFS($B$7:$B12,$B12))
B13: =IF($C13="","",IFERROR(INDEX(MUSTERILER!$B$7:$B$106,MATCH($C13,MUSTERILER!$C$7:$C$106,0)),IFERROR(INDEX(MUSTERILER!$B$7:$B$106,MATCH($C13,MUSTERILER!$B$7:$B$106,0)),IFERROR(INDEX(MUSTERILER!$B$7:$B$106,MATCH($C13&"*",MUSTERILER!$C$7:$C$106,0)),"TANIMSIZ MÜŞTERİ")))) | C13: MONAMOUR LTD.ŞTİ. | D13: 46023 | F13: Haftalık | G13: 3500 | H13: Aktif | I13: =IF(OR($C13="",$D13="",$G13="",$F13=""),0,$G13*IF($F13="Aylık",MAX(0,(YEAR(MIN(IF($E13="",TODAY(),$E13),TODAY()))-YEAR($D13))*12+MONTH(MIN(IF($E13="",TODAY(),$E13),TODAY()))-MONTH($D13)+IF(MIN(IF($E13="",TODAY(),$E13),TODAY())>=EOMONTH(MIN(IF($E13="",TODAY(),$E13),TODAY()),0),1,0)),MAX(0,INT((MIN(IF($E13="",TODAY(),$E13),TODAY())-($D13+MOD(SISTEM!$F$8-WEEKDAY($D13,2),7)))/7)+1))) | J13: =IF(OR($C13="",$D13="",$G13="",$F13=""),0,$G13*IF($F13="Aylık",MAX(0,(YEAR(MIN(IF($E13="",TODAY()-8,$E13),TODAY()-8))-YEAR($D13))*12+MONTH(MIN(IF($E13="",TODAY()-8,$E13),TODAY()-8))-MONTH($D13)+IF(MIN(IF($E13="",TODAY()-8,$E13),TODAY()-8)>=EOMONTH(MIN(IF($E13="",TODAY()-8,$E13),TODAY()-8),0),1,0)),MAX(0,INT((MIN(IF($E13="",TODAY()-8,$E13),TODAY()-8)-($D13+MOD(SISTEM!$F$8-WEEKDAY($D13,2),7)))/7)+1))) | K13: =IF(OR($C13="",$D13="",$G13="",$F13=""),0,$G13*IF($F13="Aylık",MAX(0,(YEAR(MIN(IF($E13="",TODAY()-15,$E13),TODAY()-15))-YEAR($D13))*12+MONTH(MIN(IF($E13="",TODAY()-15,$E13),TODAY()-15))-MONTH($D13)+IF(MIN(IF($E13="",TODAY()-15,$E13),TODAY()-15)>=EOMONTH(MIN(IF($E13="",TODAY()-15,$E13),TODAY()-15),0),1,0)),MAX(0,INT((MIN(IF($E13="",TODAY()-15,$E13),TODAY()-15)-($D13+MOD(SISTEM!$F$8-WEEKDAY($D13,2),7)))/7)+1))) | L13: =IF(OR($C13="",$D13="",$G13="",$F13=""),0,$G13*IF($F13="Aylık",MAX(0,(YEAR(MIN(IF($E13="",TODAY()-29,$E13),TODAY()-29))-YEAR($D13))*12+MONTH(MIN(IF($E13="",TODAY()-29,$E13),TODAY()-29))-MONTH($D13)+IF(MIN(IF($E13="",TODAY()-29,$E13),TODAY()-29)>=EOMONTH(MIN(IF($E13="",TODAY()-29,$E13),TODAY()-29),0),1,0)),MAX(0,INT((MIN(IF($E13="",TODAY()-29,$E13),TODAY()-29)-($D13+MOD(SISTEM!$F$8-WEEKDAY($D13,2),7)))/7)+1))) | M13: =IF($G13>0,$I13/$G13,0) | N13: =IF($C13="","",IF($B13="TANIMSIZ MÜŞTERİ","TANIMSIZ MÜŞTERİ",IF($F13="","MODEL SEÇİN",IF(OR($D13="",$G13<=0),"EKSİK",IF(AND($E13<>"",$E13<$D13),"TARİH HATASI",IF($H13="Pasif","KAPALI DÖNEM","UYGUN")))))) | O13: =IF(OR($C13="",$D13="",$F13=""),"",IF($F13="Aylık",EOMONTH($D13,0),($D13+MOD(SISTEM!$F$8-WEEKDAY($D13,2),7)))) | P13: Mevcut dosyadan aktarıldı | S13: =IF($B13="","",$B13&"|"&COUNTIFS($B$7:$B13,$B13))
B14: =IF($C14="","",IFERROR(INDEX(MUSTERILER!$B$7:$B$106,MATCH($C14,MUSTERILER!$C$7:$C$106,0)),IFERROR(INDEX(MUSTERILER!$B$7:$B$106,MATCH($C14,MUSTERILER!$B$7:$B$106,0)),IFERROR(INDEX(MUSTERILER!$B$7:$B$106,MATCH($C14&"*",MUSTERILER!$C$7:$C$106,0)),"TANIMSIZ MÜŞTERİ")))) | C14: KÖŞK YÜKSELEN LTD.ŞTİ. | D14: 46023 | F14: Haftalık | G14: 3500 | H14: Aktif | I14: =IF(OR($C14="",$D14="",$G14="",$F14=""),0,$G14*IF($F14="Aylık",MAX(0,(YEAR(MIN(IF($E14="",TODAY(),$E14),TODAY()))-YEAR($D14))*12+MONTH(MIN(IF($E14="",TODAY(),$E14),TODAY()))-MONTH($D14)+IF(MIN(IF($E14="",TODAY(),$E14),TODAY())>=EOMONTH(MIN(IF($E14="",TODAY(),$E14),TODAY()),0),1,0)),MAX(0,INT((MIN(IF($E14="",TODAY(),$E14),TODAY())-($D14+MOD(SISTEM!$F$8-WEEKDAY($D14,2),7)))/7)+1))) | J14: =IF(OR($C14="",$D14="",$G14="",$F14=""),0,$G14*IF($F14="Aylık",MAX(0,(YEAR(MIN(IF($E14="",TODAY()-8,$E14),TODAY()-8))-YEAR($D14))*12+MONTH(MIN(IF($E14="",TODAY()-8,$E14),TODAY()-8))-MONTH($D14)+IF(MIN(IF($E14="",TODAY()-8,$E14),TODAY()-8)>=EOMONTH(MIN(IF($E14="",TODAY()-8,$E14),TODAY()-8),0),1,0)),MAX(0,INT((MIN(IF($E14="",TODAY()-8,$E14),TODAY()-8)-($D14+MOD(SISTEM!$F$8-WEEKDAY($D14,2),7)))/7)+1))) | K14: =IF(OR($C14="",$D14="",$G14="",$F14=""),0,$G14*IF($F14="Aylık",MAX(0,(YEAR(MIN(IF($E14="",TODAY()-15,$E14),TODAY()-15))-YEAR($D14))*12+MONTH(MIN(IF($E14="",TODAY()-15,$E14),TODAY()-15))-MONTH($D14)+IF(MIN(IF($E14="",TODAY()-15,$E14),TODAY()-15)>=EOMONTH(MIN(IF($E14="",TODAY()-15,$E14),TODAY()-15),0),1,0)),MAX(0,INT((MIN(IF($E14="",TODAY()-15,$E14),TODAY()-15)-($D14+MOD(SISTEM!$F$8-WEEKDAY($D14,2),7)))/7)+1))) | L14: =IF(OR($C14="",$D14="",$G14="",$F14=""),0,$G14*IF($F14="Aylık",MAX(0,(YEAR(MIN(IF($E14="",TODAY()-29,$E14),TODAY()-29))-YEAR($D14))*12+MONTH(MIN(IF($E14="",TODAY()-29,$E14),TODAY()-29))-MONTH($D14)+IF(MIN(IF($E14="",TODAY()-29,$E14),TODAY()-29)>=EOMONTH(MIN(IF($E14="",TODAY()-29,$E14),TODAY()-29),0),1,0)),MAX(0,INT((MIN(IF($E14="",TODAY()-29,$E14),TODAY()-29)-($D14+MOD(SISTEM!$F$8-WEEKDAY($D14,2),7)))/7)+1))) | M14: =IF($G14>0,$I14/$G14,0) | N14: =IF($C14="","",IF($B14="TANIMSIZ MÜŞTERİ","TANIMSIZ MÜŞTERİ",IF($F14="","MODEL SEÇİN",IF(OR($D14="",$G14<=0),"EKSİK",IF(AND($E14<>"",$E14<$D14),"TARİH HATASI",IF($H14="Pasif","KAPALI DÖNEM","UYGUN")))))) | O14: =IF(OR($C14="",$D14="",$F14=""),"",IF($F14="Aylık",EOMONTH($D14,0),($D14+MOD(SISTEM!$F$8-WEEKDAY($D14,2),7)))) | P14: Mevcut dosyadan aktarıldı | S14: =IF($B14="","",$B14&"|"&COUNTIFS($B$7:$B14,$B14))
B15: =IF($C15="","",IFERROR(INDEX(MUSTERILER!$B$7:$B$106,MATCH($C15,MUSTERILER!$C$7:$C$106,0)),IFERROR(INDEX(MUSTERILER!$B$7:$B$106,MATCH($C15,MUSTERILER!$B$7:$B$106,0)),IFERROR(INDEX(MUSTERILER!$B$7:$B$106,MATCH($C15&"*",MUSTERILER!$C$7:$C$106,0)),"TANIMSIZ MÜŞTERİ")))) | C15: PAKYILDIZ LTD.ŞTİ. | D15: 46023 | F15: Haftalık | G15: 4000 | H15: Aktif | I15: =IF(OR($C15="",$D15="",$G15="",$F15=""),0,$G15*IF($F15="Aylık",MAX(0,(YEAR(MIN(IF($E15="",TODAY(),$E15),TODAY()))-YEAR($D15))*12+MONTH(MIN(IF($E15="",TODAY(),$E15),TODAY()))-MONTH($D15)+IF(MIN(IF($E15="",TODAY(),$E15),TODAY())>=EOMONTH(MIN(IF($E15="",TODAY(),$E15),TODAY()),0),1,0)),MAX(0,INT((MIN(IF($E15="",TODAY(),$E15),TODAY())-($D15+MOD(SISTEM!$F$8-WEEKDAY($D15,2),7)))/7)+1))) | J15: =IF(OR($C15="",$D15="",$G15="",$F15=""),0,$G15*IF($F15="Aylık",MAX(0,(YEAR(MIN(IF($E15="",TODAY()-8,$E15),TODAY()-8))-YEAR($D15))*12+MONTH(MIN(IF($E15="",TODAY()-8,$E15),TODAY()-8))-MONTH($D15)+IF(MIN(IF($E15="",TODAY()-8,$E15),TODAY()-8)>=EOMONTH(MIN(IF($E15="",TODAY()-8,$E15),TODAY()-8),0),1,0)),MAX(0,INT((MIN(IF($E15="",TODAY()-8,$E15),TODAY()-8)-($D15+MOD(SISTEM!$F$8-WEEKDAY($D15,2),7)))/7)+1))) | K15: =IF(OR($C15="",$D15="",$G15="",$F15=""),0,$G15*IF($F15="Aylık",MAX(0,(YEAR(MIN(IF($E15="",TODAY()-15,$E15),TODAY()-15))-YEAR($D15))*12+MONTH(MIN(IF($E15="",TODAY()-15,$E15),TODAY()-15))-MONTH($D15)+IF(MIN(IF($E15="",TODAY()-15,$E15),TODAY()-15)>=EOMONTH(MIN(IF($E15="",TODAY()-15,$E15),TODAY()-15),0),1,0)),MAX(0,INT((MIN(IF($E15="",TODAY()-15,$E15),TODAY()-15)-($D15+MOD(SISTEM!$F$8-WEEKDAY($D15,2),7)))/7)+1))) | L15: =IF(OR($C15="",$D15="",$G15="",$F15=""),0,$G15*IF($F15="Aylık",MAX(0,(YEAR(MIN(IF($E15="",TODAY()-29,$E15),TODAY()-29))-YEAR($D15))*12+MONTH(MIN(IF($E15="",TODAY()-29,$E15),TODAY()-29))-MONTH($D15)+IF(MIN(IF($E15="",TODAY()-29,$E15),TODAY()-29)>=EOMONTH(MIN(IF($E15="",TODAY()-29,$E15),TODAY()-29),0),1,0)),MAX(0,INT((MIN(IF($E15="",TODAY()-29,$E15),TODAY()-29)-($D15+MOD(SISTEM!$F$8-WEEKDAY($D15,2),7)))/7)+1))) | M15: =IF($G15>0,$I15/$G15,0) | N15: =IF($C15="","",IF($B15="TANIMSIZ MÜŞTERİ","TANIMSIZ MÜŞTERİ",IF($F15="","MODEL SEÇİN",IF(OR($D15="",$G15<=0),"EKSİK",IF(AND($E15<>"",$E15<$D15),"TARİH HATASI",IF($H15="Pasif","KAPALI DÖNEM","UYGUN")))))) | O15: =IF(OR($C15="",$D15="",$F15=""),"",IF($F15="Aylık",EOMONTH($D15,0),($D15+MOD(SISTEM!$F$8-WEEKDAY($D15,2),7)))) | P15: Tahakkuk modeli ve ücret girilmeli | S15: =IF($B15="","",$B15&"|"&COUNTIFS($B$7:$B15,$B15))
B16: =IF($C16="","",IFERROR(INDEX(MUSTERILER!$B$7:$B$106,MATCH($C16,MUSTERILER!$C$7:$C$106,0)),IFERROR(INDEX(MUSTERILER!$B$7:$B$106,MATCH($C16,MUSTERILER!$B$7:$B$106,0)),IFERROR(INDEX(MUSTERILER!$B$7:$B$106,MATCH($C16&"*",MUSTERILER!$C$7:$C$106,0)),"TANIMSIZ MÜŞTERİ")))) | C16: ÖZFİDANLAR LTD.ŞTİ. | D16: 46023 | F16: Haftalık | G16: 4000 | H16: Aktif | I16: =IF(OR($C16="",$D16="",$G16="",$F16=""),0,$G16*IF($F16="Aylık",MAX(0,(YEAR(MIN(IF($E16="",TODAY(),$E16),TODAY()))-YEAR($D16))*12+MONTH(MIN(IF($E16="",TODAY(),$E16),TODAY()))-MONTH($D16)+IF(MIN(IF($E16="",TODAY(),$E16),TODAY())>=EOMONTH(MIN(IF($E16="",TODAY(),$E16),TODAY()),0),1,0)),MAX(0,INT((MIN(IF($E16="",TODAY(),$E16),TODAY())-($D16+MOD(SISTEM!$F$8-WEEKDAY($D16,2),7)))/7)+1))) | J16: =IF(OR($C16="",$D16="",$G16="",$F16=""),0,$G16*IF($F16="Aylık",MAX(0,(YEAR(MIN(IF($E16="",TODAY()-8,$E16),TODAY()-8))-YEAR($D16))*12+MONTH(MIN(IF($E16="",TODAY()-8,$E16),TODAY()-8))-MONTH($D16)+IF(MIN(IF($E16="",TODAY()-8,$E16),TODAY()-8)>=EOMONTH(MIN(IF($E16="",TODAY()-8,$E16),TODAY()-8),0),1,0)),MAX(0,INT((MIN(IF($E16="",TODAY()-8,$E16),TODAY()-8)-($D16+MOD(SISTEM!$F$8-WEEKDAY($D16,2),7)))/7)+1))) | K16: =IF(OR($C16="",$D16="",$G16="",$F16=""),0,$G16*IF($F16="Aylık",MAX(0,(YEAR(MIN(IF($E16="",TODAY()-15,$E16),TODAY()-15))-YEAR($D16))*12+MONTH(MIN(IF($E16="",TODAY()-15,$E16),TODAY()-15))-MONTH($D16)+IF(MIN(IF($E16="",TODAY()-15,$E16),TODAY()-15)>=EOMONTH(MIN(IF($E16="",TODAY()-15,$E16),TODAY()-15),0),1,0)),MAX(0,INT((MIN(IF($E16="",TODAY()-15,$E16),TODAY()-15)-($D16+MOD(SISTEM!$F$8-WEEKDAY($D16,2),7)))/7)+1))) | L16: =IF(OR($C16="",$D16="",$G16="",$F16=""),0,$G16*IF($F16="Aylık",MAX(0,(YEAR(MIN(IF($E16="",TODAY()-29,$E16),TODAY()-29))-YEAR($D16))*12+MONTH(MIN(IF($E16="",TODAY()-29,$E16),TODAY()-29))-MONTH($D16)+IF(MIN(IF($E16="",TODAY()-29,$E16),TODAY()-29)>=EOMONTH(MIN(IF($E16="",TODAY()-29,$E16),TODAY()-29),0),1,0)),MAX(0,INT((MIN(IF($E16="",TODAY()-29,$E16),TODAY()-29)-($D16+MOD(SISTEM!$F$8-WEEKDAY($D16,2),7)))/7)+1))) | M16: =IF($G16>0,$I16/$G16,0) | N16: =IF($C16="","",IF($B16="TANIMSIZ MÜŞTERİ","TANIMSIZ MÜŞTERİ",IF($F16="","MODEL SEÇİN",IF(OR($D16="",$G16<=0),"EKSİK",IF(AND($E16<>"",$E16<$D16),"TARİH HATASI",IF($H16="Pasif","KAPALI DÖNEM","UYGUN")))))) | O16: =IF(OR($C16="",$D16="",$F16=""),"",IF($F16="Aylık",EOMONTH($D16,0),($D16+MOD(SISTEM!$F$8-WEEKDAY($D16,2),7)))) | P16: Tahakkuk modeli ve ücret girilmeli | S16: =IF($B16="","",$B16&"|"&COUNTIFS($B$7:$B16,$B16))
B17: =IF($C17="","",IFERROR(INDEX(MUSTERILER!$B$7:$B$106,MATCH($C17,MUSTERILER!$C$7:$C$106,0)),IFERROR(INDEX(MUSTERILER!$B$7:$B$106,MATCH($C17,MUSTERILER!$B$7:$B$106,0)),IFERROR(INDEX(MUSTERILER!$B$7:$B$106,MATCH($C17&"*",MUSTERILER!$C$7:$C$106,0)),"TANIMSIZ MÜŞTERİ")))) | C17: EĞLENGÖR LTD.ŞTİ. | D17: 46023 | F17: Haftalık | G17: 4000 | H17: Aktif | I17: =IF(OR($C17="",$D17="",$G17="",$F17=""),0,$G17*IF($F17="Aylık",MAX(0,(YEAR(MIN(IF($E17="",TODAY(),$E17),TODAY()))-YEAR($D17))*12+MONTH(MIN(IF($E17="",TODAY(),$E17),TODAY()))-MONTH($D17)+IF(MIN(IF($E17="",TODAY(),$E17),TODAY())>=EOMONTH(MIN(IF($E17="",TODAY(),$E17),TODAY()),0),1,0)),MAX(0,INT((MIN(IF($E17="",TODAY(),$E17),TODAY())-($D17+MOD(SISTEM!$F$8-WEEKDAY($D17,2),7)))/7)+1))) | J17: =IF(OR($C17="",$D17="",$G17="",$F17=""),0,$G17*IF($F17="Aylık",MAX(0,(YEAR(MIN(IF($E17="",TODAY()-8,$E17),TODAY()-8))-YEAR($D17))*12+MONTH(MIN(IF($E17="",TODAY()-8,$E17),TODAY()-8))-MONTH($D17)+IF(MIN(IF($E17="",TODAY()-8,$E17),TODAY()-8)>=EOMONTH(MIN(IF($E17="",TODAY()-8,$E17),TODAY()-8),0),1,0)),MAX(0,INT((MIN(IF($E17="",TODAY()-8,$E17),TODAY()-8)-($D17+MOD(SISTEM!$F$8-WEEKDAY($D17,2),7)))/7)+1))) | K17: =IF(OR($C17="",$D17="",$G17="",$F17=""),0,$G17*IF($F17="Aylık",MAX(0,(YEAR(MIN(IF($E17="",TODAY()-15,$E17),TODAY()-15))-YEAR($D17))*12+MONTH(MIN(IF($E17="",TODAY()-15,$E17),TODAY()-15))-MONTH($D17)+IF(MIN(IF($E17="",TODAY()-15,$E17),TODAY()-15)>=EOMONTH(MIN(IF($E17="",TODAY()-15,$E17),TODAY()-15),0),1,0)),MAX(0,INT((MIN(IF($E17="",TODAY()-15,$E17),TODAY()-15)-($D17+MOD(SISTEM!$F$8-WEEKDAY($D17,2),7)))/7)+1))) | L17: =IF(OR($C17="",$D17="",$G17="",$F17=""),0,$G17*IF($F17="Aylık",MAX(0,(YEAR(MIN(IF($E17="",TODAY()-29,$E17),TODAY()-29))-YEAR($D17))*12+MONTH(MIN(IF($E17="",TODAY()-29,$E17),TODAY()-29))-MONTH($D17)+IF(MIN(IF($E17="",TODAY()-29,$E17),TODAY()-29)>=EOMONTH(MIN(IF($E17="",TODAY()-29,$E17),TODAY()-29),0),1,0)),MAX(0,INT((MIN(IF($E17="",TODAY()-29,$E17),TODAY()-29)-($D17+MOD(SISTEM!$F$8-WEEKDAY($D17,2),7)))/7)+1))) | M17: =IF($G17>0,$I17/$G17,0) | N17: =IF($C17="","",IF($B17="TANIMSIZ MÜŞTERİ","TANIMSIZ MÜŞTERİ",IF($F17="","MODEL SEÇİN",IF(OR($D17="",$G17<=0),"EKSİK",IF(AND($E17<>"",$E17<$D17),"TARİH HATASI",IF($H17="Pasif","KAPALI DÖNEM","UYGUN")))))) | O17: =IF(OR($C17="",$D17="",$F17=""),"",IF($F17="Aylık",EOMONTH($D17,0),($D17+MOD(SISTEM!$F$8-WEEKDAY($D17,2),7)))) | P17: Tahakkuk modeli ve ücret girilmeli | S17: =IF($B17="","",$B17&"|"&COUNTIFS($B$7:$B17,$B17))
B18: =IF($C18="","",IFERROR(INDEX(MUSTERILER!$B$7:$B$106,MATCH($C18,MUSTERILER!$C$7:$C$106,0)),IFERROR(INDEX(MUSTERILER!$B$7:$B$106,MATCH($C18,MUSTERILER!$B$7:$B$106,0)),IFERROR(INDEX(MUSTERILER!$B$7:$B$106,MATCH($C18&"*",MUSTERILER!$C$7:$C$106,0)),"TANIMSIZ MÜŞTERİ")))) | C18: İLDEŞ LTD.ŞTİ. | D18: 46023 | F18: Haftalık | G18: 4000 | H18: Aktif | I18: =IF(OR($C18="",$D18="",$G18="",$F18=""),0,$G18*IF($F18="Aylık",MAX(0,(YEAR(MIN(IF($E18="",TODAY(),$E18),TODAY()))-YEAR($D18))*12+MONTH(MIN(IF($E18="",TODAY(),$E18),TODAY()))-MONTH($D18)+IF(MIN(IF($E18="",TODAY(),$E18),TODAY())>=EOMONTH(MIN(IF($E18="",TODAY(),$E18),TODAY()),0),1,0)),MAX(0,INT((MIN(IF($E18="",TODAY(),$E18),TODAY())-($D18+MOD(SISTEM!$F$8-WEEKDAY($D18,2),7)))/7)+1))) | J18: =IF(OR($C18="",$D18="",$G18="",$F18=""),0,$G18*IF($F18="Aylık",MAX(0,(YEAR(MIN(IF($E18="",TODAY()-8,$E18),TODAY()-8))-YEAR($D18))*12+MONTH(MIN(IF($E18="",TODAY()-8,$E18),TODAY()-8))-MONTH($D18)+IF(MIN(IF($E18="",TODAY()-8,$E18),TODAY()-8)>=EOMONTH(MIN(IF($E18="",TODAY()-8,$E18),TODAY()-8),0),1,0)),MAX(0,INT((MIN(IF($E18="",TODAY()-8,$E18),TODAY()-8)-($D18+MOD(SISTEM!$F$8-WEEKDAY($D18,2),7)))/7)+1))) | K18: =IF(OR($C18="",$D18="",$G18="",$F18=""),0,$G18*IF($F18="Aylık",MAX(0,(YEAR(MIN(IF($E18="",TODAY()-15,$E18),TODAY()-15))-YEAR($D18))*12+MONTH(MIN(IF($E18="",TODAY()-15,$E18),TODAY()-15))-MONTH($D18)+IF(MIN(IF($E18="",TODAY()-15,$E18),TODAY()-15)>=EOMONTH(MIN(IF($E18="",TODAY()-15,$E18),TODAY()-15),0),1,0)),MAX(0,INT((MIN(IF($E18="",TODAY()-15,$E18),TODAY()-15)-($D18+MOD(SISTEM!$F$8-WEEKDAY($D18,2),7)))/7)+1))) | L18: =IF(OR($C18="",$D18="",$G18="",$F18=""),0,$G18*IF($F18="Aylık",MAX(0,(YEAR(MIN(IF($E18="",TODAY()-29,$E18),TODAY()-29))-YEAR($D18))*12+MONTH(MIN(IF($E18="",TODAY()-29,$E18),TODAY()-29))-MONTH($D18)+IF(MIN(IF($E18="",TODAY()-29,$E18),TODAY()-29)>=EOMONTH(MIN(IF($E18="",TODAY()-29,$E18),TODAY()-29),0),1,0)),MAX(0,INT((MIN(IF($E18="",TODAY()-29,$E18),TODAY()-29)-($D18+MOD(SISTEM!$F$8-WEEKDAY($D18,2),7)))/7)+1))) | M18: =IF($G18>0,$I18/$G18,0) | N18: =IF($C18="","",IF($B18="TANIMSIZ MÜŞTERİ","TANIMSIZ MÜŞTERİ",IF($F18="","MODEL SEÇİN",IF(OR($D18="",$G18<=0),"EKSİK",IF(AND($E18<>"",$E18<$D18),"TARİH HATASI",IF($H18="Pasif","KAPALI DÖNEM","UYGUN")))))) | O18: =IF(OR($C18="",$D18="",$F18=""),"",IF($F18="Aylık",EOMONTH($D18,0),($D18+MOD(SISTEM!$F$8-WEEKDAY($D18,2),7)))) | P18: Tahakkuk modeli ve ücret girilmeli | S18: =IF($B18="","",$B18&"|"&COUNTIFS($B$7:$B18,$B18))
... B27: =IF($C27="","",IFERROR(INDEX(MUSTERILER!$B$7:$B$106,MATCH($C27,MUSTERILER!$C$7:$C$106,0)),IFERROR(INDEX(MUSTERILER!$B$7:$B$106,MATCH($C27,MUSTERILER!$B$7:$B$106,0)),IFERROR(INDEX(MUSTERILER!$B$7:$B$106,MATCH($C27&"*",MUSTERILER!$C$7:$C$106,0)),"TANIMSIZ MÜŞTERİ")))) | C27: ARON TOPTAN LTD.ŞTİ. | D27: 46023 | F27: Aylık | G27: 10000 | H27: Aktif | I27: =IF(OR($C27="",$D27="",$G27="",$F27=""),0,$G27*IF($F27="Aylık",MAX(0,(YEAR(MIN(IF($E27="",TODAY(),$E27),TODAY()))-YEAR($D27))*12+MONTH(MIN(IF($E27="",TODAY(),$E27),TODAY()))-MONTH($D27)+IF(MIN(IF($E27="",TODAY(),$E27),TODAY())>=EOMONTH(MIN(IF($E27="",TODAY(),$E27),TODAY()),0),1,0)),MAX(0,INT((MIN(IF($E27="",TODAY(),$E27),TODAY())-($D27+MOD(SISTEM!$F$8-WEEKDAY($D27,2),7)))/7)+1))) | J27: =IF(OR($C27="",$D27="",$G27="",$F27=""),0,$G27*IF($F27="Aylık",MAX(0,(YEAR(MIN(IF($E27="",TODAY()-8,$E27),TODAY()-8))-YEAR($D27))*12+MONTH(MIN(IF($E27="",TODAY()-8,$E27),TODAY()-8))-MONTH($D27)+IF(MIN(IF($E27="",TODAY()-8,$E27),TODAY()-8)>=EOMONTH(MIN(IF($E27="",TODAY()-8,$E27),TODAY()-8),0),1,0)),MAX(0,INT((MIN(IF($E27="",TODAY()-8,$E27),TODAY()-8)-($D27+MOD(SISTEM!$F$8-WEEKDAY($D27,2),7)))/7)+1))) | K27: =IF(OR($C27="",$D27="",$G27="",$F27=""),0,$G27*IF($F27="Aylık",MAX(0,(YEAR(MIN(IF($E27="",TODAY()-15,$E27),TODAY()-15))-YEAR($D27))*12+MONTH(MIN(IF($E27="",TODAY()-15,$E27),TODAY()-15))-MONTH($D27)+IF(MIN(IF($E27="",TODAY()-15,$E27),TODAY()-15)>=EOMONTH(MIN(IF($E27="",TODAY()-15,$E27),TODAY()-15),0),1,0)),MAX(0,INT((MIN(IF($E27="",TODAY()-15,$E27),TODAY()-15)-($D27+MOD(SISTEM!$F$8-WEEKDAY($D27,2),7)))/7)+1))) | L27: =IF(OR($C27="",$D27="",$G27="",$F27=""),0,$G27*IF($F27="Aylık",MAX(0,(YEAR(MIN(IF($E27="",TODAY()-29,$E27),TODAY()-29))-YEAR($D27))*12+MONTH(MIN(IF($E27="",TODAY()-29,$E27),TODAY()-29))-MONTH($D27)+IF(MIN(IF($E27="",TODAY()-29,$E27),TODAY()-29)>=EOMONTH(MIN(IF($E27="",TODAY()-29,$E27),TODAY()-29),0),1,0)),MAX(0,INT((MIN(IF($E27="",TODAY()-29,$E27),TODAY()-29)-($D27+MOD(SISTEM!$F$8-WEEKDAY($D27,2),7)))/7)+1))) | M27: =IF($G27>0,$I27/$G27,0) | N27: =IF($C27="","",IF($B27="TANIMSIZ MÜŞTERİ","TANIMSIZ MÜŞTERİ",IF($F27="","MODEL SEÇİN",IF(OR($D27="",$G27<=0),"EKSİK",IF(AND($E27<>"",$E27<$D27),"TARİH HATASI",IF($H27="Pasif","KAPALI DÖNEM","UYGUN")))))) | O27: =IF(OR($C27="",$D27="",$F27=""),"",IF($F27="Aylık",EOMONTH($D27,0),($D27+MOD(SISTEM!$F$8-WEEKDAY($D27,2),7)))) | P27: Tahakkuk modeli ve ücret girilmeli | S27: =IF($B27="","",$B27&"|"&COUNTIFS($B$7:$B27,$B27))
B28: =IF($C28="","",IFERROR(INDEX(MUSTERILER!$B$7:$B$106,MATCH($C28,MUSTERILER!$C$7:$C$106,0)),IFERROR(INDEX(MUSTERILER!$B$7:$B$106,MATCH($C28,MUSTERILER!$B$7:$B$106,0)),IFERROR(INDEX(MUSTERILER!$B$7:$B$106,MATCH($C28&"*",MUSTERILER!$C$7:$C$106,0)),"TANIMSIZ MÜŞTERİ")))) | C28: ADEM KARABENLİ | D28: 46023 | F28: Aylık | G28: 3000 | H28: Aktif | I28: =IF(OR($C28="",$D28="",$G28="",$F28=""),0,$G28*IF($F28="Aylık",MAX(0,(YEAR(MIN(IF($E28="",TODAY(),$E28),TODAY()))-YEAR($D28))*12+MONTH(MIN(IF($E28="",TODAY(),$E28),TODAY()))-MONTH($D28)+IF(MIN(IF($E28="",TODAY(),$E28),TODAY())>=EOMONTH(MIN(IF($E28="",TODAY(),$E28),TODAY()),0),1,0)),MAX(0,INT((MIN(IF($E28="",TODAY(),$E28),TODAY())-($D28+MOD(SISTEM!$F$8-WEEKDAY($D28,2),7)))/7)+1))) | J28: =IF(OR($C28="",$D28="",$G28="",$F28=""),0,$G28*IF($F28="Aylık",MAX(0,(YEAR(MIN(IF($E28="",TODAY()-8,$E28),TODAY()-8))-YEAR($D28))*12+MONTH(MIN(IF($E28="",TODAY()-8,$E28),TODAY()-8))-MONTH($D28)+IF(MIN(IF($E28="",TODAY()-8,$E28),TODAY()-8)>=EOMONTH(MIN(IF($E28="",TODAY()-8,$E28),TODAY()-8),0),1,0)),MAX(0,INT((MIN(IF($E28="",TODAY()-8,$E28),TODAY()-8)-($D28+MOD(SISTEM!$F$8-WEEKDAY($D28,2),7)))/7)+1))) | K28: =IF(OR($C28="",$D28="",$G28="",$F28=""),0,$G28*IF($F28="Aylık",MAX(0,(YEAR(MIN(IF($E28="",TODAY()-15,$E28),TODAY()-15))-YEAR($D28))*12+MONTH(MIN(IF($E28="",TODAY()-15,$E28),TODAY()-15))-MONTH($D28)+IF(MIN(IF($E28="",TODAY()-15,$E28),TODAY()-15)>=EOMONTH(MIN(IF($E28="",TODAY()-15,$E28),TODAY()-15),0),1,0)),MAX(0,INT((MIN(IF($E28="",TODAY()-15,$E28),TODAY()-15)-($D28+MOD(SISTEM!$F$8-WEEKDAY($D28,2),7)))/7)+1))) | L28: =IF(OR($C28="",$D28="",$G28="",$F28=""),0,$G28*IF($F28="Aylık",MAX(0,(YEAR(MIN(IF($E28="",TODAY()-29,$E28),TODAY()-29))-YEAR($D28))*12+MONTH(MIN(IF($E28="",TODAY()-29,$E28),TODAY()-29))-MONTH($D28)+IF(MIN(IF($E28="",TODAY()-29,$E28),TODAY()-29)>=EOMONTH(MIN(IF($E28="",TODAY()-29,$E28),TODAY()-29),0),1,0)),MAX(0,INT((MIN(IF($E28="",TODAY()-29,$E28),TODAY()-29)-($D28+MOD(SISTEM!$F$8-WEEKDAY($D28,2),7)))/7)+1))) | M28: =IF($G28>0,$I28/$G28,0) | N28: =IF($C28="","",IF($B28="TANIMSIZ MÜŞTERİ","TANIMSIZ MÜŞTERİ",IF($F28="","MODEL SEÇİN",IF(OR($D28="",$G28<=0),"EKSİK",IF(AND($E28<>"",$E28<$D28),"TARİH HATASI",IF($H28="Pasif","KAPALI DÖNEM","UYGUN")))))) | O28: =IF(OR($C28="",$D28="",$F28=""),"",IF($F28="Aylık",EOMONTH($D28,0),($D28+MOD(SISTEM!$F$8-WEEKDAY($D28,2),7)))) | S28: =IF($B28="","",$B28&"|"&COUNTIFS($B$7:$B28,$B28))
B29: =IF($C29="","",IFERROR(INDEX(MUSTERILER!$B$7:$B$106,MATCH($C29,MUSTERILER!$C$7:$C$106,0)),IFERROR(INDEX(MUSTERILER!$B$7:$B$106,MATCH($C29,MUSTERILER!$B$7:$B$106,0)),IFERROR(INDEX(MUSTERILER!$B$7:$B$106,MATCH($C29&"*",MUSTERILER!$C$7:$C$106,0)),"TANIMSIZ MÜŞTERİ")))) | C29: ALTINEL LTD.ŞTİ. | D29: 46266 | F29: Aylık | G29: 10000 | H29: Aktif | I29: =IF(OR($C29="",$D29="",$G29="",$F29=""),0,$G29*IF($F29="Aylık",MAX(0,(YEAR(MIN(IF($E29="",TODAY(),$E29),TODAY()))-YEAR($D29))*12+MONTH(MIN(IF($E29="",TODAY(),$E29),TODAY()))-MONTH($D29)+IF(MIN(IF($E29="",TODAY(),$E29),TODAY())>=EOMONTH(MIN(IF($E29="",TODAY(),$E29),TODAY()),0),1,0)),MAX(0,INT((MIN(IF($E29="",TODAY(),$E29),TODAY())-($D29+MOD(SISTEM!$F$8-WEEKDAY($D29,2),7)))/7)+1))) | J29: =IF(OR($C29="",$D29="",$G29="",$F29=""),0,$G29*IF($F29="Aylık",MAX(0,(YEAR(MIN(IF($E29="",TODAY()-8,$E29),TODAY()-8))-YEAR($D29))*12+MONTH(MIN(IF($E29="",TODAY()-8,$E29),TODAY()-8))-MONTH($D29)+IF(MIN(IF($E29="",TODAY()-8,$E29),TODAY()-8)>=EOMONTH(MIN(IF($E29="",TODAY()-8,$E29),TODAY()-8),0),1,0)),MAX(0,INT((MIN(IF($E29="",TODAY()-8,$E29),TODAY()-8)-($D29+MOD(SISTEM!$F$8-WEEKDAY($D29,2),7)))/7)+1))) | K29: =IF(OR($C29="",$D29="",$G29="",$F29=""),0,$G29*IF($F29="Aylık",MAX(0,(YEAR(MIN(IF($E29="",TODAY()-15,$E29),TODAY()-15))-YEAR($D29))*12+MONTH(MIN(IF($E29="",TODAY()-15,$E29),TODAY()-15))-MONTH($D29)+IF(MIN(IF($E29="",TODAY()-15,$E29),TODAY()-15)>=EOMONTH(MIN(IF($E29="",TODAY()-15,$E29),TODAY()-15),0),1,0)),MAX(0,INT((MIN(IF($E29="",TODAY()-15,$E29),TODAY()-15)-($D29+MOD(SISTEM!$F$8-WEEKDAY($D29,2),7)))/7)+1))) | L29: =IF(OR($C29="",$D29="",$G29="",$F29=""),0,$G29*IF($F29="Aylık",MAX(0,(YEAR(MIN(IF($E29="",TODAY()-29,$E29),TODAY()-29))-YEAR($D29))*12+MONTH(MIN(IF($E29="",TODAY()-29,$E29),TODAY()-29))-MONTH($D29)+IF(MIN(IF($E29="",TODAY()-29,$E29),TODAY()-29)>=EOMONTH(MIN(IF($E29="",TODAY()-29,$E29),TODAY()-29),0),1,0)),MAX(0,INT((MIN(IF($E29="",TODAY()-29,$E29),TODAY()-29)-($D29+MOD(SISTEM!$F$8-WEEKDAY($D29,2),7)))/7)+1))) | M29: =IF($G29>0,$I29/$G29,0) | N29: =IF($C29="","",IF($B29="TANIMSIZ MÜŞTERİ","TANIMSIZ MÜŞTERİ",IF($F29="","MODEL SEÇİN",IF(OR($D29="",$G29<=0),"EKSİK",IF(AND($E29<>"",$E29<$D29),"TARİH HATASI",IF($H29="Pasif","KAPALI DÖNEM","UYGUN")))))) | O29: =IF(OR($C29="",$D29="",$F29=""),"",IF($F29="Aylık",EOMONTH($D29,0),($D29+MOD(SISTEM!$F$8-WEEKDAY($D29,2),7)))) | S29: =IF($B29="","",$B29&"|"&COUNTIFS($B$7:$B29,$B29))
